Workbook

Sheet Petunjuk
B1: Lembar Coding Pilot: Codebook Analisis Isi Krippendorff (Versi 1.0)
B2: Sumber data: For_Codebook_1.xlsx (85 unit dengan kolom Isi terisi, baris Excel 2 sampai 86).
B4: Kode coder Anda (isi sekali):
B6: Sel yang boleh diisi
B7: Kuning (kolom V4 sampai V12) | C7: Diisi coder. V4 sampai V9 wajib (pilih dari daftar), V10 sampai V12 opsional.
B8: Abu-abu (V1, V2, V3, Pilot, Rujukan, Isi) | C8: Rujukan. Jangan diubah. V2 terisi otomatis dari sel C4 di atas. Kolom Rujukan memuat Pasal (peraturan) atau Paragraf dan Kalimat (artikel).
B9: Kolom BAB dan Bagian (tersembunyi) | C9: Disembunyikan agar judul BAB atau Bagian tidak memengaruhi pemilihan tema. Buka dengan tombol + di atas kolom hanya bila perlu memahami rujukan antarunit. Jangan menentukan V5 dari judulnya.
B10: Kolom Cek | C10: Otomatis. "OK" berarti kombinasi kode memenuhi aturan konsistensi Bagian 9. Pesan "Periksa..." berarti jelaskan di V12 atau ulangi coding.
B11: Kolom Pilot | C11: Penanda "Ya" menunjukkan unit yang masuk pilot. Untuk pilot, kodekan hanya unit bertanda Ya (12 unit).
B13: Aturan singkat
B14: 1. | C14: Kodekan isi yang tertulis di kolom Isi. Jangan menambah pengetahuan hukum dari luar baris tersebut.
B15: 2. | C15: Urutan: V4 (Uji Implikasi), V5 (pohon keputusan Bagian 6.2), V6, V7, V8, V9, lalu periksa kolom Cek.
B16: 3. | C16: Jangan mengoreksi salah ketik atau teks terpotong. Catat kendalanya di V12.
B17: 4. | C17: Tentukan V5 dan V7 dari kolom Isi, bukan dari judul BAB atau Bagian.
B18: 5. | C18: Bila tidak ada tema yang cocok: T99 pada V5 dan jelaskan di V12. Bila tidak ada jenis V6 yang cocok: pilih jenis terdekat dan catat alasannya di V12.
B19: 6. | C19: Jangan berdiskusi dengan coder lain sebelum seluruh unit selesai dikodekan.
B21: Contoh format pengisian (bukan data; hanya ilustrasi)
B22: Kolom | C22: Nilai contoh
B23: V4 Relevansi | C23: R2
B24: V5 Tema_Utama | C24: T11
B25: V6 Jenis_Pernyataan | C25: P2
B26: V7 Subjek_Norma | C26: S1
B27: V8 Tahap_Scraping | C27: F6
B28: V9 Kebutuhan_SRS | C28: K1
B29: V10 Tema_Sekunder | C29: (kosong)
B30: V11 Draf_Kebutuhan | C30: Sistem harus menghentikan pemrosesan data pribadi paling lambat 3 x 24 jam setelah penarikan persetujuan.
B31: V12 Catatan | C31: (kosong)
B33: Contoh di atas mengikuti contoh baris 67 pada codebook (Bagian 12 dan 11). Baris 67 bukan unit pilot.
B35: Kemajuan
B36: Unit terkode lengkap | C36: =COUNTIF('Lembar Coding'!R2:R86,"OK")+COUNTIF('Lembar Coding'!R2:R86,"Periksa*") -> 0
B37: Unit pilot terkode lengkap | C37: =COUNTIFS('Lembar Coding'!R2:R86,"OK",'Lembar Coding'!D2:D86,"Ya")+COUNTIFS('Lembar Coding'!R2:R86,"Periksa*",'Lembar Coding'!D2:D86,"Ya") -> 0
B38: Unit yang perlu diperbaiki | C38: =COUNTIF('Lembar Coding'!R2:R86,"R*")+COUNTIF('Lembar Coding'!R2:R86,"P9*") -> 0
B39: Unit yang perlu diperbaiki = pesan Cek yang diawali R (aturan R0, R1, R2) atau P9. Pesan "Lengkapi V4-V9" belum dihitung sebagai kesalahan.

Sheet Lembar Coding
A1: V1 ID_Unit | B1: V2 Kode_Coder | C1: V3 Dokumen | D1: Pilot | E1: Rujukan (Pasal / Paragraf, Kalimat) | F1: BAB | G1: Bagian | H1: Isi | I1: V4 Relevansi | J1: V5 Tema_Utama | K1: V6 Jenis_Pernyataan | L1: V7 Subjek_Norma | M1: V8 Tahap_Scraping | N1: V9 Kebutuhan_SRS | O1: V10 Tema_Sekunder (opsional) | P1: V11 Draf_Kebutuhan (opsional) | Q1: V12 Catatan | R1: Cek
A2: 2 | B2: =IF(Petunjuk!$C$4="","",Petunjuk!$C$4) | C2: 2019MHN201 | E2: Paragraf 3, Kalimat 1 | F2: C. Pembahasan | G2: 5. Pentingnya Perlindungan Data Pribadi | H2: Melihat banyaknya kasus penyalahgunaan data pribadi, sangat penting untuk memberikan perlindungan data pribadi. | R2: =IF(COUNTA(I2:N2)<6,"Lengkapi V4-V9",IF(AND(I2="R0",N2<>"K5"),"R0 harus berpasangan dengan K5",IF(AND(I2="R1",N2<>"K4",N2<>"K5"),"R1 hanya dengan K4 atau K5",IF(AND(I2="R2",N2="K5"),"R2 tidak boleh K5",IF(AND(K2="P9",J2<>"T17"),"P9 hanya dengan T17",IF(AND(J2="T01",K2<>"P6",Q2=""),"Periksa T01-P6: jelaskan di V12",IF(AND(K2="P1",N2<>"K4",Q2=""),"Periksa P1-K4: jelaskan di V12",IF(AND(J2="T99",Q2=""),"Periksa T99: wajib isi V12","OK")))))))) -> Lengkapi V4-V9
A3: 3 | B3: =IF(Petunjuk!$C$4="","",Petunjuk!$C$4) | C3: 2019MHN201 | E3: Paragraf 3, Kalimat 2 | F3: C. Pembahasan | G3: 5. Pentingnya Perlindungan Data Pribadi | H3: Pentingnya memberikan perlindungan data pribadi mulai menguat seiring dengan meningkatnya jumlah pengguna telepon seluler dan internet. | R3: =IF(COUNTA(I3:N3)<6,"Lengkapi V4-V9",IF(AND(I3="R0",N3<>"K5"),"R0 harus berpasangan dengan K5",IF(AND(I3="R1",N3<>"K4",N3<>"K5"),"R1 hanya dengan K4 atau K5",IF(AND(I3="R2",N3="K5"),"R2 tidak boleh K5",IF(AND(K3="P9",J3<>"T17"),"P9 hanya dengan T17",IF(AND(J3="T01",K3<>"P6",Q3=""),"Periksa T01-P6: jelaskan di V12",IF(AND(K3="P1",N3<>"K4",Q3=""),"Periksa P1-K4: jelaskan di V12",IF(AND(J3="T99",Q3=""),"Periksa T99: wajib isi V12","OK")))))))) -> Lengkapi V4-V9
A4: 4 | B4: =IF(Petunjuk!$C$4="","",Petunjuk!$C$4) | C4: 2019MHN201 | E4: Paragraf 3, Kalimat 3 | F4: C. Pembahasan | G4: 5. Pentingnya Perlindungan Data Pribadi | H4: Sejumlah kasus yang mencuat, terutama yang memiliki keterkaitan dengan kebocoran data pribadi seseorang dan bermuara kepada aksi penipuan atau tindak kriminal pornografi, menguatkan wacana pentingnya pembuatan aturan hukum untuk melindungi data pribadi. | R4: =IF(COUNTA(I4:N4)<6,"Lengkapi V4-V9",IF(AND(I4="R0",N4<>"K5"),"R0 harus berpasangan dengan K5",IF(AND(I4="R1",N4<>"K4",N4<>"K5"),"R1 hanya dengan K4 atau K5",IF(AND(I4="R2",N4="K5"),"R2 tidak boleh K5",IF(AND(K4="P9",J4<>"T17"),"P9 hanya dengan T17",IF(AND(J4="T01",K4<>"P6",Q4=""),"Periksa T01-P6: jelaskan di V12",IF(AND(K4="P1",N4<>"K4",Q4=""),"Periksa P1-K4: jelaskan di V12",IF(AND(J4="T99",Q4=""),"Periksa T99: wajib isi V12","OK")))))))) -> Lengkapi V4-V9
A5: 5 | B5: =IF(Petunjuk!$C$4="","",Petunjuk!$C$4) | C5: 2019MHN201 | E5: Paragraf 3, Kalimat 4 | F5: C. Pembahasan | G5: 5. Pentingnya Perlindungan Data Pribadi | H5: Perlindungan data pribadi berhubungan dengan konsep privasi. | R5: =IF(COUNTA(I5:N5)<6,"Lengkapi V4-V9",IF(AND(I5="R0",N5<>"K5"),"R0 harus berpasangan dengan K5",IF(AND(I5="R1",N5<>"K4",N5<>"K5"),"R1 hanya dengan K4 atau K5",IF(AND(I5="R2",N5="K5"),"R2 tidak boleh K5",IF(AND(K5="P9",J5<>"T17"),"P9 hanya dengan T17",IF(AND(J5="T01",K5<>"P6",Q5=""),"Periksa T01-P6: jelaskan di V12",IF(AND(K5="P1",N5<>"K4",Q5=""),"Periksa P1-K4: jelaskan di V12",IF(AND(J5="T99",Q5=""),"Periksa T99: wajib isi V12","OK")))))))) -> Lengkapi V4-V9
A6: 6 | B6: =IF(Petunjuk!$C$4="","",Petunjuk!$C$4) | C6: 2019MHN201 | E6: Paragraf 3, Kalimat 5 | F6: C. Pembahasan | G6: 5. Pentingnya Perlindungan Data Pribadi | H6: Konsep privasi sendiri adalah gagasan untuk menjaga integritas dan martabat pribadi. | R6: =IF(COUNTA(I6:N6)<6,"Lengkapi V4-V9",IF(AND(I6="R0",N6<>"K5"),"R0 harus berpasangan dengan K5",IF(AND(I6="R1",N6<>"K4",N6<>"K5"),"R1 hanya dengan K4 atau K5",IF(AND(I6="R2",N6="K5"),"R2 tidak boleh K5",IF(AND(K6="P9",J6<>"T17"),"P9 hanya dengan T17",IF(AND(J6="T01",K6<>"P6",Q6=""),"Periksa T01-P6: jelaskan di V12",IF(AND(K6="P1",N6<>"K4",Q6=""),"Periksa P1-K4: jelaskan di V12",IF(AND(J6="T99",Q6=""),"Periksa T99: wajib isi V12","OK")))))))) -> Lengkapi V4-V9
A7: 7 | B7: =IF(Petunjuk!$C$4="","",Petunjuk!$C$4) | C7: 2019MHN201 | E7: Paragraf 3, Kalimat 6 | F7: C. Pembahasan | G7: 5. Pentingnya Perlindungan Data Pribadi | H7: Hak privasi juga merupakan kemampuan individu untuk menentukan siapa yang memegang informasi tentang mereka dan bagaimana informasi tersebut digunakan. | R7: =IF(COUNTA(I7:N7)<6,"Lengkapi V4-V9",IF(AND(I7="R0",N7<>"K5"),"R0 harus berpasangan dengan K5",IF(AND(I7="R1",N7<>"K4",N7<>"K5"),"R1 hanya dengan K4 atau K5",IF(AND(I7="R2",N7="K5"),"R2 tidak boleh K5",IF(AND(K7="P9",J7<>"T17"),"P9 hanya dengan T17",IF(AND(J7="T01",K7<>"P6",Q7=""),"Periksa T01-P6: jelaskan di V12",IF(AND(K7="P1",N7<>"K4",Q7=""),"Periksa P1-K4: jelaskan di V12",IF(AND(J7="T99",Q7=""),"Periksa T99: wajib isi V12","OK")))))))) -> Lengkapi V4-V9
A8: 8 | B8: =IF(Petunjuk!$C$4="","",Petunjuk!$C$4) | C8: 2019MHN201 | E8: Paragraf 4, Kalimat 1 | F8: C. Pembahasan | G8: 5. Pentingnya Perlindungan Data Pribadi | H8: Konsep perlindungan data mengisyaratkan bahwa individu memiliki hak untuk menentukan apakah mereka akan membagi atau bertukar data pribadi mereka atau tidak. | R8: =IF(COUNTA(I8:N8)<6,"Lengkapi V4-V9",IF(AND(I8="R0",N8<>"K5"),"R0 harus berpasangan dengan K5",IF(AND(I8="R1",N8<>"K4",N8<>"K5"),"R1 hanya dengan K4 atau K5",IF(AND(I8="R2",N8="K5"),"R2 tidak boleh K5",IF(AND(K8="P9",J8<>"T17"),"P9 hanya dengan T17",IF(AND(J8="T01",K8<>"P6",Q8=""),"Periksa T01-P6: jelaskan di V12",IF(AND(K8="P1",N8<>"K4",Q8=""),"Periksa P1-K4: jelaskan di V12",IF(AND(J8="T99",Q8=""),"Periksa T99: wajib isi V12","OK")))))))) -> Lengkapi V4-V9
A9: 9 | B9: =IF(Petunjuk!$C$4="","",Petunjuk!$C$4) | C9: 2019MHN201 | E9: Paragraf 4, Kalimat 2 | F9: C. Pembahasan | G9: 5. Pentingnya Perlindungan Data Pribadi | H9: Selain itu, individu juga memiliki hak untuk menentukan syarat-syarat pelaksanaan pemindahan data pribadi tersebut. | R9: =IF(COUNTA(I9:N9)<6,"Lengkapi V4-V9",IF(AND(I9="R0",N9<>"K5"),"R0 harus berpasangan dengan K5",IF(AND(I9="R1",N9<>"K4",N9<>"K5"),"R1 hanya dengan K4 atau K5",IF(AND(I9="R2",N9="K5"),"R2 tidak boleh K5",IF(AND(K9="P9",J9<>"T17"),"P9 hanya dengan T17",IF(AND(J9="T01",K9<>"P6",Q9=""),"Periksa T01-P6: jelaskan di V12",IF(AND(K9="P1",N9<>"K4",Q9=""),"Periksa P1-K4: jelaskan di V12",IF(AND(J9="T99",Q9=""),"Periksa T99: wajib isi V12","OK")))))))) -> Lengkapi V4-V9
A10: 10 | B10: =IF(Petunjuk!$C$4="","",Petunjuk!$C$4) | C10: 2019MHN201 | E10: Paragraf 4, Kalimat 3 | F10: C. Pembahasan | G10: 5. Pentingnya Perlindungan Data Pribadi | H10: Lebih jauh, perlindungan privasi. | R10: =IF(COUNTA(I10:N10)<6,"Lengkapi V4-V9",IF(AND(I10="R0",N10<>"K5"),"R0 harus berpasangan dengan K5",IF(AND(I10="R1",N10<>"K4",N10<>"K5"),"R1 hanya dengan K4 atau K5",IF(AND(I10="R2",N10="K5"),"R2 tidak boleh K5",IF(AND(K10="P9",J10<>"T17"),"P9 hanya dengan T17",IF(AND(J10="T01",K10<>"P6",Q10=""),"Periksa T01-P6: jelaskan di V12",IF(AND(K10="P1",N10<>"K4",Q10=""),"Periksa P1-K4: jelaskan di V12",IF(AND(J10="T99",Q10=""),"Periksa T99: wajib isi V12","OK")))))))) -> Lengkapi V4-V9
A11: 11 | B11: =IF(Petunjuk!$C$4="","",Petunjuk!$C$4) | C11: 2019MHN201 | E11: Paragraf 4, Kalimat 4 | F11: C. Pembahasan | G11: 5. Pentingnya Perlindungan Data Pribadi | H11: Hak privasi telah berkembang sehingga dapat digunakan untuk merumuskan hak untuk melindungi data pribadi. | R11: =IF(COUNTA(I11:N11)<6,"Lengkapi V4-V9",IF(AND(I11="R0",N11<>"K5"),"R0 harus berpasangan dengan K5",IF(AND(I11="R1",N11<>"K4",N11<>"K5"),"R1 hanya dengan K4 atau K5",IF(AND(I11="R2",N11="K5"),"R2 tidak boleh K5",IF(AND(K11="P9",J11<>"T17"),"P9 hanya dengan T17",IF(AND(J11="T01",K11<>"P6",Q11=""),"Periksa T01-P6: jelaskan di V12",IF(AND(K11="P1",N11<>"K4",Q11=""),"Periksa P1-K4: jelaskan di V12",IF(AND(J11="T99",Q11=""),"Periksa T99: wajib isi V12","OK")))))))) -> Lengkapi V4-V9
A12: 12 | B12: =IF(Petunjuk!$C$4="","",Petunjuk!$C$4) | C12: 2019MHN201 | E12: Paragraf 5, Kalimat 1 | F12: C. Pembahasan | G12: 5. Pentingnya Perlindungan Data Pribadi | H12: Perlindungan data pribadi telah diatur di dalam UUD NKRI Tahun 1945. | R12: =IF(COUNTA(I12:N12)<6,"Lengkapi V4-V9",IF(AND(I12="R0",N12<>"K5"),"R0 harus berpasangan dengan K5",IF(AND(I12="R1",N12<>"K4",N12<>"K5"),"R1 hanya dengan K4 atau K5",IF(AND(I12="R2",N12="K5"),"R2 tidak boleh K5",IF(AND(K12="P9",J12<>"T17"),"P9 hanya dengan T17",IF(AND(J12="T01",K12<>"P6",Q12=""),"Periksa T01-P6: jelaskan di V12",IF(AND(K12="P1",N12<>"K4",Q12=""),"Periksa P1-K4: jelaskan di V12",IF(AND(J12="T99",Q12=""),"Periksa T99: wajib isi V12","OK")))))))) -> Lengkapi V4-V9
A13: 13 | B13: =IF(Petunjuk!$C$4="","",Petunjuk!$C$4) | C13: 2019MHN201 | D13: Ya | E13: Paragraf 5, Kalimat 2 | F13: C. Pembahasan | G13: 5. Pentingnya Perlindungan Data Pribadi | H13: Dalam Pasal 28 G ayat (1) disebutkan bahwa “Setiap orang berhak atas perlindungan diri pribadi, data juga berhubungan dengan konsep hak keluarga, kehormatan, martabat, dan harta benda yang di bawah kekuasaannya, serta berhak atas rasa aman dan perlindungan dari ancaman ketakutan untuk berbuat atau tidak berbuat sesuatu yang merupakan hak asasi.” | R13: =IF(COUNTA(I13:N13)<6,"Lengkapi V4-V9",IF(AND(I13="R0",N13<>"K5"),"R0 harus berpasangan dengan K5",IF(AND(I13="R1",N13<>"K4",N13<>"K5"),"R1 hanya dengan K4 atau K5",IF(AND(I13="R2",N13="K5"),"R2 tidak boleh K5",IF(AND(K13="P9",J13<>"T17"),"P9 hanya dengan T17",IF(AND(J13="T01",K13<>"P6",Q13=""),"Periksa T01-P6: jelaskan di V12",IF(AND(K13="P1",N13<>"K4",Q13=""),"Periksa P1-K4: jelaskan di V12",IF(AND(J13="T99",Q13=""),"Periksa T99: wajib isi V12","OK")))))))) -> Lengkapi V4-V9
A14: 14 | B14: =IF(Petunjuk!$C$4="","",Petunjuk!$C$4) | C14: 2019MHN201 | E14: Paragraf 6, Kalimat 1 | F14: C. Pembahasan | G14: 5. Pentingnya Perlindungan Data Pribadi | H14: Selain itu beberapa peraturan nasional secara umum telah mengatur untuk memberikan perlindungan data pribadi antara lain: | R14: =IF(COUNTA(I14:N14)<6,"Lengkapi V4-V9",IF(AND(I14="R0",N14<>"K5"),"R0 harus berpasangan dengan K5",IF(AND(I14="R1",N14<>"K4",N14<>"K5"),"R1 hanya dengan K4 atau K5",IF(AND(I14="R2",N14="K5"),"R2 tidak boleh K5",IF(AND(K14="P9",J14<>"T17"),"P9 hanya dengan T17",IF(AND(J14="T01",K14<>"P6",Q14=""),"Periksa T01-P6: jelaskan di V12",IF(AND(K14="P1",N14<>"K4",Q14=""),"Periksa P1-K4: jelaskan di V12",IF(AND(J14="T99",Q14=""),"Periksa T99: wajib isi V12","OK")))))))) -> Lengkapi V4-V9
A15: 15 | B15: =IF(Petunjuk!$C$4="","",Petunjuk!$C$4) | C15: 2019MHN201 | E15: Paragraf 6, Kalimat 2 | F15: C. Pembahasan | G15: 5. Pentingnya Perlindungan Data Pribadi | H15: 1) Undang-Undang Nomor 19 Tahun 2016 Tentang Perubahan Atas Undang-Undang Nomor 11 Tahun 2008 Tentang Informasi dan Transaksi Elektronik | R15: =IF(COUNTA(I15:N15)<6,"Lengkapi V4-V9",IF(AND(I15="R0",N15<>"K5"),"R0 harus berpasangan dengan K5",IF(AND(I15="R1",N15<>"K4",N15<>"K5"),"R1 hanya dengan K4 atau K5",IF(AND(I15="R2",N15="K5"),"R2 tidak boleh K5",IF(AND(K15="P9",J15<>"T17"),"P9 hanya dengan T17",IF(AND(J15="T01",K15<>"P6",Q15=""),"Periksa T01-P6: jelaskan di V12",IF(AND(K15="P1",N15<>"K4",Q15=""),"Periksa P1-K4: jelaskan di V12",IF(AND(J15="T99",Q15=""),"Periksa T99: wajib isi V12","OK")))))))) -> Lengkapi V4-V9
A16: 16 | B16: =IF(Petunjuk!$C$4="","",Petunjuk!$C$4) | C16: 2019MHN201 | E16: Paragraf 6, Kalimat 3 | F16: C. Pembahasan | G16: 5. Pentingnya Perlindungan Data Pribadi | H16: 2) Undang-Undang Nomor 11 Tahun 2008 Tentang Informasi dan Transaksi Elektronik | R16: =IF(COUNTA(I16:N16)<6,"Lengkapi V4-V9",IF(AND(I16="R0",N16<>"K5"),"R0 harus berpasangan dengan K5",IF(AND(I16="R1",N16<>"K4",N16<>"K5"),"R1 hanya dengan K4 atau K5",IF(AND(I16="R2",N16="K5"),"R2 tidak boleh K5",IF(AND(K16="P9",J16<>"T17"),"P9 hanya dengan T17",IF(AND(J16="T01",K16<>"P6",Q16=""),"Periksa T01-P6: jelaskan di V12",IF(AND(K16="P1",N16<>"K4",Q16=""),"Periksa P1-K4: jelaskan di V12",IF(AND(J16="T99",Q16=""),"Periksa T99: wajib isi V12","OK")))))))) -> Lengkapi V4-V9
A17: 17 | B17: =IF(Petunjuk!$C$4="","",Petunjuk!$C$4) | C17: 2019MHN201 | E17: Paragraf 6, Kalimat 13 | F17: C. Pembahasan | G17: 5. Pentingnya Perlindungan Data Pribadi | H17: 12) Peraturan Menteri Komunikasi dan Informasi Nomor 20 Tahun 2016 Tentang Perlindungan Data Pribadi Dalam Sistem Elektronik | R17: =IF(COUNTA(I17:N17)<6,"Lengkapi V4-V9",IF(AND(I17="R0",N17<>"K5"),"R0 harus berpasangan dengan K5",IF(AND(I17="R1",N17<>"K4",N17<>"K5"),"R1 hanya dengan K4 atau K5",IF(AND(I17="R2",N17="K5"),"R2 tidak boleh K5",IF(AND(K17="P9",J17<>"T17"),"P9 hanya dengan T17",IF(AND(J17="T01",K17<>"P6",Q17=""),"Periksa T01-P6: jelaskan di V12",IF(AND(K17="P1",N17<>"K4",Q17=""),"Periksa P1-K4: jelaskan di V12",IF(AND(J17="T99",Q17=""),"Periksa T99: wajib isi V12","OK")))))))) -> Lengkapi V4-V9
A18: 18 | B18: =IF(Petunjuk!$C$4="","",Petunjuk!$C$4) | C18: 2019MHN201 | E18: Paragraf 6, Kalimat 14 | F18: C. Pembahasan | G18: 5. Pentingnya Perlindungan Data Pribadi | H18: 13) Peraturan Pemerintah Nomor 82 Tahun 2012 Tentang Penyelenggaraan Sistem dan Transaksi Elektronik | R18: =IF(COUNTA(I18:N18)<6,"Lengkapi V4-V9",IF(AND(I18="R0",N18<>"K5"),"R0 harus berpasangan dengan K5",IF(AND(I18="R1",N18<>"K4",N18<>"K5"),"R1 hanya dengan K4 atau K5",IF(AND(I18="R2",N18="K5"),"R2 tidak boleh K5",IF(AND(K18="P9",J18<>"T17"),"P9 hanya dengan T17",IF(AND(J18="T01",K18<>"P6",Q18=""),"Periksa T01-P6: jelaskan di V12",IF(AND(K18="P1",N18<>"K4",Q18=""),"Periksa P1-K4: jelaskan di V12",IF(AND(J18="T99",Q18=""),"Periksa T99: wajib isi V12","OK")))))))) -> Lengkapi V4-V9
A19: 19 | B19: =IF(Petunjuk!$C$4="","",Petunjuk!$C$4) | C19: 2019MHN201 | E19: Paragraf 6, Kalimat 16 | F19: C. Pembahasan | G19: 5. Pentingnya Perlindungan Data Pribadi | H19: 15) Peraturan Menteri Komunikasi dan Informasi Nomor 4 Tahun 2016 Tentang Sistem Manajemen Pengaman Informasi | R19: =IF(COUNTA(I19:N19)<6,"Lengkapi V4-V9",IF(AND(I19="R0",N19<>"K5"),"R0 harus berpasangan dengan K5",IF(AND(I19="R1",N19<>"K4",N19<>"K5"),"R1 hanya dengan K4 atau K5",IF(AND(I19="R2",N19="K5"),"R2 tidak boleh K5",IF(AND(K19="P9",J19<>"T17"),"P9 hanya dengan T17",IF(AND(J19="T01",K19<>"P6",Q19=""),"Periksa T01-P6: jelaskan di V12",IF(AND(K19="P1",N19<>"K4",Q19=""),"Periksa P1-K4: jelaskan di V12",IF(AND(J19="T99",Q19=""),"Periksa T99: wajib isi V12","OK")))))))) -> Lengkapi V4-V9
A20: 20 | B20: =IF(Petunjuk!$C$4="","",Petunjuk!$C$4) | C20: 2019MHN201 | E20: Paragraf 7, Kalimat 2 | F20: C. Pembahasan | G20: 5. Pentingnya Perlindungan Data Pribadi | H20: Dalam Pasal 26 huruf a disebutkan bahwa menjaga kerahasiaan, keutuhan, dan ketersediaan data pribadi, data transaksi, dan data keuangan yang dikelolanya sejak data diperoleh hingga data tersebut dimusnahkan. | R20: =IF(COUNTA(I20:N20)<6,"Lengkapi V4-V9",IF(AND(I20="R0",N20<>"K5"),"R0 harus berpasangan dengan K5",IF(AND(I20="R1",N20<>"K4",N20<>"K5"),"R1 hanya dengan K4 atau K5",IF(AND(I20="R2",N20="K5"),"R2 tidak boleh K5",IF(AND(K20="P9",J20<>"T17"),"P9 hanya dengan T17",IF(AND(J20="T01",K20<>"P6",Q20=""),"Periksa T01-P6: jelaskan di V12",IF(AND(K20="P1",N20<>"K4",Q20=""),"Periksa P1-K4: jelaskan di V12",IF(AND(J20="T99",Q20=""),"Periksa T99: wajib isi V12","OK")))))))) -> Lengkapi V4-V9
A21: 21 | B21: =IF(Petunjuk!$C$4="","",Petunjuk!$C$4) | C21: 2019MHN201 | D21: Ya | E21: Paragraf 7, Kalimat 3 | F21: C. Pembahasan | G21: 5. Pentingnya Perlindungan Data Pribadi | H21: Selain itu Peraturan OJK Nomor 13 Tahun 2018 Tentang Inovasi Keuangan Digital di Sektor Keuangan, telah memasukkan poin terkait perlindungan dan kerahasiaan data. | R21: =IF(COUNTA(I21:N21)<6,"Lengkapi V4-V9",IF(AND(I21="R0",N21<>"K5"),"R0 harus berpasangan dengan K5",IF(AND(I21="R1",N21<>"K4",N21<>"K5"),"R1 hanya dengan K4 atau K5",IF(AND(I21="R2",N21="K5"),"R2 tidak boleh K5",IF(AND(K21="P9",J21<>"T17"),"P9 hanya dengan T17",IF(AND(J21="T01",K21<>"P6",Q21=""),"Periksa T01-P6: jelaskan di V12",IF(AND(K21="P1",N21<>"K4",Q21=""),"Periksa P1-K4: jelaskan di V12",IF(AND(J21="T99",Q21=""),"Periksa T99: wajib isi V12","OK")))))))) -> Lengkapi V4-V9
A22: 22 | B22: =IF(Petunjuk!$C$4="","",Petunjuk!$C$4) | C22: 2019MHN201 | E22: Paragraf 7, Kalimat 4 | F22: C. Pembahasan | G22: 5. Pentingnya Perlindungan Data Pribadi | H22: Pasal 30 ayat (1) menyebutkan bahwa Penyelenggara wajib menjaga kerahasiaan data pribadi, data transaksi, dan data keuangan yang dikelolanya sejak diperoleh hingga data tersebut dimusnahkan. | R22: =IF(COUNTA(I22:N22)<6,"Lengkapi V4-V9",IF(AND(I22="R0",N22<>"K5"),"R0 harus berpasangan dengan K5",IF(AND(I22="R1",N22<>"K4",N22<>"K5"),"R1 hanya dengan K4 atau K5",IF(AND(I22="R2",N22="K5"),"R2 tidak boleh K5",IF(AND(K22="P9",J22<>"T17"),"P9 hanya dengan T17",IF(AND(J22="T01",K22<>"P6",Q22=""),"Periksa T01-P6: jelaskan di V12",IF(AND(K22="P1",N22<>"K4",Q22=""),"Periksa P1-K4: jelaskan di V12",IF(AND(J22="T99",Q22=""),"Periksa T99: wajib isi V12","OK")))))))) -> Lengkapi V4-V9
A23: 23 | B23: =IF(Petunjuk!$C$4="","",Petunjuk!$C$4) | C23: 2019MHN201 | E23: Paragraf 8, Kalimat 1 | F23: C. Pembahasan | G23: 5. Pentingnya Perlindungan Data Pribadi | H23: Banyaknya peraturan yang mengatur tentang perlindungan data pribadi menunjukkan pentingnya data pribadi untuk dilindungi. | R23: =IF(COUNTA(I23:N23)<6,"Lengkapi V4-V9",IF(AND(I23="R0",N23<>"K5"),"R0 harus berpasangan dengan K5",IF(AND(I23="R1",N23<>"K4",N23<>"K5"),"R1 hanya dengan K4 atau K5",IF(AND(I23="R2",N23="K5"),"R2 tidak boleh K5",IF(AND(K23="P9",J23<>"T17"),"P9 hanya dengan T17",IF(AND(J23="T01",K23<>"P6",Q23=""),"Periksa T01-P6: jelaskan di V12",IF(AND(K23="P1",N23<>"K4",Q23=""),"Periksa P1-K4: jelaskan di V12",IF(AND(J23="T99",Q23=""),"Periksa T99: wajib isi V12","OK")))))))) -> Lengkapi V4-V9
A24: 24 | B24: =IF(Petunjuk!$C$4="","",Petunjuk!$C$4) | C24: 2019MHN201 | E24: Paragraf 8, Kalimat 3 | F24: C. Pembahasan | G24: 5. Pentingnya Perlindungan Data Pribadi | H24: Oleh karena itu perlu disusun suatu undang-undang yang secara khusus dapat memberikan perlindungan data pribadi. | R24: =IF(COUNTA(I24:N24)<6,"Lengkapi V4-V9",IF(AND(I24="R0",N24<>"K5"),"R0 harus berpasangan dengan K5",IF(AND(I24="R1",N24<>"K4",N24<>"K5"),"R1 hanya dengan K4 atau K5",IF(AND(I24="R2",N24="K5"),"R2 tidak boleh K5",IF(AND(K24="P9",J24<>"T17"),"P9 hanya dengan T17",IF(AND(J24="T01",K24<>"P6",Q24=""),"Periksa T01-P6: jelaskan di V12",IF(AND(K24="P1",N24<>"K4",Q24=""),"Periksa P1-K4: jelaskan di V12",IF(AND(J24="T99",Q24=""),"Periksa T99: wajib isi V12","OK")))))))) -> Lengkapi V4-V9
A25: 25 | B25: =IF(Petunjuk!$C$4="","",Petunjuk!$C$4) | C25: 2019MHN201 | D25: Ya | E25: Paragraf 1, Kalimat 3 | F25: D. Penutup | H25: Selain itu juga sudah ada Peraturan Menteri Nomor 20 Tahun 2016 tentang Perlindungan Data Pribadi namun belum cukup memberikan perlindungan kepada konsumen. | R25: =IF(COUNTA(I25:N25)<6,"Lengkapi V4-V9",IF(AND(I25="R0",N25<>"K5"),"R0 harus berpasangan dengan K5",IF(AND(I25="R1",N25<>"K4",N25<>"K5"),"R1 hanya dengan K4 atau K5",IF(AND(I25="R2",N25="K5"),"R2 tidak boleh K5",IF(AND(K25="P9",J25<>"T17"),"P9 hanya dengan T17",IF(AND(J25="T01",K25<>"P6",Q25=""),"Periksa T01-P6: jelaskan di V12",IF(AND(K25="P1",N25<>"K4",Q25=""),"Periksa P1-K4: jelaskan di V12",IF(AND(J25="T99",Q25=""),"Periksa T99: wajib isi V12","OK")))))))) -> Lengkapi V4-V9
A26: 26 | B26: =IF(Petunjuk!$C$4="","",Petunjuk!$C$4) | C26: 2019MHN201 | E26: Paragraf 1, Kalimat 4 | F26: D. Penutup | H26: Oleh karenanya Pemerintah perlu segera memberikan perlindungan data pribadi nasabah agar tidak disalahgunakan. | R26: =IF(COUNTA(I26:N26)<6,"Lengkapi V4-V9",IF(AND(I26="R0",N26<>"K5"),"R0 harus berpasangan dengan K5",IF(AND(I26="R1",N26<>"K4",N26<>"K5"),"R1 hanya dengan K4 atau K5",IF(AND(I26="R2",N26="K5"),"R2 tidak boleh K5",IF(AND(K26="P9",J26<>"T17"),"P9 hanya dengan T17",IF(AND(J26="T01",K26<>"P6",Q26=""),"Periksa T01-P6: jelaskan di V12",IF(AND(K26="P1",N26<>"K4",Q26=""),"Periksa P1-K4: jelaskan di V12",IF(AND(J26="T99",Q26=""),"Periksa T99: wajib isi V12","OK")))))))) -> Lengkapi V4-V9
A27: 27 | B27: =IF(Petunjuk!$C$4="","",Petunjuk!$C$4) | C27: UU 23 Thn 2002 (Perlindungan Anak) | E27: Pasal 27 | F27: BAB V KEDUDUKAN ANAK | G27: Bagian Kesatu Identitas Anak | H27: (1) Identitas diri setiap anak harus diberikan sejak kelahirannya.(2) Identitas sebagaimana dimaksud dalam ayat (1) dituangkan dalam akta kelahiran.(3) Pembuatan akta kelahiran didasarkan pada surat keterangan dari orang yang menyaksikan dan/atau membantu proses kelahiran. Dalam hal anak yang proses kelahirannya tidak diketahui, dan orang tuanya tidak diketahui keberadaannya, pembuatan akta kelahiran untuk anak tersebut didasarkan pada keterangan orang yang menemukannya. | R27: =IF(COUNTA(I27:N27)<6,"Lengkapi V4-V9",IF(AND(I27="R0",N27<>"K5"),"R0 harus berpasangan dengan K5",IF(AND(I27="R1",N27<>"K4",N27<>"K5"),"R1 hanya dengan K4 atau K5",IF(AND(I27="R2",N27="K5"),"R2 tidak boleh K5",IF(AND(K27="P9",J27<>"T17"),"P9 hanya dengan T17",IF(AND(J27="T01",K27<>"P6",Q27=""),"Periksa T01-P6: jelaskan di V12",IF(AND(K27="P1",N27<>"K4",Q27=""),"Periksa P1-K4: jelaskan di V12",IF(AND(J27="T99",Q27=""),"Periksa T99: wajib isi V12","OK")))))))) -> Lengkapi V4-V9
A28: 28 | B28: =IF(Petunjuk!$C$4="","",Petunjuk!$C$4) | C28: UU 27 Thn 2022 (PDP) | E28: Pasal 1 | F28: BAB I KETENTUAN UMUM | H28: Dalam Undang-Undang ini yang dimaksud dengan: 1. Data Pribadi adalah data tentang orang perseorangan yang teridentifikasi atau dapat diidentifikasi secara tersendiri atau dikombinasi dengan informasi lainnya baik secara langsung maupun tidak langsung melalui sistem elektronik atau nonelektronik. 2. Pelindungan Data Pribadi adalah keseluruhan upaya untuk melindungi Data Pribadi dalam rangkaian pemrosesan Data Pribadi guna menjamin hak konstitusional subjek Data Pribadi. 3. Informasi adalah keterangan, pernyataan, gagasan, dan tanda-tanda yang mengandung nilai, makna, dan pesan, baik data, fakta, maupun penjelasannya yang dapat dilihat, didengar, dan dibaca yang disajikan dalam berbagai kemasan dan format sesuai dengan perkembangan teknologi informasi dan komunikasi secara elektronik ataupun nonelektronik. 4. Pengendali Data Pribadi adalah setiap orang, badan publik, dan organisasi internasional yang bertindak sendiri-sendiri atau bersama-sama dalam menentukan tujuan dan melakukan kendali pemrosesan Data Pribadi. 5. Prosesor Data Pribadi adalah setiap orang, badan publik, dan organisasi internasional yang bertindak sendiri-sendiri atau bersama-sama dalam melakukan pemrosesan Data Pribadi atas nama Pengendali Data Pribadi. 6. Subjek Data Pribadi adalah orang perseorangan yang pada dirinya melekat Data Pribadi. 7. Setiap Orang adalah orang perseorangan atau korporasi. 8. Korporasi adalah kumpulan orang dan/ atau kekayaan yang terorganisasi baik yang berbadan hukum maupun tidak berbadan hukum. 9. Badan Publik adalah lembaga eksekutif, legislatif, yudikatif, dan badan lain yang fungsi dan tugas pokoknya berkaitan dengan penyelenggaraan negara, yang sebagian atau seluruh dananya bersumber dari Anggaran Pendapatan dan Belanja Negara dan/ atau Anggaran Pendapatan dan Belanja Daerah, atau organisasi nonpemerintah sepanjang sebagian atau seluruh dananya bersumber dari Anggaran Pendapatan dan Belanja Negara dan/ atau Anggaran. Pendapatan dan Belanja Daerah, sumbangan masyarakat, dan/atau luar negeri. 10. Organisasi Internasional adalah organisasi yang diakui sebagai subjek hukum internasional dan mempunyai kapasitas untuk membuat perjanjian internasional. | R28: =IF(COUNTA(I28:N28)<6,"Lengkapi V4-V9",IF(AND(I28="R0",N28<>"K5"),"R0 harus berpasangan dengan K5",IF(AND(I28="R1",N28<>"K4",N28<>"K5"),"R1 hanya dengan K4 atau K5",IF(AND(I28="R2",N28="K5"),"R2 tidak boleh K5",IF(AND(K28="P9",J28<>"T17"),"P9 hanya dengan T17",IF(AND(J28="T01",K28<>"P6",Q28=""),"Periksa T01-P6: jelaskan di V12",IF(AND(K28="P1",N28<>"K4",Q28=""),"Periksa P1-K4: jelaskan di V12",IF(AND(J28="T99",Q28=""),"Periksa T99: wajib isi V12","OK")))))))) -> Lengkapi V4-V9
A29: 29 | B29: =IF(Petunjuk!$C$4="","",Petunjuk!$C$4) | C29: UU 27 Thn 2022 (PDP) | E29: Pasal 2 | F29: BAB I KETENTUAN UMUM | H29: (1) Undang-Undang ini berlaku untuk Setiap Orang, Badan Publik, dan Organisasi Internasional yang melakukan perbuatan hukum sebagaimana diatur dalam Undang-Undang ini: a. yang berada di wilayah hukum Negara Republik Indonesia; dan b. di luar wilayah hukum Negara Republik Indonesia, yang memiliki akibat hukum: 1. di wilayah hukum Negara Republik Indonesia; dan/atau 2. bagi Subjek Data Pribadi warga negara Indonesia di luar wilayah hukum Negara Republik Indonesia.(2) Undang-Undang ini tidak berlaku untuk pemrosesan Data Pribadi oleh orang perseorangan dalam kegiatan pribadi atau rumah tangga. | R29: =IF(COUNTA(I29:N29)<6,"Lengkapi V4-V9",IF(AND(I29="R0",N29<>"K5"),"R0 harus berpasangan dengan K5",IF(AND(I29="R1",N29<>"K4",N29<>"K5"),"R1 hanya dengan K4 atau K5",IF(AND(I29="R2",N29="K5"),"R2 tidak boleh K5",IF(AND(K29="P9",J29<>"T17"),"P9 hanya dengan T17",IF(AND(J29="T01",K29<>"P6",Q29=""),"Periksa T01-P6: jelaskan di V12",IF(AND(K29="P1",N29<>"K4",Q29=""),"Periksa P1-K4: jelaskan di V12",IF(AND(J29="T99",Q29=""),"Periksa T99: wajib isi V12","OK")))))))) -> Lengkapi V4-V9
A30: 30 | B30: =IF(Petunjuk!$C$4="","",Petunjuk!$C$4) | C30: UU 27 Thn 2022 (PDP) | E30: Pasal 3 | F30: BAB II ASAS | H30: a. perlindungan; b. kepastian hukum; c. kepentingan umum; d. Kemanfaatan; e. Kehati-hatian; f. Keseimbangan; g. Pertanggungjawaban; dan h. kerahasiaan. | R30: =IF(COUNTA(I30:N30)<6,"Lengkapi V4-V9",IF(AND(I30="R0",N30<>"K5"),"R0 harus berpasangan dengan K5",IF(AND(I30="R1",N30<>"K4",N30<>"K5"),"R1 hanya dengan K4 atau K5",IF(AND(I30="R2",N30="K5"),"R2 tidak boleh K5",IF(AND(K30="P9",J30<>"T17"),"P9 hanya dengan T17",IF(AND(J30="T01",K30<>"P6",Q30=""),"Periksa T01-P6: jelaskan di V12",IF(AND(K30="P1",N30<>"K4",Q30=""),"Periksa P1-K4: jelaskan di V12",IF(AND(J30="T99",Q30=""),"Periksa T99: wajib isi V12","OK")))))))) -> Lengkapi V4-V9
A31: 31 | B31: =IF(Petunjuk!$C$4="","",Petunjuk!$C$4) | C31: UU 27 Thn 2022 (PDP) | E31: Pasal 4 | F31: BAB III JENIS DATA PRIBADI | H31: (1) Data Pribadi terdiri atas: a. Data Pribadi yang bersifat spesifik; danb. Data Pribadi yang bersifat umum.(2) Data Pribadi yang bersifat spesifik sebagaimana dimaksud pada ayat (l) huruf a meliputi: a. Data dan informasi kesehatan; b. Data biometrik; c. Data genetika; d. Catatan kejahatan; e. Data anak; f. Data keterangan pribadi; dan/ atau g. Data lainnya sesuai dengan ketentuan peraturan perundang-undangan.(3) Data Pribadi yang bersifat umum sebagaimana dimaksud pada ayat (l) huruf b meliputi: a. Nama lengkap; b. Jenis kelamin; c. Kewarganegaraan; d. Agama; e. Status perkawinan; dan/ atau f. Data Pribadi yang dikombinasikan untuk mengidentifikasi seseorang. | R31: =IF(COUNTA(I31:N31)<6,"Lengkapi V4-V9",IF(AND(I31="R0",N31<>"K5"),"R0 harus berpasangan dengan K5",IF(AND(I31="R1",N31<>"K4",N31<>"K5"),"R1 hanya dengan K4 atau K5",IF(AND(I31="R2",N31="K5"),"R2 tidak boleh K5",IF(AND(K31="P9",J31<>"T17"),"P9 hanya dengan T17",IF(AND(J31="T01",K31<>"P6",Q31=""),"Periksa T01-P6: jelaskan di V12",IF(AND(K31="P1",N31<>"K4",Q31=""),"Periksa P1-K4: jelaskan di V12",IF(AND(J31="T99",Q31=""),"Periksa T99: wajib isi V12","OK")))))))) -> Lengkapi V4-V9
A32: 32 | B32: =IF(Petunjuk!$C$4="","",Petunjuk!$C$4) | C32: UU 27 Thn 2022 (PDP) | E32: Pasal 5 | F32: BAB IV HAK SUBJEK DATA PRIBADI | H32: Subjek Data Pribadi berhak mendapatkan Informasi tentang kejelasan identitas, dasar kepentingan hukum, tujuan permintaan dan penggunaan Data Pribadi, dan akuntabilitas pihak yang meminta Data Pribadi. | R32: =IF(COUNTA(I32:N32)<6,"Lengkapi V4-V9",IF(AND(I32="R0",N32<>"K5"),"R0 harus berpasangan dengan K5",IF(AND(I32="R1",N32<>"K4",N32<>"K5"),"R1 hanya dengan K4 atau K5",IF(AND(I32="R2",N32="K5"),"R2 tidak boleh K5",IF(AND(K32="P9",J32<>"T17"),"P9 hanya dengan T17",IF(AND(J32="T01",K32<>"P6",Q32=""),"Periksa T01-P6: jelaskan di V12",IF(AND(K32="P1",N32<>"K4",Q32=""),"Periksa P1-K4: jelaskan di V12",IF(AND(J32="T99",Q32=""),"Periksa T99: wajib isi V12","OK")))))))) -> Lengkapi V4-V9
A33: 33 | B33: =IF(Petunjuk!$C$4="","",Petunjuk!$C$4) | C33: UU 27 Thn 2022 (PDP) | E33: Pasal 6 | F33: BAB IV HAK SUBJEK DATA PRIBADI | H33: Subjek Data Pribadi berhak melengkapi, memperbarui, dan/atau memperbaiki kesalahan dan/atau ketidakakuratan Data Pribadi tentang dirinya sesuai dengan tujuan pemrosesan Data Pribadi. | R33: =IF(COUNTA(I33:N33)<6,"Lengkapi V4-V9",IF(AND(I33="R0",N33<>"K5"),"R0 harus berpasangan dengan K5",IF(AND(I33="R1",N33<>"K4",N33<>"K5"),"R1 hanya dengan K4 atau K5",IF(AND(I33="R2",N33="K5"),"R2 tidak boleh K5",IF(AND(K33="P9",J33<>"T17"),"P9 hanya dengan T17",IF(AND(J33="T01",K33<>"P6",Q33=""),"Periksa T01-P6: jelaskan di V12",IF(AND(K33="P1",N33<>"K4",Q33=""),"Periksa P1-K4: jelaskan di V12",IF(AND(J33="T99",Q33=""),"Periksa T99: wajib isi V12","OK")))))))) -> Lengkapi V4-V9
A34: 34 | B34: =IF(Petunjuk!$C$4="","",Petunjuk!$C$4) | C34: UU 27 Thn 2022 (PDP) | E34: Pasal 7 | F34: BAB IV HAK SUBJEK DATA PRIBADI | H34: Subjek Data Pribadi berhak mendapatkan akses dan memperoleh salinan Data Pribadi tentang dirinya sesuai dengan ketentuan peraturan perundang-undangan. | R34: =IF(COUNTA(I34:N34)<6,"Lengkapi V4-V9",IF(AND(I34="R0",N34<>"K5"),"R0 harus berpasangan dengan K5",IF(AND(I34="R1",N34<>"K4",N34<>"K5"),"R1 hanya dengan K4 atau K5",IF(AND(I34="R2",N34="K5"),"R2 tidak boleh K5",IF(AND(K34="P9",J34<>"T17"),"P9 hanya dengan T17",IF(AND(J34="T01",K34<>"P6",Q34=""),"Periksa T01-P6: jelaskan di V12",IF(AND(K34="P1",N34<>"K4",Q34=""),"Periksa P1-K4: jelaskan di V12",IF(AND(J34="T99",Q34=""),"Periksa T99: wajib isi V12","OK")))))))) -> Lengkapi V4-V9
A35: 35 | B35: =IF(Petunjuk!$C$4="","",Petunjuk!$C$4) | C35: UU 27 Thn 2022 (PDP) | D35: Ya | E35: Pasal 8 | F35: BAB IV HAK SUBJEK DATA PRIBADI | H35: Subjek Data Pribadi berhak untuk mengakhiri pemrosesan, menghapus, dan/ atau memusnahkan Data Pribadi tentang dirinya sesuai dengan ketentuan peraturan perundang-undangan. | R35: =IF(COUNTA(I35:N35)<6,"Lengkapi V4-V9",IF(AND(I35="R0",N35<>"K5"),"R0 harus berpasangan dengan K5",IF(AND(I35="R1",N35<>"K4",N35<>"K5"),"R1 hanya dengan K4 atau K5",IF(AND(I35="R2",N35="K5"),"R2 tidak boleh K5",IF(AND(K35="P9",J35<>"T17"),"P9 hanya dengan T17",IF(AND(J35="T01",K35<>"P6",Q35=""),"Periksa T01-P6: jelaskan di V12",IF(AND(K35="P1",N35<>"K4",Q35=""),"Periksa P1-K4: jelaskan di V12",IF(AND(J35="T99",Q35=""),"Periksa T99: wajib isi V12","OK")))))))) -> Lengkapi V4-V9
A36: 36 | B36: =IF(Petunjuk!$C$4="","",Petunjuk!$C$4) | C36: UU 27 Thn 2022 (PDP) | E36: Pasal 9 | F36: BAB IV HAK SUBJEK DATA PRIBADI | H36: Subjek Data Pribadi berhak menarik kembali persetujuan pemrosesan Data Pribadi tentang dirinya yang telah diberikan kepada Pengendali Data Pribadi. | R36: =IF(COUNTA(I36:N36)<6,"Lengkapi V4-V9",IF(AND(I36="R0",N36<>"K5"),"R0 harus berpasangan dengan K5",IF(AND(I36="R1",N36<>"K4",N36<>"K5"),"R1 hanya dengan K4 atau K5",IF(AND(I36="R2",N36="K5"),"R2 tidak boleh K5",IF(AND(K36="P9",J36<>"T17"),"P9 hanya dengan T17",IF(AND(J36="T01",K36<>"P6",Q36=""),"Periksa T01-P6: jelaskan di V12",IF(AND(K36="P1",N36<>"K4",Q36=""),"Periksa P1-K4: jelaskan di V12",IF(AND(J36="T99",Q36=""),"Periksa T99: wajib isi V12","OK")))))))) -> Lengkapi V4-V9
A37: 37 | B37: =IF(Petunjuk!$C$4="","",Petunjuk!$C$4) | C37: UU 27 Thn 2022 (PDP) | E37: Pasal 10 | F37: BAB IV HAK SUBJEK DATA PRIBADI | H37: (1) Subjek Data Pribadi berhak untuk mengajukan keberatan atas tindakan pengambilan keputusan yang hanya didasarkan pada pemrosesan secara otomatis, termasuk pemrofilan, yang menimbulkan akibat hukum atau berdampak signifikan pada Subjek Data Pribadi.(2) Ketentuan lebih lanjut mengenai pengajuan keberatan atas pemrosesan secara otomatis sebagaimana dimaksud pada ayat (l) diatur dalam Peraturan Pemerintah. | R37: =IF(COUNTA(I37:N37)<6,"Lengkapi V4-V9",IF(AND(I37="R0",N37<>"K5"),"R0 harus berpasangan dengan K5",IF(AND(I37="R1",N37<>"K4",N37<>"K5"),"R1 hanya dengan K4 atau K5",IF(AND(I37="R2",N37="K5"),"R2 tidak boleh K5",IF(AND(K37="P9",J37<>"T17"),"P9 hanya dengan T17",IF(AND(J37="T01",K37<>"P6",Q37=""),"Periksa T01-P6: jelaskan di V12",IF(AND(K37="P1",N37<>"K4",Q37=""),"Periksa P1-K4: jelaskan di V12",IF(AND(J37="T99",Q37=""),"Periksa T99: wajib isi V12","OK")))))))) -> Lengkapi V4-V9
A38: 38 | B38: =IF(Petunjuk!$C$4="","",Petunjuk!$C$4) | C38: UU 27 Thn 2022 (PDP) | E38: Pasal 11 | F38: BAB IV HAK SUBJEK DATA PRIBADI | H38: Subjek Data Pribadi berhak menunda atau membatasi pemrosesan Data Pribadi secara proporsional sesuai dengan tujuan pemrosesan Data Pribadi. | R38: =IF(COUNTA(I38:N38)<6,"Lengkapi V4-V9",IF(AND(I38="R0",N38<>"K5"),"R0 harus berpasangan dengan K5",IF(AND(I38="R1",N38<>"K4",N38<>"K5"),"R1 hanya dengan K4 atau K5",IF(AND(I38="R2",N38="K5"),"R2 tidak boleh K5",IF(AND(K38="P9",J38<>"T17"),"P9 hanya dengan T17",IF(AND(J38="T01",K38<>"P6",Q38=""),"Periksa T01-P6: jelaskan di V12",IF(AND(K38="P1",N38<>"K4",Q38=""),"Periksa P1-K4: jelaskan di V12",IF(AND(J38="T99",Q38=""),"Periksa T99: wajib isi V12","OK")))))))) -> Lengkapi V4-V9
A39: 39 | B39: =IF(Petunjuk!$C$4="","",Petunjuk!$C$4) | C39: UU 27 Thn 2022 (PDP) | E39: Pasal 12 | F39: BAB IV HAK SUBJEK DATA PRIBADI | H39: (1) Subjek Data Pribadi berhak menggugat dan menerima ganti rugi atas pelanggaran pemrosesan Data Pribadi tentang dirinya sesuai dengan ketentuan peraturan perundang-undangan.(2) Ketentuan lebih lanjut mengenai pelanggaran pemrosesan Data Pribadi dan tata cara pengenaan ganti rugi sebagaimana dimaksud pada ayat (1) diatur dalam Peraturan Pemerintah. | R39: =IF(COUNTA(I39:N39)<6,"Lengkapi V4-V9",IF(AND(I39="R0",N39<>"K5"),"R0 harus berpasangan dengan K5",IF(AND(I39="R1",N39<>"K4",N39<>"K5"),"R1 hanya dengan K4 atau K5",IF(AND(I39="R2",N39="K5"),"R2 tidak boleh K5",IF(AND(K39="P9",J39<>"T17"),"P9 hanya dengan T17",IF(AND(J39="T01",K39<>"P6",Q39=""),"Periksa T01-P6: jelaskan di V12",IF(AND(K39="P1",N39<>"K4",Q39=""),"Periksa P1-K4: jelaskan di V12",IF(AND(J39="T99",Q39=""),"Periksa T99: wajib isi V12","OK")))))))) -> Lengkapi V4-V9
A40: 40 | B40: =IF(Petunjuk!$C$4="","",Petunjuk!$C$4) | C40: UU 27 Thn 2022 (PDP) | E40: Pasal 13 | F40: BAB IV HAK SUBJEK DATA PRIBADI | H40: (1) Subjek Data Pribadi berhak mendapatkan dan/atau menggunakan Data Pribadi tentang dirinya dari Pengendali Data Pribadi dalam bentuk yang sesuai dengan struktur dan/ atau format yang lazim digunakan atau dapat dibaca oleh sistem elektronik.(2) Subjek Data Pribadi berhak menggunakan dan mengirimkan Data Pribadi tentang dirinya ke Pengendali Data Pribadi lainnya, sepanjang sistem yang digunakan dapat saling berkomunikasi secara aman sesuai dengan prinsip Pelindungan Data Pribadi berdasarkan Undang-Undang ini.(3) Ketentuan lebih lanjut mengenai hak Subjek Data Pribadi untuk menggunakan dan mengirimkan Data Pribadi sebagaimana dimaksud pada ayat (2) diatur dalam Peraturan Pemerintah. | R40: =IF(COUNTA(I40:N40)<6,"Lengkapi V4-V9",IF(AND(I40="R0",N40<>"K5"),"R0 harus berpasangan dengan K5",IF(AND(I40="R1",N40<>"K4",N40<>"K5"),"R1 hanya dengan K4 atau K5",IF(AND(I40="R2",N40="K5"),"R2 tidak boleh K5",IF(AND(K40="P9",J40<>"T17"),"P9 hanya dengan T17",IF(AND(J40="T01",K40<>"P6",Q40=""),"Periksa T01-P6: jelaskan di V12",IF(AND(K40="P1",N40<>"K4",Q40=""),"Periksa P1-K4: jelaskan di V12",IF(AND(J40="T99",Q40=""),"Periksa T99: wajib isi V12","OK")))))))) -> Lengkapi V4-V9
...

Sheet Daftar Kode
A1: Daftar kode (ringkasan dari codebook Versi 1.0; definisi lengkap ada di codebook)
A3: V4 Relevansi
A4: R0 | B4: Tidak relevan | C4: Tidak memengaruhi desain atau perilaku sistem
A5: R1 | B5: Relevan tidak langsung | C5: Definisi, asas, konsep, latar, atau norma khusus pihak tertentu
A6: R2 | B6: Relevan langsung | C6: Kewajiban, larangan, hak, syarat, atau batasan yang dapat diturunkan menjadi kebutuhan sistem
A8: V5 Tema Utama (jalankan pohon keputusan Bagian 6.2)
A9: T01 | B9: Definisi, Istilah, dan Ruang Lingkup
A10: T02 | B10: Asas dan Prinsip Pemrosesan
A11: T03 | B11: Jenis dan Klasifikasi Data Pribadi
A12: T04 | B12: Hak Subjek Data Pribadi
A13: T05 | B13: Dasar Pemrosesan dan Persetujuan
A14: T06 | B14: Aktivitas Pemrosesan dan Pengumpulan
A15: T07 | B15: Data Pribadi Anak dan Kelompok Rentan
A16: T08 | B16: Kualitas, Akurasi, dan Pembaruan Data
A17: T09 | B17: Akuntabilitas, Pencatatan, dan Tata Kelola Kepatuhan
A18: T10 | B18: Keamanan, Kerahasiaan, dan Penanganan Insiden
A19: T11 | B19: Retensi, Penghentian, Penghapusan, dan Pemusnahan
A20: T12 | B20: Pengecualian dan Pembatasan
... A25: T17 | B25: Rujukan Regulasi Lain
A26: T99 | B26: Lainnya | C26: Residual: hanya bila pohon keputusan tidak menghasilkan tema; wajib isi V12
A28: V6 Jenis Pernyataan (prioritas bila seri: P1 > P2 > P3 > P5 > P4 > P6 > P7 > P8 > P9)
A29: P1 | B29: Larangan | C29: dilarang, tidak boleh
A30: P2 | B30: Kewajiban | C30: wajib, harus, berkewajiban
A31: P3 | B31: Hak | C31: berhak, hak
A32: P4 | B32: Kebolehan atau kewenangan | C32: dapat, boleh, berwenang
A33: P5 | B33: Pengecualian atau pembatasan | C33: dikecualikan, tidak berlaku, wajib menolak
A34: P6 | B34: Definisi, klasifikasi, atau ruang lingkup | C34: yang dimaksud dengan, meliputi, berlaku untuk
A35: P7 | B35: Asas, prinsip, atau tujuan umum
A36: P8 | B36: Deskriptif, argumentatif, atau rekomendasi | C36: khas artikel
A37: P9 | B37: Rujukan atau daftar | C37: hanya berpasangan dengan T17
A39: V7 Subjek Norma
A40: S1 | B40: Pengendali Data Pribadi
A41: S2 | B41: Prosesor Data Pribadi
A42: S3 | B42: Pengendali dan Prosesor | C42: keduanya disebut
A43: S4 | B43: Subjek Data Pribadi
A44: S5 | B44: Setiap Orang atau pihak umum
A45: S6 | B45: Instansi atau Badan Publik
A46: S7 | B46: Lembaga atau Pemerintah (otoritas)
A47: S8 | B47: Penyelenggara sektor atau pihak lain
A48: S9 | B48: Tidak ada subjek eksplisit | C48: jangan menebak subjek
...
