Workbook

Sheet Petunjuk
A1: File Kunci Adjudikasi: Analisis Isi Krippendorff
A2: Codebook versi 1.0.2 (20 Oktober 2026). Hanya untuk peneliti utama (adjudikator). Jangan dibagikan kepada coder.
B4: Alur kerja
B5: 1 | C5: Tempel korpus ke sheet Korpus (A1:F87). Kolom Dokumen, Rujukan, BAB, Bagian, dan Isi pada Kunci Adjudikasi terisi otomatis.
B6: 2 | C6: Setelah coder A dan B selesai, salin nilai V4 sampai V9 dari kolom F sampai K lembar coding masing-masing (baris 2 sampai 86) ke blok Coder A (M sampai R) dan Coder B (S sampai X) mulai baris 5. Tempel sebagai nilai (Paste Values). Urutan baris sama, ID_Unit 2 sampai 86.
B7: 3 | C7: Kolom Y sampai AD menandai Sama atau Beda per variabel. Sheet Reliabilitas menghitung Krippendorff alpha dari data sebelum rekonsiliasi.
B8: 4 | C8: Setelah α dilaporkan, selesaikan setiap perbedaan melalui diskusi, isi Keputusan Adjudikator (AF sampai AK) hanya pada variabel yang berbeda, dan tulis alasannya di AR.
B9: 5 | C9: Kode Final (AL sampai AQ) = keputusan adjudikator bila ada, selain itu kode yang disepakati kedua coder. Kolom AT memeriksa aturan konsistensi (Bagian 9) pada kode final.
B10: 6 | C10: Kode Acuan Peneliti (G sampai L) terisi untuk 11 contoh pada Bagian 12 codebook (baris 2, 15, 22, 28, 30, 32, 49, 62, 67, 83, 86). Isi baris lain bila peneliti ingin menyimpan kunci sendiri; kolom ini tidak dihitung dalam α.
B11: Catatan metode
B12: α | C12: Dihitung langsung dari data pasangan coder yang lengkap: V4, V6, V7, V8, V9 nominal dan V5 ordinal (Bagian 13). Hanya unit yang diisi kedua coder yang dihitung.
B13: Selang kepercayaan | C13: Selang kepercayaan bootstrap belum dihitung di Excel. Hitung dengan paket krippendorff (Python) atau kripp.alpha pada paket irr (R) dari data yang sama.
B14: Kriteria | C14: α ≥ 0,800 dapat diterima; 0,667 ≤ α < 0,800 hanya untuk kesimpulan tentatif; α < 0,667 revisi variabel dan kodekan ulang.
B15: Warna | C15: Kuning: sel input. Biru muda: Coder A. Oranye muda: Coder B. Hijau muda: kunci peneliti dan kode final.

Sheet Kunci Adjudikasi
A1: Kunci Adjudikasi
A2: Isi V4 sampai V9 coder A dan B (tempel nilai), lalu isi keputusan adjudikator hanya untuk variabel yang berbeda.
A3: Identitas dan teks (dari Korpus) | G3: Kode Acuan Peneliti (Bagian 12) | M3: Coder A | S3: Coder B | Y3: Sama / Beda | AE3: Beda | AF3: Keputusan Adjudikator | AL3: Kode Final | AR3: Catatan | AS3: Status | AT3: Cek
A4: V1 ID_Unit | B4: Dokumen | C4: Rujukan | D4: BAB | E4: Bagian | F4: Isi | G4: V4 Acuan | H4: V5 Acuan | I4: V6 Acuan | J4: V7 Acuan | K4: V8 Acuan | L4: V9 Acuan | M4: V4 A | N4: V5 A | O4: V6 A | P4: V7 A | Q4: V8 A | R4: V9 A | S4: V4 B | T4: V5 B | U4: V6 B | V4: V7 B | W4: V8 B | X4: V9 B | Y4: V4 | Z4: V5 | AA4: V6 | AB4: V7 | AC4: V8 | AD4: V9 | AE4: Jumlah Beda | AF4: V4 Keputusan | AG4: V5 Keputusan | AH4: V6 Keputusan | AI4: V7 Keputusan | AJ4: V8 Keputusan | AK4: V9 Keputusan | AL4: V4 Final | AM4: V5 Final | AN4: V6 Final | AO4: V7 Final | AP4: V8 Final | AQ4: V9 Final | AR4: Alasan Adjudikasi | AS4: Status | AT4: Cek Konsistensi Final
A5: 2 | B5: =IF(INDEX(Korpus!$A:$A,$A5)="","",INDEX(Korpus!$A:$A,$A5)) | C5: =TRIM(INDEX(Korpus!$D:$D,$A5)&" "&INDEX(Korpus!$E:$E,$A5)) | D5: =IF(INDEX(Korpus!$B:$B,$A5)="","",INDEX(Korpus!$B:$B,$A5)) | E5: =IF(INDEX(Korpus!$C:$C,$A5)="","",INDEX(Korpus!$C:$C,$A5)) | F5: =IF(INDEX(Korpus!$F:$F,$A5)="","",INDEX(Korpus!$F:$F,$A5)) | G5: S9 | H5: R1 | I5: T16 | J5: P8 | K5: F8 | L5: K5 | Y5: =IF(OR(M5="",S5=""),"",IF(M5=S5,"Sama","Beda")) | Z5: =IF(OR(N5="",T5=""),"",IF(N5=T5,"Sama","Beda")) | AA5: =IF(OR(O5="",U5=""),"",IF(O5=U5,"Sama","Beda")) | AB5: =IF(OR(P5="",V5=""),"",IF(P5=V5,"Sama","Beda")) | AC5: =IF(OR(Q5="",W5=""),"",IF(Q5=W5,"Sama","Beda")) | AD5: =IF(OR(R5="",X5=""),"",IF(R5=X5,"Sama","Beda")) | AE5: =COUNTIF(Y5:AD5,"Beda") -> 0 | AL5: =IF(AF5<>"",AF5,IF(AND(M5<>"",M5=S5),M5,"")) | AM5: =IF(AG5<>"",AG5,IF(AND(N5<>"",N5=T5),N5,"")) | AN5: =IF(AH5<>"",AH5,IF(AND(O5<>"",O5=U5),O5,"")) | AO5: =IF(AI5<>"",AI5,IF(AND(P5<>"",P5=V5),P5,"")) | AP5: =IF(AJ5<>"",AJ5,IF(AND(Q5<>"",Q5=W5),Q5,"")) | AQ5: =IF(AK5<>"",AK5,IF(AND(R5<>"",R5=X5),R5,"")) | AS5: =IF(COUNTA(M5:R5)+COUNTA(S5:X5)<12,"Menunggu coder",IF(AE5=0,"Sepakat",IF(SUMPRODUCT((Y5:AD5="Beda")*(AF5:AK5=""))=0,"Selesai adjudikasi","Perlu adjudikasi"))) -> Menunggu coder | AT5: =IF(COUNTIF(AL5:AQ5,"?*")<6,"",IF(IF(AND(AM5="R0",AQ5<>"K5"),"R0 harus K5; ","")&IF(AND(AM5="R1",AQ5="K3"),"R1 tidak boleh K3 (fungsional); ","")&IF(AND(AM5="R2",AQ5="K5"),"R2 tidak boleh K5; ","")&IF(AND(AM5="R2",OR(AL5="S6",AL5="S7",AL5="S8")),"R2 tidak boleh S6/S7/S8; ","")&IF(AND(AO5="P9",AN5<>"T17"),"P9 hanya dengan T17; ","")&IF(AND(OR(AN5="T17",AO5="P9"),AM5<>"R0"),"T17/P9 harus R0; ","")&IF(AND(AN5="T01",AO5<>"P6"),"T01 biasanya P6 (periksa); ","")&IF(AND(AO5="P1",AQ5<>"K4"),"P1 biasanya K4 (periksa); ","")="","OK",IF(AND(AM5="R0",AQ5<>"K5"),"R0 harus K5; ","")&IF(AND(AM5="R1",AQ5="K3"),"R1 tidak boleh K3 (fungsional); ","")&IF(AND(AM5="R2",AQ5="K5"),"R2 tidak boleh K5; ","")&IF(AND(AM5="R2",OR(AL5="S6",AL5="S7",AL5="S8")),"R2 tidak boleh S6/S7/S8; ","")&IF(AND(AO5="P9",AN5<>"T17"),"P9 hanya dengan T17; ","")&IF(AND(OR(AN5="T17",AO5="P9"),AM5<>"R0"),"T17/P9 harus R0; ","")&IF(AND(AN5="T01",AO5<>"P6"),"T01 biasanya P6 (periksa); ","")&IF(AND(AO5="P1",AQ5<>"K4"),"P1 biasanya K4 (periksa); ","")))
A6: 3 | B6: =IF(INDEX(Korpus!$A:$A,$A6)="","",INDEX(Korpus!$A:$A,$A6)) | C6: =TRIM(INDEX(Korpus!$D:$D,$A6)&" "&INDEX(Korpus!$E:$E,$A6)) | D6: =IF(INDEX(Korpus!$B:$B,$A6)="","",INDEX(Korpus!$B:$B,$A6)) | E6: =IF(INDEX(Korpus!$C:$C,$A6)="","",INDEX(Korpus!$C:$C,$A6)) | F6: =IF(INDEX(Korpus!$F:$F,$A6)="","",INDEX(Korpus!$F:$F,$A6)) | Y6: =IF(OR(M6="",S6=""),"",IF(M6=S6,"Sama","Beda")) | Z6: =IF(OR(N6="",T6=""),"",IF(N6=T6,"Sama","Beda")) | AA6: =IF(OR(O6="",U6=""),"",IF(O6=U6,"Sama","Beda")) | AB6: =IF(OR(P6="",V6=""),"",IF(P6=V6,"Sama","Beda")) | AC6: =IF(OR(Q6="",W6=""),"",IF(Q6=W6,"Sama","Beda")) | AD6: =IF(OR(R6="",X6=""),"",IF(R6=X6,"Sama","Beda")) | AE6: =COUNTIF(Y6:AD6,"Beda") -> 0 | AL6: =IF(AF6<>"",AF6,IF(AND(M6<>"",M6=S6),M6,"")) | AM6: =IF(AG6<>"",AG6,IF(AND(N6<>"",N6=T6),N6,"")) | AN6: =IF(AH6<>"",AH6,IF(AND(O6<>"",O6=U6),O6,"")) | AO6: =IF(AI6<>"",AI6,IF(AND(P6<>"",P6=V6),P6,"")) | AP6: =IF(AJ6<>"",AJ6,IF(AND(Q6<>"",Q6=W6),Q6,"")) | AQ6: =IF(AK6<>"",AK6,IF(AND(R6<>"",R6=X6),R6,"")) | AS6: =IF(COUNTA(M6:R6)+COUNTA(S6:X6)<12,"Menunggu coder",IF(AE6=0,"Sepakat",IF(SUMPRODUCT((Y6:AD6="Beda")*(AF6:AK6=""))=0,"Selesai adjudikasi","Perlu adjudikasi"))) -> Menunggu coder | AT6: =IF(COUNTIF(AL6:AQ6,"?*")<6,"",IF(IF(AND(AM6="R0",AQ6<>"K5"),"R0 harus K5; ","")&IF(AND(AM6="R1",AQ6="K3"),"R1 tidak boleh K3 (fungsional); ","")&IF(AND(AM6="R2",AQ6="K5"),"R2 tidak boleh K5; ","")&IF(AND(AM6="R2",OR(AL6="S6",AL6="S7",AL6="S8")),"R2 tidak boleh S6/S7/S8; ","")&IF(AND(AO6="P9",AN6<>"T17"),"P9 hanya dengan T17; ","")&IF(AND(OR(AN6="T17",AO6="P9"),AM6<>"R0"),"T17/P9 harus R0; ","")&IF(AND(AN6="T01",AO6<>"P6"),"T01 biasanya P6 (periksa); ","")&IF(AND(AO6="P1",AQ6<>"K4"),"P1 biasanya K4 (periksa); ","")="","OK",IF(AND(AM6="R0",AQ6<>"K5"),"R0 harus K5; ","")&IF(AND(AM6="R1",AQ6="K3"),"R1 tidak boleh K3 (fungsional); ","")&IF(AND(AM6="R2",AQ6="K5"),"R2 tidak boleh K5; ","")&IF(AND(AM6="R2",OR(AL6="S6",AL6="S7",AL6="S8")),"R2 tidak boleh S6/S7/S8; ","")&IF(AND(AO6="P9",AN6<>"T17"),"P9 hanya dengan T17; ","")&IF(AND(OR(AN6="T17",AO6="P9"),AM6<>"R0"),"T17/P9 harus R0; ","")&IF(AND(AN6="T01",AO6<>"P6"),"T01 biasanya P6 (periksa); ","")&IF(AND(AO6="P1",AQ6<>"K4"),"P1 biasanya K4 (periksa); ","")))
A7: 4 | B7: =IF(INDEX(Korpus!$A:$A,$A7)="","",INDEX(Korpus!$A:$A,$A7)) | C7: =TRIM(INDEX(Korpus!$D:$D,$A7)&" "&INDEX(Korpus!$E:$E,$A7)) | D7: =IF(INDEX(Korpus!$B:$B,$A7)="","",INDEX(Korpus!$B:$B,$A7)) | E7: =IF(INDEX(Korpus!$C:$C,$A7)="","",INDEX(Korpus!$C:$C,$A7)) | F7: =IF(INDEX(Korpus!$F:$F,$A7)="","",INDEX(Korpus!$F:$F,$A7)) | Y7: =IF(OR(M7="",S7=""),"",IF(M7=S7,"Sama","Beda")) | Z7: =IF(OR(N7="",T7=""),"",IF(N7=T7,"Sama","Beda")) | AA7: =IF(OR(O7="",U7=""),"",IF(O7=U7,"Sama","Beda")) | AB7: =IF(OR(P7="",V7=""),"",IF(P7=V7,"Sama","Beda")) | AC7: =IF(OR(Q7="",W7=""),"",IF(Q7=W7,"Sama","Beda")) | AD7: =IF(OR(R7="",X7=""),"",IF(R7=X7,"Sama","Beda")) | AE7: =COUNTIF(Y7:AD7,"Beda") -> 0 | AL7: =IF(AF7<>"",AF7,IF(AND(M7<>"",M7=S7),M7,"")) | AM7: =IF(AG7<>"",AG7,IF(AND(N7<>"",N7=T7),N7,"")) | AN7: =IF(AH7<>"",AH7,IF(AND(O7<>"",O7=U7),O7,"")) | AO7: =IF(AI7<>"",AI7,IF(AND(P7<>"",P7=V7),P7,"")) | AP7: =IF(AJ7<>"",AJ7,IF(AND(Q7<>"",Q7=W7),Q7,"")) | AQ7: =IF(AK7<>"",AK7,IF(AND(R7<>"",R7=X7),R7,"")) | AS7: =IF(COUNTA(M7:R7)+COUNTA(S7:X7)<12,"Menunggu coder",IF(AE7=0,"Sepakat",IF(SUMPRODUCT((Y7:AD7="Beda")*(AF7:AK7=""))=0,"Selesai adjudikasi","Perlu adjudikasi"))) -> Menunggu coder | AT7: =IF(COUNTIF(AL7:AQ7,"?*")<6,"",IF(IF(AND(AM7="R0",AQ7<>"K5"),"R0 harus K5; ","")&IF(AND(AM7="R1",AQ7="K3"),"R1 tidak boleh K3 (fungsional); ","")&IF(AND(AM7="R2",AQ7="K5"),"R2 tidak boleh K5; ","")&IF(AND(AM7="R2",OR(AL7="S6",AL7="S7",AL7="S8")),"R2 tidak boleh S6/S7/S8; ","")&IF(AND(AO7="P9",AN7<>"T17"),"P9 hanya dengan T17; ","")&IF(AND(OR(AN7="T17",AO7="P9"),AM7<>"R0"),"T17/P9 harus R0; ","")&IF(AND(AN7="T01",AO7<>"P6"),"T01 biasanya P6 (periksa); ","")&IF(AND(AO7="P1",AQ7<>"K4"),"P1 biasanya K4 (periksa); ","")="","OK",IF(AND(AM7="R0",AQ7<>"K5"),"R0 harus K5; ","")&IF(AND(AM7="R1",AQ7="K3"),"R1 tidak boleh K3 (fungsional); ","")&IF(AND(AM7="R2",AQ7="K5"),"R2 tidak boleh K5; ","")&IF(AND(AM7="R2",OR(AL7="S6",AL7="S7",AL7="S8")),"R2 tidak boleh S6/S7/S8; ","")&IF(AND(AO7="P9",AN7<>"T17"),"P9 hanya dengan T17; ","")&IF(AND(OR(AN7="T17",AO7="P9"),AM7<>"R0"),"T17/P9 harus R0; ","")&IF(AND(AN7="T01",AO7<>"P6"),"T01 biasanya P6 (periksa); ","")&IF(AND(AO7="P1",AQ7<>"K4"),"P1 biasanya K4 (periksa); ","")))
A8: 5 | B8: =IF(INDEX(Korpus!$A:$A,$A8)="","",INDEX(Korpus!$A:$A,$A8)) | C8: =TRIM(INDEX(Korpus!$D:$D,$A8)&" "&INDEX(Korpus!$E:$E,$A8)) | D8: =IF(INDEX(Korpus!$B:$B,$A8)="","",INDEX(Korpus!$B:$B,$A8)) | E8: =IF(INDEX(Korpus!$C:$C,$A8)="","",INDEX(Korpus!$C:$C,$A8)) | F8: =IF(INDEX(Korpus!$F:$F,$A8)="","",INDEX(Korpus!$F:$F,$A8)) | Y8: =IF(OR(M8="",S8=""),"",IF(M8=S8,"Sama","Beda")) | Z8: =IF(OR(N8="",T8=""),"",IF(N8=T8,"Sama","Beda")) | AA8: =IF(OR(O8="",U8=""),"",IF(O8=U8,"Sama","Beda")) | AB8: =IF(OR(P8="",V8=""),"",IF(P8=V8,"Sama","Beda")) | AC8: =IF(OR(Q8="",W8=""),"",IF(Q8=W8,"Sama","Beda")) | AD8: =IF(OR(R8="",X8=""),"",IF(R8=X8,"Sama","Beda")) | AE8: =COUNTIF(Y8:AD8,"Beda") -> 0 | AL8: =IF(AF8<>"",AF8,IF(AND(M8<>"",M8=S8),M8,"")) | AM8: =IF(AG8<>"",AG8,IF(AND(N8<>"",N8=T8),N8,"")) | AN8: =IF(AH8<>"",AH8,IF(AND(O8<>"",O8=U8),O8,"")) | AO8: =IF(AI8<>"",AI8,IF(AND(P8<>"",P8=V8),P8,"")) | AP8: =IF(AJ8<>"",AJ8,IF(AND(Q8<>"",Q8=W8),Q8,"")) | AQ8: =IF(AK8<>"",AK8,IF(AND(R8<>"",R8=X8),R8,"")) | AS8: =IF(COUNTA(M8:R8)+COUNTA(S8:X8)<12,"Menunggu coder",IF(AE8=0,"Sepakat",IF(SUMPRODUCT((Y8:AD8="Beda")*(AF8:AK8=""))=0,"Selesai adjudikasi","Perlu adjudikasi"))) -> Menunggu coder | AT8: =IF(COUNTIF(AL8:AQ8,"?*")<6,"",IF(IF(AND(AM8="R0",AQ8<>"K5"),"R0 harus K5; ","")&IF(AND(AM8="R1",AQ8="K3"),"R1 tidak boleh K3 (fungsional); ","")&IF(AND(AM8="R2",AQ8="K5"),"R2 tidak boleh K5; ","")&IF(AND(AM8="R2",OR(AL8="S6",AL8="S7",AL8="S8")),"R2 tidak boleh S6/S7/S8; ","")&IF(AND(AO8="P9",AN8<>"T17"),"P9 hanya dengan T17; ","")&IF(AND(OR(AN8="T17",AO8="P9"),AM8<>"R0"),"T17/P9 harus R0; ","")&IF(AND(AN8="T01",AO8<>"P6"),"T01 biasanya P6 (periksa); ","")&IF(AND(AO8="P1",AQ8<>"K4"),"P1 biasanya K4 (periksa); ","")="","OK",IF(AND(AM8="R0",AQ8<>"K5"),"R0 harus K5; ","")&IF(AND(AM8="R1",AQ8="K3"),"R1 tidak boleh K3 (fungsional); ","")&IF(AND(AM8="R2",AQ8="K5"),"R2 tidak boleh K5; ","")&IF(AND(AM8="R2",OR(AL8="S6",AL8="S7",AL8="S8")),"R2 tidak boleh S6/S7/S8; ","")&IF(AND(AO8="P9",AN8<>"T17"),"P9 hanya dengan T17; ","")&IF(AND(OR(AN8="T17",AO8="P9"),AM8<>"R0"),"T17/P9 harus R0; ","")&IF(AND(AN8="T01",AO8<>"P6"),"T01 biasanya P6 (periksa); ","")&IF(AND(AO8="P1",AQ8<>"K4"),"P1 biasanya K4 (periksa); ","")))
A9: 6 | B9: =IF(INDEX(Korpus!$A:$A,$A9)="","",INDEX(Korpus!$A:$A,$A9)) | C9: =TRIM(INDEX(Korpus!$D:$D,$A9)&" "&INDEX(Korpus!$E:$E,$A9)) | D9: =IF(INDEX(Korpus!$B:$B,$A9)="","",INDEX(Korpus!$B:$B,$A9)) | E9: =IF(INDEX(Korpus!$C:$C,$A9)="","",INDEX(Korpus!$C:$C,$A9)) | F9: =IF(INDEX(Korpus!$F:$F,$A9)="","",INDEX(Korpus!$F:$F,$A9)) | Y9: =IF(OR(M9="",S9=""),"",IF(M9=S9,"Sama","Beda")) | Z9: =IF(OR(N9="",T9=""),"",IF(N9=T9,"Sama","Beda")) | AA9: =IF(OR(O9="",U9=""),"",IF(O9=U9,"Sama","Beda")) | AB9: =IF(OR(P9="",V9=""),"",IF(P9=V9,"Sama","Beda")) | AC9: =IF(OR(Q9="",W9=""),"",IF(Q9=W9,"Sama","Beda")) | AD9: =IF(OR(R9="",X9=""),"",IF(R9=X9,"Sama","Beda")) | AE9: =COUNTIF(Y9:AD9,"Beda") -> 0 | AL9: =IF(AF9<>"",AF9,IF(AND(M9<>"",M9=S9),M9,"")) | AM9: =IF(AG9<>"",AG9,IF(AND(N9<>"",N9=T9),N9,"")) | AN9: =IF(AH9<>"",AH9,IF(AND(O9<>"",O9=U9),O9,"")) | AO9: =IF(AI9<>"",AI9,IF(AND(P9<>"",P9=V9),P9,"")) | AP9: =IF(AJ9<>"",AJ9,IF(AND(Q9<>"",Q9=W9),Q9,"")) | AQ9: =IF(AK9<>"",AK9,IF(AND(R9<>"",R9=X9),R9,"")) | AS9: =IF(COUNTA(M9:R9)+COUNTA(S9:X9)<12,"Menunggu coder",IF(AE9=0,"Sepakat",IF(SUMPRODUCT((Y9:AD9="Beda")*(AF9:AK9=""))=0,"Selesai adjudikasi","Perlu adjudikasi"))) -> Menunggu coder | AT9: =IF(COUNTIF(AL9:AQ9,"?*")<6,"",IF(IF(AND(AM9="R0",AQ9<>"K5"),"R0 harus K5; ","")&IF(AND(AM9="R1",AQ9="K3"),"R1 tidak boleh K3 (fungsional); ","")&IF(AND(AM9="R2",AQ9="K5"),"R2 tidak boleh K5; ","")&IF(AND(AM9="R2",OR(AL9="S6",AL9="S7",AL9="S8")),"R2 tidak boleh S6/S7/S8; ","")&IF(AND(AO9="P9",AN9<>"T17"),"P9 hanya dengan T17; ","")&IF(AND(OR(AN9="T17",AO9="P9"),AM9<>"R0"),"T17/P9 harus R0; ","")&IF(AND(AN9="T01",AO9<>"P6"),"T01 biasanya P6 (periksa); ","")&IF(AND(AO9="P1",AQ9<>"K4"),"P1 biasanya K4 (periksa); ","")="","OK",IF(AND(AM9="R0",AQ9<>"K5"),"R0 harus K5; ","")&IF(AND(AM9="R1",AQ9="K3"),"R1 tidak boleh K3 (fungsional); ","")&IF(AND(AM9="R2",AQ9="K5"),"R2 tidak boleh K5; ","")&IF(AND(AM9="R2",OR(AL9="S6",AL9="S7",AL9="S8")),"R2 tidak boleh S6/S7/S8; ","")&IF(AND(AO9="P9",AN9<>"T17"),"P9 hanya dengan T17; ","")&IF(AND(OR(AN9="T17",AO9="P9"),AM9<>"R0"),"T17/P9 harus R0; ","")&IF(AND(AN9="T01",AO9<>"P6"),"T01 biasanya P6 (periksa); ","")&IF(AND(AO9="P1",AQ9<>"K4"),"P1 biasanya K4 (periksa); ","")))
A10: 7 | B10: =IF(INDEX(Korpus!$A:$A,$A10)="","",INDEX(Korpus!$A:$A,$A10)) | C10: =TRIM(INDEX(Korpus!$D:$D,$A10)&" "&INDEX(Korpus!$E:$E,$A10)) | D10: =IF(INDEX(Korpus!$B:$B,$A10)="","",INDEX(Korpus!$B:$B,$A10)) | E10: =IF(INDEX(Korpus!$C:$C,$A10)="","",INDEX(Korpus!$C:$C,$A10)) | F10: =IF(INDEX(Korpus!$F:$F,$A10)="","",INDEX(Korpus!$F:$F,$A10)) | Y10: =IF(OR(M10="",S10=""),"",IF(M10=S10,"Sama","Beda")) | Z10: =IF(OR(N10="",T10=""),"",IF(N10=T10,"Sama","Beda")) | AA10: =IF(OR(O10="",U10=""),"",IF(O10=U10,"Sama","Beda")) | AB10: =IF(OR(P10="",V10=""),"",IF(P10=V10,"Sama","Beda")) | AC10: =IF(OR(Q10="",W10=""),"",IF(Q10=W10,"Sama","Beda")) | AD10: =IF(OR(R10="",X10=""),"",IF(R10=X10,"Sama","Beda")) | AE10: =COUNTIF(Y10:AD10,"Beda") -> 0 | AL10: =IF(AF10<>"",AF10,IF(AND(M10<>"",M10=S10),M10,"")) | AM10: =IF(AG10<>"",AG10,IF(AND(N10<>"",N10=T10),N10,"")) | AN10: =IF(AH10<>"",AH10,IF(AND(O10<>"",O10=U10),O10,"")) | AO10: =IF(AI10<>"",AI10,IF(AND(P10<>"",P10=V10),P10,"")) | AP10: =IF(AJ10<>"",AJ10,IF(AND(Q10<>"",Q10=W10),Q10,"")) | AQ10: =IF(AK10<>"",AK10,IF(AND(R10<>"",R10=X10),R10,"")) | AS10: =IF(COUNTA(M10:R10)+COUNTA(S10:X10)<12,"Menunggu coder",IF(AE10=0,"Sepakat",IF(SUMPRODUCT((Y10:AD10="Beda")*(AF10:AK10=""))=0,"Selesai adjudikasi","Perlu adjudikasi"))) -> Menunggu coder | AT10: =IF(COUNTIF(AL10:AQ10,"?*")<6,"",IF(IF(AND(AM10="R0",AQ10<>"K5"),"R0 harus K5; ","")&IF(AND(AM10="R1",AQ10="K3"),"R1 tidak boleh K3 (fungsional); ","")&IF(AND(AM10="R2",AQ10="K5"),"R2 tidak boleh K5; ","")&IF(AND(AM10="R2",OR(AL10="S6",AL10="S7",AL10="S8")),"R2 tidak boleh S6/S7/S8; ","")&IF(AND(AO10="P9",AN10<>"T17"),"P9 hanya dengan T17; ","")&IF(AND(OR(AN10="T17",AO10="P9"),AM10<>"R0"),"T17/P9 harus R0; ","")&IF(AND(AN10="T01",AO10<>"P6"),"T01 biasanya P6 (periksa); ","")&IF(AND(AO10="P1",AQ10<>"K4"),"P1 biasanya K4 (periksa); ","")="","OK",IF(AND(AM10="R0",AQ10<>"K5"),"R0 harus K5; ","")&IF(AND(AM10="R1",AQ10="K3"),"R1 tidak boleh K3 (fungsional); ","")&IF(AND(AM10="R2",AQ10="K5"),"R2 tidak boleh K5; ","")&IF(AND(AM10="R2",OR(AL10="S6",AL10="S7",AL10="S8")),"R2 tidak boleh S6/S7/S8; ","")&IF(AND(AO10="P9",AN10<>"T17"),"P9 hanya dengan T17; ","")&IF(AND(OR(AN10="T17",AO10="P9"),AM10<>"R0"),"T17/P9 harus R0; ","")&IF(AND(AN10="T01",AO10<>"P6"),"T01 biasanya P6 (periksa); ","")&IF(AND(AO10="P1",AQ10<>"K4"),"P1 biasanya K4 (periksa); ","")))
A11: 8 | B11: =IF(INDEX(Korpus!$A:$A,$A11)="","",INDEX(Korpus!$A:$A,$A11)) | C11: =TRIM(INDEX(Korpus!$D:$D,$A11)&" "&INDEX(Korpus!$E:$E,$A11)) | D11: =IF(INDEX(Korpus!$B:$B,$A11)="","",INDEX(Korpus!$B:$B,$A11)) | E11: =IF(INDEX(Korpus!$C:$C,$A11)="","",INDEX(Korpus!$C:$C,$A11)) | F11: =IF(INDEX(Korpus!$F:$F,$A11)="","",INDEX(Korpus!$F:$F,$A11)) | Y11: =IF(OR(M11="",S11=""),"",IF(M11=S11,"Sama","Beda")) | Z11: =IF(OR(N11="",T11=""),"",IF(N11=T11,"Sama","Beda")) | AA11: =IF(OR(O11="",U11=""),"",IF(O11=U11,"Sama","Beda")) | AB11: =IF(OR(P11="",V11=""),"",IF(P11=V11,"Sama","Beda")) | AC11: =IF(OR(Q11="",W11=""),"",IF(Q11=W11,"Sama","Beda")) | AD11: =IF(OR(R11="",X11=""),"",IF(R11=X11,"Sama","Beda")) | AE11: =COUNTIF(Y11:AD11,"Beda") -> 0 | AL11: =IF(AF11<>"",AF11,IF(AND(M11<>"",M11=S11),M11,"")) | AM11: =IF(AG11<>"",AG11,IF(AND(N11<>"",N11=T11),N11,"")) | AN11: =IF(AH11<>"",AH11,IF(AND(O11<>"",O11=U11),O11,"")) | AO11: =IF(AI11<>"",AI11,IF(AND(P11<>"",P11=V11),P11,"")) | AP11: =IF(AJ11<>"",AJ11,IF(AND(Q11<>"",Q11=W11),Q11,"")) | AQ11: =IF(AK11<>"",AK11,IF(AND(R11<>"",R11=X11),R11,"")) | AS11: =IF(COUNTA(M11:R11)+COUNTA(S11:X11)<12,"Menunggu coder",IF(AE11=0,"Sepakat",IF(SUMPRODUCT((Y11:AD11="Beda")*(AF11:AK11=""))=0,"Selesai adjudikasi","Perlu adjudikasi"))) -> Menunggu coder | AT11: =IF(COUNTIF(AL11:AQ11,"?*")<6,"",IF(IF(AND(AM11="R0",AQ11<>"K5"),"R0 harus K5; ","")&IF(AND(AM11="R1",AQ11="K3"),"R1 tidak boleh K3 (fungsional); ","")&IF(AND(AM11="R2",AQ11="K5"),"R2 tidak boleh K5; ","")&IF(AND(AM11="R2",OR(AL11="S6",AL11="S7",AL11="S8")),"R2 tidak boleh S6/S7/S8; ","")&IF(AND(AO11="P9",AN11<>"T17"),"P9 hanya dengan T17; ","")&IF(AND(OR(AN11="T17",AO11="P9"),AM11<>"R0"),"T17/P9 harus R0; ","")&IF(AND(AN11="T01",AO11<>"P6"),"T01 biasanya P6 (periksa); ","")&IF(AND(AO11="P1",AQ11<>"K4"),"P1 biasanya K4 (periksa); ","")="","OK",IF(AND(AM11="R0",AQ11<>"K5"),"R0 harus K5; ","")&IF(AND(AM11="R1",AQ11="K3"),"R1 tidak boleh K3 (fungsional); ","")&IF(AND(AM11="R2",AQ11="K5"),"R2 tidak boleh K5; ","")&IF(AND(AM11="R2",OR(AL11="S6",AL11="S7",AL11="S8")),"R2 tidak boleh S6/S7/S8; ","")&IF(AND(AO11="P9",AN11<>"T17"),"P9 hanya dengan T17; ","")&IF(AND(OR(AN11="T17",AO11="P9"),AM11<>"R0"),"T17/P9 harus R0; ","")&IF(AND(AN11="T01",AO11<>"P6"),"T01 biasanya P6 (periksa); ","")&IF(AND(AO11="P1",AQ11<>"K4"),"P1 biasanya K4 (periksa); ","")))
A12: 9 | B12: =IF(INDEX(Korpus!$A:$A,$A12)="","",INDEX(Korpus!$A:$A,$A12)) | C12: =TRIM(INDEX(Korpus!$D:$D,$A12)&" "&INDEX(Korpus!$E:$E,$A12)) | D12: =IF(INDEX(Korpus!$B:$B,$A12)="","",INDEX(Korpus!$B:$B,$A12)) | E12: =IF(INDEX(Korpus!$C:$C,$A12)="","",INDEX(Korpus!$C:$C,$A12)) | F12: =IF(INDEX(Korpus!$F:$F,$A12)="","",INDEX(Korpus!$F:$F,$A12)) | Y12: =IF(OR(M12="",S12=""),"",IF(M12=S12,"Sama","Beda")) | Z12: =IF(OR(N12="",T12=""),"",IF(N12=T12,"Sama","Beda")) | AA12: =IF(OR(O12="",U12=""),"",IF(O12=U12,"Sama","Beda")) | AB12: =IF(OR(P12="",V12=""),"",IF(P12=V12,"Sama","Beda")) | AC12: =IF(OR(Q12="",W12=""),"",IF(Q12=W12,"Sama","Beda")) | AD12: =IF(OR(R12="",X12=""),"",IF(R12=X12,"Sama","Beda")) | AE12: =COUNTIF(Y12:AD12,"Beda") -> 0 | AL12: =IF(AF12<>"",AF12,IF(AND(M12<>"",M12=S12),M12,"")) | AM12: =IF(AG12<>"",AG12,IF(AND(N12<>"",N12=T12),N12,"")) | AN12: =IF(AH12<>"",AH12,IF(AND(O12<>"",O12=U12),O12,"")) | AO12: =IF(AI12<>"",AI12,IF(AND(P12<>"",P12=V12),P12,"")) | AP12: =IF(AJ12<>"",AJ12,IF(AND(Q12<>"",Q12=W12),Q12,"")) | AQ12: =IF(AK12<>"",AK12,IF(AND(R12<>"",R12=X12),R12,"")) | AS12: =IF(COUNTA(M12:R12)+COUNTA(S12:X12)<12,"Menunggu coder",IF(AE12=0,"Sepakat",IF(SUMPRODUCT((Y12:AD12="Beda")*(AF12:AK12=""))=0,"Selesai adjudikasi","Perlu adjudikasi"))) -> Menunggu coder | AT12: =IF(COUNTIF(AL12:AQ12,"?*")<6,"",IF(IF(AND(AM12="R0",AQ12<>"K5"),"R0 harus K5; ","")&IF(AND(AM12="R1",AQ12="K3"),"R1 tidak boleh K3 (fungsional); ","")&IF(AND(AM12="R2",AQ12="K5"),"R2 tidak boleh K5; ","")&IF(AND(AM12="R2",OR(AL12="S6",AL12="S7",AL12="S8")),"R2 tidak boleh S6/S7/S8; ","")&IF(AND(AO12="P9",AN12<>"T17"),"P9 hanya dengan T17; ","")&IF(AND(OR(AN12="T17",AO12="P9"),AM12<>"R0"),"T17/P9 harus R0; ","")&IF(AND(AN12="T01",AO12<>"P6"),"T01 biasanya P6 (periksa); ","")&IF(AND(AO12="P1",AQ12<>"K4"),"P1 biasanya K4 (periksa); ","")="","OK",IF(AND(AM12="R0",AQ12<>"K5"),"R0 harus K5; ","")&IF(AND(AM12="R1",AQ12="K3"),"R1 tidak boleh K3 (fungsional); ","")&IF(AND(AM12="R2",AQ12="K5"),"R2 tidak boleh K5; ","")&IF(AND(AM12="R2",OR(AL12="S6",AL12="S7",AL12="S8")),"R2 tidak boleh S6/S7/S8; ","")&IF(AND(AO12="P9",AN12<>"T17"),"P9 hanya dengan T17; ","")&IF(AND(OR(AN12="T17",AO12="P9"),AM12<>"R0"),"T17/P9 harus R0; ","")&IF(AND(AN12="T01",AO12<>"P6"),"T01 biasanya P6 (periksa); ","")&IF(AND(AO12="P1",AQ12<>"K4"),"P1 biasanya K4 (periksa); ","")))
A13: 10 | B13: =IF(INDEX(Korpus!$A:$A,$A13)="","",INDEX(Korpus!$A:$A,$A13)) | C13: =TRIM(INDEX(Korpus!$D:$D,$A13)&" "&INDEX(Korpus!$E:$E,$A13)) | D13: =IF(INDEX(Korpus!$B:$B,$A13)="","",INDEX(Korpus!$B:$B,$A13)) | E13: =IF(INDEX(Korpus!$C:$C,$A13)="","",INDEX(Korpus!$C:$C,$A13)) | F13: =IF(INDEX(Korpus!$F:$F,$A13)="","",INDEX(Korpus!$F:$F,$A13)) | Y13: =IF(OR(M13="",S13=""),"",IF(M13=S13,"Sama","Beda")) | Z13: =IF(OR(N13="",T13=""),"",IF(N13=T13,"Sama","Beda")) | AA13: =IF(OR(O13="",U13=""),"",IF(O13=U13,"Sama","Beda")) | AB13: =IF(OR(P13="",V13=""),"",IF(P13=V13,"Sama","Beda")) | AC13: =IF(OR(Q13="",W13=""),"",IF(Q13=W13,"Sama","Beda")) | AD13: =IF(OR(R13="",X13=""),"",IF(R13=X13,"Sama","Beda")) | AE13: =COUNTIF(Y13:AD13,"Beda") -> 0 | AL13: =IF(AF13<>"",AF13,IF(AND(M13<>"",M13=S13),M13,"")) | AM13: =IF(AG13<>"",AG13,IF(AND(N13<>"",N13=T13),N13,"")) | AN13: =IF(AH13<>"",AH13,IF(AND(O13<>"",O13=U13),O13,"")) | AO13: =IF(AI13<>"",AI13,IF(AND(P13<>"",P13=V13),P13,"")) | AP13: =IF(AJ13<>"",AJ13,IF(AND(Q13<>"",Q13=W13),Q13,"")) | AQ13: =IF(AK13<>"",AK13,IF(AND(R13<>"",R13=X13),R13,"")) | AS13: =IF(COUNTA(M13:R13)+COUNTA(S13:X13)<12,"Menunggu coder",IF(AE13=0,"Sepakat",IF(SUMPRODUCT((Y13:AD13="Beda")*(AF13:AK13=""))=0,"Selesai adjudikasi","Perlu adjudikasi"))) -> Menunggu coder | AT13: =IF(COUNTIF(AL13:AQ13,"?*")<6,"",IF(IF(AND(AM13="R0",AQ13<>"K5"),"R0 harus K5; ","")&IF(AND(AM13="R1",AQ13="K3"),"R1 tidak boleh K3 (fungsional); ","")&IF(AND(AM13="R2",AQ13="K5"),"R2 tidak boleh K5; ","")&IF(AND(AM13="R2",OR(AL13="S6",AL13="S7",AL13="S8")),"R2 tidak boleh S6/S7/S8; ","")&IF(AND(AO13="P9",AN13<>"T17"),"P9 hanya dengan T17; ","")&IF(AND(OR(AN13="T17",AO13="P9"),AM13<>"R0"),"T17/P9 harus R0; ","")&IF(AND(AN13="T01",AO13<>"P6"),"T01 biasanya P6 (periksa); ","")&IF(AND(AO13="P1",AQ13<>"K4"),"P1 biasanya K4 (periksa); ","")="","OK",IF(AND(AM13="R0",AQ13<>"K5"),"R0 harus K5; ","")&IF(AND(AM13="R1",AQ13="K3"),"R1 tidak boleh K3 (fungsional); ","")&IF(AND(AM13="R2",AQ13="K5"),"R2 tidak boleh K5; ","")&IF(AND(AM13="R2",OR(AL13="S6",AL13="S7",AL13="S8")),"R2 tidak boleh S6/S7/S8; ","")&IF(AND(AO13="P9",AN13<>"T17"),"P9 hanya dengan T17; ","")&IF(AND(OR(AN13="T17",AO13="P9"),AM13<>"R0"),"T17/P9 harus R0; ","")&IF(AND(AN13="T01",AO13<>"P6"),"T01 biasanya P6 (periksa); ","")&IF(AND(AO13="P1",AQ13<>"K4"),"P1 biasanya K4 (periksa); ","")))
A14: 11 | B14: =IF(INDEX(Korpus!$A:$A,$A14)="","",INDEX(Korpus!$A:$A,$A14)) | C14: =TRIM(INDEX(Korpus!$D:$D,$A14)&" "&INDEX(Korpus!$E:$E,$A14)) | D14: =IF(INDEX(Korpus!$B:$B,$A14)="","",INDEX(Korpus!$B:$B,$A14)) | E14: =IF(INDEX(Korpus!$C:$C,$A14)="","",INDEX(Korpus!$C:$C,$A14)) | F14: =IF(INDEX(Korpus!$F:$F,$A14)="","",INDEX(Korpus!$F:$F,$A14)) | Y14: =IF(OR(M14="",S14=""),"",IF(M14=S14,"Sama","Beda")) | Z14: =IF(OR(N14="",T14=""),"",IF(N14=T14,"Sama","Beda")) | AA14: =IF(OR(O14="",U14=""),"",IF(O14=U14,"Sama","Beda")) | AB14: =IF(OR(P14="",V14=""),"",IF(P14=V14,"Sama","Beda")) | AC14: =IF(OR(Q14="",W14=""),"",IF(Q14=W14,"Sama","Beda")) | AD14: =IF(OR(R14="",X14=""),"",IF(R14=X14,"Sama","Beda")) | AE14: =COUNTIF(Y14:AD14,"Beda") -> 0 | AL14: =IF(AF14<>"",AF14,IF(AND(M14<>"",M14=S14),M14,"")) | AM14: =IF(AG14<>"",AG14,IF(AND(N14<>"",N14=T14),N14,"")) | AN14: =IF(AH14<>"",AH14,IF(AND(O14<>"",O14=U14),O14,"")) | AO14: =IF(AI14<>"",AI14,IF(AND(P14<>"",P14=V14),P14,"")) | AP14: =IF(AJ14<>"",AJ14,IF(AND(Q14<>"",Q14=W14),Q14,"")) | AQ14: =IF(AK14<>"",AK14,IF(AND(R14<>"",R14=X14),R14,"")) | AS14: =IF(COUNTA(M14:R14)+COUNTA(S14:X14)<12,"Menunggu coder",IF(AE14=0,"Sepakat",IF(SUMPRODUCT((Y14:AD14="Beda")*(AF14:AK14=""))=0,"Selesai adjudikasi","Perlu adjudikasi"))) -> Menunggu coder | AT14: =IF(COUNTIF(AL14:AQ14,"?*")<6,"",IF(IF(AND(AM14="R0",AQ14<>"K5"),"R0 harus K5; ","")&IF(AND(AM14="R1",AQ14="K3"),"R1 tidak boleh K3 (fungsional); ","")&IF(AND(AM14="R2",AQ14="K5"),"R2 tidak boleh K5; ","")&IF(AND(AM14="R2",OR(AL14="S6",AL14="S7",AL14="S8")),"R2 tidak boleh S6/S7/S8; ","")&IF(AND(AO14="P9",AN14<>"T17"),"P9 hanya dengan T17; ","")&IF(AND(OR(AN14="T17",AO14="P9"),AM14<>"R0"),"T17/P9 harus R0; ","")&IF(AND(AN14="T01",AO14<>"P6"),"T01 biasanya P6 (periksa); ","")&IF(AND(AO14="P1",AQ14<>"K4"),"P1 biasanya K4 (periksa); ","")="","OK",IF(AND(AM14="R0",AQ14<>"K5"),"R0 harus K5; ","")&IF(AND(AM14="R1",AQ14="K3"),"R1 tidak boleh K3 (fungsional); ","")&IF(AND(AM14="R2",AQ14="K5"),"R2 tidak boleh K5; ","")&IF(AND(AM14="R2",OR(AL14="S6",AL14="S7",AL14="S8")),"R2 tidak boleh S6/S7/S8; ","")&IF(AND(AO14="P9",AN14<>"T17"),"P9 hanya dengan T17; ","")&IF(AND(OR(AN14="T17",AO14="P9"),AM14<>"R0"),"T17/P9 harus R0; ","")&IF(AND(AN14="T01",AO14<>"P6"),"T01 biasanya P6 (periksa); ","")&IF(AND(AO14="P1",AQ14<>"K4"),"P1 biasanya K4 (periksa); ","")))
A15: 12 | B15: =IF(INDEX(Korpus!$A:$A,$A15)="","",INDEX(Korpus!$A:$A,$A15)) | C15: =TRIM(INDEX(Korpus!$D:$D,$A15)&" "&INDEX(Korpus!$E:$E,$A15)) | D15: =IF(INDEX(Korpus!$B:$B,$A15)="","",INDEX(Korpus!$B:$B,$A15)) | E15: =IF(INDEX(Korpus!$C:$C,$A15)="","",INDEX(Korpus!$C:$C,$A15)) | F15: =IF(INDEX(Korpus!$F:$F,$A15)="","",INDEX(Korpus!$F:$F,$A15)) | Y15: =IF(OR(M15="",S15=""),"",IF(M15=S15,"Sama","Beda")) | Z15: =IF(OR(N15="",T15=""),"",IF(N15=T15,"Sama","Beda")) | AA15: =IF(OR(O15="",U15=""),"",IF(O15=U15,"Sama","Beda")) | AB15: =IF(OR(P15="",V15=""),"",IF(P15=V15,"Sama","Beda")) | AC15: =IF(OR(Q15="",W15=""),"",IF(Q15=W15,"Sama","Beda")) | AD15: =IF(OR(R15="",X15=""),"",IF(R15=X15,"Sama","Beda")) | AE15: =COUNTIF(Y15:AD15,"Beda") -> 0 | AL15: =IF(AF15<>"",AF15,IF(AND(M15<>"",M15=S15),M15,"")) | AM15: =IF(AG15<>"",AG15,IF(AND(N15<>"",N15=T15),N15,"")) | AN15: =IF(AH15<>"",AH15,IF(AND(O15<>"",O15=U15),O15,"")) | AO15: =IF(AI15<>"",AI15,IF(AND(P15<>"",P15=V15),P15,"")) | AP15: =IF(AJ15<>"",AJ15,IF(AND(Q15<>"",Q15=W15),Q15,"")) | AQ15: =IF(AK15<>"",AK15,IF(AND(R15<>"",R15=X15),R15,"")) | AS15: =IF(COUNTA(M15:R15)+COUNTA(S15:X15)<12,"Menunggu coder",IF(AE15=0,"Sepakat",IF(SUMPRODUCT((Y15:AD15="Beda")*(AF15:AK15=""))=0,"Selesai adjudikasi","Perlu adjudikasi"))) -> Menunggu coder | AT15: =IF(COUNTIF(AL15:AQ15,"?*")<6,"",IF(IF(AND(AM15="R0",AQ15<>"K5"),"R0 harus K5; ","")&IF(AND(AM15="R1",AQ15="K3"),"R1 tidak boleh K3 (fungsional); ","")&IF(AND(AM15="R2",AQ15="K5"),"R2 tidak boleh K5; ","")&IF(AND(AM15="R2",OR(AL15="S6",AL15="S7",AL15="S8")),"R2 tidak boleh S6/S7/S8; ","")&IF(AND(AO15="P9",AN15<>"T17"),"P9 hanya dengan T17; ","")&IF(AND(OR(AN15="T17",AO15="P9"),AM15<>"R0"),"T17/P9 harus R0; ","")&IF(AND(AN15="T01",AO15<>"P6"),"T01 biasanya P6 (periksa); ","")&IF(AND(AO15="P1",AQ15<>"K4"),"P1 biasanya K4 (periksa); ","")="","OK",IF(AND(AM15="R0",AQ15<>"K5"),"R0 harus K5; ","")&IF(AND(AM15="R1",AQ15="K3"),"R1 tidak boleh K3 (fungsional); ","")&IF(AND(AM15="R2",AQ15="K5"),"R2 tidak boleh K5; ","")&IF(AND(AM15="R2",OR(AL15="S6",AL15="S7",AL15="S8")),"R2 tidak boleh S6/S7/S8; ","")&IF(AND(AO15="P9",AN15<>"T17"),"P9 hanya dengan T17; ","")&IF(AND(OR(AN15="T17",AO15="P9"),AM15<>"R0"),"T17/P9 harus R0; ","")&IF(AND(AN15="T01",AO15<>"P6"),"T01 biasanya P6 (periksa); ","")&IF(AND(AO15="P1",AQ15<>"K4"),"P1 biasanya K4 (periksa); ","")))
A16: 13 | B16: =IF(INDEX(Korpus!$A:$A,$A16)="","",INDEX(Korpus!$A:$A,$A16)) | C16: =TRIM(INDEX(Korpus!$D:$D,$A16)&" "&INDEX(Korpus!$E:$E,$A16)) | D16: =IF(INDEX(Korpus!$B:$B,$A16)="","",INDEX(Korpus!$B:$B,$A16)) | E16: =IF(INDEX(Korpus!$C:$C,$A16)="","",INDEX(Korpus!$C:$C,$A16)) | F16: =IF(INDEX(Korpus!$F:$F,$A16)="","",INDEX(Korpus!$F:$F,$A16)) | Y16: =IF(OR(M16="",S16=""),"",IF(M16=S16,"Sama","Beda")) | Z16: =IF(OR(N16="",T16=""),"",IF(N16=T16,"Sama","Beda")) | AA16: =IF(OR(O16="",U16=""),"",IF(O16=U16,"Sama","Beda")) | AB16: =IF(OR(P16="",V16=""),"",IF(P16=V16,"Sama","Beda")) | AC16: =IF(OR(Q16="",W16=""),"",IF(Q16=W16,"Sama","Beda")) | AD16: =IF(OR(R16="",X16=""),"",IF(R16=X16,"Sama","Beda")) | AE16: =COUNTIF(Y16:AD16,"Beda") -> 0 | AL16: =IF(AF16<>"",AF16,IF(AND(M16<>"",M16=S16),M16,"")) | AM16: =IF(AG16<>"",AG16,IF(AND(N16<>"",N16=T16),N16,"")) | AN16: =IF(AH16<>"",AH16,IF(AND(O16<>"",O16=U16),O16,"")) | AO16: =IF(AI16<>"",AI16,IF(AND(P16<>"",P16=V16),P16,"")) | AP16: =IF(AJ16<>"",AJ16,IF(AND(Q16<>"",Q16=W16),Q16,"")) | AQ16: =IF(AK16<>"",AK16,IF(AND(R16<>"",R16=X16),R16,"")) | AS16: =IF(COUNTA(M16:R16)+COUNTA(S16:X16)<12,"Menunggu coder",IF(AE16=0,"Sepakat",IF(SUMPRODUCT((Y16:AD16="Beda")*(AF16:AK16=""))=0,"Selesai adjudikasi","Perlu adjudikasi"))) -> Menunggu coder | AT16: =IF(COUNTIF(AL16:AQ16,"?*")<6,"",IF(IF(AND(AM16="R0",AQ16<>"K5"),"R0 harus K5; ","")&IF(AND(AM16="R1",AQ16="K3"),"R1 tidak boleh K3 (fungsional); ","")&IF(AND(AM16="R2",AQ16="K5"),"R2 tidak boleh K5; ","")&IF(AND(AM16="R2",OR(AL16="S6",AL16="S7",AL16="S8")),"R2 tidak boleh S6/S7/S8; ","")&IF(AND(AO16="P9",AN16<>"T17"),"P9 hanya dengan T17; ","")&IF(AND(OR(AN16="T17",AO16="P9"),AM16<>"R0"),"T17/P9 harus R0; ","")&IF(AND(AN16="T01",AO16<>"P6"),"T01 biasanya P6 (periksa); ","")&IF(AND(AO16="P1",AQ16<>"K4"),"P1 biasanya K4 (periksa); ","")="","OK",IF(AND(AM16="R0",AQ16<>"K5"),"R0 harus K5; ","")&IF(AND(AM16="R1",AQ16="K3"),"R1 tidak boleh K3 (fungsional); ","")&IF(AND(AM16="R2",AQ16="K5"),"R2 tidak boleh K5; ","")&IF(AND(AM16="R2",OR(AL16="S6",AL16="S7",AL16="S8")),"R2 tidak boleh S6/S7/S8; ","")&IF(AND(AO16="P9",AN16<>"T17"),"P9 hanya dengan T17; ","")&IF(AND(OR(AN16="T17",AO16="P9"),AM16<>"R0"),"T17/P9 harus R0; ","")&IF(AND(AN16="T01",AO16<>"P6"),"T01 biasanya P6 (periksa); ","")&IF(AND(AO16="P1",AQ16<>"K4"),"P1 biasanya K4 (periksa); ","")))
A17: 14 | B17: =IF(INDEX(Korpus!$A:$A,$A17)="","",INDEX(Korpus!$A:$A,$A17)) | C17: =TRIM(INDEX(Korpus!$D:$D,$A17)&" "&INDEX(Korpus!$E:$E,$A17)) | D17: =IF(INDEX(Korpus!$B:$B,$A17)="","",INDEX(Korpus!$B:$B,$A17)) | E17: =IF(INDEX(Korpus!$C:$C,$A17)="","",INDEX(Korpus!$C:$C,$A17)) | F17: =IF(INDEX(Korpus!$F:$F,$A17)="","",INDEX(Korpus!$F:$F,$A17)) | Y17: =IF(OR(M17="",S17=""),"",IF(M17=S17,"Sama","Beda")) | Z17: =IF(OR(N17="",T17=""),"",IF(N17=T17,"Sama","Beda")) | AA17: =IF(OR(O17="",U17=""),"",IF(O17=U17,"Sama","Beda")) | AB17: =IF(OR(P17="",V17=""),"",IF(P17=V17,"Sama","Beda")) | AC17: =IF(OR(Q17="",W17=""),"",IF(Q17=W17,"Sama","Beda")) | AD17: =IF(OR(R17="",X17=""),"",IF(R17=X17,"Sama","Beda")) | AE17: =COUNTIF(Y17:AD17,"Beda") -> 0 | AL17: =IF(AF17<>"",AF17,IF(AND(M17<>"",M17=S17),M17,"")) | AM17: =IF(AG17<>"",AG17,IF(AND(N17<>"",N17=T17),N17,"")) | AN17: =IF(AH17<>"",AH17,IF(AND(O17<>"",O17=U17),O17,"")) | AO17: =IF(AI17<>"",AI17,IF(AND(P17<>"",P17=V17),P17,"")) | AP17: =IF(AJ17<>"",AJ17,IF(AND(Q17<>"",Q17=W17),Q17,"")) | AQ17: =IF(AK17<>"",AK17,IF(AND(R17<>"",R17=X17),R17,"")) | AS17: =IF(COUNTA(M17:R17)+COUNTA(S17:X17)<12,"Menunggu coder",IF(AE17=0,"Sepakat",IF(SUMPRODUCT((Y17:AD17="Beda")*(AF17:AK17=""))=0,"Selesai adjudikasi","Perlu adjudikasi"))) -> Menunggu coder | AT17: =IF(COUNTIF(AL17:AQ17,"?*")<6,"",IF(IF(AND(AM17="R0",AQ17<>"K5"),"R0 harus K5; ","")&IF(AND(AM17="R1",AQ17="K3"),"R1 tidak boleh K3 (fungsional); ","")&IF(AND(AM17="R2",AQ17="K5"),"R2 tidak boleh K5; ","")&IF(AND(AM17="R2",OR(AL17="S6",AL17="S7",AL17="S8")),"R2 tidak boleh S6/S7/S8; ","")&IF(AND(AO17="P9",AN17<>"T17"),"P9 hanya dengan T17; ","")&IF(AND(OR(AN17="T17",AO17="P9"),AM17<>"R0"),"T17/P9 harus R0; ","")&IF(AND(AN17="T01",AO17<>"P6"),"T01 biasanya P6 (periksa); ","")&IF(AND(AO17="P1",AQ17<>"K4"),"P1 biasanya K4 (periksa); ","")="","OK",IF(AND(AM17="R0",AQ17<>"K5"),"R0 harus K5; ","")&IF(AND(AM17="R1",AQ17="K3"),"R1 tidak boleh K3 (fungsional); ","")&IF(AND(AM17="R2",AQ17="K5"),"R2 tidak boleh K5; ","")&IF(AND(AM17="R2",OR(AL17="S6",AL17="S7",AL17="S8")),"R2 tidak boleh S6/S7/S8; ","")&IF(AND(AO17="P9",AN17<>"T17"),"P9 hanya dengan T17; ","")&IF(AND(OR(AN17="T17",AO17="P9"),AM17<>"R0"),"T17/P9 harus R0; ","")&IF(AND(AN17="T01",AO17<>"P6"),"T01 biasanya P6 (periksa); ","")&IF(AND(AO17="P1",AQ17<>"K4"),"P1 biasanya K4 (periksa); ","")))
A18: 15 | B18: =IF(INDEX(Korpus!$A:$A,$A18)="","",INDEX(Korpus!$A:$A,$A18)) | C18: =TRIM(INDEX(Korpus!$D:$D,$A18)&" "&INDEX(Korpus!$E:$E,$A18)) | D18: =IF(INDEX(Korpus!$B:$B,$A18)="","",INDEX(Korpus!$B:$B,$A18)) | E18: =IF(INDEX(Korpus!$C:$C,$A18)="","",INDEX(Korpus!$C:$C,$A18)) | F18: =IF(INDEX(Korpus!$F:$F,$A18)="","",INDEX(Korpus!$F:$F,$A18)) | G18: S9 | H18: R0 | I18: T17 | J18: P9 | K18: F8 | L18: K5 | Y18: =IF(OR(M18="",S18=""),"",IF(M18=S18,"Sama","Beda")) | Z18: =IF(OR(N18="",T18=""),"",IF(N18=T18,"Sama","Beda")) | AA18: =IF(OR(O18="",U18=""),"",IF(O18=U18,"Sama","Beda")) | AB18: =IF(OR(P18="",V18=""),"",IF(P18=V18,"Sama","Beda")) | AC18: =IF(OR(Q18="",W18=""),"",IF(Q18=W18,"Sama","Beda")) | AD18: =IF(OR(R18="",X18=""),"",IF(R18=X18,"Sama","Beda")) | AE18: =COUNTIF(Y18:AD18,"Beda") -> 0 | AL18: =IF(AF18<>"",AF18,IF(AND(M18<>"",M18=S18),M18,"")) | AM18: =IF(AG18<>"",AG18,IF(AND(N18<>"",N18=T18),N18,"")) | AN18: =IF(AH18<>"",AH18,IF(AND(O18<>"",O18=U18),O18,"")) | AO18: =IF(AI18<>"",AI18,IF(AND(P18<>"",P18=V18),P18,"")) | AP18: =IF(AJ18<>"",AJ18,IF(AND(Q18<>"",Q18=W18),Q18,"")) | AQ18: =IF(AK18<>"",AK18,IF(AND(R18<>"",R18=X18),R18,"")) | AS18: =IF(COUNTA(M18:R18)+COUNTA(S18:X18)<12,"Menunggu coder",IF(AE18=0,"Sepakat",IF(SUMPRODUCT((Y18:AD18="Beda")*(AF18:AK18=""))=0,"Selesai adjudikasi","Perlu adjudikasi"))) -> Menunggu coder | AT18: =IF(COUNTIF(AL18:AQ18,"?*")<6,"",IF(IF(AND(AM18="R0",AQ18<>"K5"),"R0 harus K5; ","")&IF(AND(AM18="R1",AQ18="K3"),"R1 tidak boleh K3 (fungsional); ","")&IF(AND(AM18="R2",AQ18="K5"),"R2 tidak boleh K5; ","")&IF(AND(AM18="R2",OR(AL18="S6",AL18="S7",AL18="S8")),"R2 tidak boleh S6/S7/S8; ","")&IF(AND(AO18="P9",AN18<>"T17"),"P9 hanya dengan T17; ","")&IF(AND(OR(AN18="T17",AO18="P9"),AM18<>"R0"),"T17/P9 harus R0; ","")&IF(AND(AN18="T01",AO18<>"P6"),"T01 biasanya P6 (periksa); ","")&IF(AND(AO18="P1",AQ18<>"K4"),"P1 biasanya K4 (periksa); ","")="","OK",IF(AND(AM18="R0",AQ18<>"K5"),"R0 harus K5; ","")&IF(AND(AM18="R1",AQ18="K3"),"R1 tidak boleh K3 (fungsional); ","")&IF(AND(AM18="R2",AQ18="K5"),"R2 tidak boleh K5; ","")&IF(AND(AM18="R2",OR(AL18="S6",AL18="S7",AL18="S8")),"R2 tidak boleh S6/S7/S8; ","")&IF(AND(AO18="P9",AN18<>"T17"),"P9 hanya dengan T17; ","")&IF(AND(OR(AN18="T17",AO18="P9"),AM18<>"R0"),"T17/P9 harus R0; ","")&IF(AND(AN18="T01",AO18<>"P6"),"T01 biasanya P6 (periksa); ","")&IF(AND(AO18="P1",AQ18<>"K4"),"P1 biasanya K4 (periksa); ","")))
A19: 16 | B19: =IF(INDEX(Korpus!$A:$A,$A19)="","",INDEX(Korpus!$A:$A,$A19)) | C19: =TRIM(INDEX(Korpus!$D:$D,$A19)&" "&INDEX(Korpus!$E:$E,$A19)) | D19: =IF(INDEX(Korpus!$B:$B,$A19)="","",INDEX(Korpus!$B:$B,$A19)) | E19: =IF(INDEX(Korpus!$C:$C,$A19)="","",INDEX(Korpus!$C:$C,$A19)) | F19: =IF(INDEX(Korpus!$F:$F,$A19)="","",INDEX(Korpus!$F:$F,$A19)) | Y19: =IF(OR(M19="",S19=""),"",IF(M19=S19,"Sama","Beda")) | Z19: =IF(OR(N19="",T19=""),"",IF(N19=T19,"Sama","Beda")) | AA19: =IF(OR(O19="",U19=""),"",IF(O19=U19,"Sama","Beda")) | AB19: =IF(OR(P19="",V19=""),"",IF(P19=V19,"Sama","Beda")) | AC19: =IF(OR(Q19="",W19=""),"",IF(Q19=W19,"Sama","Beda")) | AD19: =IF(OR(R19="",X19=""),"",IF(R19=X19,"Sama","Beda")) | AE19: =COUNTIF(Y19:AD19,"Beda") -> 0 | AL19: =IF(AF19<>"",AF19,IF(AND(M19<>"",M19=S19),M19,"")) | AM19: =IF(AG19<>"",AG19,IF(AND(N19<>"",N19=T19),N19,"")) | AN19: =IF(AH19<>"",AH19,IF(AND(O19<>"",O19=U19),O19,"")) | AO19: =IF(AI19<>"",AI19,IF(AND(P19<>"",P19=V19),P19,"")) | AP19: =IF(AJ19<>"",AJ19,IF(AND(Q19<>"",Q19=W19),Q19,"")) | AQ19: =IF(AK19<>"",AK19,IF(AND(R19<>"",R19=X19),R19,"")) | AS19: =IF(COUNTA(M19:R19)+COUNTA(S19:X19)<12,"Menunggu coder",IF(AE19=0,"Sepakat",IF(SUMPRODUCT((Y19:AD19="Beda")*(AF19:AK19=""))=0,"Selesai adjudikasi","Perlu adjudikasi"))) -> Menunggu coder | AT19: =IF(COUNTIF(AL19:AQ19,"?*")<6,"",IF(IF(AND(AM19="R0",AQ19<>"K5"),"R0 harus K5; ","")&IF(AND(AM19="R1",AQ19="K3"),"R1 tidak boleh K3 (fungsional); ","")&IF(AND(AM19="R2",AQ19="K5"),"R2 tidak boleh K5; ","")&IF(AND(AM19="R2",OR(AL19="S6",AL19="S7",AL19="S8")),"R2 tidak boleh S6/S7/S8; ","")&IF(AND(AO19="P9",AN19<>"T17"),"P9 hanya dengan T17; ","")&IF(AND(OR(AN19="T17",AO19="P9"),AM19<>"R0"),"T17/P9 harus R0; ","")&IF(AND(AN19="T01",AO19<>"P6"),"T01 biasanya P6 (periksa); ","")&IF(AND(AO19="P1",AQ19<>"K4"),"P1 biasanya K4 (periksa); ","")="","OK",IF(AND(AM19="R0",AQ19<>"K5"),"R0 harus K5; ","")&IF(AND(AM19="R1",AQ19="K3"),"R1 tidak boleh K3 (fungsional); ","")&IF(AND(AM19="R2",AQ19="K5"),"R2 tidak boleh K5; ","")&IF(AND(AM19="R2",OR(AL19="S6",AL19="S7",AL19="S8")),"R2 tidak boleh S6/S7/S8; ","")&IF(AND(AO19="P9",AN19<>"T17"),"P9 hanya dengan T17; ","")&IF(AND(OR(AN19="T17",AO19="P9"),AM19<>"R0"),"T17/P9 harus R0; ","")&IF(AND(AN19="T01",AO19<>"P6"),"T01 biasanya P6 (periksa); ","")&IF(AND(AO19="P1",AQ19<>"K4"),"P1 biasanya K4 (periksa); ","")))
A20: 17 | B20: =IF(INDEX(Korpus!$A:$A,$A20)="","",INDEX(Korpus!$A:$A,$A20)) | C20: =TRIM(INDEX(Korpus!$D:$D,$A20)&" "&INDEX(Korpus!$E:$E,$A20)) | D20: =IF(INDEX(Korpus!$B:$B,$A20)="","",INDEX(Korpus!$B:$B,$A20)) | E20: =IF(INDEX(Korpus!$C:$C,$A20)="","",INDEX(Korpus!$C:$C,$A20)) | F20: =IF(INDEX(Korpus!$F:$F,$A20)="","",INDEX(Korpus!$F:$F,$A20)) | Y20: =IF(OR(M20="",S20=""),"",IF(M20=S20,"Sama","Beda")) | Z20: =IF(OR(N20="",T20=""),"",IF(N20=T20,"Sama","Beda")) | AA20: =IF(OR(O20="",U20=""),"",IF(O20=U20,"Sama","Beda")) | AB20: =IF(OR(P20="",V20=""),"",IF(P20=V20,"Sama","Beda")) | AC20: =IF(OR(Q20="",W20=""),"",IF(Q20=W20,"Sama","Beda")) | AD20: =IF(OR(R20="",X20=""),"",IF(R20=X20,"Sama","Beda")) | AE20: =COUNTIF(Y20:AD20,"Beda") -> 0 | AL20: =IF(AF20<>"",AF20,IF(AND(M20<>"",M20=S20),M20,"")) | AM20: =IF(AG20<>"",AG20,IF(AND(N20<>"",N20=T20),N20,"")) | AN20: =IF(AH20<>"",AH20,IF(AND(O20<>"",O20=U20),O20,"")) | AO20: =IF(AI20<>"",AI20,IF(AND(P20<>"",P20=V20),P20,"")) | AP20: =IF(AJ20<>"",AJ20,IF(AND(Q20<>"",Q20=W20),Q20,"")) | AQ20: =IF(AK20<>"",AK20,IF(AND(R20<>"",R20=X20),R20,"")) | AS20: =IF(COUNTA(M20:R20)+COUNTA(S20:X20)<12,"Menunggu coder",IF(AE20=0,"Sepakat",IF(SUMPRODUCT((Y20:AD20="Beda")*(AF20:AK20=""))=0,"Selesai adjudikasi","Perlu adjudikasi"))) -> Menunggu coder | AT20: =IF(COUNTIF(AL20:AQ20,"?*")<6,"",IF(IF(AND(AM20="R0",AQ20<>"K5"),"R0 harus K5; ","")&IF(AND(AM20="R1",AQ20="K3"),"R1 tidak boleh K3 (fungsional); ","")&IF(AND(AM20="R2",AQ20="K5"),"R2 tidak boleh K5; ","")&IF(AND(AM20="R2",OR(AL20="S6",AL20="S7",AL20="S8")),"R2 tidak boleh S6/S7/S8; ","")&IF(AND(AO20="P9",AN20<>"T17"),"P9 hanya dengan T17; ","")&IF(AND(OR(AN20="T17",AO20="P9"),AM20<>"R0"),"T17/P9 harus R0; ","")&IF(AND(AN20="T01",AO20<>"P6"),"T01 biasanya P6 (periksa); ","")&IF(AND(AO20="P1",AQ20<>"K4"),"P1 biasanya K4 (periksa); ","")="","OK",IF(AND(AM20="R0",AQ20<>"K5"),"R0 harus K5; ","")&IF(AND(AM20="R1",AQ20="K3"),"R1 tidak boleh K3 (fungsional); ","")&IF(AND(AM20="R2",AQ20="K5"),"R2 tidak boleh K5; ","")&IF(AND(AM20="R2",OR(AL20="S6",AL20="S7",AL20="S8")),"R2 tidak boleh S6/S7/S8; ","")&IF(AND(AO20="P9",AN20<>"T17"),"P9 hanya dengan T17; ","")&IF(AND(OR(AN20="T17",AO20="P9"),AM20<>"R0"),"T17/P9 harus R0; ","")&IF(AND(AN20="T01",AO20<>"P6"),"T01 biasanya P6 (periksa); ","")&IF(AND(AO20="P1",AQ20<>"K4"),"P1 biasanya K4 (periksa); ","")))
A21: 18 | B21: =IF(INDEX(Korpus!$A:$A,$A21)="","",INDEX(Korpus!$A:$A,$A21)) | C21: =TRIM(INDEX(Korpus!$D:$D,$A21)&" "&INDEX(Korpus!$E:$E,$A21)) | D21: =IF(INDEX(Korpus!$B:$B,$A21)="","",INDEX(Korpus!$B:$B,$A21)) | E21: =IF(INDEX(Korpus!$C:$C,$A21)="","",INDEX(Korpus!$C:$C,$A21)) | F21: =IF(INDEX(Korpus!$F:$F,$A21)="","",INDEX(Korpus!$F:$F,$A21)) | Y21: =IF(OR(M21="",S21=""),"",IF(M21=S21,"Sama","Beda")) | Z21: =IF(OR(N21="",T21=""),"",IF(N21=T21,"Sama","Beda")) | AA21: =IF(OR(O21="",U21=""),"",IF(O21=U21,"Sama","Beda")) | AB21: =IF(OR(P21="",V21=""),"",IF(P21=V21,"Sama","Beda")) | AC21: =IF(OR(Q21="",W21=""),"",IF(Q21=W21,"Sama","Beda")) | AD21: =IF(OR(R21="",X21=""),"",IF(R21=X21,"Sama","Beda")) | AE21: =COUNTIF(Y21:AD21,"Beda") -> 0 | AL21: =IF(AF21<>"",AF21,IF(AND(M21<>"",M21=S21),M21,"")) | AM21: =IF(AG21<>"",AG21,IF(AND(N21<>"",N21=T21),N21,"")) | AN21: =IF(AH21<>"",AH21,IF(AND(O21<>"",O21=U21),O21,"")) | AO21: =IF(AI21<>"",AI21,IF(AND(P21<>"",P21=V21),P21,"")) | AP21: =IF(AJ21<>"",AJ21,IF(AND(Q21<>"",Q21=W21),Q21,"")) | AQ21: =IF(AK21<>"",AK21,IF(AND(R21<>"",R21=X21),R21,"")) | AS21: =IF(COUNTA(M21:R21)+COUNTA(S21:X21)<12,"Menunggu coder",IF(AE21=0,"Sepakat",IF(SUMPRODUCT((Y21:AD21="Beda")*(AF21:AK21=""))=0,"Selesai adjudikasi","Perlu adjudikasi"))) -> Menunggu coder | AT21: =IF(COUNTIF(AL21:AQ21,"?*")<6,"",IF(IF(AND(AM21="R0",AQ21<>"K5"),"R0 harus K5; ","")&IF(AND(AM21="R1",AQ21="K3"),"R1 tidak boleh K3 (fungsional); ","")&IF(AND(AM21="R2",AQ21="K5"),"R2 tidak boleh K5; ","")&IF(AND(AM21="R2",OR(AL21="S6",AL21="S7",AL21="S8")),"R2 tidak boleh S6/S7/S8; ","")&IF(AND(AO21="P9",AN21<>"T17"),"P9 hanya dengan T17; ","")&IF(AND(OR(AN21="T17",AO21="P9"),AM21<>"R0"),"T17/P9 harus R0; ","")&IF(AND(AN21="T01",AO21<>"P6"),"T01 biasanya P6 (periksa); ","")&IF(AND(AO21="P1",AQ21<>"K4"),"P1 biasanya K4 (periksa); ","")="","OK",IF(AND(AM21="R0",AQ21<>"K5"),"R0 harus K5; ","")&IF(AND(AM21="R1",AQ21="K3"),"R1 tidak boleh K3 (fungsional); ","")&IF(AND(AM21="R2",AQ21="K5"),"R2 tidak boleh K5; ","")&IF(AND(AM21="R2",OR(AL21="S6",AL21="S7",AL21="S8")),"R2 tidak boleh S6/S7/S8; ","")&IF(AND(AO21="P9",AN21<>"T17"),"P9 hanya dengan T17; ","")&IF(AND(OR(AN21="T17",AO21="P9"),AM21<>"R0"),"T17/P9 harus R0; ","")&IF(AND(AN21="T01",AO21<>"P6"),"T01 biasanya P6 (periksa); ","")&IF(AND(AO21="P1",AQ21<>"K4"),"P1 biasanya K4 (periksa); ","")))
A22: 19 | B22: =IF(INDEX(Korpus!$A:$A,$A22)="","",INDEX(Korpus!$A:$A,$A22)) | C22: =TRIM(INDEX(Korpus!$D:$D,$A22)&" "&INDEX(Korpus!$E:$E,$A22)) | D22: =IF(INDEX(Korpus!$B:$B,$A22)="","",INDEX(Korpus!$B:$B,$A22)) | E22: =IF(INDEX(Korpus!$C:$C,$A22)="","",INDEX(Korpus!$C:$C,$A22)) | F22: =IF(INDEX(Korpus!$F:$F,$A22)="","",INDEX(Korpus!$F:$F,$A22)) | Y22: =IF(OR(M22="",S22=""),"",IF(M22=S22,"Sama","Beda")) | Z22: =IF(OR(N22="",T22=""),"",IF(N22=T22,"Sama","Beda")) | AA22: =IF(OR(O22="",U22=""),"",IF(O22=U22,"Sama","Beda")) | AB22: =IF(OR(P22="",V22=""),"",IF(P22=V22,"Sama","Beda")) | AC22: =IF(OR(Q22="",W22=""),"",IF(Q22=W22,"Sama","Beda")) | AD22: =IF(OR(R22="",X22=""),"",IF(R22=X22,"Sama","Beda")) | AE22: =COUNTIF(Y22:AD22,"Beda") -> 0 | AL22: =IF(AF22<>"",AF22,IF(AND(M22<>"",M22=S22),M22,"")) | AM22: =IF(AG22<>"",AG22,IF(AND(N22<>"",N22=T22),N22,"")) | AN22: =IF(AH22<>"",AH22,IF(AND(O22<>"",O22=U22),O22,"")) | AO22: =IF(AI22<>"",AI22,IF(AND(P22<>"",P22=V22),P22,"")) | AP22: =IF(AJ22<>"",AJ22,IF(AND(Q22<>"",Q22=W22),Q22,"")) | AQ22: =IF(AK22<>"",AK22,IF(AND(R22<>"",R22=X22),R22,"")) | AS22: =IF(COUNTA(M22:R22)+COUNTA(S22:X22)<12,"Menunggu coder",IF(AE22=0,"Sepakat",IF(SUMPRODUCT((Y22:AD22="Beda")*(AF22:AK22=""))=0,"Selesai adjudikasi","Perlu adjudikasi"))) -> Menunggu coder | AT22: =IF(COUNTIF(AL22:AQ22,"?*")<6,"",IF(IF(AND(AM22="R0",AQ22<>"K5"),"R0 harus K5; ","")&IF(AND(AM22="R1",AQ22="K3"),"R1 tidak boleh K3 (fungsional); ","")&IF(AND(AM22="R2",AQ22="K5"),"R2 tidak boleh K5; ","")&IF(AND(AM22="R2",OR(AL22="S6",AL22="S7",AL22="S8")),"R2 tidak boleh S6/S7/S8; ","")&IF(AND(AO22="P9",AN22<>"T17"),"P9 hanya dengan T17; ","")&IF(AND(OR(AN22="T17",AO22="P9"),AM22<>"R0"),"T17/P9 harus R0; ","")&IF(AND(AN22="T01",AO22<>"P6"),"T01 biasanya P6 (periksa); ","")&IF(AND(AO22="P1",AQ22<>"K4"),"P1 biasanya K4 (periksa); ","")="","OK",IF(AND(AM22="R0",AQ22<>"K5"),"R0 harus K5; ","")&IF(AND(AM22="R1",AQ22="K3"),"R1 tidak boleh K3 (fungsional); ","")&IF(AND(AM22="R2",AQ22="K5"),"R2 tidak boleh K5; ","")&IF(AND(AM22="R2",OR(AL22="S6",AL22="S7",AL22="S8")),"R2 tidak boleh S6/S7/S8; ","")&IF(AND(AO22="P9",AN22<>"T17"),"P9 hanya dengan T17; ","")&IF(AND(OR(AN22="T17",AO22="P9"),AM22<>"R0"),"T17/P9 harus R0; ","")&IF(AND(AN22="T01",AO22<>"P6"),"T01 biasanya P6 (periksa); ","")&IF(AND(AO22="P1",AQ22<>"K4"),"P1 biasanya K4 (periksa); ","")))
A23: 20 | B23: =IF(INDEX(Korpus!$A:$A,$A23)="","",INDEX(Korpus!$A:$A,$A23)) | C23: =TRIM(INDEX(Korpus!$D:$D,$A23)&" "&INDEX(Korpus!$E:$E,$A23)) | D23: =IF(INDEX(Korpus!$B:$B,$A23)="","",INDEX(Korpus!$B:$B,$A23)) | E23: =IF(INDEX(Korpus!$C:$C,$A23)="","",INDEX(Korpus!$C:$C,$A23)) | F23: =IF(INDEX(Korpus!$F:$F,$A23)="","",INDEX(Korpus!$F:$F,$A23)) | Y23: =IF(OR(M23="",S23=""),"",IF(M23=S23,"Sama","Beda")) | Z23: =IF(OR(N23="",T23=""),"",IF(N23=T23,"Sama","Beda")) | AA23: =IF(OR(O23="",U23=""),"",IF(O23=U23,"Sama","Beda")) | AB23: =IF(OR(P23="",V23=""),"",IF(P23=V23,"Sama","Beda")) | AC23: =IF(OR(Q23="",W23=""),"",IF(Q23=W23,"Sama","Beda")) | AD23: =IF(OR(R23="",X23=""),"",IF(R23=X23,"Sama","Beda")) | AE23: =COUNTIF(Y23:AD23,"Beda") -> 0 | AL23: =IF(AF23<>"",AF23,IF(AND(M23<>"",M23=S23),M23,"")) | AM23: =IF(AG23<>"",AG23,IF(AND(N23<>"",N23=T23),N23,"")) | AN23: =IF(AH23<>"",AH23,IF(AND(O23<>"",O23=U23),O23,"")) | AO23: =IF(AI23<>"",AI23,IF(AND(P23<>"",P23=V23),P23,"")) | AP23: =IF(AJ23<>"",AJ23,IF(AND(Q23<>"",Q23=W23),Q23,"")) | AQ23: =IF(AK23<>"",AK23,IF(AND(R23<>"",R23=X23),R23,"")) | AS23: =IF(COUNTA(M23:R23)+COUNTA(S23:X23)<12,"Menunggu coder",IF(AE23=0,"Sepakat",IF(SUMPRODUCT((Y23:AD23="Beda")*(AF23:AK23=""))=0,"Selesai adjudikasi","Perlu adjudikasi"))) -> Menunggu coder | AT23: =IF(COUNTIF(AL23:AQ23,"?*")<6,"",IF(IF(AND(AM23="R0",AQ23<>"K5"),"R0 harus K5; ","")&IF(AND(AM23="R1",AQ23="K3"),"R1 tidak boleh K3 (fungsional); ","")&IF(AND(AM23="R2",AQ23="K5"),"R2 tidak boleh K5; ","")&IF(AND(AM23="R2",OR(AL23="S6",AL23="S7",AL23="S8")),"R2 tidak boleh S6/S7/S8; ","")&IF(AND(AO23="P9",AN23<>"T17"),"P9 hanya dengan T17; ","")&IF(AND(OR(AN23="T17",AO23="P9"),AM23<>"R0"),"T17/P9 harus R0; ","")&IF(AND(AN23="T01",AO23<>"P6"),"T01 biasanya P6 (periksa); ","")&IF(AND(AO23="P1",AQ23<>"K4"),"P1 biasanya K4 (periksa); ","")="","OK",IF(AND(AM23="R0",AQ23<>"K5"),"R0 harus K5; ","")&IF(AND(AM23="R1",AQ23="K3"),"R1 tidak boleh K3 (fungsional); ","")&IF(AND(AM23="R2",AQ23="K5"),"R2 tidak boleh K5; ","")&IF(AND(AM23="R2",OR(AL23="S6",AL23="S7",AL23="S8")),"R2 tidak boleh S6/S7/S8; ","")&IF(AND(AO23="P9",AN23<>"T17"),"P9 hanya dengan T17; ","")&IF(AND(OR(AN23="T17",AO23="P9"),AM23<>"R0"),"T17/P9 harus R0; ","")&IF(AND(AN23="T01",AO23<>"P6"),"T01 biasanya P6 (periksa); ","")&IF(AND(AO23="P1",AQ23<>"K4"),"P1 biasanya K4 (periksa); ","")))
A24: 21 | B24: =IF(INDEX(Korpus!$A:$A,$A24)="","",INDEX(Korpus!$A:$A,$A24)) | C24: =TRIM(INDEX(Korpus!$D:$D,$A24)&" "&INDEX(Korpus!$E:$E,$A24)) | D24: =IF(INDEX(Korpus!$B:$B,$A24)="","",INDEX(Korpus!$B:$B,$A24)) | E24: =IF(INDEX(Korpus!$C:$C,$A24)="","",INDEX(Korpus!$C:$C,$A24)) | F24: =IF(INDEX(Korpus!$F:$F,$A24)="","",INDEX(Korpus!$F:$F,$A24)) | Y24: =IF(OR(M24="",S24=""),"",IF(M24=S24,"Sama","Beda")) | Z24: =IF(OR(N24="",T24=""),"",IF(N24=T24,"Sama","Beda")) | AA24: =IF(OR(O24="",U24=""),"",IF(O24=U24,"Sama","Beda")) | AB24: =IF(OR(P24="",V24=""),"",IF(P24=V24,"Sama","Beda")) | AC24: =IF(OR(Q24="",W24=""),"",IF(Q24=W24,"Sama","Beda")) | AD24: =IF(OR(R24="",X24=""),"",IF(R24=X24,"Sama","Beda")) | AE24: =COUNTIF(Y24:AD24,"Beda") -> 0 | AL24: =IF(AF24<>"",AF24,IF(AND(M24<>"",M24=S24),M24,"")) | AM24: =IF(AG24<>"",AG24,IF(AND(N24<>"",N24=T24),N24,"")) | AN24: =IF(AH24<>"",AH24,IF(AND(O24<>"",O24=U24),O24,"")) | AO24: =IF(AI24<>"",AI24,IF(AND(P24<>"",P24=V24),P24,"")) | AP24: =IF(AJ24<>"",AJ24,IF(AND(Q24<>"",Q24=W24),Q24,"")) | AQ24: =IF(AK24<>"",AK24,IF(AND(R24<>"",R24=X24),R24,"")) | AS24: =IF(COUNTA(M24:R24)+COUNTA(S24:X24)<12,"Menunggu coder",IF(AE24=0,"Sepakat",IF(SUMPRODUCT((Y24:AD24="Beda")*(AF24:AK24=""))=0,"Selesai adjudikasi","Perlu adjudikasi"))) -> Menunggu coder | AT24: =IF(COUNTIF(AL24:AQ24,"?*")<6,"",IF(IF(AND(AM24="R0",AQ24<>"K5"),"R0 harus K5; ","")&IF(AND(AM24="R1",AQ24="K3"),"R1 tidak boleh K3 (fungsional); ","")&IF(AND(AM24="R2",AQ24="K5"),"R2 tidak boleh K5; ","")&IF(AND(AM24="R2",OR(AL24="S6",AL24="S7",AL24="S8")),"R2 tidak boleh S6/S7/S8; ","")&IF(AND(AO24="P9",AN24<>"T17"),"P9 hanya dengan T17; ","")&IF(AND(OR(AN24="T17",AO24="P9"),AM24<>"R0"),"T17/P9 harus R0; ","")&IF(AND(AN24="T01",AO24<>"P6"),"T01 biasanya P6 (periksa); ","")&IF(AND(AO24="P1",AQ24<>"K4"),"P1 biasanya K4 (periksa); ","")="","OK",IF(AND(AM24="R0",AQ24<>"K5"),"R0 harus K5; ","")&IF(AND(AM24="R1",AQ24="K3"),"R1 tidak boleh K3 (fungsional); ","")&IF(AND(AM24="R2",AQ24="K5"),"R2 tidak boleh K5; ","")&IF(AND(AM24="R2",OR(AL24="S6",AL24="S7",AL24="S8")),"R2 tidak boleh S6/S7/S8; ","")&IF(AND(AO24="P9",AN24<>"T17"),"P9 hanya dengan T17; ","")&IF(AND(OR(AN24="T17",AO24="P9"),AM24<>"R0"),"T17/P9 harus R0; ","")&IF(AND(AN24="T01",AO24<>"P6"),"T01 biasanya P6 (periksa); ","")&IF(AND(AO24="P1",AQ24<>"K4"),"P1 biasanya K4 (periksa); ","")))
A25: 22 | B25: =IF(INDEX(Korpus!$A:$A,$A25)="","",INDEX(Korpus!$A:$A,$A25)) | C25: =TRIM(INDEX(Korpus!$D:$D,$A25)&" "&INDEX(Korpus!$E:$E,$A25)) | D25: =IF(INDEX(Korpus!$B:$B,$A25)="","",INDEX(Korpus!$B:$B,$A25)) | E25: =IF(INDEX(Korpus!$C:$C,$A25)="","",INDEX(Korpus!$C:$C,$A25)) | F25: =IF(INDEX(Korpus!$F:$F,$A25)="","",INDEX(Korpus!$F:$F,$A25)) | G25: S8 | H25: R1 | I25: T10 | J25: P2 | K25: F8 | L25: K1 | Y25: =IF(OR(M25="",S25=""),"",IF(M25=S25,"Sama","Beda")) | Z25: =IF(OR(N25="",T25=""),"",IF(N25=T25,"Sama","Beda")) | AA25: =IF(OR(O25="",U25=""),"",IF(O25=U25,"Sama","Beda")) | AB25: =IF(OR(P25="",V25=""),"",IF(P25=V25,"Sama","Beda")) | AC25: =IF(OR(Q25="",W25=""),"",IF(Q25=W25,"Sama","Beda")) | AD25: =IF(OR(R25="",X25=""),"",IF(R25=X25,"Sama","Beda")) | AE25: =COUNTIF(Y25:AD25,"Beda") -> 0 | AL25: =IF(AF25<>"",AF25,IF(AND(M25<>"",M25=S25),M25,"")) | AM25: =IF(AG25<>"",AG25,IF(AND(N25<>"",N25=T25),N25,"")) | AN25: =IF(AH25<>"",AH25,IF(AND(O25<>"",O25=U25),O25,"")) | AO25: =IF(AI25<>"",AI25,IF(AND(P25<>"",P25=V25),P25,"")) | AP25: =IF(AJ25<>"",AJ25,IF(AND(Q25<>"",Q25=W25),Q25,"")) | AQ25: =IF(AK25<>"",AK25,IF(AND(R25<>"",R25=X25),R25,"")) | AS25: =IF(COUNTA(M25:R25)+COUNTA(S25:X25)<12,"Menunggu coder",IF(AE25=0,"Sepakat",IF(SUMPRODUCT((Y25:AD25="Beda")*(AF25:AK25=""))=0,"Selesai adjudikasi","Perlu adjudikasi"))) -> Menunggu coder | AT25: =IF(COUNTIF(AL25:AQ25,"?*")<6,"",IF(IF(AND(AM25="R0",AQ25<>"K5"),"R0 harus K5; ","")&IF(AND(AM25="R1",AQ25="K3"),"R1 tidak boleh K3 (fungsional); ","")&IF(AND(AM25="R2",AQ25="K5"),"R2 tidak boleh K5; ","")&IF(AND(AM25="R2",OR(AL25="S6",AL25="S7",AL25="S8")),"R2 tidak boleh S6/S7/S8; ","")&IF(AND(AO25="P9",AN25<>"T17"),"P9 hanya dengan T17; ","")&IF(AND(OR(AN25="T17",AO25="P9"),AM25<>"R0"),"T17/P9 harus R0; ","")&IF(AND(AN25="T01",AO25<>"P6"),"T01 biasanya P6 (periksa); ","")&IF(AND(AO25="P1",AQ25<>"K4"),"P1 biasanya K4 (periksa); ","")="","OK",IF(AND(AM25="R0",AQ25<>"K5"),"R0 harus K5; ","")&IF(AND(AM25="R1",AQ25="K3"),"R1 tidak boleh K3 (fungsional); ","")&IF(AND(AM25="R2",AQ25="K5"),"R2 tidak boleh K5; ","")&IF(AND(AM25="R2",OR(AL25="S6",AL25="S7",AL25="S8")),"R2 tidak boleh S6/S7/S8; ","")&IF(AND(AO25="P9",AN25<>"T17"),"P9 hanya dengan T17; ","")&IF(AND(OR(AN25="T17",AO25="P9"),AM25<>"R0"),"T17/P9 harus R0; ","")&IF(AND(AN25="T01",AO25<>"P6"),"T01 biasanya P6 (periksa); ","")&IF(AND(AO25="P1",AQ25<>"K4"),"P1 biasanya K4 (periksa); ","")))
A26: 23 | B26: =IF(INDEX(Korpus!$A:$A,$A26)="","",INDEX(Korpus!$A:$A,$A26)) | C26: =TRIM(INDEX(Korpus!$D:$D,$A26)&" "&INDEX(Korpus!$E:$E,$A26)) | D26: =IF(INDEX(Korpus!$B:$B,$A26)="","",INDEX(Korpus!$B:$B,$A26)) | E26: =IF(INDEX(Korpus!$C:$C,$A26)="","",INDEX(Korpus!$C:$C,$A26)) | F26: =IF(INDEX(Korpus!$F:$F,$A26)="","",INDEX(Korpus!$F:$F,$A26)) | Y26: =IF(OR(M26="",S26=""),"",IF(M26=S26,"Sama","Beda")) | Z26: =IF(OR(N26="",T26=""),"",IF(N26=T26,"Sama","Beda")) | AA26: =IF(OR(O26="",U26=""),"",IF(O26=U26,"Sama","Beda")) | AB26: =IF(OR(P26="",V26=""),"",IF(P26=V26,"Sama","Beda")) | AC26: =IF(OR(Q26="",W26=""),"",IF(Q26=W26,"Sama","Beda")) | AD26: =IF(OR(R26="",X26=""),"",IF(R26=X26,"Sama","Beda")) | AE26: =COUNTIF(Y26:AD26,"Beda") -> 0 | AL26: =IF(AF26<>"",AF26,IF(AND(M26<>"",M26=S26),M26,"")) | AM26: =IF(AG26<>"",AG26,IF(AND(N26<>"",N26=T26),N26,"")) | AN26: =IF(AH26<>"",AH26,IF(AND(O26<>"",O26=U26),O26,"")) | AO26: =IF(AI26<>"",AI26,IF(AND(P26<>"",P26=V26),P26,"")) | AP26: =IF(AJ26<>"",AJ26,IF(AND(Q26<>"",Q26=W26),Q26,"")) | AQ26: =IF(AK26<>"",AK26,IF(AND(R26<>"",R26=X26),R26,"")) | AS26: =IF(COUNTA(M26:R26)+COUNTA(S26:X26)<12,"Menunggu coder",IF(AE26=0,"Sepakat",IF(SUMPRODUCT((Y26:AD26="Beda")*(AF26:AK26=""))=0,"Selesai adjudikasi","Perlu adjudikasi"))) -> Menunggu coder | AT26: =IF(COUNTIF(AL26:AQ26,"?*")<6,"",IF(IF(AND(AM26="R0",AQ26<>"K5"),"R0 harus K5; ","")&IF(AND(AM26="R1",AQ26="K3"),"R1 tidak boleh K3 (fungsional); ","")&IF(AND(AM26="R2",AQ26="K5"),"R2 tidak boleh K5; ","")&IF(AND(AM26="R2",OR(AL26="S6",AL26="S7",AL26="S8")),"R2 tidak boleh S6/S7/S8; ","")&IF(AND(AO26="P9",AN26<>"T17"),"P9 hanya dengan T17; ","")&IF(AND(OR(AN26="T17",AO26="P9"),AM26<>"R0"),"T17/P9 harus R0; ","")&IF(AND(AN26="T01",AO26<>"P6"),"T01 biasanya P6 (periksa); ","")&IF(AND(AO26="P1",AQ26<>"K4"),"P1 biasanya K4 (periksa); ","")="","OK",IF(AND(AM26="R0",AQ26<>"K5"),"R0 harus K5; ","")&IF(AND(AM26="R1",AQ26="K3"),"R1 tidak boleh K3 (fungsional); ","")&IF(AND(AM26="R2",AQ26="K5"),"R2 tidak boleh K5; ","")&IF(AND(AM26="R2",OR(AL26="S6",AL26="S7",AL26="S8")),"R2 tidak boleh S6/S7/S8; ","")&IF(AND(AO26="P9",AN26<>"T17"),"P9 hanya dengan T17; ","")&IF(AND(OR(AN26="T17",AO26="P9"),AM26<>"R0"),"T17/P9 harus R0; ","")&IF(AND(AN26="T01",AO26<>"P6"),"T01 biasanya P6 (periksa); ","")&IF(AND(AO26="P1",AQ26<>"K4"),"P1 biasanya K4 (periksa); ","")))
A27: 24 | B27: =IF(INDEX(Korpus!$A:$A,$A27)="","",INDEX(Korpus!$A:$A,$A27)) | C27: =TRIM(INDEX(Korpus!$D:$D,$A27)&" "&INDEX(Korpus!$E:$E,$A27)) | D27: =IF(INDEX(Korpus!$B:$B,$A27)="","",INDEX(Korpus!$B:$B,$A27)) | E27: =IF(INDEX(Korpus!$C:$C,$A27)="","",INDEX(Korpus!$C:$C,$A27)) | F27: =IF(INDEX(Korpus!$F:$F,$A27)="","",INDEX(Korpus!$F:$F,$A27)) | Y27: =IF(OR(M27="",S27=""),"",IF(M27=S27,"Sama","Beda")) | Z27: =IF(OR(N27="",T27=""),"",IF(N27=T27,"Sama","Beda")) | AA27: =IF(OR(O27="",U27=""),"",IF(O27=U27,"Sama","Beda")) | AB27: =IF(OR(P27="",V27=""),"",IF(P27=V27,"Sama","Beda")) | AC27: =IF(OR(Q27="",W27=""),"",IF(Q27=W27,"Sama","Beda")) | AD27: =IF(OR(R27="",X27=""),"",IF(R27=X27,"Sama","Beda")) | AE27: =COUNTIF(Y27:AD27,"Beda") -> 0 | AL27: =IF(AF27<>"",AF27,IF(AND(M27<>"",M27=S27),M27,"")) | AM27: =IF(AG27<>"",AG27,IF(AND(N27<>"",N27=T27),N27,"")) | AN27: =IF(AH27<>"",AH27,IF(AND(O27<>"",O27=U27),O27,"")) | AO27: =IF(AI27<>"",AI27,IF(AND(P27<>"",P27=V27),P27,"")) | AP27: =IF(AJ27<>"",AJ27,IF(AND(Q27<>"",Q27=W27),Q27,"")) | AQ27: =IF(AK27<>"",AK27,IF(AND(R27<>"",R27=X27),R27,"")) | AS27: =IF(COUNTA(M27:R27)+COUNTA(S27:X27)<12,"Menunggu coder",IF(AE27=0,"Sepakat",IF(SUMPRODUCT((Y27:AD27="Beda")*(AF27:AK27=""))=0,"Selesai adjudikasi","Perlu adjudikasi"))) -> Menunggu coder | AT27: =IF(COUNTIF(AL27:AQ27,"?*")<6,"",IF(IF(AND(AM27="R0",AQ27<>"K5"),"R0 harus K5; ","")&IF(AND(AM27="R1",AQ27="K3"),"R1 tidak boleh K3 (fungsional); ","")&IF(AND(AM27="R2",AQ27="K5"),"R2 tidak boleh K5; ","")&IF(AND(AM27="R2",OR(AL27="S6",AL27="S7",AL27="S8")),"R2 tidak boleh S6/S7/S8; ","")&IF(AND(AO27="P9",AN27<>"T17"),"P9 hanya dengan T17; ","")&IF(AND(OR(AN27="T17",AO27="P9"),AM27<>"R0"),"T17/P9 harus R0; ","")&IF(AND(AN27="T01",AO27<>"P6"),"T01 biasanya P6 (periksa); ","")&IF(AND(AO27="P1",AQ27<>"K4"),"P1 biasanya K4 (periksa); ","")="","OK",IF(AND(AM27="R0",AQ27<>"K5"),"R0 harus K5; ","")&IF(AND(AM27="R1",AQ27="K3"),"R1 tidak boleh K3 (fungsional); ","")&IF(AND(AM27="R2",AQ27="K5"),"R2 tidak boleh K5; ","")&IF(AND(AM27="R2",OR(AL27="S6",AL27="S7",AL27="S8")),"R2 tidak boleh S6/S7/S8; ","")&IF(AND(AO27="P9",AN27<>"T17"),"P9 hanya dengan T17; ","")&IF(AND(OR(AN27="T17",AO27="P9"),AM27<>"R0"),"T17/P9 harus R0; ","")&IF(AND(AN27="T01",AO27<>"P6"),"T01 biasanya P6 (periksa); ","")&IF(AND(AO27="P1",AQ27<>"K4"),"P1 biasanya K4 (periksa); ","")))
A28: 25 | B28: =IF(INDEX(Korpus!$A:$A,$A28)="","",INDEX(Korpus!$A:$A,$A28)) | C28: =TRIM(INDEX(Korpus!$D:$D,$A28)&" "&INDEX(Korpus!$E:$E,$A28)) | D28: =IF(INDEX(Korpus!$B:$B,$A28)="","",INDEX(Korpus!$B:$B,$A28)) | E28: =IF(INDEX(Korpus!$C:$C,$A28)="","",INDEX(Korpus!$C:$C,$A28)) | F28: =IF(INDEX(Korpus!$F:$F,$A28)="","",INDEX(Korpus!$F:$F,$A28)) | Y28: =IF(OR(M28="",S28=""),"",IF(M28=S28,"Sama","Beda")) | Z28: =IF(OR(N28="",T28=""),"",IF(N28=T28,"Sama","Beda")) | AA28: =IF(OR(O28="",U28=""),"",IF(O28=U28,"Sama","Beda")) | AB28: =IF(OR(P28="",V28=""),"",IF(P28=V28,"Sama","Beda")) | AC28: =IF(OR(Q28="",W28=""),"",IF(Q28=W28,"Sama","Beda")) | AD28: =IF(OR(R28="",X28=""),"",IF(R28=X28,"Sama","Beda")) | AE28: =COUNTIF(Y28:AD28,"Beda") -> 0 | AL28: =IF(AF28<>"",AF28,IF(AND(M28<>"",M28=S28),M28,"")) | AM28: =IF(AG28<>"",AG28,IF(AND(N28<>"",N28=T28),N28,"")) | AN28: =IF(AH28<>"",AH28,IF(AND(O28<>"",O28=U28),O28,"")) | AO28: =IF(AI28<>"",AI28,IF(AND(P28<>"",P28=V28),P28,"")) | AP28: =IF(AJ28<>"",AJ28,IF(AND(Q28<>"",Q28=W28),Q28,"")) | AQ28: =IF(AK28<>"",AK28,IF(AND(R28<>"",R28=X28),R28,"")) | AS28: =IF(COUNTA(M28:R28)+COUNTA(S28:X28)<12,"Menunggu coder",IF(AE28=0,"Sepakat",IF(SUMPRODUCT((Y28:AD28="Beda")*(AF28:AK28=""))=0,"Selesai adjudikasi","Perlu adjudikasi"))) -> Menunggu coder | AT28: =IF(COUNTIF(AL28:AQ28,"?*")<6,"",IF(IF(AND(AM28="R0",AQ28<>"K5"),"R0 harus K5; ","")&IF(AND(AM28="R1",AQ28="K3"),"R1 tidak boleh K3 (fungsional); ","")&IF(AND(AM28="R2",AQ28="K5"),"R2 tidak boleh K5; ","")&IF(AND(AM28="R2",OR(AL28="S6",AL28="S7",AL28="S8")),"R2 tidak boleh S6/S7/S8; ","")&IF(AND(AO28="P9",AN28<>"T17"),"P9 hanya dengan T17; ","")&IF(AND(OR(AN28="T17",AO28="P9"),AM28<>"R0"),"T17/P9 harus R0; ","")&IF(AND(AN28="T01",AO28<>"P6"),"T01 biasanya P6 (periksa); ","")&IF(AND(AO28="P1",AQ28<>"K4"),"P1 biasanya K4 (periksa); ","")="","OK",IF(AND(AM28="R0",AQ28<>"K5"),"R0 harus K5; ","")&IF(AND(AM28="R1",AQ28="K3"),"R1 tidak boleh K3 (fungsional); ","")&IF(AND(AM28="R2",AQ28="K5"),"R2 tidak boleh K5; ","")&IF(AND(AM28="R2",OR(AL28="S6",AL28="S7",AL28="S8")),"R2 tidak boleh S6/S7/S8; ","")&IF(AND(AO28="P9",AN28<>"T17"),"P9 hanya dengan T17; ","")&IF(AND(OR(AN28="T17",AO28="P9"),AM28<>"R0"),"T17/P9 harus R0; ","")&IF(AND(AN28="T01",AO28<>"P6"),"T01 biasanya P6 (periksa); ","")&IF(AND(AO28="P1",AQ28<>"K4"),"P1 biasanya K4 (periksa); ","")))
