Workbook

Sheet Petunjuk
A1: File Kunci Adjudikasi: Analisis Isi Krippendorff
A2: Codebook versi 1.0.3 (25 Oktober 2026). Hanya untuk peneliti utama (adjudikator). Jangan dibagikan kepada coder.
B4: Alur kerja
B5: 1 | C5: Korpus sudah terisi di sheet Korpus (A1:F87) dari Korpus_Codebook_1.xlsx; tempel ulang bila korpus berubah. Kolom Dokumen, Rujukan, BAB, Bagian, dan Isi pada Kunci Adjudikasi terisi otomatis.
B6: 2 | C6: Pilih jumlah coder yang dinilai pada sel D1 sheet Kunci Adjudikasi (2 coder: A dan B; 3 coder: A, B, dan C; 4 coder: A sampai D). Setelah coder selesai, salin nilai V4 sampai V9 dari kolom F sampai K lembar coding masing-masing (baris 2 sampai 86) ke blok coder mulai baris 5: Coder A (M sampai R), Coder B (S sampai X), Coder C (Y sampai AD), dan Coder D (AE sampai AJ). Tempel sebagai nilai (Paste Values); nilai berformat Kode - Label ditempel apa adanya. Urutan baris sama, ID_Unit 2 sampai 86.
B7: 3 | C7: Kolom AK sampai AP menandai Sama (semua coder aktif identik) atau Beda per variabel. Sheet Reliabilitas menghitung Krippendorff alpha dari data sebelum rekonsiliasi; sheet Hitung adalah sheet bantu perhitungan dan tidak perlu diedit.
B8: 4 | C8: Setelah α dilaporkan, selesaikan setiap perbedaan melalui diskusi, isi Keputusan Adjudikator (AR sampai AW) hanya pada variabel yang berbeda, dan tulis alasannya di BD.
B9: 5 | C9: Kode Final (AX sampai BC) = keputusan adjudikator bila ada, selain itu kode yang disepakati semua coder aktif. Kolom BF memeriksa aturan konsistensi (Bagian 9) pada kode final. Sheet Ringkasan Final merangkum kemajuan adjudikasi, perbedaan per variabel, kecocokan coder dengan acuan, dan sebaran Kode Final.
B10: 6 | C10: Kode Acuan Peneliti (G sampai L) terisi untuk 11 contoh pada Bagian 10 codebook (baris 2, 15, 22, 28, 32, 49, 55, 62, 67, 83, 86). Kolom BG sampai BJ membandingkan jawaban tiap coder dengan acuan pada baris-baris itu (Ya bila 6 dari 6 variabel cocok); kolom ini tidak dihitung dalam α. Isi baris lain bila peneliti ingin menyimpan kunci sendiri.
B11: Catatan metode
B12: α | C12: Dihitung dari data coder aktif (2, 3, atau 4 coder): V4, V6, V7, V8, V9 nominal dan V5 ordinal (Bagian 12.1). Unit yang memiliki sedikitnya dua nilai dari coder aktif ikut dihitung; sel kosong dianggap data hilang. Hasil paling andal bila semua coder aktif mengisi semua unit.
B13: Selang kepercayaan | C13: Selang kepercayaan bootstrap belum dihitung di Excel. Hitung dengan paket krippendorff (Python) atau kripp.alpha pada paket irr (R) dari data yang sama.
B14: Kriteria | C14: α ≥ 0,800 dapat diterima; 0,667 ≤ α < 0,800 hanya untuk kesimpulan tentatif; α < 0,667 revisi variabel dan kodekan ulang.
B15: Warna | C15: Kuning: sel input. Biru muda: Coder A. Oranye muda: Coder B. Ungu muda: Coder C. Tosca muda: Coder D. Hijau muda: kunci peneliti dan kode final. Abu-abu: blok coder yang tidak aktif pada pilihan jumlah coder.

Sheet Kunci Adjudikasi
A1: Kunci Adjudikasi | C1: Jumlah coder dinilai: | D1: 2 coder | E1: =IFERROR(VALUE(LEFT(D1,1)),2) -> 2
A2: Isi V4 sampai V9 setiap coder (A, B, C, D). Pilih jumlah coder pada D1: 2 coder (A, B), 3 coder (A, B, C), atau 4 coder (A sampai D). Hanya coder aktif yang dihitung; blok coder tidak aktif berwarna abu-abu.
A3: Identitas dan teks (dari Korpus) | G3: Kode Acuan Peneliti (Bagian 10) | M3: Fenny | S3: Coder B | Y3: Coder C (aktif bila 3 atau 4 coder) | AE3: Coder D (aktif bila 4 coder) | AK3: Sama / Beda | AQ3: Beda | AR3: Keputusan Adjudikator | AX3: Kode Final | BD3: Catatan | BE3: Status | BF3: Cek | BG3: Cocok dengan acuan? (hanya baris yang berkode acuan)
A4: V1 ID_Unit | B4: Dokumen | C4: Rujukan | D4: BAB | E4: Bagian | F4: Isi | G4: V4 Acuan | H4: V5 Acuan | I4: V6 Acuan | J4: V7 Acuan | K4: V8 Acuan | L4: V9 Acuan | M4: V4 A | N4: V5 A | O4: V6 A | P4: V7 A | Q4: V8 A | R4: V9 A | S4: V4 B | T4: V5 B | U4: V6 B | V4: V7 B | W4: V8 B | X4: V9 B | Y4: V4 C | Z4: V5 C | AA4: V6 C | AB4: V7 C | AC4: V8 C | AD4: V9 C | AE4: V4 D | AF4: V5 D | AG4: V6 D | AH4: V7 D | AI4: V8 D | AJ4: V9 D | AK4: V4 | AL4: V5 | AM4: V6 | AN4: V7 | AO4: V8 | AP4: V9 | AQ4: Jumlah Beda | AR4: V4 Keputusan | AS4: V5 Keputusan | AT4: V6 Keputusan | AU4: V7 Keputusan | AV4: V8 Keputusan | AW4: V9 Keputusan | AX4: V4 Final | AY4: V5 Final | AZ4: V6 Final | BA4: V7 Final | BB4: V8 Final | BC4: V9 Final | BD4: Alasan Adjudikasi | BE4: Status | BF4: Cek Konsistensi Final | BG4: Cocok acuan A | BH4: Cocok acuan B | BI4: Cocok acuan C | BJ4: Cocok acuan D | BK4: Pilot
A5: 2 | B5: =IF(INDEX(Korpus!$A:$A,$A5)="","",INDEX(Korpus!$A:$A,$A5)) -> 2019MHN201 | C5: =TRIM(INDEX(Korpus!$D:$D,$A5)&" "&INDEX(Korpus!$E:$E,$A5)) -> Paragraf 3 Kalimat 1 | D5: =IF(INDEX(Korpus!$B:$B,$A5)="","",INDEX(Korpus!$B:$B,$A5)) -> C. Pembahasan | E5: =IF(INDEX(Korpus!$C:$C,$A5)="","",INDEX(Korpus!$C:$C,$A5)) -> 5. Pentingnya Perlindungan Data Pribadi | F5: =IF(INDEX(Korpus!$F:$F,$A5)="","",INDEX(Korpus!$F:$F,$A5)) -> Melihat banyaknya kasus penyalahgunaan data pribadi, sangat penting untuk memberikan perlindungan data pribadi. | G5: S9 - Tidak ada subjek perorangan atau organisasi eksplisit | H5: R1 - Relevan tidak langsung | I5: T02 - Latar Normatif dan Rujukan Non-operasional | J5: P8 - Deskriptif, argumentatif, dan rujukan | K5: F8 - Lintas tahap atau tidak spesifik | L5: K5 - Tidak menghasilkan kebutuhan. Apakah teks benar-benar tidak dapat diterjemahkan menjadi kalimat "Sistem harus/tidak boleh …"? | M5: S4 - Subjek Data Pribadi | N5: R2 - Relevan langsung | O5: T07 - Hak Subjek Data Pribadi | P5: P3 - Hak | Q5: F4 - Penyimpanan dan pengamanan | R5: K2 - Non-fungsional: mutu data, kepatuhan, dan akuntabilitas. Apakah ini mutu atau bukti yang berlaku untuk seluruh sistem, bukan hanya satu operasi? | AK5: =IF(Hitung!B5<$E$1,"",IF(Hitung!C5>0,"Beda","Sama")) | AL5: =IF(Hitung!D5<$E$1,"",IF(Hitung!E5>0,"Beda","Sama")) | AM5: =IF(Hitung!F5<$E$1,"",IF(Hitung!G5>0,"Beda","Sama")) | AN5: =IF(Hitung!H5<$E$1,"",IF(Hitung!I5>0,"Beda","Sama")) | AO5: =IF(Hitung!J5<$E$1,"",IF(Hitung!K5>0,"Beda","Sama")) | AP5: =IF(Hitung!L5<$E$1,"",IF(Hitung!M5>0,"Beda","Sama")) | AQ5: =COUNTIF(AK5:AP5,"Beda") -> 0 | AX5: =IF(AR5<>"",AR5,IF(AND(Hitung!B5=$E$1,Hitung!C5=0),M5,"")) | AY5: =IF(AS5<>"",AS5,IF(AND(Hitung!D5=$E$1,Hitung!E5=0),N5,"")) | AZ5: =IF(AT5<>"",AT5,IF(AND(Hitung!F5=$E$1,Hitung!G5=0),O5,"")) | BA5: =IF(AU5<>"",AU5,IF(AND(Hitung!H5=$E$1,Hitung!I5=0),P5,"")) | BB5: =IF(AV5<>"",AV5,IF(AND(Hitung!J5=$E$1,Hitung!K5=0),Q5,"")) | BC5: =IF(AW5<>"",AW5,IF(AND(Hitung!L5=$E$1,Hitung!M5=0),R5,"")) | BE5: =IF(COUNTA(M5:R5)+COUNTA(S5:X5)+($E$1>=3)*COUNTA(Y5:AD5)+($E$1>=4)*COUNTA(AE5:AJ5)<6*$E$1,"Menunggu coder",IF(AQ5=0,"Sepakat",IF(SUMPRODUCT((AK5:AP5="Beda")*(AR5:AW5=""))=0,"Selesai adjudikasi","Perlu adjudikasi"))) -> Menunggu coder | BF5: =IF(COUNTIF(AX5:BC5,"?*")<6,"",IF(IF(AND(LEFT(AY5,2)="R0",LEFT(BC5,2)<>"K5"),"R0 harus K5; ","")&IF(AND(LEFT(AY5,2)="R1",LEFT(BC5,2)="K3"),"R1 tidak boleh K3 (fungsional); ","")&IF(AND(LEFT(AY5,2)="R2",LEFT(BC5,2)="K5"),"R2 tidak boleh K5; ","")&IF(AND(LEFT(AY5,2)="R2",OR(LEFT(AX5,2)="S6",LEFT(AX5,2)="S7",LEFT(AX5,2)="S8")),"R2 tidak boleh S6/S7/S8; ","")&IF(AND(LEFT(AY5,2)="R2",OR(LEFT(AZ5,3)="T02",LEFT(BA5,2)="P8")),"T02 atau P8 tidak boleh R2; ","")&IF(AND(LEFT(AZ5,3)="T01",LEFT(BA5,2)<>"P6"),"T01 biasanya P6 (periksa); ","")&IF(AND(LEFT(BA5,2)="P1",LEFT(BC5,2)<>"K4"),"P1 biasanya K4 (periksa); ","")="","OK",IF(AND(LEFT(AY5,2)="R0",LEFT(BC5,2)<>"K5"),"R0 harus K5; ","")&IF(AND(LEFT(AY5,2)="R1",LEFT(BC5,2)="K3"),"R1 tidak boleh K3 (fungsional); ","")&IF(AND(LEFT(AY5,2)="R2",LEFT(BC5,2)="K5"),"R2 tidak boleh K5; ","")&IF(AND(LEFT(AY5,2)="R2",OR(LEFT(AX5,2)="S6",LEFT(AX5,2)="S7",LEFT(AX5,2)="S8")),"R2 tidak boleh S6/S7/S8; ","")&IF(AND(LEFT(AY5,2)="R2",OR(LEFT(AZ5,3)="T02",LEFT(BA5,2)="P8")),"T02 atau P8 tidak boleh R2; ","")&IF(AND(LEFT(AZ5,3)="T01",LEFT(BA5,2)<>"P6"),"T01 biasanya P6 (periksa); ","")&IF(AND(LEFT(BA5,2)="P1",LEFT(BC5,2)<>"K4"),"P1 biasanya K4 (periksa); ",""))) | BG5: =IF(COUNTA($G5:$L5)<6,"",IF(COUNTA(M5:R5)<6,"Belum lengkap",IF((LEFT(M5,2)=LEFT(G5,2))+(LEFT(N5,2)=LEFT(H5,2))+(LEFT(O5,3)=LEFT(I5,3))+(LEFT(P5,2)=LEFT(J5,2))+(LEFT(Q5,2)=LEFT(K5,2))+(LEFT(R5,2)=LEFT(L5,2))=6,"Ya (6/6)","Tidak ("&(LEFT(M5,2)=LEFT(G5,2))+(LEFT(N5,2)=LEFT(H5,2))+(LEFT(O5,3)=LEFT(I5,3))+(LEFT(P5,2)=LEFT(J5,2))+(LEFT(Q5,2)=LEFT(K5,2))+(LEFT(R5,2)=LEFT(L5,2))&"/6): "&TRIM(IF(NOT(LEFT(M5,2)=LEFT(G5,2)),"V4 ","")&IF(NOT(LEFT(N5,2)=LEFT(H5,2)),"V5 ","")&IF(NOT(LEFT(O5,3)=LEFT(I5,3)),"V6 ","")&IF(NOT(LEFT(P5,2)=LEFT(J5,2)),"V7 ","")&IF(NOT(LEFT(Q5,2)=LEFT(K5,2)),"V8 ","")&IF(NOT(LEFT(R5,2)=LEFT(L5,2)),"V9 ",""))))) -> Tidak (0/6): V4 V5 V6 V7 V8 V9 | BH5: =IF(COUNTA($G5:$L5)<6,"",IF(COUNTA(S5:X5)<6,"Belum lengkap",IF((LEFT(S5,2)=LEFT(G5,2))+(LEFT(T5,2)=LEFT(H5,2))+(LEFT(U5,3)=LEFT(I5,3))+(LEFT(V5,2)=LEFT(J5,2))+(LEFT(W5,2)=LEFT(K5,2))+(LEFT(X5,2)=LEFT(L5,2))=6,"Ya (6/6)","Tidak ("&(LEFT(S5,2)=LEFT(G5,2))+(LEFT(T5,2)=LEFT(H5,2))+(LEFT(U5,3)=LEFT(I5,3))+(LEFT(V5,2)=LEFT(J5,2))+(LEFT(W5,2)=LEFT(K5,2))+(LEFT(X5,2)=LEFT(L5,2))&"/6): "&TRIM(IF(NOT(LEFT(S5,2)=LEFT(G5,2)),"V4 ","")&IF(NOT(LEFT(T5,2)=LEFT(H5,2)),"V5 ","")&IF(NOT(LEFT(U5,3)=LEFT(I5,3)),"V6 ","")&IF(NOT(LEFT(V5,2)=LEFT(J5,2)),"V7 ","")&IF(NOT(LEFT(W5,2)=LEFT(K5,2)),"V8 ","")&IF(NOT(LEFT(X5,2)=LEFT(L5,2)),"V9 ",""))))) -> Belum lengkap | BI5: =IF(COUNTA($G5:$L5)<6,"",IF($E$1<3,"",IF(COUNTA(Y5:AD5)<6,"Belum lengkap",IF((LEFT(Y5,2)=LEFT(G5,2))+(LEFT(Z5,2)=LEFT(H5,2))+(LEFT(AA5,3)=LEFT(I5,3))+(LEFT(AB5,2)=LEFT(J5,2))+(LEFT(AC5,2)=LEFT(K5,2))+(LEFT(AD5,2)=LEFT(L5,2))=6,"Ya (6/6)","Tidak ("&(LEFT(Y5,2)=LEFT(G5,2))+(LEFT(Z5,2)=LEFT(H5,2))+(LEFT(AA5,3)=LEFT(I5,3))+(LEFT(AB5,2)=LEFT(J5,2))+(LEFT(AC5,2)=LEFT(K5,2))+(LEFT(AD5,2)=LEFT(L5,2))&"/6): "&TRIM(IF(NOT(LEFT(Y5,2)=LEFT(G5,2)),"V4 ","")&IF(NOT(LEFT(Z5,2)=LEFT(H5,2)),"V5 ","")&IF(NOT(LEFT(AA5,3)=LEFT(I5,3)),"V6 ","")&IF(NOT(LEFT(AB5,2)=LEFT(J5,2)),"V7 ","")&IF(NOT(LEFT(AC5,2)=LEFT(K5,2)),"V8 ","")&IF(NOT(LEFT(AD5,2)=LEFT(L5,2)),"V9 ","")))))) | BJ5: =IF(COUNTA($G5:$L5)<6,"",IF($E$1<4,"",IF(COUNTA(AE5:AJ5)<6,"Belum lengkap",IF((LEFT(AE5,2)=LEFT(G5,2))+(LEFT(AF5,2)=LEFT(H5,2))+(LEFT(AG5,3)=LEFT(I5,3))+(LEFT(AH5,2)=LEFT(J5,2))+(LEFT(AI5,2)=LEFT(K5,2))+(LEFT(AJ5,2)=LEFT(L5,2))=6,"Ya (6/6)","Tidak ("&(LEFT(AE5,2)=LEFT(G5,2))+(LEFT(AF5,2)=LEFT(H5,2))+(LEFT(AG5,3)=LEFT(I5,3))+(LEFT(AH5,2)=LEFT(J5,2))+(LEFT(AI5,2)=LEFT(K5,2))+(LEFT(AJ5,2)=LEFT(L5,2))&"/6): "&TRIM(IF(NOT(LEFT(AE5,2)=LEFT(G5,2)),"V4 ","")&IF(NOT(LEFT(AF5,2)=LEFT(H5,2)),"V5 ","")&IF(NOT(LEFT(AG5,3)=LEFT(I5,3)),"V6 ","")&IF(NOT(LEFT(AH5,2)=LEFT(J5,2)),"V7 ","")&IF(NOT(LEFT(AI5,2)=LEFT(K5,2)),"V8 ","")&IF(NOT(LEFT(AJ5,2)=LEFT(L5,2)),"V9 ","")))))) | BK5: CC
A6: 3 | B6: =IF(INDEX(Korpus!$A:$A,$A6)="","",INDEX(Korpus!$A:$A,$A6)) -> 2019MHN201 | C6: =TRIM(INDEX(Korpus!$D:$D,$A6)&" "&INDEX(Korpus!$E:$E,$A6)) -> Paragraf 3 Kalimat 2 | D6: =IF(INDEX(Korpus!$B:$B,$A6)="","",INDEX(Korpus!$B:$B,$A6)) -> C. Pembahasan | E6: =IF(INDEX(Korpus!$C:$C,$A6)="","",INDEX(Korpus!$C:$C,$A6)) -> 5. Pentingnya Perlindungan Data Pribadi | F6: =IF(INDEX(Korpus!$F:$F,$A6)="","",INDEX(Korpus!$F:$F,$A6)) -> Pentingnya memberikan perlindungan data pribadi mulai menguat seiring dengan meningkatnya jumlah pengguna telepon seluler dan internet. | AK6: =IF(Hitung!B6<$E$1,"",IF(Hitung!C6>0,"Beda","Sama")) | AL6: =IF(Hitung!D6<$E$1,"",IF(Hitung!E6>0,"Beda","Sama")) | AM6: =IF(Hitung!F6<$E$1,"",IF(Hitung!G6>0,"Beda","Sama")) | AN6: =IF(Hitung!H6<$E$1,"",IF(Hitung!I6>0,"Beda","Sama")) | AO6: =IF(Hitung!J6<$E$1,"",IF(Hitung!K6>0,"Beda","Sama")) | AP6: =IF(Hitung!L6<$E$1,"",IF(Hitung!M6>0,"Beda","Sama")) | AQ6: =COUNTIF(AK6:AP6,"Beda") -> 0 | AX6: =IF(AR6<>"",AR6,IF(AND(Hitung!B6=$E$1,Hitung!C6=0),M6,"")) | AY6: =IF(AS6<>"",AS6,IF(AND(Hitung!D6=$E$1,Hitung!E6=0),N6,"")) | AZ6: =IF(AT6<>"",AT6,IF(AND(Hitung!F6=$E$1,Hitung!G6=0),O6,"")) | BA6: =IF(AU6<>"",AU6,IF(AND(Hitung!H6=$E$1,Hitung!I6=0),P6,"")) | BB6: =IF(AV6<>"",AV6,IF(AND(Hitung!J6=$E$1,Hitung!K6=0),Q6,"")) | BC6: =IF(AW6<>"",AW6,IF(AND(Hitung!L6=$E$1,Hitung!M6=0),R6,"")) | BE6: =IF(COUNTA(M6:R6)+COUNTA(S6:X6)+($E$1>=3)*COUNTA(Y6:AD6)+($E$1>=4)*COUNTA(AE6:AJ6)<6*$E$1,"Menunggu coder",IF(AQ6=0,"Sepakat",IF(SUMPRODUCT((AK6:AP6="Beda")*(AR6:AW6=""))=0,"Selesai adjudikasi","Perlu adjudikasi"))) -> Menunggu coder | BF6: =IF(COUNTIF(AX6:BC6,"?*")<6,"",IF(IF(AND(LEFT(AY6,2)="R0",LEFT(BC6,2)<>"K5"),"R0 harus K5; ","")&IF(AND(LEFT(AY6,2)="R1",LEFT(BC6,2)="K3"),"R1 tidak boleh K3 (fungsional); ","")&IF(AND(LEFT(AY6,2)="R2",LEFT(BC6,2)="K5"),"R2 tidak boleh K5; ","")&IF(AND(LEFT(AY6,2)="R2",OR(LEFT(AX6,2)="S6",LEFT(AX6,2)="S7",LEFT(AX6,2)="S8")),"R2 tidak boleh S6/S7/S8; ","")&IF(AND(LEFT(AY6,2)="R2",OR(LEFT(AZ6,3)="T02",LEFT(BA6,2)="P8")),"T02 atau P8 tidak boleh R2; ","")&IF(AND(LEFT(AZ6,3)="T01",LEFT(BA6,2)<>"P6"),"T01 biasanya P6 (periksa); ","")&IF(AND(LEFT(BA6,2)="P1",LEFT(BC6,2)<>"K4"),"P1 biasanya K4 (periksa); ","")="","OK",IF(AND(LEFT(AY6,2)="R0",LEFT(BC6,2)<>"K5"),"R0 harus K5; ","")&IF(AND(LEFT(AY6,2)="R1",LEFT(BC6,2)="K3"),"R1 tidak boleh K3 (fungsional); ","")&IF(AND(LEFT(AY6,2)="R2",LEFT(BC6,2)="K5"),"R2 tidak boleh K5; ","")&IF(AND(LEFT(AY6,2)="R2",OR(LEFT(AX6,2)="S6",LEFT(AX6,2)="S7",LEFT(AX6,2)="S8")),"R2 tidak boleh S6/S7/S8; ","")&IF(AND(LEFT(AY6,2)="R2",OR(LEFT(AZ6,3)="T02",LEFT(BA6,2)="P8")),"T02 atau P8 tidak boleh R2; ","")&IF(AND(LEFT(AZ6,3)="T01",LEFT(BA6,2)<>"P6"),"T01 biasanya P6 (periksa); ","")&IF(AND(LEFT(BA6,2)="P1",LEFT(BC6,2)<>"K4"),"P1 biasanya K4 (periksa); ",""))) | BG6: =IF(COUNTA($G6:$L6)<6,"",IF(COUNTA(M6:R6)<6,"Belum lengkap",IF((LEFT(M6,2)=LEFT(G6,2))+(LEFT(N6,2)=LEFT(H6,2))+(LEFT(O6,3)=LEFT(I6,3))+(LEFT(P6,2)=LEFT(J6,2))+(LEFT(Q6,2)=LEFT(K6,2))+(LEFT(R6,2)=LEFT(L6,2))=6,"Ya (6/6)","Tidak ("&(LEFT(M6,2)=LEFT(G6,2))+(LEFT(N6,2)=LEFT(H6,2))+(LEFT(O6,3)=LEFT(I6,3))+(LEFT(P6,2)=LEFT(J6,2))+(LEFT(Q6,2)=LEFT(K6,2))+(LEFT(R6,2)=LEFT(L6,2))&"/6): "&TRIM(IF(NOT(LEFT(M6,2)=LEFT(G6,2)),"V4 ","")&IF(NOT(LEFT(N6,2)=LEFT(H6,2)),"V5 ","")&IF(NOT(LEFT(O6,3)=LEFT(I6,3)),"V6 ","")&IF(NOT(LEFT(P6,2)=LEFT(J6,2)),"V7 ","")&IF(NOT(LEFT(Q6,2)=LEFT(K6,2)),"V8 ","")&IF(NOT(LEFT(R6,2)=LEFT(L6,2)),"V9 ",""))))) | BH6: =IF(COUNTA($G6:$L6)<6,"",IF(COUNTA(S6:X6)<6,"Belum lengkap",IF((LEFT(S6,2)=LEFT(G6,2))+(LEFT(T6,2)=LEFT(H6,2))+(LEFT(U6,3)=LEFT(I6,3))+(LEFT(V6,2)=LEFT(J6,2))+(LEFT(W6,2)=LEFT(K6,2))+(LEFT(X6,2)=LEFT(L6,2))=6,"Ya (6/6)","Tidak ("&(LEFT(S6,2)=LEFT(G6,2))+(LEFT(T6,2)=LEFT(H6,2))+(LEFT(U6,3)=LEFT(I6,3))+(LEFT(V6,2)=LEFT(J6,2))+(LEFT(W6,2)=LEFT(K6,2))+(LEFT(X6,2)=LEFT(L6,2))&"/6): "&TRIM(IF(NOT(LEFT(S6,2)=LEFT(G6,2)),"V4 ","")&IF(NOT(LEFT(T6,2)=LEFT(H6,2)),"V5 ","")&IF(NOT(LEFT(U6,3)=LEFT(I6,3)),"V6 ","")&IF(NOT(LEFT(V6,2)=LEFT(J6,2)),"V7 ","")&IF(NOT(LEFT(W6,2)=LEFT(K6,2)),"V8 ","")&IF(NOT(LEFT(X6,2)=LEFT(L6,2)),"V9 ",""))))) | BI6: =IF(COUNTA($G6:$L6)<6,"",IF($E$1<3,"",IF(COUNTA(Y6:AD6)<6,"Belum lengkap",IF((LEFT(Y6,2)=LEFT(G6,2))+(LEFT(Z6,2)=LEFT(H6,2))+(LEFT(AA6,3)=LEFT(I6,3))+(LEFT(AB6,2)=LEFT(J6,2))+(LEFT(AC6,2)=LEFT(K6,2))+(LEFT(AD6,2)=LEFT(L6,2))=6,"Ya (6/6)","Tidak ("&(LEFT(Y6,2)=LEFT(G6,2))+(LEFT(Z6,2)=LEFT(H6,2))+(LEFT(AA6,3)=LEFT(I6,3))+(LEFT(AB6,2)=LEFT(J6,2))+(LEFT(AC6,2)=LEFT(K6,2))+(LEFT(AD6,2)=LEFT(L6,2))&"/6): "&TRIM(IF(NOT(LEFT(Y6,2)=LEFT(G6,2)),"V4 ","")&IF(NOT(LEFT(Z6,2)=LEFT(H6,2)),"V5 ","")&IF(NOT(LEFT(AA6,3)=LEFT(I6,3)),"V6 ","")&IF(NOT(LEFT(AB6,2)=LEFT(J6,2)),"V7 ","")&IF(NOT(LEFT(AC6,2)=LEFT(K6,2)),"V8 ","")&IF(NOT(LEFT(AD6,2)=LEFT(L6,2)),"V9 ","")))))) | BJ6: =IF(COUNTA($G6:$L6)<6,"",IF($E$1<4,"",IF(COUNTA(AE6:AJ6)<6,"Belum lengkap",IF((LEFT(AE6,2)=LEFT(G6,2))+(LEFT(AF6,2)=LEFT(H6,2))+(LEFT(AG6,3)=LEFT(I6,3))+(LEFT(AH6,2)=LEFT(J6,2))+(LEFT(AI6,2)=LEFT(K6,2))+(LEFT(AJ6,2)=LEFT(L6,2))=6,"Ya (6/6)","Tidak ("&(LEFT(AE6,2)=LEFT(G6,2))+(LEFT(AF6,2)=LEFT(H6,2))+(LEFT(AG6,3)=LEFT(I6,3))+(LEFT(AH6,2)=LEFT(J6,2))+(LEFT(AI6,2)=LEFT(K6,2))+(LEFT(AJ6,2)=LEFT(L6,2))&"/6): "&TRIM(IF(NOT(LEFT(AE6,2)=LEFT(G6,2)),"V4 ","")&IF(NOT(LEFT(AF6,2)=LEFT(H6,2)),"V5 ","")&IF(NOT(LEFT(AG6,3)=LEFT(I6,3)),"V6 ","")&IF(NOT(LEFT(AH6,2)=LEFT(J6,2)),"V7 ","")&IF(NOT(LEFT(AI6,2)=LEFT(K6,2)),"V8 ","")&IF(NOT(LEFT(AJ6,2)=LEFT(L6,2)),"V9 ",""))))))
A7: 4 | B7: =IF(INDEX(Korpus!$A:$A,$A7)="","",INDEX(Korpus!$A:$A,$A7)) -> 2019MHN201 | C7: =TRIM(INDEX(Korpus!$D:$D,$A7)&" "&INDEX(Korpus!$E:$E,$A7)) -> Paragraf 3 Kalimat 3 | D7: =IF(INDEX(Korpus!$B:$B,$A7)="","",INDEX(Korpus!$B:$B,$A7)) -> C. Pembahasan | E7: =IF(INDEX(Korpus!$C:$C,$A7)="","",INDEX(Korpus!$C:$C,$A7)) -> 5. Pentingnya Perlindungan Data Pribadi | F7: =IF(INDEX(Korpus!$F:$F,$A7)="","",INDEX(Korpus!$F:$F,$A7)) -> Sejumlah kasus yang mencuat, terutama yang memiliki keterkaitan dengan kebocoran data pribadi seseorang dan bermuara kepada aksi penipuan atau tindak kriminal pornografi, menguatkan wacana pentingnya pembuatan aturan hukum untuk melindungi data pribadi. | AK7: =IF(Hitung!B7<$E$1,"",IF(Hitung!C7>0,"Beda","Sama")) | AL7: =IF(Hitung!D7<$E$1,"",IF(Hitung!E7>0,"Beda","Sama")) | AM7: =IF(Hitung!F7<$E$1,"",IF(Hitung!G7>0,"Beda","Sama")) | AN7: =IF(Hitung!H7<$E$1,"",IF(Hitung!I7>0,"Beda","Sama")) | AO7: =IF(Hitung!J7<$E$1,"",IF(Hitung!K7>0,"Beda","Sama")) | AP7: =IF(Hitung!L7<$E$1,"",IF(Hitung!M7>0,"Beda","Sama")) | AQ7: =COUNTIF(AK7:AP7,"Beda") -> 0 | AX7: =IF(AR7<>"",AR7,IF(AND(Hitung!B7=$E$1,Hitung!C7=0),M7,"")) | AY7: =IF(AS7<>"",AS7,IF(AND(Hitung!D7=$E$1,Hitung!E7=0),N7,"")) | AZ7: =IF(AT7<>"",AT7,IF(AND(Hitung!F7=$E$1,Hitung!G7=0),O7,"")) | BA7: =IF(AU7<>"",AU7,IF(AND(Hitung!H7=$E$1,Hitung!I7=0),P7,"")) | BB7: =IF(AV7<>"",AV7,IF(AND(Hitung!J7=$E$1,Hitung!K7=0),Q7,"")) | BC7: =IF(AW7<>"",AW7,IF(AND(Hitung!L7=$E$1,Hitung!M7=0),R7,"")) | BE7: =IF(COUNTA(M7:R7)+COUNTA(S7:X7)+($E$1>=3)*COUNTA(Y7:AD7)+($E$1>=4)*COUNTA(AE7:AJ7)<6*$E$1,"Menunggu coder",IF(AQ7=0,"Sepakat",IF(SUMPRODUCT((AK7:AP7="Beda")*(AR7:AW7=""))=0,"Selesai adjudikasi","Perlu adjudikasi"))) -> Menunggu coder | BF7: =IF(COUNTIF(AX7:BC7,"?*")<6,"",IF(IF(AND(LEFT(AY7,2)="R0",LEFT(BC7,2)<>"K5"),"R0 harus K5; ","")&IF(AND(LEFT(AY7,2)="R1",LEFT(BC7,2)="K3"),"R1 tidak boleh K3 (fungsional); ","")&IF(AND(LEFT(AY7,2)="R2",LEFT(BC7,2)="K5"),"R2 tidak boleh K5; ","")&IF(AND(LEFT(AY7,2)="R2",OR(LEFT(AX7,2)="S6",LEFT(AX7,2)="S7",LEFT(AX7,2)="S8")),"R2 tidak boleh S6/S7/S8; ","")&IF(AND(LEFT(AY7,2)="R2",OR(LEFT(AZ7,3)="T02",LEFT(BA7,2)="P8")),"T02 atau P8 tidak boleh R2; ","")&IF(AND(LEFT(AZ7,3)="T01",LEFT(BA7,2)<>"P6"),"T01 biasanya P6 (periksa); ","")&IF(AND(LEFT(BA7,2)="P1",LEFT(BC7,2)<>"K4"),"P1 biasanya K4 (periksa); ","")="","OK",IF(AND(LEFT(AY7,2)="R0",LEFT(BC7,2)<>"K5"),"R0 harus K5; ","")&IF(AND(LEFT(AY7,2)="R1",LEFT(BC7,2)="K3"),"R1 tidak boleh K3 (fungsional); ","")&IF(AND(LEFT(AY7,2)="R2",LEFT(BC7,2)="K5"),"R2 tidak boleh K5; ","")&IF(AND(LEFT(AY7,2)="R2",OR(LEFT(AX7,2)="S6",LEFT(AX7,2)="S7",LEFT(AX7,2)="S8")),"R2 tidak boleh S6/S7/S8; ","")&IF(AND(LEFT(AY7,2)="R2",OR(LEFT(AZ7,3)="T02",LEFT(BA7,2)="P8")),"T02 atau P8 tidak boleh R2; ","")&IF(AND(LEFT(AZ7,3)="T01",LEFT(BA7,2)<>"P6"),"T01 biasanya P6 (periksa); ","")&IF(AND(LEFT(BA7,2)="P1",LEFT(BC7,2)<>"K4"),"P1 biasanya K4 (periksa); ",""))) | BG7: =IF(COUNTA($G7:$L7)<6,"",IF(COUNTA(M7:R7)<6,"Belum lengkap",IF((LEFT(M7,2)=LEFT(G7,2))+(LEFT(N7,2)=LEFT(H7,2))+(LEFT(O7,3)=LEFT(I7,3))+(LEFT(P7,2)=LEFT(J7,2))+(LEFT(Q7,2)=LEFT(K7,2))+(LEFT(R7,2)=LEFT(L7,2))=6,"Ya (6/6)","Tidak ("&(LEFT(M7,2)=LEFT(G7,2))+(LEFT(N7,2)=LEFT(H7,2))+(LEFT(O7,3)=LEFT(I7,3))+(LEFT(P7,2)=LEFT(J7,2))+(LEFT(Q7,2)=LEFT(K7,2))+(LEFT(R7,2)=LEFT(L7,2))&"/6): "&TRIM(IF(NOT(LEFT(M7,2)=LEFT(G7,2)),"V4 ","")&IF(NOT(LEFT(N7,2)=LEFT(H7,2)),"V5 ","")&IF(NOT(LEFT(O7,3)=LEFT(I7,3)),"V6 ","")&IF(NOT(LEFT(P7,2)=LEFT(J7,2)),"V7 ","")&IF(NOT(LEFT(Q7,2)=LEFT(K7,2)),"V8 ","")&IF(NOT(LEFT(R7,2)=LEFT(L7,2)),"V9 ",""))))) | BH7: =IF(COUNTA($G7:$L7)<6,"",IF(COUNTA(S7:X7)<6,"Belum lengkap",IF((LEFT(S7,2)=LEFT(G7,2))+(LEFT(T7,2)=LEFT(H7,2))+(LEFT(U7,3)=LEFT(I7,3))+(LEFT(V7,2)=LEFT(J7,2))+(LEFT(W7,2)=LEFT(K7,2))+(LEFT(X7,2)=LEFT(L7,2))=6,"Ya (6/6)","Tidak ("&(LEFT(S7,2)=LEFT(G7,2))+(LEFT(T7,2)=LEFT(H7,2))+(LEFT(U7,3)=LEFT(I7,3))+(LEFT(V7,2)=LEFT(J7,2))+(LEFT(W7,2)=LEFT(K7,2))+(LEFT(X7,2)=LEFT(L7,2))&"/6): "&TRIM(IF(NOT(LEFT(S7,2)=LEFT(G7,2)),"V4 ","")&IF(NOT(LEFT(T7,2)=LEFT(H7,2)),"V5 ","")&IF(NOT(LEFT(U7,3)=LEFT(I7,3)),"V6 ","")&IF(NOT(LEFT(V7,2)=LEFT(J7,2)),"V7 ","")&IF(NOT(LEFT(W7,2)=LEFT(K7,2)),"V8 ","")&IF(NOT(LEFT(X7,2)=LEFT(L7,2)),"V9 ",""))))) | BI7: =IF(COUNTA($G7:$L7)<6,"",IF($E$1<3,"",IF(COUNTA(Y7:AD7)<6,"Belum lengkap",IF((LEFT(Y7,2)=LEFT(G7,2))+(LEFT(Z7,2)=LEFT(H7,2))+(LEFT(AA7,3)=LEFT(I7,3))+(LEFT(AB7,2)=LEFT(J7,2))+(LEFT(AC7,2)=LEFT(K7,2))+(LEFT(AD7,2)=LEFT(L7,2))=6,"Ya (6/6)","Tidak ("&(LEFT(Y7,2)=LEFT(G7,2))+(LEFT(Z7,2)=LEFT(H7,2))+(LEFT(AA7,3)=LEFT(I7,3))+(LEFT(AB7,2)=LEFT(J7,2))+(LEFT(AC7,2)=LEFT(K7,2))+(LEFT(AD7,2)=LEFT(L7,2))&"/6): "&TRIM(IF(NOT(LEFT(Y7,2)=LEFT(G7,2)),"V4 ","")&IF(NOT(LEFT(Z7,2)=LEFT(H7,2)),"V5 ","")&IF(NOT(LEFT(AA7,3)=LEFT(I7,3)),"V6 ","")&IF(NOT(LEFT(AB7,2)=LEFT(J7,2)),"V7 ","")&IF(NOT(LEFT(AC7,2)=LEFT(K7,2)),"V8 ","")&IF(NOT(LEFT(AD7,2)=LEFT(L7,2)),"V9 ","")))))) | BJ7: =IF(COUNTA($G7:$L7)<6,"",IF($E$1<4,"",IF(COUNTA(AE7:AJ7)<6,"Belum lengkap",IF((LEFT(AE7,2)=LEFT(G7,2))+(LEFT(AF7,2)=LEFT(H7,2))+(LEFT(AG7,3)=LEFT(I7,3))+(LEFT(AH7,2)=LEFT(J7,2))+(LEFT(AI7,2)=LEFT(K7,2))+(LEFT(AJ7,2)=LEFT(L7,2))=6,"Ya (6/6)","Tidak ("&(LEFT(AE7,2)=LEFT(G7,2))+(LEFT(AF7,2)=LEFT(H7,2))+(LEFT(AG7,3)=LEFT(I7,3))+(LEFT(AH7,2)=LEFT(J7,2))+(LEFT(AI7,2)=LEFT(K7,2))+(LEFT(AJ7,2)=LEFT(L7,2))&"/6): "&TRIM(IF(NOT(LEFT(AE7,2)=LEFT(G7,2)),"V4 ","")&IF(NOT(LEFT(AF7,2)=LEFT(H7,2)),"V5 ","")&IF(NOT(LEFT(AG7,3)=LEFT(I7,3)),"V6 ","")&IF(NOT(LEFT(AH7,2)=LEFT(J7,2)),"V7 ","")&IF(NOT(LEFT(AI7,2)=LEFT(K7,2)),"V8 ","")&IF(NOT(LEFT(AJ7,2)=LEFT(L7,2)),"V9 ",""))))))
A8: 5 | B8: =IF(INDEX(Korpus!$A:$A,$A8)="","",INDEX(Korpus!$A:$A,$A8)) -> 2019MHN201 | C8: =TRIM(INDEX(Korpus!$D:$D,$A8)&" "&INDEX(Korpus!$E:$E,$A8)) -> Paragraf 3 Kalimat 4 | D8: =IF(INDEX(Korpus!$B:$B,$A8)="","",INDEX(Korpus!$B:$B,$A8)) -> C. Pembahasan | E8: =IF(INDEX(Korpus!$C:$C,$A8)="","",INDEX(Korpus!$C:$C,$A8)) -> 5. Pentingnya Perlindungan Data Pribadi | F8: =IF(INDEX(Korpus!$F:$F,$A8)="","",INDEX(Korpus!$F:$F,$A8)) -> Perlindungan data pribadi berhubungan dengan konsep privasi. | AK8: =IF(Hitung!B8<$E$1,"",IF(Hitung!C8>0,"Beda","Sama")) | AL8: =IF(Hitung!D8<$E$1,"",IF(Hitung!E8>0,"Beda","Sama")) | AM8: =IF(Hitung!F8<$E$1,"",IF(Hitung!G8>0,"Beda","Sama")) | AN8: =IF(Hitung!H8<$E$1,"",IF(Hitung!I8>0,"Beda","Sama")) | AO8: =IF(Hitung!J8<$E$1,"",IF(Hitung!K8>0,"Beda","Sama")) | AP8: =IF(Hitung!L8<$E$1,"",IF(Hitung!M8>0,"Beda","Sama")) | AQ8: =COUNTIF(AK8:AP8,"Beda") -> 0 | AX8: =IF(AR8<>"",AR8,IF(AND(Hitung!B8=$E$1,Hitung!C8=0),M8,"")) | AY8: =IF(AS8<>"",AS8,IF(AND(Hitung!D8=$E$1,Hitung!E8=0),N8,"")) | AZ8: =IF(AT8<>"",AT8,IF(AND(Hitung!F8=$E$1,Hitung!G8=0),O8,"")) | BA8: =IF(AU8<>"",AU8,IF(AND(Hitung!H8=$E$1,Hitung!I8=0),P8,"")) | BB8: =IF(AV8<>"",AV8,IF(AND(Hitung!J8=$E$1,Hitung!K8=0),Q8,"")) | BC8: =IF(AW8<>"",AW8,IF(AND(Hitung!L8=$E$1,Hitung!M8=0),R8,"")) | BE8: =IF(COUNTA(M8:R8)+COUNTA(S8:X8)+($E$1>=3)*COUNTA(Y8:AD8)+($E$1>=4)*COUNTA(AE8:AJ8)<6*$E$1,"Menunggu coder",IF(AQ8=0,"Sepakat",IF(SUMPRODUCT((AK8:AP8="Beda")*(AR8:AW8=""))=0,"Selesai adjudikasi","Perlu adjudikasi"))) -> Menunggu coder | BF8: =IF(COUNTIF(AX8:BC8,"?*")<6,"",IF(IF(AND(LEFT(AY8,2)="R0",LEFT(BC8,2)<>"K5"),"R0 harus K5; ","")&IF(AND(LEFT(AY8,2)="R1",LEFT(BC8,2)="K3"),"R1 tidak boleh K3 (fungsional); ","")&IF(AND(LEFT(AY8,2)="R2",LEFT(BC8,2)="K5"),"R2 tidak boleh K5; ","")&IF(AND(LEFT(AY8,2)="R2",OR(LEFT(AX8,2)="S6",LEFT(AX8,2)="S7",LEFT(AX8,2)="S8")),"R2 tidak boleh S6/S7/S8; ","")&IF(AND(LEFT(AY8,2)="R2",OR(LEFT(AZ8,3)="T02",LEFT(BA8,2)="P8")),"T02 atau P8 tidak boleh R2; ","")&IF(AND(LEFT(AZ8,3)="T01",LEFT(BA8,2)<>"P6"),"T01 biasanya P6 (periksa); ","")&IF(AND(LEFT(BA8,2)="P1",LEFT(BC8,2)<>"K4"),"P1 biasanya K4 (periksa); ","")="","OK",IF(AND(LEFT(AY8,2)="R0",LEFT(BC8,2)<>"K5"),"R0 harus K5; ","")&IF(AND(LEFT(AY8,2)="R1",LEFT(BC8,2)="K3"),"R1 tidak boleh K3 (fungsional); ","")&IF(AND(LEFT(AY8,2)="R2",LEFT(BC8,2)="K5"),"R2 tidak boleh K5; ","")&IF(AND(LEFT(AY8,2)="R2",OR(LEFT(AX8,2)="S6",LEFT(AX8,2)="S7",LEFT(AX8,2)="S8")),"R2 tidak boleh S6/S7/S8; ","")&IF(AND(LEFT(AY8,2)="R2",OR(LEFT(AZ8,3)="T02",LEFT(BA8,2)="P8")),"T02 atau P8 tidak boleh R2; ","")&IF(AND(LEFT(AZ8,3)="T01",LEFT(BA8,2)<>"P6"),"T01 biasanya P6 (periksa); ","")&IF(AND(LEFT(BA8,2)="P1",LEFT(BC8,2)<>"K4"),"P1 biasanya K4 (periksa); ",""))) | BG8: =IF(COUNTA($G8:$L8)<6,"",IF(COUNTA(M8:R8)<6,"Belum lengkap",IF((LEFT(M8,2)=LEFT(G8,2))+(LEFT(N8,2)=LEFT(H8,2))+(LEFT(O8,3)=LEFT(I8,3))+(LEFT(P8,2)=LEFT(J8,2))+(LEFT(Q8,2)=LEFT(K8,2))+(LEFT(R8,2)=LEFT(L8,2))=6,"Ya (6/6)","Tidak ("&(LEFT(M8,2)=LEFT(G8,2))+(LEFT(N8,2)=LEFT(H8,2))+(LEFT(O8,3)=LEFT(I8,3))+(LEFT(P8,2)=LEFT(J8,2))+(LEFT(Q8,2)=LEFT(K8,2))+(LEFT(R8,2)=LEFT(L8,2))&"/6): "&TRIM(IF(NOT(LEFT(M8,2)=LEFT(G8,2)),"V4 ","")&IF(NOT(LEFT(N8,2)=LEFT(H8,2)),"V5 ","")&IF(NOT(LEFT(O8,3)=LEFT(I8,3)),"V6 ","")&IF(NOT(LEFT(P8,2)=LEFT(J8,2)),"V7 ","")&IF(NOT(LEFT(Q8,2)=LEFT(K8,2)),"V8 ","")&IF(NOT(LEFT(R8,2)=LEFT(L8,2)),"V9 ",""))))) | BH8: =IF(COUNTA($G8:$L8)<6,"",IF(COUNTA(S8:X8)<6,"Belum lengkap",IF((LEFT(S8,2)=LEFT(G8,2))+(LEFT(T8,2)=LEFT(H8,2))+(LEFT(U8,3)=LEFT(I8,3))+(LEFT(V8,2)=LEFT(J8,2))+(LEFT(W8,2)=LEFT(K8,2))+(LEFT(X8,2)=LEFT(L8,2))=6,"Ya (6/6)","Tidak ("&(LEFT(S8,2)=LEFT(G8,2))+(LEFT(T8,2)=LEFT(H8,2))+(LEFT(U8,3)=LEFT(I8,3))+(LEFT(V8,2)=LEFT(J8,2))+(LEFT(W8,2)=LEFT(K8,2))+(LEFT(X8,2)=LEFT(L8,2))&"/6): "&TRIM(IF(NOT(LEFT(S8,2)=LEFT(G8,2)),"V4 ","")&IF(NOT(LEFT(T8,2)=LEFT(H8,2)),"V5 ","")&IF(NOT(LEFT(U8,3)=LEFT(I8,3)),"V6 ","")&IF(NOT(LEFT(V8,2)=LEFT(J8,2)),"V7 ","")&IF(NOT(LEFT(W8,2)=LEFT(K8,2)),"V8 ","")&IF(NOT(LEFT(X8,2)=LEFT(L8,2)),"V9 ",""))))) | BI8: =IF(COUNTA($G8:$L8)<6,"",IF($E$1<3,"",IF(COUNTA(Y8:AD8)<6,"Belum lengkap",IF((LEFT(Y8,2)=LEFT(G8,2))+(LEFT(Z8,2)=LEFT(H8,2))+(LEFT(AA8,3)=LEFT(I8,3))+(LEFT(AB8,2)=LEFT(J8,2))+(LEFT(AC8,2)=LEFT(K8,2))+(LEFT(AD8,2)=LEFT(L8,2))=6,"Ya (6/6)","Tidak ("&(LEFT(Y8,2)=LEFT(G8,2))+(LEFT(Z8,2)=LEFT(H8,2))+(LEFT(AA8,3)=LEFT(I8,3))+(LEFT(AB8,2)=LEFT(J8,2))+(LEFT(AC8,2)=LEFT(K8,2))+(LEFT(AD8,2)=LEFT(L8,2))&"/6): "&TRIM(IF(NOT(LEFT(Y8,2)=LEFT(G8,2)),"V4 ","")&IF(NOT(LEFT(Z8,2)=LEFT(H8,2)),"V5 ","")&IF(NOT(LEFT(AA8,3)=LEFT(I8,3)),"V6 ","")&IF(NOT(LEFT(AB8,2)=LEFT(J8,2)),"V7 ","")&IF(NOT(LEFT(AC8,2)=LEFT(K8,2)),"V8 ","")&IF(NOT(LEFT(AD8,2)=LEFT(L8,2)),"V9 ","")))))) | BJ8: =IF(COUNTA($G8:$L8)<6,"",IF($E$1<4,"",IF(COUNTA(AE8:AJ8)<6,"Belum lengkap",IF((LEFT(AE8,2)=LEFT(G8,2))+(LEFT(AF8,2)=LEFT(H8,2))+(LEFT(AG8,3)=LEFT(I8,3))+(LEFT(AH8,2)=LEFT(J8,2))+(LEFT(AI8,2)=LEFT(K8,2))+(LEFT(AJ8,2)=LEFT(L8,2))=6,"Ya (6/6)","Tidak ("&(LEFT(AE8,2)=LEFT(G8,2))+(LEFT(AF8,2)=LEFT(H8,2))+(LEFT(AG8,3)=LEFT(I8,3))+(LEFT(AH8,2)=LEFT(J8,2))+(LEFT(AI8,2)=LEFT(K8,2))+(LEFT(AJ8,2)=LEFT(L8,2))&"/6): "&TRIM(IF(NOT(LEFT(AE8,2)=LEFT(G8,2)),"V4 ","")&IF(NOT(LEFT(AF8,2)=LEFT(H8,2)),"V5 ","")&IF(NOT(LEFT(AG8,3)=LEFT(I8,3)),"V6 ","")&IF(NOT(LEFT(AH8,2)=LEFT(J8,2)),"V7 ","")&IF(NOT(LEFT(AI8,2)=LEFT(K8,2)),"V8 ","")&IF(NOT(LEFT(AJ8,2)=LEFT(L8,2)),"V9 ",""))))))
A9: 6 | B9: =IF(INDEX(Korpus!$A:$A,$A9)="","",INDEX(Korpus!$A:$A,$A9)) -> 2019MHN201 | C9: =TRIM(INDEX(Korpus!$D:$D,$A9)&" "&INDEX(Korpus!$E:$E,$A9)) -> Paragraf 3 Kalimat 5 | D9: =IF(INDEX(Korpus!$B:$B,$A9)="","",INDEX(Korpus!$B:$B,$A9)) -> C. Pembahasan | E9: =IF(INDEX(Korpus!$C:$C,$A9)="","",INDEX(Korpus!$C:$C,$A9)) -> 5. Pentingnya Perlindungan Data Pribadi | F9: =IF(INDEX(Korpus!$F:$F,$A9)="","",INDEX(Korpus!$F:$F,$A9)) -> Konsep privasi sendiri adalah gagasan untuk menjaga integritas dan martabat pribadi. | AK9: =IF(Hitung!B9<$E$1,"",IF(Hitung!C9>0,"Beda","Sama")) | AL9: =IF(Hitung!D9<$E$1,"",IF(Hitung!E9>0,"Beda","Sama")) | AM9: =IF(Hitung!F9<$E$1,"",IF(Hitung!G9>0,"Beda","Sama")) | AN9: =IF(Hitung!H9<$E$1,"",IF(Hitung!I9>0,"Beda","Sama")) | AO9: =IF(Hitung!J9<$E$1,"",IF(Hitung!K9>0,"Beda","Sama")) | AP9: =IF(Hitung!L9<$E$1,"",IF(Hitung!M9>0,"Beda","Sama")) | AQ9: =COUNTIF(AK9:AP9,"Beda") -> 0 | AX9: =IF(AR9<>"",AR9,IF(AND(Hitung!B9=$E$1,Hitung!C9=0),M9,"")) | AY9: =IF(AS9<>"",AS9,IF(AND(Hitung!D9=$E$1,Hitung!E9=0),N9,"")) | AZ9: =IF(AT9<>"",AT9,IF(AND(Hitung!F9=$E$1,Hitung!G9=0),O9,"")) | BA9: =IF(AU9<>"",AU9,IF(AND(Hitung!H9=$E$1,Hitung!I9=0),P9,"")) | BB9: =IF(AV9<>"",AV9,IF(AND(Hitung!J9=$E$1,Hitung!K9=0),Q9,"")) | BC9: =IF(AW9<>"",AW9,IF(AND(Hitung!L9=$E$1,Hitung!M9=0),R9,"")) | BE9: =IF(COUNTA(M9:R9)+COUNTA(S9:X9)+($E$1>=3)*COUNTA(Y9:AD9)+($E$1>=4)*COUNTA(AE9:AJ9)<6*$E$1,"Menunggu coder",IF(AQ9=0,"Sepakat",IF(SUMPRODUCT((AK9:AP9="Beda")*(AR9:AW9=""))=0,"Selesai adjudikasi","Perlu adjudikasi"))) -> Menunggu coder | BF9: =IF(COUNTIF(AX9:BC9,"?*")<6,"",IF(IF(AND(LEFT(AY9,2)="R0",LEFT(BC9,2)<>"K5"),"R0 harus K5; ","")&IF(AND(LEFT(AY9,2)="R1",LEFT(BC9,2)="K3"),"R1 tidak boleh K3 (fungsional); ","")&IF(AND(LEFT(AY9,2)="R2",LEFT(BC9,2)="K5"),"R2 tidak boleh K5; ","")&IF(AND(LEFT(AY9,2)="R2",OR(LEFT(AX9,2)="S6",LEFT(AX9,2)="S7",LEFT(AX9,2)="S8")),"R2 tidak boleh S6/S7/S8; ","")&IF(AND(LEFT(AY9,2)="R2",OR(LEFT(AZ9,3)="T02",LEFT(BA9,2)="P8")),"T02 atau P8 tidak boleh R2; ","")&IF(AND(LEFT(AZ9,3)="T01",LEFT(BA9,2)<>"P6"),"T01 biasanya P6 (periksa); ","")&IF(AND(LEFT(BA9,2)="P1",LEFT(BC9,2)<>"K4"),"P1 biasanya K4 (periksa); ","")="","OK",IF(AND(LEFT(AY9,2)="R0",LEFT(BC9,2)<>"K5"),"R0 harus K5; ","")&IF(AND(LEFT(AY9,2)="R1",LEFT(BC9,2)="K3"),"R1 tidak boleh K3 (fungsional); ","")&IF(AND(LEFT(AY9,2)="R2",LEFT(BC9,2)="K5"),"R2 tidak boleh K5; ","")&IF(AND(LEFT(AY9,2)="R2",OR(LEFT(AX9,2)="S6",LEFT(AX9,2)="S7",LEFT(AX9,2)="S8")),"R2 tidak boleh S6/S7/S8; ","")&IF(AND(LEFT(AY9,2)="R2",OR(LEFT(AZ9,3)="T02",LEFT(BA9,2)="P8")),"T02 atau P8 tidak boleh R2; ","")&IF(AND(LEFT(AZ9,3)="T01",LEFT(BA9,2)<>"P6"),"T01 biasanya P6 (periksa); ","")&IF(AND(LEFT(BA9,2)="P1",LEFT(BC9,2)<>"K4"),"P1 biasanya K4 (periksa); ",""))) | BG9: =IF(COUNTA($G9:$L9)<6,"",IF(COUNTA(M9:R9)<6,"Belum lengkap",IF((LEFT(M9,2)=LEFT(G9,2))+(LEFT(N9,2)=LEFT(H9,2))+(LEFT(O9,3)=LEFT(I9,3))+(LEFT(P9,2)=LEFT(J9,2))+(LEFT(Q9,2)=LEFT(K9,2))+(LEFT(R9,2)=LEFT(L9,2))=6,"Ya (6/6)","Tidak ("&(LEFT(M9,2)=LEFT(G9,2))+(LEFT(N9,2)=LEFT(H9,2))+(LEFT(O9,3)=LEFT(I9,3))+(LEFT(P9,2)=LEFT(J9,2))+(LEFT(Q9,2)=LEFT(K9,2))+(LEFT(R9,2)=LEFT(L9,2))&"/6): "&TRIM(IF(NOT(LEFT(M9,2)=LEFT(G9,2)),"V4 ","")&IF(NOT(LEFT(N9,2)=LEFT(H9,2)),"V5 ","")&IF(NOT(LEFT(O9,3)=LEFT(I9,3)),"V6 ","")&IF(NOT(LEFT(P9,2)=LEFT(J9,2)),"V7 ","")&IF(NOT(LEFT(Q9,2)=LEFT(K9,2)),"V8 ","")&IF(NOT(LEFT(R9,2)=LEFT(L9,2)),"V9 ",""))))) | BH9: =IF(COUNTA($G9:$L9)<6,"",IF(COUNTA(S9:X9)<6,"Belum lengkap",IF((LEFT(S9,2)=LEFT(G9,2))+(LEFT(T9,2)=LEFT(H9,2))+(LEFT(U9,3)=LEFT(I9,3))+(LEFT(V9,2)=LEFT(J9,2))+(LEFT(W9,2)=LEFT(K9,2))+(LEFT(X9,2)=LEFT(L9,2))=6,"Ya (6/6)","Tidak ("&(LEFT(S9,2)=LEFT(G9,2))+(LEFT(T9,2)=LEFT(H9,2))+(LEFT(U9,3)=LEFT(I9,3))+(LEFT(V9,2)=LEFT(J9,2))+(LEFT(W9,2)=LEFT(K9,2))+(LEFT(X9,2)=LEFT(L9,2))&"/6): "&TRIM(IF(NOT(LEFT(S9,2)=LEFT(G9,2)),"V4 ","")&IF(NOT(LEFT(T9,2)=LEFT(H9,2)),"V5 ","")&IF(NOT(LEFT(U9,3)=LEFT(I9,3)),"V6 ","")&IF(NOT(LEFT(V9,2)=LEFT(J9,2)),"V7 ","")&IF(NOT(LEFT(W9,2)=LEFT(K9,2)),"V8 ","")&IF(NOT(LEFT(X9,2)=LEFT(L9,2)),"V9 ",""))))) | BI9: =IF(COUNTA($G9:$L9)<6,"",IF($E$1<3,"",IF(COUNTA(Y9:AD9)<6,"Belum lengkap",IF((LEFT(Y9,2)=LEFT(G9,2))+(LEFT(Z9,2)=LEFT(H9,2))+(LEFT(AA9,3)=LEFT(I9,3))+(LEFT(AB9,2)=LEFT(J9,2))+(LEFT(AC9,2)=LEFT(K9,2))+(LEFT(AD9,2)=LEFT(L9,2))=6,"Ya (6/6)","Tidak ("&(LEFT(Y9,2)=LEFT(G9,2))+(LEFT(Z9,2)=LEFT(H9,2))+(LEFT(AA9,3)=LEFT(I9,3))+(LEFT(AB9,2)=LEFT(J9,2))+(LEFT(AC9,2)=LEFT(K9,2))+(LEFT(AD9,2)=LEFT(L9,2))&"/6): "&TRIM(IF(NOT(LEFT(Y9,2)=LEFT(G9,2)),"V4 ","")&IF(NOT(LEFT(Z9,2)=LEFT(H9,2)),"V5 ","")&IF(NOT(LEFT(AA9,3)=LEFT(I9,3)),"V6 ","")&IF(NOT(LEFT(AB9,2)=LEFT(J9,2)),"V7 ","")&IF(NOT(LEFT(AC9,2)=LEFT(K9,2)),"V8 ","")&IF(NOT(LEFT(AD9,2)=LEFT(L9,2)),"V9 ","")))))) | BJ9: =IF(COUNTA($G9:$L9)<6,"",IF($E$1<4,"",IF(COUNTA(AE9:AJ9)<6,"Belum lengkap",IF((LEFT(AE9,2)=LEFT(G9,2))+(LEFT(AF9,2)=LEFT(H9,2))+(LEFT(AG9,3)=LEFT(I9,3))+(LEFT(AH9,2)=LEFT(J9,2))+(LEFT(AI9,2)=LEFT(K9,2))+(LEFT(AJ9,2)=LEFT(L9,2))=6,"Ya (6/6)","Tidak ("&(LEFT(AE9,2)=LEFT(G9,2))+(LEFT(AF9,2)=LEFT(H9,2))+(LEFT(AG9,3)=LEFT(I9,3))+(LEFT(AH9,2)=LEFT(J9,2))+(LEFT(AI9,2)=LEFT(K9,2))+(LEFT(AJ9,2)=LEFT(L9,2))&"/6): "&TRIM(IF(NOT(LEFT(AE9,2)=LEFT(G9,2)),"V4 ","")&IF(NOT(LEFT(AF9,2)=LEFT(H9,2)),"V5 ","")&IF(NOT(LEFT(AG9,3)=LEFT(I9,3)),"V6 ","")&IF(NOT(LEFT(AH9,2)=LEFT(J9,2)),"V7 ","")&IF(NOT(LEFT(AI9,2)=LEFT(K9,2)),"V8 ","")&IF(NOT(LEFT(AJ9,2)=LEFT(L9,2)),"V9 ",""))))))
A10: 7 | B10: =IF(INDEX(Korpus!$A:$A,$A10)="","",INDEX(Korpus!$A:$A,$A10)) -> 2019MHN201 | C10: =TRIM(INDEX(Korpus!$D:$D,$A10)&" "&INDEX(Korpus!$E:$E,$A10)) -> Paragraf 3 Kalimat 6 | D10: =IF(INDEX(Korpus!$B:$B,$A10)="","",INDEX(Korpus!$B:$B,$A10)) -> C. Pembahasan | E10: =IF(INDEX(Korpus!$C:$C,$A10)="","",INDEX(Korpus!$C:$C,$A10)) -> 5. Pentingnya Perlindungan Data Pribadi | F10: =IF(INDEX(Korpus!$F:$F,$A10)="","",INDEX(Korpus!$F:$F,$A10)) -> Hak privasi juga merupakan kemampuan individu untuk menentukan siapa yang memegang informasi tentang mereka dan bagaimana informasi tersebut digunakan. | AK10: =IF(Hitung!B10<$E$1,"",IF(Hitung!C10>0,"Beda","Sama")) | AL10: =IF(Hitung!D10<$E$1,"",IF(Hitung!E10>0,"Beda","Sama")) | AM10: =IF(Hitung!F10<$E$1,"",IF(Hitung!G10>0,"Beda","Sama")) | AN10: =IF(Hitung!H10<$E$1,"",IF(Hitung!I10>0,"Beda","Sama")) | AO10: =IF(Hitung!J10<$E$1,"",IF(Hitung!K10>0,"Beda","Sama")) | AP10: =IF(Hitung!L10<$E$1,"",IF(Hitung!M10>0,"Beda","Sama")) | AQ10: =COUNTIF(AK10:AP10,"Beda") -> 0 | AX10: =IF(AR10<>"",AR10,IF(AND(Hitung!B10=$E$1,Hitung!C10=0),M10,"")) | AY10: =IF(AS10<>"",AS10,IF(AND(Hitung!D10=$E$1,Hitung!E10=0),N10,"")) | AZ10: =IF(AT10<>"",AT10,IF(AND(Hitung!F10=$E$1,Hitung!G10=0),O10,"")) | BA10: =IF(AU10<>"",AU10,IF(AND(Hitung!H10=$E$1,Hitung!I10=0),P10,"")) | BB10: =IF(AV10<>"",AV10,IF(AND(Hitung!J10=$E$1,Hitung!K10=0),Q10,"")) | BC10: =IF(AW10<>"",AW10,IF(AND(Hitung!L10=$E$1,Hitung!M10=0),R10,"")) | BE10: =IF(COUNTA(M10:R10)+COUNTA(S10:X10)+($E$1>=3)*COUNTA(Y10:AD10)+($E$1>=4)*COUNTA(AE10:AJ10)<6*$E$1,"Menunggu coder",IF(AQ10=0,"Sepakat",IF(SUMPRODUCT((AK10:AP10="Beda")*(AR10:AW10=""))=0,"Selesai adjudikasi","Perlu adjudikasi"))) -> Menunggu coder | BF10: =IF(COUNTIF(AX10:BC10,"?*")<6,"",IF(IF(AND(LEFT(AY10,2)="R0",LEFT(BC10,2)<>"K5"),"R0 harus K5; ","")&IF(AND(LEFT(AY10,2)="R1",LEFT(BC10,2)="K3"),"R1 tidak boleh K3 (fungsional); ","")&IF(AND(LEFT(AY10,2)="R2",LEFT(BC10,2)="K5"),"R2 tidak boleh K5; ","")&IF(AND(LEFT(AY10,2)="R2",OR(LEFT(AX10,2)="S6",LEFT(AX10,2)="S7",LEFT(AX10,2)="S8")),"R2 tidak boleh S6/S7/S8; ","")&IF(AND(LEFT(AY10,2)="R2",OR(LEFT(AZ10,3)="T02",LEFT(BA10,2)="P8")),"T02 atau P8 tidak boleh R2; ","")&IF(AND(LEFT(AZ10,3)="T01",LEFT(BA10,2)<>"P6"),"T01 biasanya P6 (periksa); ","")&IF(AND(LEFT(BA10,2)="P1",LEFT(BC10,2)<>"K4"),"P1 biasanya K4 (periksa); ","")="","OK",IF(AND(LEFT(AY10,2)="R0",LEFT(BC10,2)<>"K5"),"R0 harus K5; ","")&IF(AND(LEFT(AY10,2)="R1",LEFT(BC10,2)="K3"),"R1 tidak boleh K3 (fungsional); ","")&IF(AND(LEFT(AY10,2)="R2",LEFT(BC10,2)="K5"),"R2 tidak boleh K5; ","")&IF(AND(LEFT(AY10,2)="R2",OR(LEFT(AX10,2)="S6",LEFT(AX10,2)="S7",LEFT(AX10,2)="S8")),"R2 tidak boleh S6/S7/S8; ","")&IF(AND(LEFT(AY10,2)="R2",OR(LEFT(AZ10,3)="T02",LEFT(BA10,2)="P8")),"T02 atau P8 tidak boleh R2; ","")&IF(AND(LEFT(AZ10,3)="T01",LEFT(BA10,2)<>"P6"),"T01 biasanya P6 (periksa); ","")&IF(AND(LEFT(BA10,2)="P1",LEFT(BC10,2)<>"K4"),"P1 biasanya K4 (periksa); ",""))) | BG10: =IF(COUNTA($G10:$L10)<6,"",IF(COUNTA(M10:R10)<6,"Belum lengkap",IF((LEFT(M10,2)=LEFT(G10,2))+(LEFT(N10,2)=LEFT(H10,2))+(LEFT(O10,3)=LEFT(I10,3))+(LEFT(P10,2)=LEFT(J10,2))+(LEFT(Q10,2)=LEFT(K10,2))+(LEFT(R10,2)=LEFT(L10,2))=6,"Ya (6/6)","Tidak ("&(LEFT(M10,2)=LEFT(G10,2))+(LEFT(N10,2)=LEFT(H10,2))+(LEFT(O10,3)=LEFT(I10,3))+(LEFT(P10,2)=LEFT(J10,2))+(LEFT(Q10,2)=LEFT(K10,2))+(LEFT(R10,2)=LEFT(L10,2))&"/6): "&TRIM(IF(NOT(LEFT(M10,2)=LEFT(G10,2)),"V4 ","")&IF(NOT(LEFT(N10,2)=LEFT(H10,2)),"V5 ","")&IF(NOT(LEFT(O10,3)=LEFT(I10,3)),"V6 ","")&IF(NOT(LEFT(P10,2)=LEFT(J10,2)),"V7 ","")&IF(NOT(LEFT(Q10,2)=LEFT(K10,2)),"V8 ","")&IF(NOT(LEFT(R10,2)=LEFT(L10,2)),"V9 ",""))))) | BH10: =IF(COUNTA($G10:$L10)<6,"",IF(COUNTA(S10:X10)<6,"Belum lengkap",IF((LEFT(S10,2)=LEFT(G10,2))+(LEFT(T10,2)=LEFT(H10,2))+(LEFT(U10,3)=LEFT(I10,3))+(LEFT(V10,2)=LEFT(J10,2))+(LEFT(W10,2)=LEFT(K10,2))+(LEFT(X10,2)=LEFT(L10,2))=6,"Ya (6/6)","Tidak ("&(LEFT(S10,2)=LEFT(G10,2))+(LEFT(T10,2)=LEFT(H10,2))+(LEFT(U10,3)=LEFT(I10,3))+(LEFT(V10,2)=LEFT(J10,2))+(LEFT(W10,2)=LEFT(K10,2))+(LEFT(X10,2)=LEFT(L10,2))&"/6): "&TRIM(IF(NOT(LEFT(S10,2)=LEFT(G10,2)),"V4 ","")&IF(NOT(LEFT(T10,2)=LEFT(H10,2)),"V5 ","")&IF(NOT(LEFT(U10,3)=LEFT(I10,3)),"V6 ","")&IF(NOT(LEFT(V10,2)=LEFT(J10,2)),"V7 ","")&IF(NOT(LEFT(W10,2)=LEFT(K10,2)),"V8 ","")&IF(NOT(LEFT(X10,2)=LEFT(L10,2)),"V9 ",""))))) | BI10: =IF(COUNTA($G10:$L10)<6,"",IF($E$1<3,"",IF(COUNTA(Y10:AD10)<6,"Belum lengkap",IF((LEFT(Y10,2)=LEFT(G10,2))+(LEFT(Z10,2)=LEFT(H10,2))+(LEFT(AA10,3)=LEFT(I10,3))+(LEFT(AB10,2)=LEFT(J10,2))+(LEFT(AC10,2)=LEFT(K10,2))+(LEFT(AD10,2)=LEFT(L10,2))=6,"Ya (6/6)","Tidak ("&(LEFT(Y10,2)=LEFT(G10,2))+(LEFT(Z10,2)=LEFT(H10,2))+(LEFT(AA10,3)=LEFT(I10,3))+(LEFT(AB10,2)=LEFT(J10,2))+(LEFT(AC10,2)=LEFT(K10,2))+(LEFT(AD10,2)=LEFT(L10,2))&"/6): "&TRIM(IF(NOT(LEFT(Y10,2)=LEFT(G10,2)),"V4 ","")&IF(NOT(LEFT(Z10,2)=LEFT(H10,2)),"V5 ","")&IF(NOT(LEFT(AA10,3)=LEFT(I10,3)),"V6 ","")&IF(NOT(LEFT(AB10,2)=LEFT(J10,2)),"V7 ","")&IF(NOT(LEFT(AC10,2)=LEFT(K10,2)),"V8 ","")&IF(NOT(LEFT(AD10,2)=LEFT(L10,2)),"V9 ","")))))) | BJ10: =IF(COUNTA($G10:$L10)<6,"",IF($E$1<4,"",IF(COUNTA(AE10:AJ10)<6,"Belum lengkap",IF((LEFT(AE10,2)=LEFT(G10,2))+(LEFT(AF10,2)=LEFT(H10,2))+(LEFT(AG10,3)=LEFT(I10,3))+(LEFT(AH10,2)=LEFT(J10,2))+(LEFT(AI10,2)=LEFT(K10,2))+(LEFT(AJ10,2)=LEFT(L10,2))=6,"Ya (6/6)","Tidak ("&(LEFT(AE10,2)=LEFT(G10,2))+(LEFT(AF10,2)=LEFT(H10,2))+(LEFT(AG10,3)=LEFT(I10,3))+(LEFT(AH10,2)=LEFT(J10,2))+(LEFT(AI10,2)=LEFT(K10,2))+(LEFT(AJ10,2)=LEFT(L10,2))&"/6): "&TRIM(IF(NOT(LEFT(AE10,2)=LEFT(G10,2)),"V4 ","")&IF(NOT(LEFT(AF10,2)=LEFT(H10,2)),"V5 ","")&IF(NOT(LEFT(AG10,3)=LEFT(I10,3)),"V6 ","")&IF(NOT(LEFT(AH10,2)=LEFT(J10,2)),"V7 ","")&IF(NOT(LEFT(AI10,2)=LEFT(K10,2)),"V8 ","")&IF(NOT(LEFT(AJ10,2)=LEFT(L10,2)),"V9 ",""))))))
A11: 8 | B11: =IF(INDEX(Korpus!$A:$A,$A11)="","",INDEX(Korpus!$A:$A,$A11)) -> 2019MHN201 | C11: =TRIM(INDEX(Korpus!$D:$D,$A11)&" "&INDEX(Korpus!$E:$E,$A11)) -> Paragraf 4 Kalimat 1 | D11: =IF(INDEX(Korpus!$B:$B,$A11)="","",INDEX(Korpus!$B:$B,$A11)) -> C. Pembahasan | E11: =IF(INDEX(Korpus!$C:$C,$A11)="","",INDEX(Korpus!$C:$C,$A11)) -> 5. Pentingnya Perlindungan Data Pribadi | F11: =IF(INDEX(Korpus!$F:$F,$A11)="","",INDEX(Korpus!$F:$F,$A11)) -> Konsep perlindungan data mengisyaratkan bahwa individu memiliki hak untuk menentukan apakah mereka akan membagi atau bertukar data pribadi mereka atau tidak. | AK11: =IF(Hitung!B11<$E$1,"",IF(Hitung!C11>0,"Beda","Sama")) | AL11: =IF(Hitung!D11<$E$1,"",IF(Hitung!E11>0,"Beda","Sama")) | AM11: =IF(Hitung!F11<$E$1,"",IF(Hitung!G11>0,"Beda","Sama")) | AN11: =IF(Hitung!H11<$E$1,"",IF(Hitung!I11>0,"Beda","Sama")) | AO11: =IF(Hitung!J11<$E$1,"",IF(Hitung!K11>0,"Beda","Sama")) | AP11: =IF(Hitung!L11<$E$1,"",IF(Hitung!M11>0,"Beda","Sama")) | AQ11: =COUNTIF(AK11:AP11,"Beda") -> 0 | AX11: =IF(AR11<>"",AR11,IF(AND(Hitung!B11=$E$1,Hitung!C11=0),M11,"")) | AY11: =IF(AS11<>"",AS11,IF(AND(Hitung!D11=$E$1,Hitung!E11=0),N11,"")) | AZ11: =IF(AT11<>"",AT11,IF(AND(Hitung!F11=$E$1,Hitung!G11=0),O11,"")) | BA11: =IF(AU11<>"",AU11,IF(AND(Hitung!H11=$E$1,Hitung!I11=0),P11,"")) | BB11: =IF(AV11<>"",AV11,IF(AND(Hitung!J11=$E$1,Hitung!K11=0),Q11,"")) | BC11: =IF(AW11<>"",AW11,IF(AND(Hitung!L11=$E$1,Hitung!M11=0),R11,"")) | BE11: =IF(COUNTA(M11:R11)+COUNTA(S11:X11)+($E$1>=3)*COUNTA(Y11:AD11)+($E$1>=4)*COUNTA(AE11:AJ11)<6*$E$1,"Menunggu coder",IF(AQ11=0,"Sepakat",IF(SUMPRODUCT((AK11:AP11="Beda")*(AR11:AW11=""))=0,"Selesai adjudikasi","Perlu adjudikasi"))) -> Menunggu coder | BF11: =IF(COUNTIF(AX11:BC11,"?*")<6,"",IF(IF(AND(LEFT(AY11,2)="R0",LEFT(BC11,2)<>"K5"),"R0 harus K5; ","")&IF(AND(LEFT(AY11,2)="R1",LEFT(BC11,2)="K3"),"R1 tidak boleh K3 (fungsional); ","")&IF(AND(LEFT(AY11,2)="R2",LEFT(BC11,2)="K5"),"R2 tidak boleh K5; ","")&IF(AND(LEFT(AY11,2)="R2",OR(LEFT(AX11,2)="S6",LEFT(AX11,2)="S7",LEFT(AX11,2)="S8")),"R2 tidak boleh S6/S7/S8; ","")&IF(AND(LEFT(AY11,2)="R2",OR(LEFT(AZ11,3)="T02",LEFT(BA11,2)="P8")),"T02 atau P8 tidak boleh R2; ","")&IF(AND(LEFT(AZ11,3)="T01",LEFT(BA11,2)<>"P6"),"T01 biasanya P6 (periksa); ","")&IF(AND(LEFT(BA11,2)="P1",LEFT(BC11,2)<>"K4"),"P1 biasanya K4 (periksa); ","")="","OK",IF(AND(LEFT(AY11,2)="R0",LEFT(BC11,2)<>"K5"),"R0 harus K5; ","")&IF(AND(LEFT(AY11,2)="R1",LEFT(BC11,2)="K3"),"R1 tidak boleh K3 (fungsional); ","")&IF(AND(LEFT(AY11,2)="R2",LEFT(BC11,2)="K5"),"R2 tidak boleh K5; ","")&IF(AND(LEFT(AY11,2)="R2",OR(LEFT(AX11,2)="S6",LEFT(AX11,2)="S7",LEFT(AX11,2)="S8")),"R2 tidak boleh S6/S7/S8; ","")&IF(AND(LEFT(AY11,2)="R2",OR(LEFT(AZ11,3)="T02",LEFT(BA11,2)="P8")),"T02 atau P8 tidak boleh R2; ","")&IF(AND(LEFT(AZ11,3)="T01",LEFT(BA11,2)<>"P6"),"T01 biasanya P6 (periksa); ","")&IF(AND(LEFT(BA11,2)="P1",LEFT(BC11,2)<>"K4"),"P1 biasanya K4 (periksa); ",""))) | BG11: =IF(COUNTA($G11:$L11)<6,"",IF(COUNTA(M11:R11)<6,"Belum lengkap",IF((LEFT(M11,2)=LEFT(G11,2))+(LEFT(N11,2)=LEFT(H11,2))+(LEFT(O11,3)=LEFT(I11,3))+(LEFT(P11,2)=LEFT(J11,2))+(LEFT(Q11,2)=LEFT(K11,2))+(LEFT(R11,2)=LEFT(L11,2))=6,"Ya (6/6)","Tidak ("&(LEFT(M11,2)=LEFT(G11,2))+(LEFT(N11,2)=LEFT(H11,2))+(LEFT(O11,3)=LEFT(I11,3))+(LEFT(P11,2)=LEFT(J11,2))+(LEFT(Q11,2)=LEFT(K11,2))+(LEFT(R11,2)=LEFT(L11,2))&"/6): "&TRIM(IF(NOT(LEFT(M11,2)=LEFT(G11,2)),"V4 ","")&IF(NOT(LEFT(N11,2)=LEFT(H11,2)),"V5 ","")&IF(NOT(LEFT(O11,3)=LEFT(I11,3)),"V6 ","")&IF(NOT(LEFT(P11,2)=LEFT(J11,2)),"V7 ","")&IF(NOT(LEFT(Q11,2)=LEFT(K11,2)),"V8 ","")&IF(NOT(LEFT(R11,2)=LEFT(L11,2)),"V9 ",""))))) | BH11: =IF(COUNTA($G11:$L11)<6,"",IF(COUNTA(S11:X11)<6,"Belum lengkap",IF((LEFT(S11,2)=LEFT(G11,2))+(LEFT(T11,2)=LEFT(H11,2))+(LEFT(U11,3)=LEFT(I11,3))+(LEFT(V11,2)=LEFT(J11,2))+(LEFT(W11,2)=LEFT(K11,2))+(LEFT(X11,2)=LEFT(L11,2))=6,"Ya (6/6)","Tidak ("&(LEFT(S11,2)=LEFT(G11,2))+(LEFT(T11,2)=LEFT(H11,2))+(LEFT(U11,3)=LEFT(I11,3))+(LEFT(V11,2)=LEFT(J11,2))+(LEFT(W11,2)=LEFT(K11,2))+(LEFT(X11,2)=LEFT(L11,2))&"/6): "&TRIM(IF(NOT(LEFT(S11,2)=LEFT(G11,2)),"V4 ","")&IF(NOT(LEFT(T11,2)=LEFT(H11,2)),"V5 ","")&IF(NOT(LEFT(U11,3)=LEFT(I11,3)),"V6 ","")&IF(NOT(LEFT(V11,2)=LEFT(J11,2)),"V7 ","")&IF(NOT(LEFT(W11,2)=LEFT(K11,2)),"V8 ","")&IF(NOT(LEFT(X11,2)=LEFT(L11,2)),"V9 ",""))))) | BI11: =IF(COUNTA($G11:$L11)<6,"",IF($E$1<3,"",IF(COUNTA(Y11:AD11)<6,"Belum lengkap",IF((LEFT(Y11,2)=LEFT(G11,2))+(LEFT(Z11,2)=LEFT(H11,2))+(LEFT(AA11,3)=LEFT(I11,3))+(LEFT(AB11,2)=LEFT(J11,2))+(LEFT(AC11,2)=LEFT(K11,2))+(LEFT(AD11,2)=LEFT(L11,2))=6,"Ya (6/6)","Tidak ("&(LEFT(Y11,2)=LEFT(G11,2))+(LEFT(Z11,2)=LEFT(H11,2))+(LEFT(AA11,3)=LEFT(I11,3))+(LEFT(AB11,2)=LEFT(J11,2))+(LEFT(AC11,2)=LEFT(K11,2))+(LEFT(AD11,2)=LEFT(L11,2))&"/6): "&TRIM(IF(NOT(LEFT(Y11,2)=LEFT(G11,2)),"V4 ","")&IF(NOT(LEFT(Z11,2)=LEFT(H11,2)),"V5 ","")&IF(NOT(LEFT(AA11,3)=LEFT(I11,3)),"V6 ","")&IF(NOT(LEFT(AB11,2)=LEFT(J11,2)),"V7 ","")&IF(NOT(LEFT(AC11,2)=LEFT(K11,2)),"V8 ","")&IF(NOT(LEFT(AD11,2)=LEFT(L11,2)),"V9 ","")))))) | BJ11: =IF(COUNTA($G11:$L11)<6,"",IF($E$1<4,"",IF(COUNTA(AE11:AJ11)<6,"Belum lengkap",IF((LEFT(AE11,2)=LEFT(G11,2))+(LEFT(AF11,2)=LEFT(H11,2))+(LEFT(AG11,3)=LEFT(I11,3))+(LEFT(AH11,2)=LEFT(J11,2))+(LEFT(AI11,2)=LEFT(K11,2))+(LEFT(AJ11,2)=LEFT(L11,2))=6,"Ya (6/6)","Tidak ("&(LEFT(AE11,2)=LEFT(G11,2))+(LEFT(AF11,2)=LEFT(H11,2))+(LEFT(AG11,3)=LEFT(I11,3))+(LEFT(AH11,2)=LEFT(J11,2))+(LEFT(AI11,2)=LEFT(K11,2))+(LEFT(AJ11,2)=LEFT(L11,2))&"/6): "&TRIM(IF(NOT(LEFT(AE11,2)=LEFT(G11,2)),"V4 ","")&IF(NOT(LEFT(AF11,2)=LEFT(H11,2)),"V5 ","")&IF(NOT(LEFT(AG11,3)=LEFT(I11,3)),"V6 ","")&IF(NOT(LEFT(AH11,2)=LEFT(J11,2)),"V7 ","")&IF(NOT(LEFT(AI11,2)=LEFT(K11,2)),"V8 ","")&IF(NOT(LEFT(AJ11,2)=LEFT(L11,2)),"V9 ",""))))))
A12: 9 | B12: =IF(INDEX(Korpus!$A:$A,$A12)="","",INDEX(Korpus!$A:$A,$A12)) -> 2019MHN201 | C12: =TRIM(INDEX(Korpus!$D:$D,$A12)&" "&INDEX(Korpus!$E:$E,$A12)) -> Paragraf 4 Kalimat 2 | D12: =IF(INDEX(Korpus!$B:$B,$A12)="","",INDEX(Korpus!$B:$B,$A12)) -> C. Pembahasan | E12: =IF(INDEX(Korpus!$C:$C,$A12)="","",INDEX(Korpus!$C:$C,$A12)) -> 5. Pentingnya Perlindungan Data Pribadi | F12: =IF(INDEX(Korpus!$F:$F,$A12)="","",INDEX(Korpus!$F:$F,$A12)) -> Selain itu, individu juga memiliki hak untuk menentukan syarat-syarat pelaksanaan pemindahan data pribadi tersebut. | AK12: =IF(Hitung!B12<$E$1,"",IF(Hitung!C12>0,"Beda","Sama")) | AL12: =IF(Hitung!D12<$E$1,"",IF(Hitung!E12>0,"Beda","Sama")) | AM12: =IF(Hitung!F12<$E$1,"",IF(Hitung!G12>0,"Beda","Sama")) | AN12: =IF(Hitung!H12<$E$1,"",IF(Hitung!I12>0,"Beda","Sama")) | AO12: =IF(Hitung!J12<$E$1,"",IF(Hitung!K12>0,"Beda","Sama")) | AP12: =IF(Hitung!L12<$E$1,"",IF(Hitung!M12>0,"Beda","Sama")) | AQ12: =COUNTIF(AK12:AP12,"Beda") -> 0 | AX12: =IF(AR12<>"",AR12,IF(AND(Hitung!B12=$E$1,Hitung!C12=0),M12,"")) | AY12: =IF(AS12<>"",AS12,IF(AND(Hitung!D12=$E$1,Hitung!E12=0),N12,"")) | AZ12: =IF(AT12<>"",AT12,IF(AND(Hitung!F12=$E$1,Hitung!G12=0),O12,"")) | BA12: =IF(AU12<>"",AU12,IF(AND(Hitung!H12=$E$1,Hitung!I12=0),P12,"")) | BB12: =IF(AV12<>"",AV12,IF(AND(Hitung!J12=$E$1,Hitung!K12=0),Q12,"")) | BC12: =IF(AW12<>"",AW12,IF(AND(Hitung!L12=$E$1,Hitung!M12=0),R12,"")) | BE12: =IF(COUNTA(M12:R12)+COUNTA(S12:X12)+($E$1>=3)*COUNTA(Y12:AD12)+($E$1>=4)*COUNTA(AE12:AJ12)<6*$E$1,"Menunggu coder",IF(AQ12=0,"Sepakat",IF(SUMPRODUCT((AK12:AP12="Beda")*(AR12:AW12=""))=0,"Selesai adjudikasi","Perlu adjudikasi"))) -> Menunggu coder | BF12: =IF(COUNTIF(AX12:BC12,"?*")<6,"",IF(IF(AND(LEFT(AY12,2)="R0",LEFT(BC12,2)<>"K5"),"R0 harus K5; ","")&IF(AND(LEFT(AY12,2)="R1",LEFT(BC12,2)="K3"),"R1 tidak boleh K3 (fungsional); ","")&IF(AND(LEFT(AY12,2)="R2",LEFT(BC12,2)="K5"),"R2 tidak boleh K5; ","")&IF(AND(LEFT(AY12,2)="R2",OR(LEFT(AX12,2)="S6",LEFT(AX12,2)="S7",LEFT(AX12,2)="S8")),"R2 tidak boleh S6/S7/S8; ","")&IF(AND(LEFT(AY12,2)="R2",OR(LEFT(AZ12,3)="T02",LEFT(BA12,2)="P8")),"T02 atau P8 tidak boleh R2; ","")&IF(AND(LEFT(AZ12,3)="T01",LEFT(BA12,2)<>"P6"),"T01 biasanya P6 (periksa); ","")&IF(AND(LEFT(BA12,2)="P1",LEFT(BC12,2)<>"K4"),"P1 biasanya K4 (periksa); ","")="","OK",IF(AND(LEFT(AY12,2)="R0",LEFT(BC12,2)<>"K5"),"R0 harus K5; ","")&IF(AND(LEFT(AY12,2)="R1",LEFT(BC12,2)="K3"),"R1 tidak boleh K3 (fungsional); ","")&IF(AND(LEFT(AY12,2)="R2",LEFT(BC12,2)="K5"),"R2 tidak boleh K5; ","")&IF(AND(LEFT(AY12,2)="R2",OR(LEFT(AX12,2)="S6",LEFT(AX12,2)="S7",LEFT(AX12,2)="S8")),"R2 tidak boleh S6/S7/S8; ","")&IF(AND(LEFT(AY12,2)="R2",OR(LEFT(AZ12,3)="T02",LEFT(BA12,2)="P8")),"T02 atau P8 tidak boleh R2; ","")&IF(AND(LEFT(AZ12,3)="T01",LEFT(BA12,2)<>"P6"),"T01 biasanya P6 (periksa); ","")&IF(AND(LEFT(BA12,2)="P1",LEFT(BC12,2)<>"K4"),"P1 biasanya K4 (periksa); ",""))) | BG12: =IF(COUNTA($G12:$L12)<6,"",IF(COUNTA(M12:R12)<6,"Belum lengkap",IF((LEFT(M12,2)=LEFT(G12,2))+(LEFT(N12,2)=LEFT(H12,2))+(LEFT(O12,3)=LEFT(I12,3))+(LEFT(P12,2)=LEFT(J12,2))+(LEFT(Q12,2)=LEFT(K12,2))+(LEFT(R12,2)=LEFT(L12,2))=6,"Ya (6/6)","Tidak ("&(LEFT(M12,2)=LEFT(G12,2))+(LEFT(N12,2)=LEFT(H12,2))+(LEFT(O12,3)=LEFT(I12,3))+(LEFT(P12,2)=LEFT(J12,2))+(LEFT(Q12,2)=LEFT(K12,2))+(LEFT(R12,2)=LEFT(L12,2))&"/6): "&TRIM(IF(NOT(LEFT(M12,2)=LEFT(G12,2)),"V4 ","")&IF(NOT(LEFT(N12,2)=LEFT(H12,2)),"V5 ","")&IF(NOT(LEFT(O12,3)=LEFT(I12,3)),"V6 ","")&IF(NOT(LEFT(P12,2)=LEFT(J12,2)),"V7 ","")&IF(NOT(LEFT(Q12,2)=LEFT(K12,2)),"V8 ","")&IF(NOT(LEFT(R12,2)=LEFT(L12,2)),"V9 ",""))))) | BH12: =IF(COUNTA($G12:$L12)<6,"",IF(COUNTA(S12:X12)<6,"Belum lengkap",IF((LEFT(S12,2)=LEFT(G12,2))+(LEFT(T12,2)=LEFT(H12,2))+(LEFT(U12,3)=LEFT(I12,3))+(LEFT(V12,2)=LEFT(J12,2))+(LEFT(W12,2)=LEFT(K12,2))+(LEFT(X12,2)=LEFT(L12,2))=6,"Ya (6/6)","Tidak ("&(LEFT(S12,2)=LEFT(G12,2))+(LEFT(T12,2)=LEFT(H12,2))+(LEFT(U12,3)=LEFT(I12,3))+(LEFT(V12,2)=LEFT(J12,2))+(LEFT(W12,2)=LEFT(K12,2))+(LEFT(X12,2)=LEFT(L12,2))&"/6): "&TRIM(IF(NOT(LEFT(S12,2)=LEFT(G12,2)),"V4 ","")&IF(NOT(LEFT(T12,2)=LEFT(H12,2)),"V5 ","")&IF(NOT(LEFT(U12,3)=LEFT(I12,3)),"V6 ","")&IF(NOT(LEFT(V12,2)=LEFT(J12,2)),"V7 ","")&IF(NOT(LEFT(W12,2)=LEFT(K12,2)),"V8 ","")&IF(NOT(LEFT(X12,2)=LEFT(L12,2)),"V9 ",""))))) | BI12: =IF(COUNTA($G12:$L12)<6,"",IF($E$1<3,"",IF(COUNTA(Y12:AD12)<6,"Belum lengkap",IF((LEFT(Y12,2)=LEFT(G12,2))+(LEFT(Z12,2)=LEFT(H12,2))+(LEFT(AA12,3)=LEFT(I12,3))+(LEFT(AB12,2)=LEFT(J12,2))+(LEFT(AC12,2)=LEFT(K12,2))+(LEFT(AD12,2)=LEFT(L12,2))=6,"Ya (6/6)","Tidak ("&(LEFT(Y12,2)=LEFT(G12,2))+(LEFT(Z12,2)=LEFT(H12,2))+(LEFT(AA12,3)=LEFT(I12,3))+(LEFT(AB12,2)=LEFT(J12,2))+(LEFT(AC12,2)=LEFT(K12,2))+(LEFT(AD12,2)=LEFT(L12,2))&"/6): "&TRIM(IF(NOT(LEFT(Y12,2)=LEFT(G12,2)),"V4 ","")&IF(NOT(LEFT(Z12,2)=LEFT(H12,2)),"V5 ","")&IF(NOT(LEFT(AA12,3)=LEFT(I12,3)),"V6 ","")&IF(NOT(LEFT(AB12,2)=LEFT(J12,2)),"V7 ","")&IF(NOT(LEFT(AC12,2)=LEFT(K12,2)),"V8 ","")&IF(NOT(LEFT(AD12,2)=LEFT(L12,2)),"V9 ","")))))) | BJ12: =IF(COUNTA($G12:$L12)<6,"",IF($E$1<4,"",IF(COUNTA(AE12:AJ12)<6,"Belum lengkap",IF((LEFT(AE12,2)=LEFT(G12,2))+(LEFT(AF12,2)=LEFT(H12,2))+(LEFT(AG12,3)=LEFT(I12,3))+(LEFT(AH12,2)=LEFT(J12,2))+(LEFT(AI12,2)=LEFT(K12,2))+(LEFT(AJ12,2)=LEFT(L12,2))=6,"Ya (6/6)","Tidak ("&(LEFT(AE12,2)=LEFT(G12,2))+(LEFT(AF12,2)=LEFT(H12,2))+(LEFT(AG12,3)=LEFT(I12,3))+(LEFT(AH12,2)=LEFT(J12,2))+(LEFT(AI12,2)=LEFT(K12,2))+(LEFT(AJ12,2)=LEFT(L12,2))&"/6): "&TRIM(IF(NOT(LEFT(AE12,2)=LEFT(G12,2)),"V4 ","")&IF(NOT(LEFT(AF12,2)=LEFT(H12,2)),"V5 ","")&IF(NOT(LEFT(AG12,3)=LEFT(I12,3)),"V6 ","")&IF(NOT(LEFT(AH12,2)=LEFT(J12,2)),"V7 ","")&IF(NOT(LEFT(AI12,2)=LEFT(K12,2)),"V8 ","")&IF(NOT(LEFT(AJ12,2)=LEFT(L12,2)),"V9 ",""))))))
A13: 10 | B13: =IF(INDEX(Korpus!$A:$A,$A13)="","",INDEX(Korpus!$A:$A,$A13)) -> 2019MHN201 | C13: =TRIM(INDEX(Korpus!$D:$D,$A13)&" "&INDEX(Korpus!$E:$E,$A13)) -> Paragraf 4 Kalimat 3 | D13: =IF(INDEX(Korpus!$B:$B,$A13)="","",INDEX(Korpus!$B:$B,$A13)) -> C. Pembahasan | E13: =IF(INDEX(Korpus!$C:$C,$A13)="","",INDEX(Korpus!$C:$C,$A13)) -> 5. Pentingnya Perlindungan Data Pribadi | F13: =IF(INDEX(Korpus!$F:$F,$A13)="","",INDEX(Korpus!$F:$F,$A13)) -> Lebih jauh, perlindungan privasi. | AK13: =IF(Hitung!B13<$E$1,"",IF(Hitung!C13>0,"Beda","Sama")) | AL13: =IF(Hitung!D13<$E$1,"",IF(Hitung!E13>0,"Beda","Sama")) | AM13: =IF(Hitung!F13<$E$1,"",IF(Hitung!G13>0,"Beda","Sama")) | AN13: =IF(Hitung!H13<$E$1,"",IF(Hitung!I13>0,"Beda","Sama")) | AO13: =IF(Hitung!J13<$E$1,"",IF(Hitung!K13>0,"Beda","Sama")) | AP13: =IF(Hitung!L13<$E$1,"",IF(Hitung!M13>0,"Beda","Sama")) | AQ13: =COUNTIF(AK13:AP13,"Beda") -> 0 | AX13: =IF(AR13<>"",AR13,IF(AND(Hitung!B13=$E$1,Hitung!C13=0),M13,"")) | AY13: =IF(AS13<>"",AS13,IF(AND(Hitung!D13=$E$1,Hitung!E13=0),N13,"")) | AZ13: =IF(AT13<>"",AT13,IF(AND(Hitung!F13=$E$1,Hitung!G13=0),O13,"")) | BA13: =IF(AU13<>"",AU13,IF(AND(Hitung!H13=$E$1,Hitung!I13=0),P13,"")) | BB13: =IF(AV13<>"",AV13,IF(AND(Hitung!J13=$E$1,Hitung!K13=0),Q13,"")) | BC13: =IF(AW13<>"",AW13,IF(AND(Hitung!L13=$E$1,Hitung!M13=0),R13,"")) | BE13: =IF(COUNTA(M13:R13)+COUNTA(S13:X13)+($E$1>=3)*COUNTA(Y13:AD13)+($E$1>=4)*COUNTA(AE13:AJ13)<6*$E$1,"Menunggu coder",IF(AQ13=0,"Sepakat",IF(SUMPRODUCT((AK13:AP13="Beda")*(AR13:AW13=""))=0,"Selesai adjudikasi","Perlu adjudikasi"))) -> Menunggu coder | BF13: =IF(COUNTIF(AX13:BC13,"?*")<6,"",IF(IF(AND(LEFT(AY13,2)="R0",LEFT(BC13,2)<>"K5"),"R0 harus K5; ","")&IF(AND(LEFT(AY13,2)="R1",LEFT(BC13,2)="K3"),"R1 tidak boleh K3 (fungsional); ","")&IF(AND(LEFT(AY13,2)="R2",LEFT(BC13,2)="K5"),"R2 tidak boleh K5; ","")&IF(AND(LEFT(AY13,2)="R2",OR(LEFT(AX13,2)="S6",LEFT(AX13,2)="S7",LEFT(AX13,2)="S8")),"R2 tidak boleh S6/S7/S8; ","")&IF(AND(LEFT(AY13,2)="R2",OR(LEFT(AZ13,3)="T02",LEFT(BA13,2)="P8")),"T02 atau P8 tidak boleh R2; ","")&IF(AND(LEFT(AZ13,3)="T01",LEFT(BA13,2)<>"P6"),"T01 biasanya P6 (periksa); ","")&IF(AND(LEFT(BA13,2)="P1",LEFT(BC13,2)<>"K4"),"P1 biasanya K4 (periksa); ","")="","OK",IF(AND(LEFT(AY13,2)="R0",LEFT(BC13,2)<>"K5"),"R0 harus K5; ","")&IF(AND(LEFT(AY13,2)="R1",LEFT(BC13,2)="K3"),"R1 tidak boleh K3 (fungsional); ","")&IF(AND(LEFT(AY13,2)="R2",LEFT(BC13,2)="K5"),"R2 tidak boleh K5; ","")&IF(AND(LEFT(AY13,2)="R2",OR(LEFT(AX13,2)="S6",LEFT(AX13,2)="S7",LEFT(AX13,2)="S8")),"R2 tidak boleh S6/S7/S8; ","")&IF(AND(LEFT(AY13,2)="R2",OR(LEFT(AZ13,3)="T02",LEFT(BA13,2)="P8")),"T02 atau P8 tidak boleh R2; ","")&IF(AND(LEFT(AZ13,3)="T01",LEFT(BA13,2)<>"P6"),"T01 biasanya P6 (periksa); ","")&IF(AND(LEFT(BA13,2)="P1",LEFT(BC13,2)<>"K4"),"P1 biasanya K4 (periksa); ",""))) | BG13: =IF(COUNTA($G13:$L13)<6,"",IF(COUNTA(M13:R13)<6,"Belum lengkap",IF((LEFT(M13,2)=LEFT(G13,2))+(LEFT(N13,2)=LEFT(H13,2))+(LEFT(O13,3)=LEFT(I13,3))+(LEFT(P13,2)=LEFT(J13,2))+(LEFT(Q13,2)=LEFT(K13,2))+(LEFT(R13,2)=LEFT(L13,2))=6,"Ya (6/6)","Tidak ("&(LEFT(M13,2)=LEFT(G13,2))+(LEFT(N13,2)=LEFT(H13,2))+(LEFT(O13,3)=LEFT(I13,3))+(LEFT(P13,2)=LEFT(J13,2))+(LEFT(Q13,2)=LEFT(K13,2))+(LEFT(R13,2)=LEFT(L13,2))&"/6): "&TRIM(IF(NOT(LEFT(M13,2)=LEFT(G13,2)),"V4 ","")&IF(NOT(LEFT(N13,2)=LEFT(H13,2)),"V5 ","")&IF(NOT(LEFT(O13,3)=LEFT(I13,3)),"V6 ","")&IF(NOT(LEFT(P13,2)=LEFT(J13,2)),"V7 ","")&IF(NOT(LEFT(Q13,2)=LEFT(K13,2)),"V8 ","")&IF(NOT(LEFT(R13,2)=LEFT(L13,2)),"V9 ",""))))) | BH13: =IF(COUNTA($G13:$L13)<6,"",IF(COUNTA(S13:X13)<6,"Belum lengkap",IF((LEFT(S13,2)=LEFT(G13,2))+(LEFT(T13,2)=LEFT(H13,2))+(LEFT(U13,3)=LEFT(I13,3))+(LEFT(V13,2)=LEFT(J13,2))+(LEFT(W13,2)=LEFT(K13,2))+(LEFT(X13,2)=LEFT(L13,2))=6,"Ya (6/6)","Tidak ("&(LEFT(S13,2)=LEFT(G13,2))+(LEFT(T13,2)=LEFT(H13,2))+(LEFT(U13,3)=LEFT(I13,3))+(LEFT(V13,2)=LEFT(J13,2))+(LEFT(W13,2)=LEFT(K13,2))+(LEFT(X13,2)=LEFT(L13,2))&"/6): "&TRIM(IF(NOT(LEFT(S13,2)=LEFT(G13,2)),"V4 ","")&IF(NOT(LEFT(T13,2)=LEFT(H13,2)),"V5 ","")&IF(NOT(LEFT(U13,3)=LEFT(I13,3)),"V6 ","")&IF(NOT(LEFT(V13,2)=LEFT(J13,2)),"V7 ","")&IF(NOT(LEFT(W13,2)=LEFT(K13,2)),"V8 ","")&IF(NOT(LEFT(X13,2)=LEFT(L13,2)),"V9 ",""))))) | BI13: =IF(COUNTA($G13:$L13)<6,"",IF($E$1<3,"",IF(COUNTA(Y13:AD13)<6,"Belum lengkap",IF((LEFT(Y13,2)=LEFT(G13,2))+(LEFT(Z13,2)=LEFT(H13,2))+(LEFT(AA13,3)=LEFT(I13,3))+(LEFT(AB13,2)=LEFT(J13,2))+(LEFT(AC13,2)=LEFT(K13,2))+(LEFT(AD13,2)=LEFT(L13,2))=6,"Ya (6/6)","Tidak ("&(LEFT(Y13,2)=LEFT(G13,2))+(LEFT(Z13,2)=LEFT(H13,2))+(LEFT(AA13,3)=LEFT(I13,3))+(LEFT(AB13,2)=LEFT(J13,2))+(LEFT(AC13,2)=LEFT(K13,2))+(LEFT(AD13,2)=LEFT(L13,2))&"/6): "&TRIM(IF(NOT(LEFT(Y13,2)=LEFT(G13,2)),"V4 ","")&IF(NOT(LEFT(Z13,2)=LEFT(H13,2)),"V5 ","")&IF(NOT(LEFT(AA13,3)=LEFT(I13,3)),"V6 ","")&IF(NOT(LEFT(AB13,2)=LEFT(J13,2)),"V7 ","")&IF(NOT(LEFT(AC13,2)=LEFT(K13,2)),"V8 ","")&IF(NOT(LEFT(AD13,2)=LEFT(L13,2)),"V9 ","")))))) | BJ13: =IF(COUNTA($G13:$L13)<6,"",IF($E$1<4,"",IF(COUNTA(AE13:AJ13)<6,"Belum lengkap",IF((LEFT(AE13,2)=LEFT(G13,2))+(LEFT(AF13,2)=LEFT(H13,2))+(LEFT(AG13,3)=LEFT(I13,3))+(LEFT(AH13,2)=LEFT(J13,2))+(LEFT(AI13,2)=LEFT(K13,2))+(LEFT(AJ13,2)=LEFT(L13,2))=6,"Ya (6/6)","Tidak ("&(LEFT(AE13,2)=LEFT(G13,2))+(LEFT(AF13,2)=LEFT(H13,2))+(LEFT(AG13,3)=LEFT(I13,3))+(LEFT(AH13,2)=LEFT(J13,2))+(LEFT(AI13,2)=LEFT(K13,2))+(LEFT(AJ13,2)=LEFT(L13,2))&"/6): "&TRIM(IF(NOT(LEFT(AE13,2)=LEFT(G13,2)),"V4 ","")&IF(NOT(LEFT(AF13,2)=LEFT(H13,2)),"V5 ","")&IF(NOT(LEFT(AG13,3)=LEFT(I13,3)),"V6 ","")&IF(NOT(LEFT(AH13,2)=LEFT(J13,2)),"V7 ","")&IF(NOT(LEFT(AI13,2)=LEFT(K13,2)),"V8 ","")&IF(NOT(LEFT(AJ13,2)=LEFT(L13,2)),"V9 ",""))))))
