Workbook

Sheet Petunjuk
B1: Template Krippendorff's Alpha (Nominal & Ordinal)
B2: Kapasitas: 2–20 coder · maks 1000 unit · maks 20 kategori · tanpa data kosong.
B3: A. Cara pakai
B4: 1. Sheet Pengaturan: pilih Jenis data (Nominal / Ordinal) di sel C4.
B5: 2. Sheet Pengaturan: isi Kode kategori (B8:B27) mulai dari baris pertama, tanpa baris kosong. Untuk ordinal, urutkan dari skala terendah ke tertinggi. Kode boleh angka (1,2,3…) atau teks ("Rendah", "Tinggi").
B6: 3. Sheet Data: hapus contoh di B6:U1005, lalu isi data Anda. Satu baris = satu unit, satu kolom = satu coder. Ganti judul kolom (Coder 1, dst.) sesuai kebutuhan.
B7: 4. Kolom coder dan baris unit yang tidak dipakai dibiarkan kosong seluruhnya. Semua unit yang dipakai harus diisi oleh SEMUA coder.
B8: 5. Sheet Hasil: baca α. Status data harus "VALID". Jika "PERIKSA DATA", lihat nomor unit bermasalah (C10) dan kolom Status di sheet Hitung.
B9: B. Aturan data
B10: • Setiap nilai di Data harus ada di daftar kategori (sheet Pengaturan). Dropdown Data memberi peringatan jika tidak cocok.
B11: • Template ini khusus data lengkap (tanpa missing). Sel kosong di tengah blok data akan ditandai bermasalah.
B12: • Template menampilkan α nominal dan ordinal sekaligus; α utama mengikuti pilihan di Pengaturan!C4.
... B31: Sel kuning bertulisan biru = input pengguna. Sel putih bertulisan hitam = rumus otomatis.

Sheet Pengaturan
A1: Pengaturan
A2: Sel kuning bertulisan biru = input. Jangan ubah sel lain.
B4: Jenis data (untuk α utama) | C4: Ordinal
B5: Daftar kategori: isi dari baris pertama tanpa baris kosong. Untuk data ORDINAL urutkan dari terendah ke tertinggi (urutan baris = urutan skala). Kode boleh angka atau teks.
A7: No | B7: Kode kategori | C7: Keterangan (opsional)
A8: 1 | B8: 1 | C8: Sangat rendah
A9: 2 | B9: 2 | C9: Rendah
A10: 3 | B10: 3 | C10: Sedang
A11: 4 | B11: 4 | C11: Tinggi
A12: 5 | B12: 5 | C12: Sangat tinggi
A13: 6
A14: 7
A15: 8
A16: 9
A17: 10
A18: 11
A19: 12
A20: 13
A21: 14
A22: 15
A23: 16
A24: 17
... A27: 20

Sheet Data
A1: Data Koding
A2: Baris = unit analisis, kolom = coder (maks 20 coder, 1000 unit). Isi sel kuning; tanpa sel kosong di dalam blok data; kolom/baris yang tidak terpakai dibiarkan kosong seluruhnya.
A3: Contoh data (4 coder, 25 unit, skala ordinal 1–5) sudah terisi. Hapus isi B6:U1005 lalu isi data Anda sendiri.
A5: Unit | B5: Coder 1 | C5: Coder 2 | D5: Coder 3 | E5: Coder 4 | F5: Coder 5 | G5: Coder 6 | H5: Coder 7 | I5: Coder 8 | J5: Coder 9 | K5: Coder 10 | L5: Coder 11 | M5: Coder 12 | N5: Coder 13 | O5: Coder 14 | P5: Coder 15 | Q5: Coder 16 | R5: Coder 17 | S5: Coder 18 | T5: Coder 19 | U5: Coder 20
A6: 1 | B6: 3 | C6: 4 | D6: 3 | E6: 3
A7: 2 | B7: 5 | C7: 5 | D7: 3 | E7: 5
A8: 3 | B8: 5 | C8: 5 | D8: 5 | E8: 5
A9: 4 | B9: 4 | C9: 4 | D9: 4 | E9: 5
A10: 5 | B10: 4 | C10: 5 | D10: 2 | E10: 4
A11: 6 | B11: 2 | C11: 2 | D11: 1 | E11: 2
A12: 7 | B12: 4 | C12: 5 | D12: 5 | E12: 5
A13: 8 | B13: 1 | C13: 2 | D13: 1 | E13: 1
A14: 9 | B14: 4 | C14: 3 | D14: 4 | E14: 2
A15: 10 | B15: 2 | C15: 4 | D15: 3 | E15: 3
A16: 11 | B16: 4 | C16: 5 | D16: 5 | E16: 5
A17: 12 | B17: 1 | C17: 1 | D17: 1 | E17: 1
... A30: 25 | B30: 4 | C30: 4 | D30: 5 | E30: 4
A31: 26
A32: 27
A33: 28
A34: 29
A35: 30
A36: 31
A37: 32
A38: 33
A39: 34
A40: 35
A41: 36
A42: 37
... A1005: 1000

Sheet Hasil
B1: Hasil Krippendorff's Alpha
B2: Semua nilai di sheet ini dihitung otomatis dari sheet Data dan Pengaturan.
B4: Jumlah coder (m) | C4: =MAX(Hitung!V6:V1005) -> 4
B5: Jumlah unit lengkap (N) | C5: =COUNTIF(Hitung!W6:W1005,"OK") -> 25
B6: Jumlah nilai berpasangan (n = N × m) | C6: =C5*C4 -> 100
B7: Jumlah kategori terpakai | C7: =COUNTIF(Matriks!W6:W25,">0") -> 5
B8: Jumlah baris bermasalah | C8: =SUM(Hitung!X6:X1005) -> 0
B9: Status data | C9: =IF(AND(C4>=2,C5>=1,C8=0),"VALID","PERIKSA DATA") -> VALID
B10: Unit pertama yang bermasalah | C10: =IFERROR(INDEX(Data!A6:A1005,MATCH(1,Hitung!X6:X1005,0)),"-") -> -
B12: Ukuran | C12: Nominal | D12: Ordinal
B13: Disagreement teramati (D_o) | C13: =IF($C$9="VALID",SUMPRODUCT(Matriks!$C$6:$V$25,Matriks!$C$56:$V$75)/$C$6,"-") -> 0.50666667 | D13: =IF($C$9="VALID",SUMPRODUCT(Matriks!$C$6:$V$25,Matriks!$C$81:$V$100)/$C$6,"-") -> 392.23667
B14: Disagreement harapan (D_e) | C14: =IF($C$9="VALID",SUMPRODUCT(Matriks!$C$31:$V$50,Matriks!$C$56:$V$75)/$C$6,"-") -> 0.79010101 | D14: =IF($C$9="VALID",SUMPRODUCT(Matriks!$C$31:$V$50,Matriks!$C$81:$V$100)/$C$6,"-") -> 1598.6061
B15: Krippendorff's α | C15: =IF(AND(ISNUMBER(C13),ISNUMBER(C14)),IF(C14=0,"n/a",1-C13/C14),"-") -> 0.35873178 | D15: =IF(AND(ISNUMBER(D13),ISNUMBER(D14)),IF(D14=0,"n/a",1-D13/D14),"-") -> 0.75463832
B16: Interpretasi | C16: =IF(ISNUMBER(C15),IF(C15>=0.8,"Reliabel",IF(C15>=0.667,"Tentatif","Tidak reliabel")),"-") -> Tidak reliabel | D16: =IF(ISNUMBER(D15),IF(D15>=0.8,"Reliabel",IF(D15>=0.667,"Tentatif","Tidak reliabel")),"-") -> Tentatif
B18: Jenis data terpilih (sheet Pengaturan) | C18: =Pengaturan!C4 -> Ordinal
B19: α UTAMA YANG DILAPORKAN | C19: =IF(C18="Nominal",C15,D15) -> 0.75463832
B20: Interpretasi | C20: =IF(C18="Nominal",C16,D16) -> Tentatif
B21: Acuan Krippendorff (2018): α ≥ 0,800 reliabel; 0,667 ≤ α < 0,800 tentatif; α < 0,667 tidak reliabel.
B23: Distribusi kategori
B24: Kode kategori | C24: Keterangan | D24: Jumlah nilai (n_c) | E24: Proporsi
B25: =IF(INDEX(Pengaturan!$B$8:$B$27,1)="","",INDEX(Pengaturan!$B$8:$B$27,1)) -> 1 | C25: =IF(B25="","",IF(INDEX(Pengaturan!$C$8:$C$27,1)="","",INDEX(Pengaturan!$C$8:$C$27,1))) -> Sangat rendah | D25: =IF(B25="","",Matriks!W6) -> 22 | E25: =IF(OR(B25="",$C$6=0),"",D25/$C$6) -> 0.22
B26: =IF(INDEX(Pengaturan!$B$8:$B$27,2)="","",INDEX(Pengaturan!$B$8:$B$27,2)) -> 2 | C26: =IF(B26="","",IF(INDEX(Pengaturan!$C$8:$C$27,2)="","",INDEX(Pengaturan!$C$8:$C$27,2))) -> Rendah | D26: =IF(B26="","",Matriks!W7) -> 14 | E26: =IF(OR(B26="",$C$6=0),"",D26/$C$6) -> 0.14
B27: =IF(INDEX(Pengaturan!$B$8:$B$27,3)="","",INDEX(Pengaturan!$B$8:$B$27,3)) -> 3 | C27: =IF(B27="","",IF(INDEX(Pengaturan!$C$8:$C$27,3)="","",INDEX(Pengaturan!$C$8:$C$27,3))) -> Sedang | D27: =IF(B27="","",Matriks!W8) -> 12 | E27: =IF(OR(B27="",$C$6=0),"",D27/$C$6) -> 0.12
B28: =IF(INDEX(Pengaturan!$B$8:$B$27,4)="","",INDEX(Pengaturan!$B$8:$B$27,4)) -> 4 | C28: =IF(B28="","",IF(INDEX(Pengaturan!$C$8:$C$27,4)="","",INDEX(Pengaturan!$C$8:$C$27,4))) -> Tinggi | D28: =IF(B28="","",Matriks!W9) -> 25 | E28: =IF(OR(B28="",$C$6=0),"",D28/$C$6) -> 0.25
B29: =IF(INDEX(Pengaturan!$B$8:$B$27,5)="","",INDEX(Pengaturan!$B$8:$B$27,5)) -> 5 | C29: =IF(B29="","",IF(INDEX(Pengaturan!$C$8:$C$27,5)="","",INDEX(Pengaturan!$C$8:$C$27,5))) -> Sangat tinggi | D29: =IF(B29="","",Matriks!W10) -> 27 | E29: =IF(OR(B29="",$C$6=0),"",D29/$C$6) -> 0.27
B30: =IF(INDEX(Pengaturan!$B$8:$B$27,6)="","",INDEX(Pengaturan!$B$8:$B$27,6)) | C30: =IF(B30="","",IF(INDEX(Pengaturan!$C$8:$C$27,6)="","",INDEX(Pengaturan!$C$8:$C$27,6))) | D30: =IF(B30="","",Matriks!W11) | E30: =IF(OR(B30="",$C$6=0),"",D30/$C$6)
B31: =IF(INDEX(Pengaturan!$B$8:$B$27,7)="","",INDEX(Pengaturan!$B$8:$B$27,7)) | C31: =IF(B31="","",IF(INDEX(Pengaturan!$C$8:$C$27,7)="","",INDEX(Pengaturan!$C$8:$C$27,7))) | D31: =IF(B31="","",Matriks!W12) | E31: =IF(OR(B31="",$C$6=0),"",D31/$C$6)
B32: =IF(INDEX(Pengaturan!$B$8:$B$27,8)="","",INDEX(Pengaturan!$B$8:$B$27,8)) | C32: =IF(B32="","",IF(INDEX(Pengaturan!$C$8:$C$27,8)="","",INDEX(Pengaturan!$C$8:$C$27,8))) | D32: =IF(B32="","",Matriks!W13) | E32: =IF(OR(B32="",$C$6=0),"",D32/$C$6)
B33: =IF(INDEX(Pengaturan!$B$8:$B$27,9)="","",INDEX(Pengaturan!$B$8:$B$27,9)) | C33: =IF(B33="","",IF(INDEX(Pengaturan!$C$8:$C$27,9)="","",INDEX(Pengaturan!$C$8:$C$27,9))) | D33: =IF(B33="","",Matriks!W14) | E33: =IF(OR(B33="",$C$6=0),"",D33/$C$6)
B34: =IF(INDEX(Pengaturan!$B$8:$B$27,10)="","",INDEX(Pengaturan!$B$8:$B$27,10)) | C34: =IF(B34="","",IF(INDEX(Pengaturan!$C$8:$C$27,10)="","",INDEX(Pengaturan!$C$8:$C$27,10))) | D34: =IF(B34="","",Matriks!W15) | E34: =IF(OR(B34="",$C$6=0),"",D34/$C$6)
B35: =IF(INDEX(Pengaturan!$B$8:$B$27,11)="","",INDEX(Pengaturan!$B$8:$B$27,11)) | C35: =IF(B35="","",IF(INDEX(Pengaturan!$C$8:$C$27,11)="","",INDEX(Pengaturan!$C$8:$C$27,11))) | D35: =IF(B35="","",Matriks!W16) | E35: =IF(OR(B35="",$C$6=0),"",D35/$C$6)
B36: =IF(INDEX(Pengaturan!$B$8:$B$27,12)="","",INDEX(Pengaturan!$B$8:$B$27,12)) | C36: =IF(B36="","",IF(INDEX(Pengaturan!$C$8:$C$27,12)="","",INDEX(Pengaturan!$C$8:$C$27,12))) | D36: =IF(B36="","",Matriks!W17) | E36: =IF(OR(B36="",$C$6=0),"",D36/$C$6)
B37: =IF(INDEX(Pengaturan!$B$8:$B$27,13)="","",INDEX(Pengaturan!$B$8:$B$27,13)) | C37: =IF(B37="","",IF(INDEX(Pengaturan!$C$8:$C$27,13)="","",INDEX(Pengaturan!$C$8:$C$27,13))) | D37: =IF(B37="","",Matriks!W18) | E37: =IF(OR(B37="",$C$6=0),"",D37/$C$6)
B38: =IF(INDEX(Pengaturan!$B$8:$B$27,14)="","",INDEX(Pengaturan!$B$8:$B$27,14)) | C38: =IF(B38="","",IF(INDEX(Pengaturan!$C$8:$C$27,14)="","",INDEX(Pengaturan!$C$8:$C$27,14))) | D38: =IF(B38="","",Matriks!W19) | E38: =IF(OR(B38="",$C$6=0),"",D38/$C$6)
B39: =IF(INDEX(Pengaturan!$B$8:$B$27,15)="","",INDEX(Pengaturan!$B$8:$B$27,15)) | C39: =IF(B39="","",IF(INDEX(Pengaturan!$C$8:$C$27,15)="","",INDEX(Pengaturan!$C$8:$C$27,15))) | D39: =IF(B39="","",Matriks!W20) | E39: =IF(OR(B39="",$C$6=0),"",D39/$C$6)
B40: =IF(INDEX(Pengaturan!$B$8:$B$27,16)="","",INDEX(Pengaturan!$B$8:$B$27,16)) | C40: =IF(B40="","",IF(INDEX(Pengaturan!$C$8:$C$27,16)="","",INDEX(Pengaturan!$C$8:$C$27,16))) | D40: =IF(B40="","",Matriks!W21) | E40: =IF(OR(B40="",$C$6=0),"",D40/$C$6)
B41: =IF(INDEX(Pengaturan!$B$8:$B$27,17)="","",INDEX(Pengaturan!$B$8:$B$27,17)) | C41: =IF(B41="","",IF(INDEX(Pengaturan!$C$8:$C$27,17)="","",INDEX(Pengaturan!$C$8:$C$27,17))) | D41: =IF(B41="","",Matriks!W22) | E41: =IF(OR(B41="",$C$6=0),"",D41/$C$6)
B42: =IF(INDEX(Pengaturan!$B$8:$B$27,18)="","",INDEX(Pengaturan!$B$8:$B$27,18)) | C42: =IF(B42="","",IF(INDEX(Pengaturan!$C$8:$C$27,18)="","",INDEX(Pengaturan!$C$8:$C$27,18))) | D42: =IF(B42="","",Matriks!W23) | E42: =IF(OR(B42="",$C$6=0),"",D42/$C$6)
B43: =IF(INDEX(Pengaturan!$B$8:$B$27,19)="","",INDEX(Pengaturan!$B$8:$B$27,19)) | C43: =IF(B43="","",IF(INDEX(Pengaturan!$C$8:$C$27,19)="","",INDEX(Pengaturan!$C$8:$C$27,19))) | D43: =IF(B43="","",Matriks!W24) | E43: =IF(OR(B43="",$C$6=0),"",D43/$C$6)
B44: =IF(INDEX(Pengaturan!$B$8:$B$27,20)="","",INDEX(Pengaturan!$B$8:$B$27,20)) | C44: =IF(B44="","",IF(INDEX(Pengaturan!$C$8:$C$27,20)="","",INDEX(Pengaturan!$C$8:$C$27,20))) | D44: =IF(B44="","",Matriks!W25) | E44: =IF(OR(B44="",$C$6=0),"",D44/$C$6)

Sheet Hitung
A1: Perhitungan Antara: jumlah nilai per unit per kategori (n_uc)
A2: Sheet ini otomatis. Tidak perlu diubah.
A4: indeks → | B4: 1 | C4: 2 | D4: 3 | E4: 4 | F4: 5 | G4: 6 | H4: 7 | I4: 8 | J4: 9 | K4: 10 | L4: 11 | M4: 12 | N4: 13 | O4: 14 | P4: 15 | Q4: 16 | R4: 17 | S4: 18 | T4: 19 | U4: 20
A5: Unit | B5: =IF(INDEX(Pengaturan!$B$8:$B$27,B$4)="","",INDEX(Pengaturan!$B$8:$B$27,B$4)) -> 1 | C5: =IF(INDEX(Pengaturan!$B$8:$B$27,C$4)="","",INDEX(Pengaturan!$B$8:$B$27,C$4)) -> 2 | D5: =IF(INDEX(Pengaturan!$B$8:$B$27,D$4)="","",INDEX(Pengaturan!$B$8:$B$27,D$4)) -> 3 | E5: =IF(INDEX(Pengaturan!$B$8:$B$27,E$4)="","",INDEX(Pengaturan!$B$8:$B$27,E$4)) -> 4 | F5: =IF(INDEX(Pengaturan!$B$8:$B$27,F$4)="","",INDEX(Pengaturan!$B$8:$B$27,F$4)) -> 5 | G5: =IF(INDEX(Pengaturan!$B$8:$B$27,G$4)="","",INDEX(Pengaturan!$B$8:$B$27,G$4)) | H5: =IF(INDEX(Pengaturan!$B$8:$B$27,H$4)="","",INDEX(Pengaturan!$B$8:$B$27,H$4)) | I5: =IF(INDEX(Pengaturan!$B$8:$B$27,I$4)="","",INDEX(Pengaturan!$B$8:$B$27,I$4)) | ... U5: =IF(INDEX(Pengaturan!$B$8:$B$27,U$4)="","",INDEX(Pengaturan!$B$8:$B$27,U$4)) | V5: Nilai terisi | W5: Status | X5: Bermasalah
A6: =Data!A6 -> 1 | B6: =IF(INDEX(Pengaturan!$B$8:$B$27,B$4)="",0,COUNTIF(Data!$B6:$U6,INDEX(Pengaturan!$B$8:$B$27,B$4))) -> 0 | C6: =IF(INDEX(Pengaturan!$B$8:$B$27,C$4)="",0,COUNTIF(Data!$B6:$U6,INDEX(Pengaturan!$B$8:$B$27,C$4))) -> 0 | D6: =IF(INDEX(Pengaturan!$B$8:$B$27,D$4)="",0,COUNTIF(Data!$B6:$U6,INDEX(Pengaturan!$B$8:$B$27,D$4))) -> 3 | E6: =IF(INDEX(Pengaturan!$B$8:$B$27,E$4)="",0,COUNTIF(Data!$B6:$U6,INDEX(Pengaturan!$B$8:$B$27,E$4))) -> 1 | F6: =IF(INDEX(Pengaturan!$B$8:$B$27,F$4)="",0,COUNTIF(Data!$B6:$U6,INDEX(Pengaturan!$B$8:$B$27,F$4))) -> 0 | G6: =IF(INDEX(Pengaturan!$B$8:$B$27,G$4)="",0,COUNTIF(Data!$B6:$U6,INDEX(Pengaturan!$B$8:$B$27,G$4))) -> 0 | H6: =IF(INDEX(Pengaturan!$B$8:$B$27,H$4)="",0,COUNTIF(Data!$B6:$U6,INDEX(Pengaturan!$B$8:$B$27,H$4))) -> 0 | I6: =IF(INDEX(Pengaturan!$B$8:$B$27,I$4)="",0,COUNTIF(Data!$B6:$U6,INDEX(Pengaturan!$B$8:$B$27,I$4))) -> 0 | ... U6: =IF(INDEX(Pengaturan!$B$8:$B$27,U$4)="",0,COUNTIF(Data!$B6:$U6,INDEX(Pengaturan!$B$8:$B$27,U$4))) -> 0 | V6: =COUNTA(Data!$B6:$U6) -> 4 | W6: =IF(V6=0,"",IF(V6<>Hasil!$C$4,"Data kosong/tidak lengkap",IF(SUM(B6:U6)<>V6,"Kategori tidak dikenal","OK"))) -> OK | X6: =IF(OR(W6="",W6="OK"),0,1) -> 0
A7: =Data!A7 -> 2 | B7: =IF(INDEX(Pengaturan!$B$8:$B$27,B$4)="",0,COUNTIF(Data!$B7:$U7,INDEX(Pengaturan!$B$8:$B$27,B$4))) -> 0 | C7: =IF(INDEX(Pengaturan!$B$8:$B$27,C$4)="",0,COUNTIF(Data!$B7:$U7,INDEX(Pengaturan!$B$8:$B$27,C$4))) -> 0 | D7: =IF(INDEX(Pengaturan!$B$8:$B$27,D$4)="",0,COUNTIF(Data!$B7:$U7,INDEX(Pengaturan!$B$8:$B$27,D$4))) -> 1 | E7: =IF(INDEX(Pengaturan!$B$8:$B$27,E$4)="",0,COUNTIF(Data!$B7:$U7,INDEX(Pengaturan!$B$8:$B$27,E$4))) -> 0 | F7: =IF(INDEX(Pengaturan!$B$8:$B$27,F$4)="",0,COUNTIF(Data!$B7:$U7,INDEX(Pengaturan!$B$8:$B$27,F$4))) -> 3 | G7: =IF(INDEX(Pengaturan!$B$8:$B$27,G$4)="",0,COUNTIF(Data!$B7:$U7,INDEX(Pengaturan!$B$8:$B$27,G$4))) -> 0 | H7: =IF(INDEX(Pengaturan!$B$8:$B$27,H$4)="",0,COUNTIF(Data!$B7:$U7,INDEX(Pengaturan!$B$8:$B$27,H$4))) -> 0 | I7: =IF(INDEX(Pengaturan!$B$8:$B$27,I$4)="",0,COUNTIF(Data!$B7:$U7,INDEX(Pengaturan!$B$8:$B$27,I$4))) -> 0 | ... U7: =IF(INDEX(Pengaturan!$B$8:$B$27,U$4)="",0,COUNTIF(Data!$B7:$U7,INDEX(Pengaturan!$B$8:$B$27,U$4))) -> 0 | V7: =COUNTA(Data!$B7:$U7) -> 4 | W7: =IF(V7=0,"",IF(V7<>Hasil!$C$4,"Data kosong/tidak lengkap",IF(SUM(B7:U7)<>V7,"Kategori tidak dikenal","OK"))) -> OK | X7: =IF(OR(W7="",W7="OK"),0,1) -> 0
A8: =Data!A8 -> 3 | B8: =IF(INDEX(Pengaturan!$B$8:$B$27,B$4)="",0,COUNTIF(Data!$B8:$U8,INDEX(Pengaturan!$B$8:$B$27,B$4))) -> 0 | C8: =IF(INDEX(Pengaturan!$B$8:$B$27,C$4)="",0,COUNTIF(Data!$B8:$U8,INDEX(Pengaturan!$B$8:$B$27,C$4))) -> 0 | D8: =IF(INDEX(Pengaturan!$B$8:$B$27,D$4)="",0,COUNTIF(Data!$B8:$U8,INDEX(Pengaturan!$B$8:$B$27,D$4))) -> 0 | E8: =IF(INDEX(Pengaturan!$B$8:$B$27,E$4)="",0,COUNTIF(Data!$B8:$U8,INDEX(Pengaturan!$B$8:$B$27,E$4))) -> 0 | F8: =IF(INDEX(Pengaturan!$B$8:$B$27,F$4)="",0,COUNTIF(Data!$B8:$U8,INDEX(Pengaturan!$B$8:$B$27,F$4))) -> 4 | G8: =IF(INDEX(Pengaturan!$B$8:$B$27,G$4)="",0,COUNTIF(Data!$B8:$U8,INDEX(Pengaturan!$B$8:$B$27,G$4))) -> 0 | H8: =IF(INDEX(Pengaturan!$B$8:$B$27,H$4)="",0,COUNTIF(Data!$B8:$U8,INDEX(Pengaturan!$B$8:$B$27,H$4))) -> 0 | I8: =IF(INDEX(Pengaturan!$B$8:$B$27,I$4)="",0,COUNTIF(Data!$B8:$U8,INDEX(Pengaturan!$B$8:$B$27,I$4))) -> 0 | ... U8: =IF(INDEX(Pengaturan!$B$8:$B$27,U$4)="",0,COUNTIF(Data!$B8:$U8,INDEX(Pengaturan!$B$8:$B$27,U$4))) -> 0 | V8: =COUNTA(Data!$B8:$U8) -> 4 | W8: =IF(V8=0,"",IF(V8<>Hasil!$C$4,"Data kosong/tidak lengkap",IF(SUM(B8:U8)<>V8,"Kategori tidak dikenal","OK"))) -> OK | X8: =IF(OR(W8="",W8="OK"),0,1) -> 0
A9: =Data!A9 -> 4 | B9: =IF(INDEX(Pengaturan!$B$8:$B$27,B$4)="",0,COUNTIF(Data!$B9:$U9,INDEX(Pengaturan!$B$8:$B$27,B$4))) -> 0 | C9: =IF(INDEX(Pengaturan!$B$8:$B$27,C$4)="",0,COUNTIF(Data!$B9:$U9,INDEX(Pengaturan!$B$8:$B$27,C$4))) -> 0 | D9: =IF(INDEX(Pengaturan!$B$8:$B$27,D$4)="",0,COUNTIF(Data!$B9:$U9,INDEX(Pengaturan!$B$8:$B$27,D$4))) -> 0 | E9: =IF(INDEX(Pengaturan!$B$8:$B$27,E$4)="",0,COUNTIF(Data!$B9:$U9,INDEX(Pengaturan!$B$8:$B$27,E$4))) -> 3 | F9: =IF(INDEX(Pengaturan!$B$8:$B$27,F$4)="",0,COUNTIF(Data!$B9:$U9,INDEX(Pengaturan!$B$8:$B$27,F$4))) -> 1 | G9: =IF(INDEX(Pengaturan!$B$8:$B$27,G$4)="",0,COUNTIF(Data!$B9:$U9,INDEX(Pengaturan!$B$8:$B$27,G$4))) -> 0 | H9: =IF(INDEX(Pengaturan!$B$8:$B$27,H$4)="",0,COUNTIF(Data!$B9:$U9,INDEX(Pengaturan!$B$8:$B$27,H$4))) -> 0 | I9: =IF(INDEX(Pengaturan!$B$8:$B$27,I$4)="",0,COUNTIF(Data!$B9:$U9,INDEX(Pengaturan!$B$8:$B$27,I$4))) -> 0 | ... U9: =IF(INDEX(Pengaturan!$B$8:$B$27,U$4)="",0,COUNTIF(Data!$B9:$U9,INDEX(Pengaturan!$B$8:$B$27,U$4))) -> 0 | V9: =COUNTA(Data!$B9:$U9) -> 4 | W9: =IF(V9=0,"",IF(V9<>Hasil!$C$4,"Data kosong/tidak lengkap",IF(SUM(B9:U9)<>V9,"Kategori tidak dikenal","OK"))) -> OK | X9: =IF(OR(W9="",W9="OK"),0,1) -> 0
A10: =Data!A10 -> 5 | B10: =IF(INDEX(Pengaturan!$B$8:$B$27,B$4)="",0,COUNTIF(Data!$B10:$U10,INDEX(Pengaturan!$B$8:$B$27,B$4))) -> 0 | C10: =IF(INDEX(Pengaturan!$B$8:$B$27,C$4)="",0,COUNTIF(Data!$B10:$U10,INDEX(Pengaturan!$B$8:$B$27,C$4))) -> 1 | D10: =IF(INDEX(Pengaturan!$B$8:$B$27,D$4)="",0,COUNTIF(Data!$B10:$U10,INDEX(Pengaturan!$B$8:$B$27,D$4))) -> 0 | E10: =IF(INDEX(Pengaturan!$B$8:$B$27,E$4)="",0,COUNTIF(Data!$B10:$U10,INDEX(Pengaturan!$B$8:$B$27,E$4))) -> 2 | F10: =IF(INDEX(Pengaturan!$B$8:$B$27,F$4)="",0,COUNTIF(Data!$B10:$U10,INDEX(Pengaturan!$B$8:$B$27,F$4))) -> 1 | G10: =IF(INDEX(Pengaturan!$B$8:$B$27,G$4)="",0,COUNTIF(Data!$B10:$U10,INDEX(Pengaturan!$B$8:$B$27,G$4))) -> 0 | H10: =IF(INDEX(Pengaturan!$B$8:$B$27,H$4)="",0,COUNTIF(Data!$B10:$U10,INDEX(Pengaturan!$B$8:$B$27,H$4))) -> 0 | I10: =IF(INDEX(Pengaturan!$B$8:$B$27,I$4)="",0,COUNTIF(Data!$B10:$U10,INDEX(Pengaturan!$B$8:$B$27,I$4))) -> 0 | ... U10: =IF(INDEX(Pengaturan!$B$8:$B$27,U$4)="",0,COUNTIF(Data!$B10:$U10,INDEX(Pengaturan!$B$8:$B$27,U$4))) -> 0 | V10: =COUNTA(Data!$B10:$U10) -> 4 | W10: =IF(V10=0,"",IF(V10<>Hasil!$C$4,"Data kosong/tidak lengkap",IF(SUM(B10:U10)<>V10,"Kategori tidak dikenal","OK"))) -> OK | X10: =IF(OR(W10="",W10="OK"),0,1) -> 0
A11: =Data!A11 -> 6 | B11: =IF(INDEX(Pengaturan!$B$8:$B$27,B$4)="",0,COUNTIF(Data!$B11:$U11,INDEX(Pengaturan!$B$8:$B$27,B$4))) -> 1 | C11: =IF(INDEX(Pengaturan!$B$8:$B$27,C$4)="",0,COUNTIF(Data!$B11:$U11,INDEX(Pengaturan!$B$8:$B$27,C$4))) -> 3 | D11: =IF(INDEX(Pengaturan!$B$8:$B$27,D$4)="",0,COUNTIF(Data!$B11:$U11,INDEX(Pengaturan!$B$8:$B$27,D$4))) -> 0 | E11: =IF(INDEX(Pengaturan!$B$8:$B$27,E$4)="",0,COUNTIF(Data!$B11:$U11,INDEX(Pengaturan!$B$8:$B$27,E$4))) -> 0 | F11: =IF(INDEX(Pengaturan!$B$8:$B$27,F$4)="",0,COUNTIF(Data!$B11:$U11,INDEX(Pengaturan!$B$8:$B$27,F$4))) -> 0 | G11: =IF(INDEX(Pengaturan!$B$8:$B$27,G$4)="",0,COUNTIF(Data!$B11:$U11,INDEX(Pengaturan!$B$8:$B$27,G$4))) -> 0 | H11: =IF(INDEX(Pengaturan!$B$8:$B$27,H$4)="",0,COUNTIF(Data!$B11:$U11,INDEX(Pengaturan!$B$8:$B$27,H$4))) -> 0 | I11: =IF(INDEX(Pengaturan!$B$8:$B$27,I$4)="",0,COUNTIF(Data!$B11:$U11,INDEX(Pengaturan!$B$8:$B$27,I$4))) -> 0 | ... U11: =IF(INDEX(Pengaturan!$B$8:$B$27,U$4)="",0,COUNTIF(Data!$B11:$U11,INDEX(Pengaturan!$B$8:$B$27,U$4))) -> 0 | V11: =COUNTA(Data!$B11:$U11) -> 4 | W11: =IF(V11=0,"",IF(V11<>Hasil!$C$4,"Data kosong/tidak lengkap",IF(SUM(B11:U11)<>V11,"Kategori tidak dikenal","OK"))) -> OK | X11: =IF(OR(W11="",W11="OK"),0,1) -> 0
A12: =Data!A12 -> 7 | B12: =IF(INDEX(Pengaturan!$B$8:$B$27,B$4)="",0,COUNTIF(Data!$B12:$U12,INDEX(Pengaturan!$B$8:$B$27,B$4))) -> 0 | C12: =IF(INDEX(Pengaturan!$B$8:$B$27,C$4)="",0,COUNTIF(Data!$B12:$U12,INDEX(Pengaturan!$B$8:$B$27,C$4))) -> 0 | D12: =IF(INDEX(Pengaturan!$B$8:$B$27,D$4)="",0,COUNTIF(Data!$B12:$U12,INDEX(Pengaturan!$B$8:$B$27,D$4))) -> 0 | E12: =IF(INDEX(Pengaturan!$B$8:$B$27,E$4)="",0,COUNTIF(Data!$B12:$U12,INDEX(Pengaturan!$B$8:$B$27,E$4))) -> 1 | F12: =IF(INDEX(Pengaturan!$B$8:$B$27,F$4)="",0,COUNTIF(Data!$B12:$U12,INDEX(Pengaturan!$B$8:$B$27,F$4))) -> 3 | G12: =IF(INDEX(Pengaturan!$B$8:$B$27,G$4)="",0,COUNTIF(Data!$B12:$U12,INDEX(Pengaturan!$B$8:$B$27,G$4))) -> 0 | H12: =IF(INDEX(Pengaturan!$B$8:$B$27,H$4)="",0,COUNTIF(Data!$B12:$U12,INDEX(Pengaturan!$B$8:$B$27,H$4))) -> 0 | I12: =IF(INDEX(Pengaturan!$B$8:$B$27,I$4)="",0,COUNTIF(Data!$B12:$U12,INDEX(Pengaturan!$B$8:$B$27,I$4))) -> 0 | ... U12: =IF(INDEX(Pengaturan!$B$8:$B$27,U$4)="",0,COUNTIF(Data!$B12:$U12,INDEX(Pengaturan!$B$8:$B$27,U$4))) -> 0 | V12: =COUNTA(Data!$B12:$U12) -> 4 | W12: =IF(V12=0,"",IF(V12<>Hasil!$C$4,"Data kosong/tidak lengkap",IF(SUM(B12:U12)<>V12,"Kategori tidak dikenal","OK"))) -> OK | X12: =IF(OR(W12="",W12="OK"),0,1) -> 0
A13: =Data!A13 -> 8 | B13: =IF(INDEX(Pengaturan!$B$8:$B$27,B$4)="",0,COUNTIF(Data!$B13:$U13,INDEX(Pengaturan!$B$8:$B$27,B$4))) -> 3 | C13: =IF(INDEX(Pengaturan!$B$8:$B$27,C$4)="",0,COUNTIF(Data!$B13:$U13,INDEX(Pengaturan!$B$8:$B$27,C$4))) -> 1 | D13: =IF(INDEX(Pengaturan!$B$8:$B$27,D$4)="",0,COUNTIF(Data!$B13:$U13,INDEX(Pengaturan!$B$8:$B$27,D$4))) -> 0 | E13: =IF(INDEX(Pengaturan!$B$8:$B$27,E$4)="",0,COUNTIF(Data!$B13:$U13,INDEX(Pengaturan!$B$8:$B$27,E$4))) -> 0 | F13: =IF(INDEX(Pengaturan!$B$8:$B$27,F$4)="",0,COUNTIF(Data!$B13:$U13,INDEX(Pengaturan!$B$8:$B$27,F$4))) -> 0 | G13: =IF(INDEX(Pengaturan!$B$8:$B$27,G$4)="",0,COUNTIF(Data!$B13:$U13,INDEX(Pengaturan!$B$8:$B$27,G$4))) -> 0 | H13: =IF(INDEX(Pengaturan!$B$8:$B$27,H$4)="",0,COUNTIF(Data!$B13:$U13,INDEX(Pengaturan!$B$8:$B$27,H$4))) -> 0 | I13: =IF(INDEX(Pengaturan!$B$8:$B$27,I$4)="",0,COUNTIF(Data!$B13:$U13,INDEX(Pengaturan!$B$8:$B$27,I$4))) -> 0 | ... U13: =IF(INDEX(Pengaturan!$B$8:$B$27,U$4)="",0,COUNTIF(Data!$B13:$U13,INDEX(Pengaturan!$B$8:$B$27,U$4))) -> 0 | V13: =COUNTA(Data!$B13:$U13) -> 4 | W13: =IF(V13=0,"",IF(V13<>Hasil!$C$4,"Data kosong/tidak lengkap",IF(SUM(B13:U13)<>V13,"Kategori tidak dikenal","OK"))) -> OK | X13: =IF(OR(W13="",W13="OK"),0,1) -> 0
A14: =Data!A14 -> 9 | B14: =IF(INDEX(Pengaturan!$B$8:$B$27,B$4)="",0,COUNTIF(Data!$B14:$U14,INDEX(Pengaturan!$B$8:$B$27,B$4))) -> 0 | C14: =IF(INDEX(Pengaturan!$B$8:$B$27,C$4)="",0,COUNTIF(Data!$B14:$U14,INDEX(Pengaturan!$B$8:$B$27,C$4))) -> 1 | D14: =IF(INDEX(Pengaturan!$B$8:$B$27,D$4)="",0,COUNTIF(Data!$B14:$U14,INDEX(Pengaturan!$B$8:$B$27,D$4))) -> 1 | E14: =IF(INDEX(Pengaturan!$B$8:$B$27,E$4)="",0,COUNTIF(Data!$B14:$U14,INDEX(Pengaturan!$B$8:$B$27,E$4))) -> 2 | F14: =IF(INDEX(Pengaturan!$B$8:$B$27,F$4)="",0,COUNTIF(Data!$B14:$U14,INDEX(Pengaturan!$B$8:$B$27,F$4))) -> 0 | G14: =IF(INDEX(Pengaturan!$B$8:$B$27,G$4)="",0,COUNTIF(Data!$B14:$U14,INDEX(Pengaturan!$B$8:$B$27,G$4))) -> 0 | H14: =IF(INDEX(Pengaturan!$B$8:$B$27,H$4)="",0,COUNTIF(Data!$B14:$U14,INDEX(Pengaturan!$B$8:$B$27,H$4))) -> 0 | I14: =IF(INDEX(Pengaturan!$B$8:$B$27,I$4)="",0,COUNTIF(Data!$B14:$U14,INDEX(Pengaturan!$B$8:$B$27,I$4))) -> 0 | ... U14: =IF(INDEX(Pengaturan!$B$8:$B$27,U$4)="",0,COUNTIF(Data!$B14:$U14,INDEX(Pengaturan!$B$8:$B$27,U$4))) -> 0 | V14: =COUNTA(Data!$B14:$U14) -> 4 | W14: =IF(V14=0,"",IF(V14<>Hasil!$C$4,"Data kosong/tidak lengkap",IF(SUM(B14:U14)<>V14,"Kategori tidak dikenal","OK"))) -> OK | X14: =IF(OR(W14="",W14="OK"),0,1) -> 0
A15: =Data!A15 -> 10 | B15: =IF(INDEX(Pengaturan!$B$8:$B$27,B$4)="",0,COUNTIF(Data!$B15:$U15,INDEX(Pengaturan!$B$8:$B$27,B$4))) -> 0 | C15: =IF(INDEX(Pengaturan!$B$8:$B$27,C$4)="",0,COUNTIF(Data!$B15:$U15,INDEX(Pengaturan!$B$8:$B$27,C$4))) -> 1 | D15: =IF(INDEX(Pengaturan!$B$8:$B$27,D$4)="",0,COUNTIF(Data!$B15:$U15,INDEX(Pengaturan!$B$8:$B$27,D$4))) -> 2 | E15: =IF(INDEX(Pengaturan!$B$8:$B$27,E$4)="",0,COUNTIF(Data!$B15:$U15,INDEX(Pengaturan!$B$8:$B$27,E$4))) -> 1 | F15: =IF(INDEX(Pengaturan!$B$8:$B$27,F$4)="",0,COUNTIF(Data!$B15:$U15,INDEX(Pengaturan!$B$8:$B$27,F$4))) -> 0 | G15: =IF(INDEX(Pengaturan!$B$8:$B$27,G$4)="",0,COUNTIF(Data!$B15:$U15,INDEX(Pengaturan!$B$8:$B$27,G$4))) -> 0 | H15: =IF(INDEX(Pengaturan!$B$8:$B$27,H$4)="",0,COUNTIF(Data!$B15:$U15,INDEX(Pengaturan!$B$8:$B$27,H$4))) -> 0 | I15: =IF(INDEX(Pengaturan!$B$8:$B$27,I$4)="",0,COUNTIF(Data!$B15:$U15,INDEX(Pengaturan!$B$8:$B$27,I$4))) -> 0 | ... U15: =IF(INDEX(Pengaturan!$B$8:$B$27,U$4)="",0,COUNTIF(Data!$B15:$U15,INDEX(Pengaturan!$B$8:$B$27,U$4))) -> 0 | V15: =COUNTA(Data!$B15:$U15) -> 4 | W15: =IF(V15=0,"",IF(V15<>Hasil!$C$4,"Data kosong/tidak lengkap",IF(SUM(B15:U15)<>V15,"Kategori tidak dikenal","OK"))) -> OK | X15: =IF(OR(W15="",W15="OK"),0,1) -> 0
A16: =Data!A16 -> 11 | B16: =IF(INDEX(Pengaturan!$B$8:$B$27,B$4)="",0,COUNTIF(Data!$B16:$U16,INDEX(Pengaturan!$B$8:$B$27,B$4))) -> 0 | C16: =IF(INDEX(Pengaturan!$B$8:$B$27,C$4)="",0,COUNTIF(Data!$B16:$U16,INDEX(Pengaturan!$B$8:$B$27,C$4))) -> 0 | D16: =IF(INDEX(Pengaturan!$B$8:$B$27,D$4)="",0,COUNTIF(Data!$B16:$U16,INDEX(Pengaturan!$B$8:$B$27,D$4))) -> 0 | E16: =IF(INDEX(Pengaturan!$B$8:$B$27,E$4)="",0,COUNTIF(Data!$B16:$U16,INDEX(Pengaturan!$B$8:$B$27,E$4))) -> 1 | F16: =IF(INDEX(Pengaturan!$B$8:$B$27,F$4)="",0,COUNTIF(Data!$B16:$U16,INDEX(Pengaturan!$B$8:$B$27,F$4))) -> 3 | G16: =IF(INDEX(Pengaturan!$B$8:$B$27,G$4)="",0,COUNTIF(Data!$B16:$U16,INDEX(Pengaturan!$B$8:$B$27,G$4))) -> 0 | H16: =IF(INDEX(Pengaturan!$B$8:$B$27,H$4)="",0,COUNTIF(Data!$B16:$U16,INDEX(Pengaturan!$B$8:$B$27,H$4))) -> 0 | I16: =IF(INDEX(Pengaturan!$B$8:$B$27,I$4)="",0,COUNTIF(Data!$B16:$U16,INDEX(Pengaturan!$B$8:$B$27,I$4))) -> 0 | ... U16: =IF(INDEX(Pengaturan!$B$8:$B$27,U$4)="",0,COUNTIF(Data!$B16:$U16,INDEX(Pengaturan!$B$8:$B$27,U$4))) -> 0 | V16: =COUNTA(Data!$B16:$U16) -> 4 | W16: =IF(V16=0,"",IF(V16<>Hasil!$C$4,"Data kosong/tidak lengkap",IF(SUM(B16:U16)<>V16,"Kategori tidak dikenal","OK"))) -> OK | X16: =IF(OR(W16="",W16="OK"),0,1) -> 0
A17: =Data!A17 -> 12 | B17: =IF(INDEX(Pengaturan!$B$8:$B$27,B$4)="",0,COUNTIF(Data!$B17:$U17,INDEX(Pengaturan!$B$8:$B$27,B$4))) -> 4 | C17: =IF(INDEX(Pengaturan!$B$8:$B$27,C$4)="",0,COUNTIF(Data!$B17:$U17,INDEX(Pengaturan!$B$8:$B$27,C$4))) -> 0 | D17: =IF(INDEX(Pengaturan!$B$8:$B$27,D$4)="",0,COUNTIF(Data!$B17:$U17,INDEX(Pengaturan!$B$8:$B$27,D$4))) -> 0 | E17: =IF(INDEX(Pengaturan!$B$8:$B$27,E$4)="",0,COUNTIF(Data!$B17:$U17,INDEX(Pengaturan!$B$8:$B$27,E$4))) -> 0 | F17: =IF(INDEX(Pengaturan!$B$8:$B$27,F$4)="",0,COUNTIF(Data!$B17:$U17,INDEX(Pengaturan!$B$8:$B$27,F$4))) -> 0 | G17: =IF(INDEX(Pengaturan!$B$8:$B$27,G$4)="",0,COUNTIF(Data!$B17:$U17,INDEX(Pengaturan!$B$8:$B$27,G$4))) -> 0 | H17: =IF(INDEX(Pengaturan!$B$8:$B$27,H$4)="",0,COUNTIF(Data!$B17:$U17,INDEX(Pengaturan!$B$8:$B$27,H$4))) -> 0 | I17: =IF(INDEX(Pengaturan!$B$8:$B$27,I$4)="",0,COUNTIF(Data!$B17:$U17,INDEX(Pengaturan!$B$8:$B$27,I$4))) -> 0 | ... U17: =IF(INDEX(Pengaturan!$B$8:$B$27,U$4)="",0,COUNTIF(Data!$B17:$U17,INDEX(Pengaturan!$B$8:$B$27,U$4))) -> 0 | V17: =COUNTA(Data!$B17:$U17) -> 4 | W17: =IF(V17=0,"",IF(V17<>Hasil!$C$4,"Data kosong/tidak lengkap",IF(SUM(B17:U17)<>V17,"Kategori tidak dikenal","OK"))) -> OK | X17: =IF(OR(W17="",W17="OK"),0,1) -> 0
... A1005: =Data!A1005 -> 1000 | B1005: =IF(INDEX(Pengaturan!$B$8:$B$27,B$4)="",0,COUNTIF(Data!$B1005:$U1005,INDEX(Pengaturan!$B$8:$B$27,B$4))) -> 0 | C1005: =IF(INDEX(Pengaturan!$B$8:$B$27,C$4)="",0,COUNTIF(Data!$B1005:$U1005,INDEX(Pengaturan!$B$8:$B$27,C$4))) -> 0 | D1005: =IF(INDEX(Pengaturan!$B$8:$B$27,D$4)="",0,COUNTIF(Data!$B1005:$U1005,INDEX(Pengaturan!$B$8:$B$27,D$4))) -> 0 | E1005: =IF(INDEX(Pengaturan!$B$8:$B$27,E$4)="",0,COUNTIF(Data!$B1005:$U1005,INDEX(Pengaturan!$B$8:$B$27,E$4))) -> 0 | F1005: =IF(INDEX(Pengaturan!$B$8:$B$27,F$4)="",0,COUNTIF(Data!$B1005:$U1005,INDEX(Pengaturan!$B$8:$B$27,F$4))) -> 0 | G1005: =IF(INDEX(Pengaturan!$B$8:$B$27,G$4)="",0,COUNTIF(Data!$B1005:$U1005,INDEX(Pengaturan!$B$8:$B$27,G$4))) -> 0 | H1005: =IF(INDEX(Pengaturan!$B$8:$B$27,H$4)="",0,COUNTIF(Data!$B1005:$U1005,INDEX(Pengaturan!$B$8:$B$27,H$4))) -> 0 | I1005: =IF(INDEX(Pengaturan!$B$8:$B$27,I$4)="",0,COUNTIF(Data!$B1005:$U1005,INDEX(Pengaturan!$B$8:$B$27,I$4))) -> 0 | ... U1005: =IF(INDEX(Pengaturan!$B$8:$B$27,U$4)="",0,COUNTIF(Data!$B1005:$U1005,INDEX(Pengaturan!$B$8:$B$27,U$4))) -> 0 | V1005: =COUNTA(Data!$B1005:$U1005) -> 0 | W1005: =IF(V1005=0,"",IF(V1005<>Hasil!$C$4,"Data kosong/tidak lengkap",IF(SUM(B1005:U1005)<>V1005,"Kategori tidak dikenal","OK"))) | X1005: =IF(OR(W1005="",W1005="OK"),0,1) -> 0

Sheet Matriks
A1: Matriks Perhitungan Krippendorff's Alpha
A2: Sheet ini otomatis. Tidak perlu diubah. Baris/kolom ke-i = kategori ke-i di sheet Pengaturan.
A3: 1) Matriks koincidensi teramati (o_ck)
B4: indeks | C4: 1 | D4: 2 | E4: 3 | F4: 4 | G4: 5 | H4: 6 | I4: 7 | J4: 8 | K4: 9 | L4: 10 | M4: 11 | N4: 12 | O4: 13 | P4: 14 | Q4: 15 | R4: 16 | S4: 17 | T4: 18 | U4: 19 | V4: 20
A5: i | B5: Kategori | C5: =IF(INDEX(Pengaturan!$B$8:$B$27,C$4)="","",INDEX(Pengaturan!$B$8:$B$27,C$4)) -> 1 | D5: =IF(INDEX(Pengaturan!$B$8:$B$27,D$4)="","",INDEX(Pengaturan!$B$8:$B$27,D$4)) -> 2 | E5: =IF(INDEX(Pengaturan!$B$8:$B$27,E$4)="","",INDEX(Pengaturan!$B$8:$B$27,E$4)) -> 3 | F5: =IF(INDEX(Pengaturan!$B$8:$B$27,F$4)="","",INDEX(Pengaturan!$B$8:$B$27,F$4)) -> 4 | G5: =IF(INDEX(Pengaturan!$B$8:$B$27,G$4)="","",INDEX(Pengaturan!$B$8:$B$27,G$4)) -> 5 | H5: =IF(INDEX(Pengaturan!$B$8:$B$27,H$4)="","",INDEX(Pengaturan!$B$8:$B$27,H$4)) | I5: =IF(INDEX(Pengaturan!$B$8:$B$27,I$4)="","",INDEX(Pengaturan!$B$8:$B$27,I$4)) | J5: =IF(INDEX(Pengaturan!$B$8:$B$27,J$4)="","",INDEX(Pengaturan!$B$8:$B$27,J$4)) | ... V5: =IF(INDEX(Pengaturan!$B$8:$B$27,V$4)="","",INDEX(Pengaturan!$B$8:$B$27,V$4)) | W5: n_c
A6: 1 | B6: =IF(INDEX(Pengaturan!$B$8:$B$27,$A6)="","",INDEX(Pengaturan!$B$8:$B$27,$A6)) -> 1 | C6: =IF(Hasil!$C$4<2,0,(SUMPRODUCT(INDEX(Hitung!$B$6:$U$1005,0,$A6),INDEX(Hitung!$B$6:$U$1005,0,C$4))-IF($A6=C$4,SUM(INDEX(Hitung!$B$6:$U$1005,0,$A6)),0))/(Hasil!$C$4-1)) -> 14.666667 | D6: =IF(Hasil!$C$4<2,0,(SUMPRODUCT(INDEX(Hitung!$B$6:$U$1005,0,$A6),INDEX(Hitung!$B$6:$U$1005,0,D$4))-IF($A6=D$4,SUM(INDEX(Hitung!$B$6:$U$1005,0,$A6)),0))/(Hasil!$C$4-1)) -> 5 | E6: =IF(Hasil!$C$4<2,0,(SUMPRODUCT(INDEX(Hitung!$B$6:$U$1005,0,$A6),INDEX(Hitung!$B$6:$U$1005,0,E$4))-IF($A6=E$4,SUM(INDEX(Hitung!$B$6:$U$1005,0,$A6)),0))/(Hasil!$C$4-1)) -> 1.3333333 | F6: =IF(Hasil!$C$4<2,0,(SUMPRODUCT(INDEX(Hitung!$B$6:$U$1005,0,$A6),INDEX(Hitung!$B$6:$U$1005,0,F$4))-IF($A6=F$4,SUM(INDEX(Hitung!$B$6:$U$1005,0,$A6)),0))/(Hasil!$C$4-1)) -> 1 | G6: =IF(Hasil!$C$4<2,0,(SUMPRODUCT(INDEX(Hitung!$B$6:$U$1005,0,$A6),INDEX(Hitung!$B$6:$U$1005,0,G$4))-IF($A6=G$4,SUM(INDEX(Hitung!$B$6:$U$1005,0,$A6)),0))/(Hasil!$C$4-1)) -> 0 | H6: =IF(Hasil!$C$4<2,0,(SUMPRODUCT(INDEX(Hitung!$B$6:$U$1005,0,$A6),INDEX(Hitung!$B$6:$U$1005,0,H$4))-IF($A6=H$4,SUM(INDEX(Hitung!$B$6:$U$1005,0,$A6)),0))/(Hasil!$C$4-1)) -> 0 | I6: =IF(Hasil!$C$4<2,0,(SUMPRODUCT(INDEX(Hitung!$B$6:$U$1005,0,$A6),INDEX(Hitung!$B$6:$U$1005,0,I$4))-IF($A6=I$4,SUM(INDEX(Hitung!$B$6:$U$1005,0,$A6)),0))/(Hasil!$C$4-1)) -> 0 | J6: =IF(Hasil!$C$4<2,0,(SUMPRODUCT(INDEX(Hitung!$B$6:$U$1005,0,$A6),INDEX(Hitung!$B$6:$U$1005,0,J$4))-IF($A6=J$4,SUM(INDEX(Hitung!$B$6:$U$1005,0,$A6)),0))/(Hasil!$C$4-1)) -> 0 | ... V6: =IF(Hasil!$C$4<2,0,(SUMPRODUCT(INDEX(Hitung!$B$6:$U$1005,0,$A6),INDEX(Hitung!$B$6:$U$1005,0,V$4))-IF($A6=V$4,SUM(INDEX(Hitung!$B$6:$U$1005,0,$A6)),0))/(Hasil!$C$4-1)) -> 0 | W6: =SUM(C6:V6) -> 22
A7: 2 | B7: =IF(INDEX(Pengaturan!$B$8:$B$27,$A7)="","",INDEX(Pengaturan!$B$8:$B$27,$A7)) -> 2 | C7: =IF(Hasil!$C$4<2,0,(SUMPRODUCT(INDEX(Hitung!$B$6:$U$1005,0,$A7),INDEX(Hitung!$B$6:$U$1005,0,C$4))-IF($A7=C$4,SUM(INDEX(Hitung!$B$6:$U$1005,0,$A7)),0))/(Hasil!$C$4-1)) -> 5 | D7: =IF(Hasil!$C$4<2,0,(SUMPRODUCT(INDEX(Hitung!$B$6:$U$1005,0,$A7),INDEX(Hitung!$B$6:$U$1005,0,D$4))-IF($A7=D$4,SUM(INDEX(Hitung!$B$6:$U$1005,0,$A7)),0))/(Hasil!$C$4-1)) -> 3.3333333 | E7: =IF(Hasil!$C$4<2,0,(SUMPRODUCT(INDEX(Hitung!$B$6:$U$1005,0,$A7),INDEX(Hitung!$B$6:$U$1005,0,E$4))-IF($A7=E$4,SUM(INDEX(Hitung!$B$6:$U$1005,0,$A7)),0))/(Hasil!$C$4-1)) -> 2 | F7: =IF(Hasil!$C$4<2,0,(SUMPRODUCT(INDEX(Hitung!$B$6:$U$1005,0,$A7),INDEX(Hitung!$B$6:$U$1005,0,F$4))-IF($A7=F$4,SUM(INDEX(Hitung!$B$6:$U$1005,0,$A7)),0))/(Hasil!$C$4-1)) -> 3 | G7: =IF(Hasil!$C$4<2,0,(SUMPRODUCT(INDEX(Hitung!$B$6:$U$1005,0,$A7),INDEX(Hitung!$B$6:$U$1005,0,G$4))-IF($A7=G$4,SUM(INDEX(Hitung!$B$6:$U$1005,0,$A7)),0))/(Hasil!$C$4-1)) -> 0.66666667 | H7: =IF(Hasil!$C$4<2,0,(SUMPRODUCT(INDEX(Hitung!$B$6:$U$1005,0,$A7),INDEX(Hitung!$B$6:$U$1005,0,H$4))-IF($A7=H$4,SUM(INDEX(Hitung!$B$6:$U$1005,0,$A7)),0))/(Hasil!$C$4-1)) -> 0 | I7: =IF(Hasil!$C$4<2,0,(SUMPRODUCT(INDEX(Hitung!$B$6:$U$1005,0,$A7),INDEX(Hitung!$B$6:$U$1005,0,I$4))-IF($A7=I$4,SUM(INDEX(Hitung!$B$6:$U$1005,0,$A7)),0))/(Hasil!$C$4-1)) -> 0 | J7: =IF(Hasil!$C$4<2,0,(SUMPRODUCT(INDEX(Hitung!$B$6:$U$1005,0,$A7),INDEX(Hitung!$B$6:$U$1005,0,J$4))-IF($A7=J$4,SUM(INDEX(Hitung!$B$6:$U$1005,0,$A7)),0))/(Hasil!$C$4-1)) -> 0 | ... V7: =IF(Hasil!$C$4<2,0,(SUMPRODUCT(INDEX(Hitung!$B$6:$U$1005,0,$A7),INDEX(Hitung!$B$6:$U$1005,0,V$4))-IF($A7=V$4,SUM(INDEX(Hitung!$B$6:$U$1005,0,$A7)),0))/(Hasil!$C$4-1)) -> 0 | W7: =SUM(C7:V7) -> 14
A8: 3 | B8: =IF(INDEX(Pengaturan!$B$8:$B$27,$A8)="","",INDEX(Pengaturan!$B$8:$B$27,$A8)) -> 3 | C8: =IF(Hasil!$C$4<2,0,(SUMPRODUCT(INDEX(Hitung!$B$6:$U$1005,0,$A8),INDEX(Hitung!$B$6:$U$1005,0,C$4))-IF($A8=C$4,SUM(INDEX(Hitung!$B$6:$U$1005,0,$A8)),0))/(Hasil!$C$4-1)) -> 1.3333333 | D8: =IF(Hasil!$C$4<2,0,(SUMPRODUCT(INDEX(Hitung!$B$6:$U$1005,0,$A8),INDEX(Hitung!$B$6:$U$1005,0,D$4))-IF($A8=D$4,SUM(INDEX(Hitung!$B$6:$U$1005,0,$A8)),0))/(Hasil!$C$4-1)) -> 2 | E8: =IF(Hasil!$C$4<2,0,(SUMPRODUCT(INDEX(Hitung!$B$6:$U$1005,0,$A8),INDEX(Hitung!$B$6:$U$1005,0,E$4))-IF($A8=E$4,SUM(INDEX(Hitung!$B$6:$U$1005,0,$A8)),0))/(Hasil!$C$4-1)) -> 3.3333333 | F8: =IF(Hasil!$C$4<2,0,(SUMPRODUCT(INDEX(Hitung!$B$6:$U$1005,0,$A8),INDEX(Hitung!$B$6:$U$1005,0,F$4))-IF($A8=F$4,SUM(INDEX(Hitung!$B$6:$U$1005,0,$A8)),0))/(Hasil!$C$4-1)) -> 4 | G8: =IF(Hasil!$C$4<2,0,(SUMPRODUCT(INDEX(Hitung!$B$6:$U$1005,0,$A8),INDEX(Hitung!$B$6:$U$1005,0,G$4))-IF($A8=G$4,SUM(INDEX(Hitung!$B$6:$U$1005,0,$A8)),0))/(Hasil!$C$4-1)) -> 1.3333333 | H8: =IF(Hasil!$C$4<2,0,(SUMPRODUCT(INDEX(Hitung!$B$6:$U$1005,0,$A8),INDEX(Hitung!$B$6:$U$1005,0,H$4))-IF($A8=H$4,SUM(INDEX(Hitung!$B$6:$U$1005,0,$A8)),0))/(Hasil!$C$4-1)) -> 0 | I8: =IF(Hasil!$C$4<2,0,(SUMPRODUCT(INDEX(Hitung!$B$6:$U$1005,0,$A8),INDEX(Hitung!$B$6:$U$1005,0,I$4))-IF($A8=I$4,SUM(INDEX(Hitung!$B$6:$U$1005,0,$A8)),0))/(Hasil!$C$4-1)) -> 0 | J8: =IF(Hasil!$C$4<2,0,(SUMPRODUCT(INDEX(Hitung!$B$6:$U$1005,0,$A8),INDEX(Hitung!$B$6:$U$1005,0,J$4))-IF($A8=J$4,SUM(INDEX(Hitung!$B$6:$U$1005,0,$A8)),0))/(Hasil!$C$4-1)) -> 0 | ... V8: =IF(Hasil!$C$4<2,0,(SUMPRODUCT(INDEX(Hitung!$B$6:$U$1005,0,$A8),INDEX(Hitung!$B$6:$U$1005,0,V$4))-IF($A8=V$4,SUM(INDEX(Hitung!$B$6:$U$1005,0,$A8)),0))/(Hasil!$C$4-1)) -> 0 | W8: =SUM(C8:V8) -> 12
A9: 4 | B9: =IF(INDEX(Pengaturan!$B$8:$B$27,$A9)="","",INDEX(Pengaturan!$B$8:$B$27,$A9)) -> 4 | C9: =IF(Hasil!$C$4<2,0,(SUMPRODUCT(INDEX(Hitung!$B$6:$U$1005,0,$A9),INDEX(Hitung!$B$6:$U$1005,0,C$4))-IF($A9=C$4,SUM(INDEX(Hitung!$B$6:$U$1005,0,$A9)),0))/(Hasil!$C$4-1)) -> 1 | D9: =IF(Hasil!$C$4<2,0,(SUMPRODUCT(INDEX(Hitung!$B$6:$U$1005,0,$A9),INDEX(Hitung!$B$6:$U$1005,0,D$4))-IF($A9=D$4,SUM(INDEX(Hitung!$B$6:$U$1005,0,$A9)),0))/(Hasil!$C$4-1)) -> 3 | E9: =IF(Hasil!$C$4<2,0,(SUMPRODUCT(INDEX(Hitung!$B$6:$U$1005,0,$A9),INDEX(Hitung!$B$6:$U$1005,0,E$4))-IF($A9=E$4,SUM(INDEX(Hitung!$B$6:$U$1005,0,$A9)),0))/(Hasil!$C$4-1)) -> 4 | F9: =IF(Hasil!$C$4<2,0,(SUMPRODUCT(INDEX(Hitung!$B$6:$U$1005,0,$A9),INDEX(Hitung!$B$6:$U$1005,0,F$4))-IF($A9=F$4,SUM(INDEX(Hitung!$B$6:$U$1005,0,$A9)),0))/(Hasil!$C$4-1)) -> 10 | G9: =IF(Hasil!$C$4<2,0,(SUMPRODUCT(INDEX(Hitung!$B$6:$U$1005,0,$A9),INDEX(Hitung!$B$6:$U$1005,0,G$4))-IF($A9=G$4,SUM(INDEX(Hitung!$B$6:$U$1005,0,$A9)),0))/(Hasil!$C$4-1)) -> 7 | H9: =IF(Hasil!$C$4<2,0,(SUMPRODUCT(INDEX(Hitung!$B$6:$U$1005,0,$A9),INDEX(Hitung!$B$6:$U$1005,0,H$4))-IF($A9=H$4,SUM(INDEX(Hitung!$B$6:$U$1005,0,$A9)),0))/(Hasil!$C$4-1)) -> 0 | I9: =IF(Hasil!$C$4<2,0,(SUMPRODUCT(INDEX(Hitung!$B$6:$U$1005,0,$A9),INDEX(Hitung!$B$6:$U$1005,0,I$4))-IF($A9=I$4,SUM(INDEX(Hitung!$B$6:$U$1005,0,$A9)),0))/(Hasil!$C$4-1)) -> 0 | J9: =IF(Hasil!$C$4<2,0,(SUMPRODUCT(INDEX(Hitung!$B$6:$U$1005,0,$A9),INDEX(Hitung!$B$6:$U$1005,0,J$4))-IF($A9=J$4,SUM(INDEX(Hitung!$B$6:$U$1005,0,$A9)),0))/(Hasil!$C$4-1)) -> 0 | ... V9: =IF(Hasil!$C$4<2,0,(SUMPRODUCT(INDEX(Hitung!$B$6:$U$1005,0,$A9),INDEX(Hitung!$B$6:$U$1005,0,V$4))-IF($A9=V$4,SUM(INDEX(Hitung!$B$6:$U$1005,0,$A9)),0))/(Hasil!$C$4-1)) -> 0 | W9: =SUM(C9:V9) -> 25
A10: 5 | B10: =IF(INDEX(Pengaturan!$B$8:$B$27,$A10)="","",INDEX(Pengaturan!$B$8:$B$27,$A10)) -> 5 | C10: =IF(Hasil!$C$4<2,0,(SUMPRODUCT(INDEX(Hitung!$B$6:$U$1005,0,$A10),INDEX(Hitung!$B$6:$U$1005,0,C$4))-IF($A10=C$4,SUM(INDEX(Hitung!$B$6:$U$1005,0,$A10)),0))/(Hasil!$C$4-1)) -> 0 | D10: =IF(Hasil!$C$4<2,0,(SUMPRODUCT(INDEX(Hitung!$B$6:$U$1005,0,$A10),INDEX(Hitung!$B$6:$U$1005,0,D$4))-IF($A10=D$4,SUM(INDEX(Hitung!$B$6:$U$1005,0,$A10)),0))/(Hasil!$C$4-1)) -> 0.66666667 | E10: =IF(Hasil!$C$4<2,0,(SUMPRODUCT(INDEX(Hitung!$B$6:$U$1005,0,$A10),INDEX(Hitung!$B$6:$U$1005,0,E$4))-IF($A10=E$4,SUM(INDEX(Hitung!$B$6:$U$1005,0,$A10)),0))/(Hasil!$C$4-1)) -> 1.3333333 | F10: =IF(Hasil!$C$4<2,0,(SUMPRODUCT(INDEX(Hitung!$B$6:$U$1005,0,$A10),INDEX(Hitung!$B$6:$U$1005,0,F$4))-IF($A10=F$4,SUM(INDEX(Hitung!$B$6:$U$1005,0,$A10)),0))/(Hasil!$C$4-1)) -> 7 | G10: =IF(Hasil!$C$4<2,0,(SUMPRODUCT(INDEX(Hitung!$B$6:$U$1005,0,$A10),INDEX(Hitung!$B$6:$U$1005,0,G$4))-IF($A10=G$4,SUM(INDEX(Hitung!$B$6:$U$1005,0,$A10)),0))/(Hasil!$C$4-1)) -> 18 | H10: =IF(Hasil!$C$4<2,0,(SUMPRODUCT(INDEX(Hitung!$B$6:$U$1005,0,$A10),INDEX(Hitung!$B$6:$U$1005,0,H$4))-IF($A10=H$4,SUM(INDEX(Hitung!$B$6:$U$1005,0,$A10)),0))/(Hasil!$C$4-1)) -> 0 | I10: =IF(Hasil!$C$4<2,0,(SUMPRODUCT(INDEX(Hitung!$B$6:$U$1005,0,$A10),INDEX(Hitung!$B$6:$U$1005,0,I$4))-IF($A10=I$4,SUM(INDEX(Hitung!$B$6:$U$1005,0,$A10)),0))/(Hasil!$C$4-1)) -> 0 | J10: =IF(Hasil!$C$4<2,0,(SUMPRODUCT(INDEX(Hitung!$B$6:$U$1005,0,$A10),INDEX(Hitung!$B$6:$U$1005,0,J$4))-IF($A10=J$4,SUM(INDEX(Hitung!$B$6:$U$1005,0,$A10)),0))/(Hasil!$C$4-1)) -> 0 | ... V10: =IF(Hasil!$C$4<2,0,(SUMPRODUCT(INDEX(Hitung!$B$6:$U$1005,0,$A10),INDEX(Hitung!$B$6:$U$1005,0,V$4))-IF($A10=V$4,SUM(INDEX(Hitung!$B$6:$U$1005,0,$A10)),0))/(Hasil!$C$4-1)) -> 0 | W10: =SUM(C10:V10) -> 27
A11: 6 | B11: =IF(INDEX(Pengaturan!$B$8:$B$27,$A11)="","",INDEX(Pengaturan!$B$8:$B$27,$A11)) | C11: =IF(Hasil!$C$4<2,0,(SUMPRODUCT(INDEX(Hitung!$B$6:$U$1005,0,$A11),INDEX(Hitung!$B$6:$U$1005,0,C$4))-IF($A11=C$4,SUM(INDEX(Hitung!$B$6:$U$1005,0,$A11)),0))/(Hasil!$C$4-1)) -> 0 | D11: =IF(Hasil!$C$4<2,0,(SUMPRODUCT(INDEX(Hitung!$B$6:$U$1005,0,$A11),INDEX(Hitung!$B$6:$U$1005,0,D$4))-IF($A11=D$4,SUM(INDEX(Hitung!$B$6:$U$1005,0,$A11)),0))/(Hasil!$C$4-1)) -> 0 | E11: =IF(Hasil!$C$4<2,0,(SUMPRODUCT(INDEX(Hitung!$B$6:$U$1005,0,$A11),INDEX(Hitung!$B$6:$U$1005,0,E$4))-IF($A11=E$4,SUM(INDEX(Hitung!$B$6:$U$1005,0,$A11)),0))/(Hasil!$C$4-1)) -> 0 | F11: =IF(Hasil!$C$4<2,0,(SUMPRODUCT(INDEX(Hitung!$B$6:$U$1005,0,$A11),INDEX(Hitung!$B$6:$U$1005,0,F$4))-IF($A11=F$4,SUM(INDEX(Hitung!$B$6:$U$1005,0,$A11)),0))/(Hasil!$C$4-1)) -> 0 | G11: =IF(Hasil!$C$4<2,0,(SUMPRODUCT(INDEX(Hitung!$B$6:$U$1005,0,$A11),INDEX(Hitung!$B$6:$U$1005,0,G$4))-IF($A11=G$4,SUM(INDEX(Hitung!$B$6:$U$1005,0,$A11)),0))/(Hasil!$C$4-1)) -> 0 | H11: =IF(Hasil!$C$4<2,0,(SUMPRODUCT(INDEX(Hitung!$B$6:$U$1005,0,$A11),INDEX(Hitung!$B$6:$U$1005,0,H$4))-IF($A11=H$4,SUM(INDEX(Hitung!$B$6:$U$1005,0,$A11)),0))/(Hasil!$C$4-1)) -> 0 | I11: =IF(Hasil!$C$4<2,0,(SUMPRODUCT(INDEX(Hitung!$B$6:$U$1005,0,$A11),INDEX(Hitung!$B$6:$U$1005,0,I$4))-IF($A11=I$4,SUM(INDEX(Hitung!$B$6:$U$1005,0,$A11)),0))/(Hasil!$C$4-1)) -> 0 | J11: =IF(Hasil!$C$4<2,0,(SUMPRODUCT(INDEX(Hitung!$B$6:$U$1005,0,$A11),INDEX(Hitung!$B$6:$U$1005,0,J$4))-IF($A11=J$4,SUM(INDEX(Hitung!$B$6:$U$1005,0,$A11)),0))/(Hasil!$C$4-1)) -> 0 | ... V11: =IF(Hasil!$C$4<2,0,(SUMPRODUCT(INDEX(Hitung!$B$6:$U$1005,0,$A11),INDEX(Hitung!$B$6:$U$1005,0,V$4))-IF($A11=V$4,SUM(INDEX(Hitung!$B$6:$U$1005,0,$A11)),0))/(Hasil!$C$4-1)) -> 0 | W11: =SUM(C11:V11) -> 0
A12: 7 | B12: =IF(INDEX(Pengaturan!$B$8:$B$27,$A12)="","",INDEX(Pengaturan!$B$8:$B$27,$A12)) | C12: =IF(Hasil!$C$4<2,0,(SUMPRODUCT(INDEX(Hitung!$B$6:$U$1005,0,$A12),INDEX(Hitung!$B$6:$U$1005,0,C$4))-IF($A12=C$4,SUM(INDEX(Hitung!$B$6:$U$1005,0,$A12)),0))/(Hasil!$C$4-1)) -> 0 | D12: =IF(Hasil!$C$4<2,0,(SUMPRODUCT(INDEX(Hitung!$B$6:$U$1005,0,$A12),INDEX(Hitung!$B$6:$U$1005,0,D$4))-IF($A12=D$4,SUM(INDEX(Hitung!$B$6:$U$1005,0,$A12)),0))/(Hasil!$C$4-1)) -> 0 | E12: =IF(Hasil!$C$4<2,0,(SUMPRODUCT(INDEX(Hitung!$B$6:$U$1005,0,$A12),INDEX(Hitung!$B$6:$U$1005,0,E$4))-IF($A12=E$4,SUM(INDEX(Hitung!$B$6:$U$1005,0,$A12)),0))/(Hasil!$C$4-1)) -> 0 | F12: =IF(Hasil!$C$4<2,0,(SUMPRODUCT(INDEX(Hitung!$B$6:$U$1005,0,$A12),INDEX(Hitung!$B$6:$U$1005,0,F$4))-IF($A12=F$4,SUM(INDEX(Hitung!$B$6:$U$1005,0,$A12)),0))/(Hasil!$C$4-1)) -> 0 | G12: =IF(Hasil!$C$4<2,0,(SUMPRODUCT(INDEX(Hitung!$B$6:$U$1005,0,$A12),INDEX(Hitung!$B$6:$U$1005,0,G$4))-IF($A12=G$4,SUM(INDEX(Hitung!$B$6:$U$1005,0,$A12)),0))/(Hasil!$C$4-1)) -> 0 | H12: =IF(Hasil!$C$4<2,0,(SUMPRODUCT(INDEX(Hitung!$B$6:$U$1005,0,$A12),INDEX(Hitung!$B$6:$U$1005,0,H$4))-IF($A12=H$4,SUM(INDEX(Hitung!$B$6:$U$1005,0,$A12)),0))/(Hasil!$C$4-1)) -> 0 | I12: =IF(Hasil!$C$4<2,0,(SUMPRODUCT(INDEX(Hitung!$B$6:$U$1005,0,$A12),INDEX(Hitung!$B$6:$U$1005,0,I$4))-IF($A12=I$4,SUM(INDEX(Hitung!$B$6:$U$1005,0,$A12)),0))/(Hasil!$C$4-1)) -> 0 | J12: =IF(Hasil!$C$4<2,0,(SUMPRODUCT(INDEX(Hitung!$B$6:$U$1005,0,$A12),INDEX(Hitung!$B$6:$U$1005,0,J$4))-IF($A12=J$4,SUM(INDEX(Hitung!$B$6:$U$1005,0,$A12)),0))/(Hasil!$C$4-1)) -> 0 | ... V12: =IF(Hasil!$C$4<2,0,(SUMPRODUCT(INDEX(Hitung!$B$6:$U$1005,0,$A12),INDEX(Hitung!$B$6:$U$1005,0,V$4))-IF($A12=V$4,SUM(INDEX(Hitung!$B$6:$U$1005,0,$A12)),0))/(Hasil!$C$4-1)) -> 0 | W12: =SUM(C12:V12) -> 0
A13: 8 | B13: =IF(INDEX(Pengaturan!$B$8:$B$27,$A13)="","",INDEX(Pengaturan!$B$8:$B$27,$A13)) | C13: =IF(Hasil!$C$4<2,0,(SUMPRODUCT(INDEX(Hitung!$B$6:$U$1005,0,$A13),INDEX(Hitung!$B$6:$U$1005,0,C$4))-IF($A13=C$4,SUM(INDEX(Hitung!$B$6:$U$1005,0,$A13)),0))/(Hasil!$C$4-1)) -> 0 | D13: =IF(Hasil!$C$4<2,0,(SUMPRODUCT(INDEX(Hitung!$B$6:$U$1005,0,$A13),INDEX(Hitung!$B$6:$U$1005,0,D$4))-IF($A13=D$4,SUM(INDEX(Hitung!$B$6:$U$1005,0,$A13)),0))/(Hasil!$C$4-1)) -> 0 | E13: =IF(Hasil!$C$4<2,0,(SUMPRODUCT(INDEX(Hitung!$B$6:$U$1005,0,$A13),INDEX(Hitung!$B$6:$U$1005,0,E$4))-IF($A13=E$4,SUM(INDEX(Hitung!$B$6:$U$1005,0,$A13)),0))/(Hasil!$C$4-1)) -> 0 | F13: =IF(Hasil!$C$4<2,0,(SUMPRODUCT(INDEX(Hitung!$B$6:$U$1005,0,$A13),INDEX(Hitung!$B$6:$U$1005,0,F$4))-IF($A13=F$4,SUM(INDEX(Hitung!$B$6:$U$1005,0,$A13)),0))/(Hasil!$C$4-1)) -> 0 | G13: =IF(Hasil!$C$4<2,0,(SUMPRODUCT(INDEX(Hitung!$B$6:$U$1005,0,$A13),INDEX(Hitung!$B$6:$U$1005,0,G$4))-IF($A13=G$4,SUM(INDEX(Hitung!$B$6:$U$1005,0,$A13)),0))/(Hasil!$C$4-1)) -> 0 | H13: =IF(Hasil!$C$4<2,0,(SUMPRODUCT(INDEX(Hitung!$B$6:$U$1005,0,$A13),INDEX(Hitung!$B$6:$U$1005,0,H$4))-IF($A13=H$4,SUM(INDEX(Hitung!$B$6:$U$1005,0,$A13)),0))/(Hasil!$C$4-1)) -> 0 | I13: =IF(Hasil!$C$4<2,0,(SUMPRODUCT(INDEX(Hitung!$B$6:$U$1005,0,$A13),INDEX(Hitung!$B$6:$U$1005,0,I$4))-IF($A13=I$4,SUM(INDEX(Hitung!$B$6:$U$1005,0,$A13)),0))/(Hasil!$C$4-1)) -> 0 | J13: =IF(Hasil!$C$4<2,0,(SUMPRODUCT(INDEX(Hitung!$B$6:$U$1005,0,$A13),INDEX(Hitung!$B$6:$U$1005,0,J$4))-IF($A13=J$4,SUM(INDEX(Hitung!$B$6:$U$1005,0,$A13)),0))/(Hasil!$C$4-1)) -> 0 | ... V13: =IF(Hasil!$C$4<2,0,(SUMPRODUCT(INDEX(Hitung!$B$6:$U$1005,0,$A13),INDEX(Hitung!$B$6:$U$1005,0,V$4))-IF($A13=V$4,SUM(INDEX(Hitung!$B$6:$U$1005,0,$A13)),0))/(Hasil!$C$4-1)) -> 0 | W13: =SUM(C13:V13) -> 0
A14: 9 | B14: =IF(INDEX(Pengaturan!$B$8:$B$27,$A14)="","",INDEX(Pengaturan!$B$8:$B$27,$A14)) | C14: =IF(Hasil!$C$4<2,0,(SUMPRODUCT(INDEX(Hitung!$B$6:$U$1005,0,$A14),INDEX(Hitung!$B$6:$U$1005,0,C$4))-IF($A14=C$4,SUM(INDEX(Hitung!$B$6:$U$1005,0,$A14)),0))/(Hasil!$C$4-1)) -> 0 | D14: =IF(Hasil!$C$4<2,0,(SUMPRODUCT(INDEX(Hitung!$B$6:$U$1005,0,$A14),INDEX(Hitung!$B$6:$U$1005,0,D$4))-IF($A14=D$4,SUM(INDEX(Hitung!$B$6:$U$1005,0,$A14)),0))/(Hasil!$C$4-1)) -> 0 | E14: =IF(Hasil!$C$4<2,0,(SUMPRODUCT(INDEX(Hitung!$B$6:$U$1005,0,$A14),INDEX(Hitung!$B$6:$U$1005,0,E$4))-IF($A14=E$4,SUM(INDEX(Hitung!$B$6:$U$1005,0,$A14)),0))/(Hasil!$C$4-1)) -> 0 | F14: =IF(Hasil!$C$4<2,0,(SUMPRODUCT(INDEX(Hitung!$B$6:$U$1005,0,$A14),INDEX(Hitung!$B$6:$U$1005,0,F$4))-IF($A14=F$4,SUM(INDEX(Hitung!$B$6:$U$1005,0,$A14)),0))/(Hasil!$C$4-1)) -> 0 | G14: =IF(Hasil!$C$4<2,0,(SUMPRODUCT(INDEX(Hitung!$B$6:$U$1005,0,$A14),INDEX(Hitung!$B$6:$U$1005,0,G$4))-IF($A14=G$4,SUM(INDEX(Hitung!$B$6:$U$1005,0,$A14)),0))/(Hasil!$C$4-1)) -> 0 | H14: =IF(Hasil!$C$4<2,0,(SUMPRODUCT(INDEX(Hitung!$B$6:$U$1005,0,$A14),INDEX(Hitung!$B$6:$U$1005,0,H$4))-IF($A14=H$4,SUM(INDEX(Hitung!$B$6:$U$1005,0,$A14)),0))/(Hasil!$C$4-1)) -> 0 | I14: =IF(Hasil!$C$4<2,0,(SUMPRODUCT(INDEX(Hitung!$B$6:$U$1005,0,$A14),INDEX(Hitung!$B$6:$U$1005,0,I$4))-IF($A14=I$4,SUM(INDEX(Hitung!$B$6:$U$1005,0,$A14)),0))/(Hasil!$C$4-1)) -> 0 | J14: =IF(Hasil!$C$4<2,0,(SUMPRODUCT(INDEX(Hitung!$B$6:$U$1005,0,$A14),INDEX(Hitung!$B$6:$U$1005,0,J$4))-IF($A14=J$4,SUM(INDEX(Hitung!$B$6:$U$1005,0,$A14)),0))/(Hasil!$C$4-1)) -> 0 | ... V14: =IF(Hasil!$C$4<2,0,(SUMPRODUCT(INDEX(Hitung!$B$6:$U$1005,0,$A14),INDEX(Hitung!$B$6:$U$1005,0,V$4))-IF($A14=V$4,SUM(INDEX(Hitung!$B$6:$U$1005,0,$A14)),0))/(Hasil!$C$4-1)) -> 0 | W14: =SUM(C14:V14) -> 0
A15: 10 | B15: =IF(INDEX(Pengaturan!$B$8:$B$27,$A15)="","",INDEX(Pengaturan!$B$8:$B$27,$A15)) | C15: =IF(Hasil!$C$4<2,0,(SUMPRODUCT(INDEX(Hitung!$B$6:$U$1005,0,$A15),INDEX(Hitung!$B$6:$U$1005,0,C$4))-IF($A15=C$4,SUM(INDEX(Hitung!$B$6:$U$1005,0,$A15)),0))/(Hasil!$C$4-1)) -> 0 | D15: =IF(Hasil!$C$4<2,0,(SUMPRODUCT(INDEX(Hitung!$B$6:$U$1005,0,$A15),INDEX(Hitung!$B$6:$U$1005,0,D$4))-IF($A15=D$4,SUM(INDEX(Hitung!$B$6:$U$1005,0,$A15)),0))/(Hasil!$C$4-1)) -> 0 | E15: =IF(Hasil!$C$4<2,0,(SUMPRODUCT(INDEX(Hitung!$B$6:$U$1005,0,$A15),INDEX(Hitung!$B$6:$U$1005,0,E$4))-IF($A15=E$4,SUM(INDEX(Hitung!$B$6:$U$1005,0,$A15)),0))/(Hasil!$C$4-1)) -> 0 | F15: =IF(Hasil!$C$4<2,0,(SUMPRODUCT(INDEX(Hitung!$B$6:$U$1005,0,$A15),INDEX(Hitung!$B$6:$U$1005,0,F$4))-IF($A15=F$4,SUM(INDEX(Hitung!$B$6:$U$1005,0,$A15)),0))/(Hasil!$C$4-1)) -> 0 | G15: =IF(Hasil!$C$4<2,0,(SUMPRODUCT(INDEX(Hitung!$B$6:$U$1005,0,$A15),INDEX(Hitung!$B$6:$U$1005,0,G$4))-IF($A15=G$4,SUM(INDEX(Hitung!$B$6:$U$1005,0,$A15)),0))/(Hasil!$C$4-1)) -> 0 | H15: =IF(Hasil!$C$4<2,0,(SUMPRODUCT(INDEX(Hitung!$B$6:$U$1005,0,$A15),INDEX(Hitung!$B$6:$U$1005,0,H$4))-IF($A15=H$4,SUM(INDEX(Hitung!$B$6:$U$1005,0,$A15)),0))/(Hasil!$C$4-1)) -> 0 | I15: =IF(Hasil!$C$4<2,0,(SUMPRODUCT(INDEX(Hitung!$B$6:$U$1005,0,$A15),INDEX(Hitung!$B$6:$U$1005,0,I$4))-IF($A15=I$4,SUM(INDEX(Hitung!$B$6:$U$1005,0,$A15)),0))/(Hasil!$C$4-1)) -> 0 | J15: =IF(Hasil!$C$4<2,0,(SUMPRODUCT(INDEX(Hitung!$B$6:$U$1005,0,$A15),INDEX(Hitung!$B$6:$U$1005,0,J$4))-IF($A15=J$4,SUM(INDEX(Hitung!$B$6:$U$1005,0,$A15)),0))/(Hasil!$C$4-1)) -> 0 | ... V15: =IF(Hasil!$C$4<2,0,(SUMPRODUCT(INDEX(Hitung!$B$6:$U$1005,0,$A15),INDEX(Hitung!$B$6:$U$1005,0,V$4))-IF($A15=V$4,SUM(INDEX(Hitung!$B$6:$U$1005,0,$A15)),0))/(Hasil!$C$4-1)) -> 0 | W15: =SUM(C15:V15) -> 0
A16: 11 | B16: =IF(INDEX(Pengaturan!$B$8:$B$27,$A16)="","",INDEX(Pengaturan!$B$8:$B$27,$A16)) | C16: =IF(Hasil!$C$4<2,0,(SUMPRODUCT(INDEX(Hitung!$B$6:$U$1005,0,$A16),INDEX(Hitung!$B$6:$U$1005,0,C$4))-IF($A16=C$4,SUM(INDEX(Hitung!$B$6:$U$1005,0,$A16)),0))/(Hasil!$C$4-1)) -> 0 | D16: =IF(Hasil!$C$4<2,0,(SUMPRODUCT(INDEX(Hitung!$B$6:$U$1005,0,$A16),INDEX(Hitung!$B$6:$U$1005,0,D$4))-IF($A16=D$4,SUM(INDEX(Hitung!$B$6:$U$1005,0,$A16)),0))/(Hasil!$C$4-1)) -> 0 | E16: =IF(Hasil!$C$4<2,0,(SUMPRODUCT(INDEX(Hitung!$B$6:$U$1005,0,$A16),INDEX(Hitung!$B$6:$U$1005,0,E$4))-IF($A16=E$4,SUM(INDEX(Hitung!$B$6:$U$1005,0,$A16)),0))/(Hasil!$C$4-1)) -> 0 | F16: =IF(Hasil!$C$4<2,0,(SUMPRODUCT(INDEX(Hitung!$B$6:$U$1005,0,$A16),INDEX(Hitung!$B$6:$U$1005,0,F$4))-IF($A16=F$4,SUM(INDEX(Hitung!$B$6:$U$1005,0,$A16)),0))/(Hasil!$C$4-1)) -> 0 | G16: =IF(Hasil!$C$4<2,0,(SUMPRODUCT(INDEX(Hitung!$B$6:$U$1005,0,$A16),INDEX(Hitung!$B$6:$U$1005,0,G$4))-IF($A16=G$4,SUM(INDEX(Hitung!$B$6:$U$1005,0,$A16)),0))/(Hasil!$C$4-1)) -> 0 | H16: =IF(Hasil!$C$4<2,0,(SUMPRODUCT(INDEX(Hitung!$B$6:$U$1005,0,$A16),INDEX(Hitung!$B$6:$U$1005,0,H$4))-IF($A16=H$4,SUM(INDEX(Hitung!$B$6:$U$1005,0,$A16)),0))/(Hasil!$C$4-1)) -> 0 | I16: =IF(Hasil!$C$4<2,0,(SUMPRODUCT(INDEX(Hitung!$B$6:$U$1005,0,$A16),INDEX(Hitung!$B$6:$U$1005,0,I$4))-IF($A16=I$4,SUM(INDEX(Hitung!$B$6:$U$1005,0,$A16)),0))/(Hasil!$C$4-1)) -> 0 | J16: =IF(Hasil!$C$4<2,0,(SUMPRODUCT(INDEX(Hitung!$B$6:$U$1005,0,$A16),INDEX(Hitung!$B$6:$U$1005,0,J$4))-IF($A16=J$4,SUM(INDEX(Hitung!$B$6:$U$1005,0,$A16)),0))/(Hasil!$C$4-1)) -> 0 | ... V16: =IF(Hasil!$C$4<2,0,(SUMPRODUCT(INDEX(Hitung!$B$6:$U$1005,0,$A16),INDEX(Hitung!$B$6:$U$1005,0,V$4))-IF($A16=V$4,SUM(INDEX(Hitung!$B$6:$U$1005,0,$A16)),0))/(Hasil!$C$4-1)) -> 0 | W16: =SUM(C16:V16) -> 0
A17: 12 | B17: =IF(INDEX(Pengaturan!$B$8:$B$27,$A17)="","",INDEX(Pengaturan!$B$8:$B$27,$A17)) | C17: =IF(Hasil!$C$4<2,0,(SUMPRODUCT(INDEX(Hitung!$B$6:$U$1005,0,$A17),INDEX(Hitung!$B$6:$U$1005,0,C$4))-IF($A17=C$4,SUM(INDEX(Hitung!$B$6:$U$1005,0,$A17)),0))/(Hasil!$C$4-1)) -> 0 | D17: =IF(Hasil!$C$4<2,0,(SUMPRODUCT(INDEX(Hitung!$B$6:$U$1005,0,$A17),INDEX(Hitung!$B$6:$U$1005,0,D$4))-IF($A17=D$4,SUM(INDEX(Hitung!$B$6:$U$1005,0,$A17)),0))/(Hasil!$C$4-1)) -> 0 | E17: =IF(Hasil!$C$4<2,0,(SUMPRODUCT(INDEX(Hitung!$B$6:$U$1005,0,$A17),INDEX(Hitung!$B$6:$U$1005,0,E$4))-IF($A17=E$4,SUM(INDEX(Hitung!$B$6:$U$1005,0,$A17)),0))/(Hasil!$C$4-1)) -> 0 | F17: =IF(Hasil!$C$4<2,0,(SUMPRODUCT(INDEX(Hitung!$B$6:$U$1005,0,$A17),INDEX(Hitung!$B$6:$U$1005,0,F$4))-IF($A17=F$4,SUM(INDEX(Hitung!$B$6:$U$1005,0,$A17)),0))/(Hasil!$C$4-1)) -> 0 | G17: =IF(Hasil!$C$4<2,0,(SUMPRODUCT(INDEX(Hitung!$B$6:$U$1005,0,$A17),INDEX(Hitung!$B$6:$U$1005,0,G$4))-IF($A17=G$4,SUM(INDEX(Hitung!$B$6:$U$1005,0,$A17)),0))/(Hasil!$C$4-1)) -> 0 | H17: =IF(Hasil!$C$4<2,0,(SUMPRODUCT(INDEX(Hitung!$B$6:$U$1005,0,$A17),INDEX(Hitung!$B$6:$U$1005,0,H$4))-IF($A17=H$4,SUM(INDEX(Hitung!$B$6:$U$1005,0,$A17)),0))/(Hasil!$C$4-1)) -> 0 | I17: =IF(Hasil!$C$4<2,0,(SUMPRODUCT(INDEX(Hitung!$B$6:$U$1005,0,$A17),INDEX(Hitung!$B$6:$U$1005,0,I$4))-IF($A17=I$4,SUM(INDEX(Hitung!$B$6:$U$1005,0,$A17)),0))/(Hasil!$C$4-1)) -> 0 | J17: =IF(Hasil!$C$4<2,0,(SUMPRODUCT(INDEX(Hitung!$B$6:$U$1005,0,$A17),INDEX(Hitung!$B$6:$U$1005,0,J$4))-IF($A17=J$4,SUM(INDEX(Hitung!$B$6:$U$1005,0,$A17)),0))/(Hasil!$C$4-1)) -> 0 | ... V17: =IF(Hasil!$C$4<2,0,(SUMPRODUCT(INDEX(Hitung!$B$6:$U$1005,0,$A17),INDEX(Hitung!$B$6:$U$1005,0,V$4))-IF($A17=V$4,SUM(INDEX(Hitung!$B$6:$U$1005,0,$A17)),0))/(Hasil!$C$4-1)) -> 0 | W17: =SUM(C17:V17) -> 0
... A25: 20 | B25: =IF(INDEX(Pengaturan!$B$8:$B$27,$A25)="","",INDEX(Pengaturan!$B$8:$B$27,$A25)) | C25: =IF(Hasil!$C$4<2,0,(SUMPRODUCT(INDEX(Hitung!$B$6:$U$1005,0,$A25),INDEX(Hitung!$B$6:$U$1005,0,C$4))-IF($A25=C$4,SUM(INDEX(Hitung!$B$6:$U$1005,0,$A25)),0))/(Hasil!$C$4-1)) -> 0 | D25: =IF(Hasil!$C$4<2,0,(SUMPRODUCT(INDEX(Hitung!$B$6:$U$1005,0,$A25),INDEX(Hitung!$B$6:$U$1005,0,D$4))-IF($A25=D$4,SUM(INDEX(Hitung!$B$6:$U$1005,0,$A25)),0))/(Hasil!$C$4-1)) -> 0 | E25: =IF(Hasil!$C$4<2,0,(SUMPRODUCT(INDEX(Hitung!$B$6:$U$1005,0,$A25),INDEX(Hitung!$B$6:$U$1005,0,E$4))-IF($A25=E$4,SUM(INDEX(Hitung!$B$6:$U$1005,0,$A25)),0))/(Hasil!$C$4-1)) -> 0 | F25: =IF(Hasil!$C$4<2,0,(SUMPRODUCT(INDEX(Hitung!$B$6:$U$1005,0,$A25),INDEX(Hitung!$B$6:$U$1005,0,F$4))-IF($A25=F$4,SUM(INDEX(Hitung!$B$6:$U$1005,0,$A25)),0))/(Hasil!$C$4-1)) -> 0 | G25: =IF(Hasil!$C$4<2,0,(SUMPRODUCT(INDEX(Hitung!$B$6:$U$1005,0,$A25),INDEX(Hitung!$B$6:$U$1005,0,G$4))-IF($A25=G$4,SUM(INDEX(Hitung!$B$6:$U$1005,0,$A25)),0))/(Hasil!$C$4-1)) -> 0 | H25: =IF(Hasil!$C$4<2,0,(SUMPRODUCT(INDEX(Hitung!$B$6:$U$1005,0,$A25),INDEX(Hitung!$B$6:$U$1005,0,H$4))-IF($A25=H$4,SUM(INDEX(Hitung!$B$6:$U$1005,0,$A25)),0))/(Hasil!$C$4-1)) -> 0 | I25: =IF(Hasil!$C$4<2,0,(SUMPRODUCT(INDEX(Hitung!$B$6:$U$1005,0,$A25),INDEX(Hitung!$B$6:$U$1005,0,I$4))-IF($A25=I$4,SUM(INDEX(Hitung!$B$6:$U$1005,0,$A25)),0))/(Hasil!$C$4-1)) -> 0 | J25: =IF(Hasil!$C$4<2,0,(SUMPRODUCT(INDEX(Hitung!$B$6:$U$1005,0,$A25),INDEX(Hitung!$B$6:$U$1005,0,J$4))-IF($A25=J$4,SUM(INDEX(Hitung!$B$6:$U$1005,0,$A25)),0))/(Hasil!$C$4-1)) -> 0 | ... V25: =IF(Hasil!$C$4<2,0,(SUMPRODUCT(INDEX(Hitung!$B$6:$U$1005,0,$A25),INDEX(Hitung!$B$6:$U$1005,0,V$4))-IF($A25=V$4,SUM(INDEX(Hitung!$B$6:$U$1005,0,$A25)),0))/(Hasil!$C$4-1)) -> 0 | W25: =SUM(C25:V25) -> 0
B26: Total (n) | W26: =SUM(W6:W25) -> 100
A28: 2) Matriks koincidensi harapan (e_ck)
B29: indeks | C29: 1 | D29: 2 | E29: 3 | F29: 4 | G29: 5 | H29: 6 | I29: 7 | J29: 8 | K29: 9 | L29: 10 | M29: 11 | N29: 12 | O29: 13 | P29: 14 | Q29: 15 | R29: 16 | S29: 17 | T29: 18 | U29: 19 | V29: 20
A30: i | B30: Kategori | C30: =IF(INDEX(Pengaturan!$B$8:$B$27,C$29)="","",INDEX(Pengaturan!$B$8:$B$27,C$29)) -> 1 | D30: =IF(INDEX(Pengaturan!$B$8:$B$27,D$29)="","",INDEX(Pengaturan!$B$8:$B$27,D$29)) -> 2 | E30: =IF(INDEX(Pengaturan!$B$8:$B$27,E$29)="","",INDEX(Pengaturan!$B$8:$B$27,E$29)) -> 3 | F30: =IF(INDEX(Pengaturan!$B$8:$B$27,F$29)="","",INDEX(Pengaturan!$B$8:$B$27,F$29)) -> 4 | G30: =IF(INDEX(Pengaturan!$B$8:$B$27,G$29)="","",INDEX(Pengaturan!$B$8:$B$27,G$29)) -> 5 | H30: =IF(INDEX(Pengaturan!$B$8:$B$27,H$29)="","",INDEX(Pengaturan!$B$8:$B$27,H$29)) | I30: =IF(INDEX(Pengaturan!$B$8:$B$27,I$29)="","",INDEX(Pengaturan!$B$8:$B$27,I$29)) | J30: =IF(INDEX(Pengaturan!$B$8:$B$27,J$29)="","",INDEX(Pengaturan!$B$8:$B$27,J$29)) | ... V30: =IF(INDEX(Pengaturan!$B$8:$B$27,V$29)="","",INDEX(Pengaturan!$B$8:$B$27,V$29))
A31: 1 | B31: =IF(INDEX(Pengaturan!$B$8:$B$27,$A31)="","",INDEX(Pengaturan!$B$8:$B$27,$A31)) -> 1 | C31: =IF(Hasil!$C$6<2,0,IF($A31=C$29,INDEX($W$6:$W$25,$A31)*(INDEX($W$6:$W$25,$A31)-1),INDEX($W$6:$W$25,$A31)*INDEX($W$6:$W$25,C$29))/(Hasil!$C$6-1)) -> 4.6666667 | D31: =IF(Hasil!$C$6<2,0,IF($A31=D$29,INDEX($W$6:$W$25,$A31)*(INDEX($W$6:$W$25,$A31)-1),INDEX($W$6:$W$25,$A31)*INDEX($W$6:$W$25,D$29))/(Hasil!$C$6-1)) -> 3.1111111 | E31: =IF(Hasil!$C$6<2,0,IF($A31=E$29,INDEX($W$6:$W$25,$A31)*(INDEX($W$6:$W$25,$A31)-1),INDEX($W$6:$W$25,$A31)*INDEX($W$6:$W$25,E$29))/(Hasil!$C$6-1)) -> 2.6666667 | F31: =IF(Hasil!$C$6<2,0,IF($A31=F$29,INDEX($W$6:$W$25,$A31)*(INDEX($W$6:$W$25,$A31)-1),INDEX($W$6:$W$25,$A31)*INDEX($W$6:$W$25,F$29))/(Hasil!$C$6-1)) -> 5.5555556 | G31: =IF(Hasil!$C$6<2,0,IF($A31=G$29,INDEX($W$6:$W$25,$A31)*(INDEX($W$6:$W$25,$A31)-1),INDEX($W$6:$W$25,$A31)*INDEX($W$6:$W$25,G$29))/(Hasil!$C$6-1)) -> 6 | H31: =IF(Hasil!$C$6<2,0,IF($A31=H$29,INDEX($W$6:$W$25,$A31)*(INDEX($W$6:$W$25,$A31)-1),INDEX($W$6:$W$25,$A31)*INDEX($W$6:$W$25,H$29))/(Hasil!$C$6-1)) -> 0 | I31: =IF(Hasil!$C$6<2,0,IF($A31=I$29,INDEX($W$6:$W$25,$A31)*(INDEX($W$6:$W$25,$A31)-1),INDEX($W$6:$W$25,$A31)*INDEX($W$6:$W$25,I$29))/(Hasil!$C$6-1)) -> 0 | J31: =IF(Hasil!$C$6<2,0,IF($A31=J$29,INDEX($W$6:$W$25,$A31)*(INDEX($W$6:$W$25,$A31)-1),INDEX($W$6:$W$25,$A31)*INDEX($W$6:$W$25,J$29))/(Hasil!$C$6-1)) -> 0 | ... V31: =IF(Hasil!$C$6<2,0,IF($A31=V$29,INDEX($W$6:$W$25,$A31)*(INDEX($W$6:$W$25,$A31)-1),INDEX($W$6:$W$25,$A31)*INDEX($W$6:$W$25,V$29))/(Hasil!$C$6-1)) -> 0
A32: 2 | B32: =IF(INDEX(Pengaturan!$B$8:$B$27,$A32)="","",INDEX(Pengaturan!$B$8:$B$27,$A32)) -> 2 | C32: =IF(Hasil!$C$6<2,0,IF($A32=C$29,INDEX($W$6:$W$25,$A32)*(INDEX($W$6:$W$25,$A32)-1),INDEX($W$6:$W$25,$A32)*INDEX($W$6:$W$25,C$29))/(Hasil!$C$6-1)) -> 3.1111111 | D32: =IF(Hasil!$C$6<2,0,IF($A32=D$29,INDEX($W$6:$W$25,$A32)*(INDEX($W$6:$W$25,$A32)-1),INDEX($W$6:$W$25,$A32)*INDEX($W$6:$W$25,D$29))/(Hasil!$C$6-1)) -> 1.8383838 | E32: =IF(Hasil!$C$6<2,0,IF($A32=E$29,INDEX($W$6:$W$25,$A32)*(INDEX($W$6:$W$25,$A32)-1),INDEX($W$6:$W$25,$A32)*INDEX($W$6:$W$25,E$29))/(Hasil!$C$6-1)) -> 1.6969697 | F32: =IF(Hasil!$C$6<2,0,IF($A32=F$29,INDEX($W$6:$W$25,$A32)*(INDEX($W$6:$W$25,$A32)-1),INDEX($W$6:$W$25,$A32)*INDEX($W$6:$W$25,F$29))/(Hasil!$C$6-1)) -> 3.5353535 | G32: =IF(Hasil!$C$6<2,0,IF($A32=G$29,INDEX($W$6:$W$25,$A32)*(INDEX($W$6:$W$25,$A32)-1),INDEX($W$6:$W$25,$A32)*INDEX($W$6:$W$25,G$29))/(Hasil!$C$6-1)) -> 3.8181818 | H32: =IF(Hasil!$C$6<2,0,IF($A32=H$29,INDEX($W$6:$W$25,$A32)*(INDEX($W$6:$W$25,$A32)-1),INDEX($W$6:$W$25,$A32)*INDEX($W$6:$W$25,H$29))/(Hasil!$C$6-1)) -> 0 | I32: =IF(Hasil!$C$6<2,0,IF($A32=I$29,INDEX($W$6:$W$25,$A32)*(INDEX($W$6:$W$25,$A32)-1),INDEX($W$6:$W$25,$A32)*INDEX($W$6:$W$25,I$29))/(Hasil!$C$6-1)) -> 0 | J32: =IF(Hasil!$C$6<2,0,IF($A32=J$29,INDEX($W$6:$W$25,$A32)*(INDEX($W$6:$W$25,$A32)-1),INDEX($W$6:$W$25,$A32)*INDEX($W$6:$W$25,J$29))/(Hasil!$C$6-1)) -> 0 | ... V32: =IF(Hasil!$C$6<2,0,IF($A32=V$29,INDEX($W$6:$W$25,$A32)*(INDEX($W$6:$W$25,$A32)-1),INDEX($W$6:$W$25,$A32)*INDEX($W$6:$W$25,V$29))/(Hasil!$C$6-1)) -> 0
A33: 3 | B33: =IF(INDEX(Pengaturan!$B$8:$B$27,$A33)="","",INDEX(Pengaturan!$B$8:$B$27,$A33)) -> 3 | C33: =IF(Hasil!$C$6<2,0,IF($A33=C$29,INDEX($W$6:$W$25,$A33)*(INDEX($W$6:$W$25,$A33)-1),INDEX($W$6:$W$25,$A33)*INDEX($W$6:$W$25,C$29))/(Hasil!$C$6-1)) -> 2.6666667 | D33: =IF(Hasil!$C$6<2,0,IF($A33=D$29,INDEX($W$6:$W$25,$A33)*(INDEX($W$6:$W$25,$A33)-1),INDEX($W$6:$W$25,$A33)*INDEX($W$6:$W$25,D$29))/(Hasil!$C$6-1)) -> 1.6969697 | E33: =IF(Hasil!$C$6<2,0,IF($A33=E$29,INDEX($W$6:$W$25,$A33)*(INDEX($W$6:$W$25,$A33)-1),INDEX($W$6:$W$25,$A33)*INDEX($W$6:$W$25,E$29))/(Hasil!$C$6-1)) -> 1.3333333 | F33: =IF(Hasil!$C$6<2,0,IF($A33=F$29,INDEX($W$6:$W$25,$A33)*(INDEX($W$6:$W$25,$A33)-1),INDEX($W$6:$W$25,$A33)*INDEX($W$6:$W$25,F$29))/(Hasil!$C$6-1)) -> 3.030303 | G33: =IF(Hasil!$C$6<2,0,IF($A33=G$29,INDEX($W$6:$W$25,$A33)*(INDEX($W$6:$W$25,$A33)-1),INDEX($W$6:$W$25,$A33)*INDEX($W$6:$W$25,G$29))/(Hasil!$C$6-1)) -> 3.2727273 | H33: =IF(Hasil!$C$6<2,0,IF($A33=H$29,INDEX($W$6:$W$25,$A33)*(INDEX($W$6:$W$25,$A33)-1),INDEX($W$6:$W$25,$A33)*INDEX($W$6:$W$25,H$29))/(Hasil!$C$6-1)) -> 0 | I33: =IF(Hasil!$C$6<2,0,IF($A33=I$29,INDEX($W$6:$W$25,$A33)*(INDEX($W$6:$W$25,$A33)-1),INDEX($W$6:$W$25,$A33)*INDEX($W$6:$W$25,I$29))/(Hasil!$C$6-1)) -> 0 | J33: =IF(Hasil!$C$6<2,0,IF($A33=J$29,INDEX($W$6:$W$25,$A33)*(INDEX($W$6:$W$25,$A33)-1),INDEX($W$6:$W$25,$A33)*INDEX($W$6:$W$25,J$29))/(Hasil!$C$6-1)) -> 0 | ... V33: =IF(Hasil!$C$6<2,0,IF($A33=V$29,INDEX($W$6:$W$25,$A33)*(INDEX($W$6:$W$25,$A33)-1),INDEX($W$6:$W$25,$A33)*INDEX($W$6:$W$25,V$29))/(Hasil!$C$6-1)) -> 0
A34: 4 | B34: =IF(INDEX(Pengaturan!$B$8:$B$27,$A34)="","",INDEX(Pengaturan!$B$8:$B$27,$A34)) -> 4 | C34: =IF(Hasil!$C$6<2,0,IF($A34=C$29,INDEX($W$6:$W$25,$A34)*(INDEX($W$6:$W$25,$A34)-1),INDEX($W$6:$W$25,$A34)*INDEX($W$6:$W$25,C$29))/(Hasil!$C$6-1)) -> 5.5555556 | D34: =IF(Hasil!$C$6<2,0,IF($A34=D$29,INDEX($W$6:$W$25,$A34)*(INDEX($W$6:$W$25,$A34)-1),INDEX($W$6:$W$25,$A34)*INDEX($W$6:$W$25,D$29))/(Hasil!$C$6-1)) -> 3.5353535 | E34: =IF(Hasil!$C$6<2,0,IF($A34=E$29,INDEX($W$6:$W$25,$A34)*(INDEX($W$6:$W$25,$A34)-1),INDEX($W$6:$W$25,$A34)*INDEX($W$6:$W$25,E$29))/(Hasil!$C$6-1)) -> 3.030303 | F34: =IF(Hasil!$C$6<2,0,IF($A34=F$29,INDEX($W$6:$W$25,$A34)*(INDEX($W$6:$W$25,$A34)-1),INDEX($W$6:$W$25,$A34)*INDEX($W$6:$W$25,F$29))/(Hasil!$C$6-1)) -> 6.0606061 | G34: =IF(Hasil!$C$6<2,0,IF($A34=G$29,INDEX($W$6:$W$25,$A34)*(INDEX($W$6:$W$25,$A34)-1),INDEX($W$6:$W$25,$A34)*INDEX($W$6:$W$25,G$29))/(Hasil!$C$6-1)) -> 6.8181818 | H34: =IF(Hasil!$C$6<2,0,IF($A34=H$29,INDEX($W$6:$W$25,$A34)*(INDEX($W$6:$W$25,$A34)-1),INDEX($W$6:$W$25,$A34)*INDEX($W$6:$W$25,H$29))/(Hasil!$C$6-1)) -> 0 | I34: =IF(Hasil!$C$6<2,0,IF($A34=I$29,INDEX($W$6:$W$25,$A34)*(INDEX($W$6:$W$25,$A34)-1),INDEX($W$6:$W$25,$A34)*INDEX($W$6:$W$25,I$29))/(Hasil!$C$6-1)) -> 0 | J34: =IF(Hasil!$C$6<2,0,IF($A34=J$29,INDEX($W$6:$W$25,$A34)*(INDEX($W$6:$W$25,$A34)-1),INDEX($W$6:$W$25,$A34)*INDEX($W$6:$W$25,J$29))/(Hasil!$C$6-1)) -> 0 | ... V34: =IF(Hasil!$C$6<2,0,IF($A34=V$29,INDEX($W$6:$W$25,$A34)*(INDEX($W$6:$W$25,$A34)-1),INDEX($W$6:$W$25,$A34)*INDEX($W$6:$W$25,V$29))/(Hasil!$C$6-1)) -> 0
