Workbook

Sheet Petunjuk
A1: Lembar Coding: Analisis Isi Krippendorff
A2: Codebook versi 1.0.3 (25 Oktober 2026). Panduan Coder untuk Penyusunan SRS Web Scraping yang Mengintegrasikan Aspek Legalitas dan Etika Privasi Data.
B4: Kode coder (isi satu kali): | C4: Afriansyah | D4: V2 pada Lembar Coding terisi otomatis dari sel ini.
B6: Prosedur singkat (Bagian 5 codebook)
B7: 1 | C7: Baca kolom Isi secara utuh, lalu kolom Rujukan. Buka BAB dan Bagian (kolom R dan S, tersembunyi) hanya bila perlu memahami rujukan antarunit.
B8: 2 | C8: Tentukan V4 Subjek Norma terlebih dahulu (Bagian 7.1), lalu V5 Relevansi dengan Uji Implikasi (Bagian 6 dan 7.2).
B9: 3 | C9: Tentukan V6 Tema Utama dengan pohon keputusan (Bagian 7.3), lalu V7 (Bagian 7.4), V8 (Bagian 7.5), dan V9 (Bagian 7.6).
B10: 4 | C10: Untuk unit R2, tulis V11 Draf Kebutuhan satu kalimat (opsional). Catat keraguan di V12. Kode residual T99 hanya bila tidak ada tema yang cocok.
B11: 5 | C11: Periksa kolom Cek Konsistensi (Q) setiap selesai satu baris (Bagian 9). Bila tidak OK, ulangi coding atau jelaskan di V12.
B12: 6 | C12: Kodekan setiap unit secara independen. Jangan berdiskusi dengan coder lain sebelum seluruh unit selesai.
B13: Legenda
B14: Sel kuning | C14: Sel yang diisi coder (V4 sampai V12). Sel V4 sampai V10 memakai daftar pilihan (Kode - Label).
B15: Sel putih | C15: Terisi otomatis dari sheet Korpus atau formula. Jangan diubah.
B16: Kolom Pilot | C16: Unit bertanda Ya dipakai pada uji coba (pilot): baris 13, 21, 25, 30, 35, 42, 44, 52, 54, 56, 70, 79, 81.
B18: Variabel dan nilai sah (Bagian 4)
B19: V1 ID_Unit | C19: Nomor baris Excel (2 sampai 86), terisi otomatis
B20: V2 Kode_Coder | C20: Dari sel C4
B21: V3 Dokumen | C21: Salinan kolom Dokumen, terisi otomatis
B22: V4 Subjek_Norma | C22: S1 sampai S9
B23: V5 Relevansi | C23: R0, R1, R2
B24: V6 Tema_Utama | C24: T01 sampai T16, T99
B25: V7 Jenis_Pernyataan | C25: P1 sampai P8
B26: V8 Tahap_Scraping | C26: F1 sampai F8
B27: V9 Kebutuhan_SRS | C27: K1 sampai K5 (K1 keamanan, K2 mutu data dan akuntabilitas, K3 fungsional, K4 batasan hukum, K5 tidak menghasilkan kebutuhan)
B28: V10 Tema_Sekunder | C28: T01 sampai T16 (opsional)
B29: V11 Draf_Kebutuhan | C29: Teks bebas, satu kalimat "Sistem harus/tidak boleh..." (opsional, untuk R2)
B30: V12 Catatan | C30: Teks bebas
B32: Contoh pengisian satu baris (Bagian 3 dan 10)
B33: Isi (ringkas) | C33: Baris 67, Pasal 40 UU 27/2022: wajib menghentikan pemrosesan setelah persetujuan ditarik, paling lambat 3 x 24 jam.
B34: Kode | C34: V4 S1 | V5 R2 | V6 T08 | V7 P2 | V8 F6 | V9 K3. Alasan: kewajiban dengan batas waktu yang dapat diuji.

Sheet Lembar Coding
A1: V1 ID_Unit | B1: V2 Kode_Coder | C1: V3 Dokumen | D1: Rujukan (Pasal atau Paragraf dan Kalimat) | E1: Isi | F1: V4 Subjek_Norma | G1: V5 Relevansi | H1: V6 Tema_Utama | I1: V7 Jenis_Pernyataan | J1: V8 Tahap_Scraping | K1: V9 Kebutuhan_SRS | L1: V10 Tema_Sekunder | M1: V11 Draf_Kebutuhan | N1: V12 Catatan | O1: Pilot | P1: Kelengkapan V4 sampai V9 | Q1: Cek Konsistensi (Bagian 9) | R1: BAB | S1: Bagian
A2: 2 | B2: =IF(Petunjuk!$C$4="","",Petunjuk!$C$4) -> Afriansyah | C2: =IF(INDEX(Korpus!$A:$A,$A2)="","",INDEX(Korpus!$A:$A,$A2)) -> 2019MHN201 | D2: =TRIM(INDEX(Korpus!$D:$D,$A2)&" "&INDEX(Korpus!$E:$E,$A2)) -> Paragraf 3 Kalimat 1 | E2: =IF(INDEX(Korpus!$F:$F,$A2)="","",INDEX(Korpus!$F:$F,$A2)) -> Melihat banyaknya kasus penyalahgunaan data pribadi, sangat penting untuk memberikan perlindungan data pribadi. | P2: =IF(COUNTA(F2:K2)=6,"Lengkap","Belum lengkap ("&(6-COUNTA(F2:K2))&")") -> Belum lengkap (6) | Q2: =IF(COUNTA(F2:K2)<6,"",IF(IF(AND(LEFT(G2,2)="R0",LEFT(K2,2)<>"K5"),"R0 harus K5; ","")&IF(AND(LEFT(G2,2)="R1",LEFT(K2,2)="K3"),"R1 tidak boleh K3 (fungsional); ","")&IF(AND(LEFT(G2,2)="R2",LEFT(K2,2)="K5"),"R2 tidak boleh K5; ","")&IF(AND(LEFT(G2,2)="R2",OR(LEFT(F2,2)="S6",LEFT(F2,2)="S7",LEFT(F2,2)="S8")),"R2 tidak boleh S6/S7/S8; ","")&IF(AND(LEFT(G2,2)="R2",OR(LEFT(H2,3)="T02",LEFT(I2,2)="P8")),"T02 atau P8 tidak boleh R2; ","")&IF(AND(LEFT(H2,3)="T01",LEFT(I2,2)<>"P6",N2=""),"T01 biasanya P6; jelaskan di V12; ","")&IF(AND(LEFT(I2,2)="P1",LEFT(K2,2)<>"K4",N2=""),"P1 biasanya K4; jelaskan di V12; ","")="","OK",IF(AND(LEFT(G2,2)="R0",LEFT(K2,2)<>"K5"),"R0 harus K5; ","")&IF(AND(LEFT(G2,2)="R1",LEFT(K2,2)="K3"),"R1 tidak boleh K3 (fungsional); ","")&IF(AND(LEFT(G2,2)="R2",LEFT(K2,2)="K5"),"R2 tidak boleh K5; ","")&IF(AND(LEFT(G2,2)="R2",OR(LEFT(F2,2)="S6",LEFT(F2,2)="S7",LEFT(F2,2)="S8")),"R2 tidak boleh S6/S7/S8; ","")&IF(AND(LEFT(G2,2)="R2",OR(LEFT(H2,3)="T02",LEFT(I2,2)="P8")),"T02 atau P8 tidak boleh R2; ","")&IF(AND(LEFT(H2,3)="T01",LEFT(I2,2)<>"P6",N2=""),"T01 biasanya P6; jelaskan di V12; ","")&IF(AND(LEFT(I2,2)="P1",LEFT(K2,2)<>"K4",N2=""),"P1 biasanya K4; jelaskan di V12; ",""))) | R2: =IF(INDEX(Korpus!$B:$B,$A2)="","",INDEX(Korpus!$B:$B,$A2)) -> C. Pembahasan | S2: =IF(INDEX(Korpus!$C:$C,$A2)="","",INDEX(Korpus!$C:$C,$A2)) -> 5. Pentingnya Perlindungan Data Pribadi
A3: 3 | B3: =IF(Petunjuk!$C$4="","",Petunjuk!$C$4) -> Afriansyah | C3: =IF(INDEX(Korpus!$A:$A,$A3)="","",INDEX(Korpus!$A:$A,$A3)) -> 2019MHN201 | D3: =TRIM(INDEX(Korpus!$D:$D,$A3)&" "&INDEX(Korpus!$E:$E,$A3)) -> Paragraf 3 Kalimat 2 | E3: =IF(INDEX(Korpus!$F:$F,$A3)="","",INDEX(Korpus!$F:$F,$A3)) -> Pentingnya memberikan perlindungan data pribadi mulai menguat seiring dengan meningkatnya jumlah pengguna telepon seluler dan internet. | P3: =IF(COUNTA(F3:K3)=6,"Lengkap","Belum lengkap ("&(6-COUNTA(F3:K3))&")") -> Belum lengkap (6) | Q3: =IF(COUNTA(F3:K3)<6,"",IF(IF(AND(LEFT(G3,2)="R0",LEFT(K3,2)<>"K5"),"R0 harus K5; ","")&IF(AND(LEFT(G3,2)="R1",LEFT(K3,2)="K3"),"R1 tidak boleh K3 (fungsional); ","")&IF(AND(LEFT(G3,2)="R2",LEFT(K3,2)="K5"),"R2 tidak boleh K5; ","")&IF(AND(LEFT(G3,2)="R2",OR(LEFT(F3,2)="S6",LEFT(F3,2)="S7",LEFT(F3,2)="S8")),"R2 tidak boleh S6/S7/S8; ","")&IF(AND(LEFT(G3,2)="R2",OR(LEFT(H3,3)="T02",LEFT(I3,2)="P8")),"T02 atau P8 tidak boleh R2; ","")&IF(AND(LEFT(H3,3)="T01",LEFT(I3,2)<>"P6",N3=""),"T01 biasanya P6; jelaskan di V12; ","")&IF(AND(LEFT(I3,2)="P1",LEFT(K3,2)<>"K4",N3=""),"P1 biasanya K4; jelaskan di V12; ","")="","OK",IF(AND(LEFT(G3,2)="R0",LEFT(K3,2)<>"K5"),"R0 harus K5; ","")&IF(AND(LEFT(G3,2)="R1",LEFT(K3,2)="K3"),"R1 tidak boleh K3 (fungsional); ","")&IF(AND(LEFT(G3,2)="R2",LEFT(K3,2)="K5"),"R2 tidak boleh K5; ","")&IF(AND(LEFT(G3,2)="R2",OR(LEFT(F3,2)="S6",LEFT(F3,2)="S7",LEFT(F3,2)="S8")),"R2 tidak boleh S6/S7/S8; ","")&IF(AND(LEFT(G3,2)="R2",OR(LEFT(H3,3)="T02",LEFT(I3,2)="P8")),"T02 atau P8 tidak boleh R2; ","")&IF(AND(LEFT(H3,3)="T01",LEFT(I3,2)<>"P6",N3=""),"T01 biasanya P6; jelaskan di V12; ","")&IF(AND(LEFT(I3,2)="P1",LEFT(K3,2)<>"K4",N3=""),"P1 biasanya K4; jelaskan di V12; ",""))) | R3: =IF(INDEX(Korpus!$B:$B,$A3)="","",INDEX(Korpus!$B:$B,$A3)) -> C. Pembahasan | S3: =IF(INDEX(Korpus!$C:$C,$A3)="","",INDEX(Korpus!$C:$C,$A3)) -> 5. Pentingnya Perlindungan Data Pribadi
A4: 4 | B4: =IF(Petunjuk!$C$4="","",Petunjuk!$C$4) -> Afriansyah | C4: =IF(INDEX(Korpus!$A:$A,$A4)="","",INDEX(Korpus!$A:$A,$A4)) -> 2019MHN201 | D4: =TRIM(INDEX(Korpus!$D:$D,$A4)&" "&INDEX(Korpus!$E:$E,$A4)) -> Paragraf 3 Kalimat 3 | E4: =IF(INDEX(Korpus!$F:$F,$A4)="","",INDEX(Korpus!$F:$F,$A4)) -> Sejumlah kasus yang mencuat, terutama yang memiliki keterkaitan dengan kebocoran data pribadi seseorang dan bermuara kepada aksi penipuan atau tindak kriminal pornografi, menguatkan wacana pentingnya pembuatan aturan hukum untuk melindungi data pribadi. | P4: =IF(COUNTA(F4:K4)=6,"Lengkap","Belum lengkap ("&(6-COUNTA(F4:K4))&")") -> Belum lengkap (6) | Q4: =IF(COUNTA(F4:K4)<6,"",IF(IF(AND(LEFT(G4,2)="R0",LEFT(K4,2)<>"K5"),"R0 harus K5; ","")&IF(AND(LEFT(G4,2)="R1",LEFT(K4,2)="K3"),"R1 tidak boleh K3 (fungsional); ","")&IF(AND(LEFT(G4,2)="R2",LEFT(K4,2)="K5"),"R2 tidak boleh K5; ","")&IF(AND(LEFT(G4,2)="R2",OR(LEFT(F4,2)="S6",LEFT(F4,2)="S7",LEFT(F4,2)="S8")),"R2 tidak boleh S6/S7/S8; ","")&IF(AND(LEFT(G4,2)="R2",OR(LEFT(H4,3)="T02",LEFT(I4,2)="P8")),"T02 atau P8 tidak boleh R2; ","")&IF(AND(LEFT(H4,3)="T01",LEFT(I4,2)<>"P6",N4=""),"T01 biasanya P6; jelaskan di V12; ","")&IF(AND(LEFT(I4,2)="P1",LEFT(K4,2)<>"K4",N4=""),"P1 biasanya K4; jelaskan di V12; ","")="","OK",IF(AND(LEFT(G4,2)="R0",LEFT(K4,2)<>"K5"),"R0 harus K5; ","")&IF(AND(LEFT(G4,2)="R1",LEFT(K4,2)="K3"),"R1 tidak boleh K3 (fungsional); ","")&IF(AND(LEFT(G4,2)="R2",LEFT(K4,2)="K5"),"R2 tidak boleh K5; ","")&IF(AND(LEFT(G4,2)="R2",OR(LEFT(F4,2)="S6",LEFT(F4,2)="S7",LEFT(F4,2)="S8")),"R2 tidak boleh S6/S7/S8; ","")&IF(AND(LEFT(G4,2)="R2",OR(LEFT(H4,3)="T02",LEFT(I4,2)="P8")),"T02 atau P8 tidak boleh R2; ","")&IF(AND(LEFT(H4,3)="T01",LEFT(I4,2)<>"P6",N4=""),"T01 biasanya P6; jelaskan di V12; ","")&IF(AND(LEFT(I4,2)="P1",LEFT(K4,2)<>"K4",N4=""),"P1 biasanya K4; jelaskan di V12; ",""))) | R4: =IF(INDEX(Korpus!$B:$B,$A4)="","",INDEX(Korpus!$B:$B,$A4)) -> C. Pembahasan | S4: =IF(INDEX(Korpus!$C:$C,$A4)="","",INDEX(Korpus!$C:$C,$A4)) -> 5. Pentingnya Perlindungan Data Pribadi
A5: 5 | B5: =IF(Petunjuk!$C$4="","",Petunjuk!$C$4) -> Afriansyah | C5: =IF(INDEX(Korpus!$A:$A,$A5)="","",INDEX(Korpus!$A:$A,$A5)) -> 2019MHN201 | D5: =TRIM(INDEX(Korpus!$D:$D,$A5)&" "&INDEX(Korpus!$E:$E,$A5)) -> Paragraf 3 Kalimat 4 | E5: =IF(INDEX(Korpus!$F:$F,$A5)="","",INDEX(Korpus!$F:$F,$A5)) -> Perlindungan data pribadi berhubungan dengan konsep privasi. | P5: =IF(COUNTA(F5:K5)=6,"Lengkap","Belum lengkap ("&(6-COUNTA(F5:K5))&")") -> Belum lengkap (6) | Q5: =IF(COUNTA(F5:K5)<6,"",IF(IF(AND(LEFT(G5,2)="R0",LEFT(K5,2)<>"K5"),"R0 harus K5; ","")&IF(AND(LEFT(G5,2)="R1",LEFT(K5,2)="K3"),"R1 tidak boleh K3 (fungsional); ","")&IF(AND(LEFT(G5,2)="R2",LEFT(K5,2)="K5"),"R2 tidak boleh K5; ","")&IF(AND(LEFT(G5,2)="R2",OR(LEFT(F5,2)="S6",LEFT(F5,2)="S7",LEFT(F5,2)="S8")),"R2 tidak boleh S6/S7/S8; ","")&IF(AND(LEFT(G5,2)="R2",OR(LEFT(H5,3)="T02",LEFT(I5,2)="P8")),"T02 atau P8 tidak boleh R2; ","")&IF(AND(LEFT(H5,3)="T01",LEFT(I5,2)<>"P6",N5=""),"T01 biasanya P6; jelaskan di V12; ","")&IF(AND(LEFT(I5,2)="P1",LEFT(K5,2)<>"K4",N5=""),"P1 biasanya K4; jelaskan di V12; ","")="","OK",IF(AND(LEFT(G5,2)="R0",LEFT(K5,2)<>"K5"),"R0 harus K5; ","")&IF(AND(LEFT(G5,2)="R1",LEFT(K5,2)="K3"),"R1 tidak boleh K3 (fungsional); ","")&IF(AND(LEFT(G5,2)="R2",LEFT(K5,2)="K5"),"R2 tidak boleh K5; ","")&IF(AND(LEFT(G5,2)="R2",OR(LEFT(F5,2)="S6",LEFT(F5,2)="S7",LEFT(F5,2)="S8")),"R2 tidak boleh S6/S7/S8; ","")&IF(AND(LEFT(G5,2)="R2",OR(LEFT(H5,3)="T02",LEFT(I5,2)="P8")),"T02 atau P8 tidak boleh R2; ","")&IF(AND(LEFT(H5,3)="T01",LEFT(I5,2)<>"P6",N5=""),"T01 biasanya P6; jelaskan di V12; ","")&IF(AND(LEFT(I5,2)="P1",LEFT(K5,2)<>"K4",N5=""),"P1 biasanya K4; jelaskan di V12; ",""))) | R5: =IF(INDEX(Korpus!$B:$B,$A5)="","",INDEX(Korpus!$B:$B,$A5)) -> C. Pembahasan | S5: =IF(INDEX(Korpus!$C:$C,$A5)="","",INDEX(Korpus!$C:$C,$A5)) -> 5. Pentingnya Perlindungan Data Pribadi
A6: 6 | B6: =IF(Petunjuk!$C$4="","",Petunjuk!$C$4) -> Afriansyah | C6: =IF(INDEX(Korpus!$A:$A,$A6)="","",INDEX(Korpus!$A:$A,$A6)) -> 2019MHN201 | D6: =TRIM(INDEX(Korpus!$D:$D,$A6)&" "&INDEX(Korpus!$E:$E,$A6)) -> Paragraf 3 Kalimat 5 | E6: =IF(INDEX(Korpus!$F:$F,$A6)="","",INDEX(Korpus!$F:$F,$A6)) -> Konsep privasi sendiri adalah gagasan untuk menjaga integritas dan martabat pribadi. | P6: =IF(COUNTA(F6:K6)=6,"Lengkap","Belum lengkap ("&(6-COUNTA(F6:K6))&")") -> Belum lengkap (6) | Q6: =IF(COUNTA(F6:K6)<6,"",IF(IF(AND(LEFT(G6,2)="R0",LEFT(K6,2)<>"K5"),"R0 harus K5; ","")&IF(AND(LEFT(G6,2)="R1",LEFT(K6,2)="K3"),"R1 tidak boleh K3 (fungsional); ","")&IF(AND(LEFT(G6,2)="R2",LEFT(K6,2)="K5"),"R2 tidak boleh K5; ","")&IF(AND(LEFT(G6,2)="R2",OR(LEFT(F6,2)="S6",LEFT(F6,2)="S7",LEFT(F6,2)="S8")),"R2 tidak boleh S6/S7/S8; ","")&IF(AND(LEFT(G6,2)="R2",OR(LEFT(H6,3)="T02",LEFT(I6,2)="P8")),"T02 atau P8 tidak boleh R2; ","")&IF(AND(LEFT(H6,3)="T01",LEFT(I6,2)<>"P6",N6=""),"T01 biasanya P6; jelaskan di V12; ","")&IF(AND(LEFT(I6,2)="P1",LEFT(K6,2)<>"K4",N6=""),"P1 biasanya K4; jelaskan di V12; ","")="","OK",IF(AND(LEFT(G6,2)="R0",LEFT(K6,2)<>"K5"),"R0 harus K5; ","")&IF(AND(LEFT(G6,2)="R1",LEFT(K6,2)="K3"),"R1 tidak boleh K3 (fungsional); ","")&IF(AND(LEFT(G6,2)="R2",LEFT(K6,2)="K5"),"R2 tidak boleh K5; ","")&IF(AND(LEFT(G6,2)="R2",OR(LEFT(F6,2)="S6",LEFT(F6,2)="S7",LEFT(F6,2)="S8")),"R2 tidak boleh S6/S7/S8; ","")&IF(AND(LEFT(G6,2)="R2",OR(LEFT(H6,3)="T02",LEFT(I6,2)="P8")),"T02 atau P8 tidak boleh R2; ","")&IF(AND(LEFT(H6,3)="T01",LEFT(I6,2)<>"P6",N6=""),"T01 biasanya P6; jelaskan di V12; ","")&IF(AND(LEFT(I6,2)="P1",LEFT(K6,2)<>"K4",N6=""),"P1 biasanya K4; jelaskan di V12; ",""))) | R6: =IF(INDEX(Korpus!$B:$B,$A6)="","",INDEX(Korpus!$B:$B,$A6)) -> C. Pembahasan | S6: =IF(INDEX(Korpus!$C:$C,$A6)="","",INDEX(Korpus!$C:$C,$A6)) -> 5. Pentingnya Perlindungan Data Pribadi
A7: 7 | B7: =IF(Petunjuk!$C$4="","",Petunjuk!$C$4) -> Afriansyah | C7: =IF(INDEX(Korpus!$A:$A,$A7)="","",INDEX(Korpus!$A:$A,$A7)) -> 2019MHN201 | D7: =TRIM(INDEX(Korpus!$D:$D,$A7)&" "&INDEX(Korpus!$E:$E,$A7)) -> Paragraf 3 Kalimat 6 | E7: =IF(INDEX(Korpus!$F:$F,$A7)="","",INDEX(Korpus!$F:$F,$A7)) -> Hak privasi juga merupakan kemampuan individu untuk menentukan siapa yang memegang informasi tentang mereka dan bagaimana informasi tersebut digunakan. | P7: =IF(COUNTA(F7:K7)=6,"Lengkap","Belum lengkap ("&(6-COUNTA(F7:K7))&")") -> Belum lengkap (6) | Q7: =IF(COUNTA(F7:K7)<6,"",IF(IF(AND(LEFT(G7,2)="R0",LEFT(K7,2)<>"K5"),"R0 harus K5; ","")&IF(AND(LEFT(G7,2)="R1",LEFT(K7,2)="K3"),"R1 tidak boleh K3 (fungsional); ","")&IF(AND(LEFT(G7,2)="R2",LEFT(K7,2)="K5"),"R2 tidak boleh K5; ","")&IF(AND(LEFT(G7,2)="R2",OR(LEFT(F7,2)="S6",LEFT(F7,2)="S7",LEFT(F7,2)="S8")),"R2 tidak boleh S6/S7/S8; ","")&IF(AND(LEFT(G7,2)="R2",OR(LEFT(H7,3)="T02",LEFT(I7,2)="P8")),"T02 atau P8 tidak boleh R2; ","")&IF(AND(LEFT(H7,3)="T01",LEFT(I7,2)<>"P6",N7=""),"T01 biasanya P6; jelaskan di V12; ","")&IF(AND(LEFT(I7,2)="P1",LEFT(K7,2)<>"K4",N7=""),"P1 biasanya K4; jelaskan di V12; ","")="","OK",IF(AND(LEFT(G7,2)="R0",LEFT(K7,2)<>"K5"),"R0 harus K5; ","")&IF(AND(LEFT(G7,2)="R1",LEFT(K7,2)="K3"),"R1 tidak boleh K3 (fungsional); ","")&IF(AND(LEFT(G7,2)="R2",LEFT(K7,2)="K5"),"R2 tidak boleh K5; ","")&IF(AND(LEFT(G7,2)="R2",OR(LEFT(F7,2)="S6",LEFT(F7,2)="S7",LEFT(F7,2)="S8")),"R2 tidak boleh S6/S7/S8; ","")&IF(AND(LEFT(G7,2)="R2",OR(LEFT(H7,3)="T02",LEFT(I7,2)="P8")),"T02 atau P8 tidak boleh R2; ","")&IF(AND(LEFT(H7,3)="T01",LEFT(I7,2)<>"P6",N7=""),"T01 biasanya P6; jelaskan di V12; ","")&IF(AND(LEFT(I7,2)="P1",LEFT(K7,2)<>"K4",N7=""),"P1 biasanya K4; jelaskan di V12; ",""))) | R7: =IF(INDEX(Korpus!$B:$B,$A7)="","",INDEX(Korpus!$B:$B,$A7)) -> C. Pembahasan | S7: =IF(INDEX(Korpus!$C:$C,$A7)="","",INDEX(Korpus!$C:$C,$A7)) -> 5. Pentingnya Perlindungan Data Pribadi
A8: 8 | B8: =IF(Petunjuk!$C$4="","",Petunjuk!$C$4) -> Afriansyah | C8: =IF(INDEX(Korpus!$A:$A,$A8)="","",INDEX(Korpus!$A:$A,$A8)) -> 2019MHN201 | D8: =TRIM(INDEX(Korpus!$D:$D,$A8)&" "&INDEX(Korpus!$E:$E,$A8)) -> Paragraf 4 Kalimat 1 | E8: =IF(INDEX(Korpus!$F:$F,$A8)="","",INDEX(Korpus!$F:$F,$A8)) -> Konsep perlindungan data mengisyaratkan bahwa individu memiliki hak untuk menentukan apakah mereka akan membagi atau bertukar data pribadi mereka atau tidak. | P8: =IF(COUNTA(F8:K8)=6,"Lengkap","Belum lengkap ("&(6-COUNTA(F8:K8))&")") -> Belum lengkap (6) | Q8: =IF(COUNTA(F8:K8)<6,"",IF(IF(AND(LEFT(G8,2)="R0",LEFT(K8,2)<>"K5"),"R0 harus K5; ","")&IF(AND(LEFT(G8,2)="R1",LEFT(K8,2)="K3"),"R1 tidak boleh K3 (fungsional); ","")&IF(AND(LEFT(G8,2)="R2",LEFT(K8,2)="K5"),"R2 tidak boleh K5; ","")&IF(AND(LEFT(G8,2)="R2",OR(LEFT(F8,2)="S6",LEFT(F8,2)="S7",LEFT(F8,2)="S8")),"R2 tidak boleh S6/S7/S8; ","")&IF(AND(LEFT(G8,2)="R2",OR(LEFT(H8,3)="T02",LEFT(I8,2)="P8")),"T02 atau P8 tidak boleh R2; ","")&IF(AND(LEFT(H8,3)="T01",LEFT(I8,2)<>"P6",N8=""),"T01 biasanya P6; jelaskan di V12; ","")&IF(AND(LEFT(I8,2)="P1",LEFT(K8,2)<>"K4",N8=""),"P1 biasanya K4; jelaskan di V12; ","")="","OK",IF(AND(LEFT(G8,2)="R0",LEFT(K8,2)<>"K5"),"R0 harus K5; ","")&IF(AND(LEFT(G8,2)="R1",LEFT(K8,2)="K3"),"R1 tidak boleh K3 (fungsional); ","")&IF(AND(LEFT(G8,2)="R2",LEFT(K8,2)="K5"),"R2 tidak boleh K5; ","")&IF(AND(LEFT(G8,2)="R2",OR(LEFT(F8,2)="S6",LEFT(F8,2)="S7",LEFT(F8,2)="S8")),"R2 tidak boleh S6/S7/S8; ","")&IF(AND(LEFT(G8,2)="R2",OR(LEFT(H8,3)="T02",LEFT(I8,2)="P8")),"T02 atau P8 tidak boleh R2; ","")&IF(AND(LEFT(H8,3)="T01",LEFT(I8,2)<>"P6",N8=""),"T01 biasanya P6; jelaskan di V12; ","")&IF(AND(LEFT(I8,2)="P1",LEFT(K8,2)<>"K4",N8=""),"P1 biasanya K4; jelaskan di V12; ",""))) | R8: =IF(INDEX(Korpus!$B:$B,$A8)="","",INDEX(Korpus!$B:$B,$A8)) -> C. Pembahasan | S8: =IF(INDEX(Korpus!$C:$C,$A8)="","",INDEX(Korpus!$C:$C,$A8)) -> 5. Pentingnya Perlindungan Data Pribadi
A9: 9 | B9: =IF(Petunjuk!$C$4="","",Petunjuk!$C$4) -> Afriansyah | C9: =IF(INDEX(Korpus!$A:$A,$A9)="","",INDEX(Korpus!$A:$A,$A9)) -> 2019MHN201 | D9: =TRIM(INDEX(Korpus!$D:$D,$A9)&" "&INDEX(Korpus!$E:$E,$A9)) -> Paragraf 4 Kalimat 2 | E9: =IF(INDEX(Korpus!$F:$F,$A9)="","",INDEX(Korpus!$F:$F,$A9)) -> Selain itu, individu juga memiliki hak untuk menentukan syarat-syarat pelaksanaan pemindahan data pribadi tersebut. | P9: =IF(COUNTA(F9:K9)=6,"Lengkap","Belum lengkap ("&(6-COUNTA(F9:K9))&")") -> Belum lengkap (6) | Q9: =IF(COUNTA(F9:K9)<6,"",IF(IF(AND(LEFT(G9,2)="R0",LEFT(K9,2)<>"K5"),"R0 harus K5; ","")&IF(AND(LEFT(G9,2)="R1",LEFT(K9,2)="K3"),"R1 tidak boleh K3 (fungsional); ","")&IF(AND(LEFT(G9,2)="R2",LEFT(K9,2)="K5"),"R2 tidak boleh K5; ","")&IF(AND(LEFT(G9,2)="R2",OR(LEFT(F9,2)="S6",LEFT(F9,2)="S7",LEFT(F9,2)="S8")),"R2 tidak boleh S6/S7/S8; ","")&IF(AND(LEFT(G9,2)="R2",OR(LEFT(H9,3)="T02",LEFT(I9,2)="P8")),"T02 atau P8 tidak boleh R2; ","")&IF(AND(LEFT(H9,3)="T01",LEFT(I9,2)<>"P6",N9=""),"T01 biasanya P6; jelaskan di V12; ","")&IF(AND(LEFT(I9,2)="P1",LEFT(K9,2)<>"K4",N9=""),"P1 biasanya K4; jelaskan di V12; ","")="","OK",IF(AND(LEFT(G9,2)="R0",LEFT(K9,2)<>"K5"),"R0 harus K5; ","")&IF(AND(LEFT(G9,2)="R1",LEFT(K9,2)="K3"),"R1 tidak boleh K3 (fungsional); ","")&IF(AND(LEFT(G9,2)="R2",LEFT(K9,2)="K5"),"R2 tidak boleh K5; ","")&IF(AND(LEFT(G9,2)="R2",OR(LEFT(F9,2)="S6",LEFT(F9,2)="S7",LEFT(F9,2)="S8")),"R2 tidak boleh S6/S7/S8; ","")&IF(AND(LEFT(G9,2)="R2",OR(LEFT(H9,3)="T02",LEFT(I9,2)="P8")),"T02 atau P8 tidak boleh R2; ","")&IF(AND(LEFT(H9,3)="T01",LEFT(I9,2)<>"P6",N9=""),"T01 biasanya P6; jelaskan di V12; ","")&IF(AND(LEFT(I9,2)="P1",LEFT(K9,2)<>"K4",N9=""),"P1 biasanya K4; jelaskan di V12; ",""))) | R9: =IF(INDEX(Korpus!$B:$B,$A9)="","",INDEX(Korpus!$B:$B,$A9)) -> C. Pembahasan | S9: =IF(INDEX(Korpus!$C:$C,$A9)="","",INDEX(Korpus!$C:$C,$A9)) -> 5. Pentingnya Perlindungan Data Pribadi
A10: 10 | B10: =IF(Petunjuk!$C$4="","",Petunjuk!$C$4) -> Afriansyah | C10: =IF(INDEX(Korpus!$A:$A,$A10)="","",INDEX(Korpus!$A:$A,$A10)) -> 2019MHN201 | D10: =TRIM(INDEX(Korpus!$D:$D,$A10)&" "&INDEX(Korpus!$E:$E,$A10)) -> Paragraf 4 Kalimat 3 | E10: =IF(INDEX(Korpus!$F:$F,$A10)="","",INDEX(Korpus!$F:$F,$A10)) -> Lebih jauh, perlindungan privasi. | P10: =IF(COUNTA(F10:K10)=6,"Lengkap","Belum lengkap ("&(6-COUNTA(F10:K10))&")") -> Belum lengkap (6) | Q10: =IF(COUNTA(F10:K10)<6,"",IF(IF(AND(LEFT(G10,2)="R0",LEFT(K10,2)<>"K5"),"R0 harus K5; ","")&IF(AND(LEFT(G10,2)="R1",LEFT(K10,2)="K3"),"R1 tidak boleh K3 (fungsional); ","")&IF(AND(LEFT(G10,2)="R2",LEFT(K10,2)="K5"),"R2 tidak boleh K5; ","")&IF(AND(LEFT(G10,2)="R2",OR(LEFT(F10,2)="S6",LEFT(F10,2)="S7",LEFT(F10,2)="S8")),"R2 tidak boleh S6/S7/S8; ","")&IF(AND(LEFT(G10,2)="R2",OR(LEFT(H10,3)="T02",LEFT(I10,2)="P8")),"T02 atau P8 tidak boleh R2; ","")&IF(AND(LEFT(H10,3)="T01",LEFT(I10,2)<>"P6",N10=""),"T01 biasanya P6; jelaskan di V12; ","")&IF(AND(LEFT(I10,2)="P1",LEFT(K10,2)<>"K4",N10=""),"P1 biasanya K4; jelaskan di V12; ","")="","OK",IF(AND(LEFT(G10,2)="R0",LEFT(K10,2)<>"K5"),"R0 harus K5; ","")&IF(AND(LEFT(G10,2)="R1",LEFT(K10,2)="K3"),"R1 tidak boleh K3 (fungsional); ","")&IF(AND(LEFT(G10,2)="R2",LEFT(K10,2)="K5"),"R2 tidak boleh K5; ","")&IF(AND(LEFT(G10,2)="R2",OR(LEFT(F10,2)="S6",LEFT(F10,2)="S7",LEFT(F10,2)="S8")),"R2 tidak boleh S6/S7/S8; ","")&IF(AND(LEFT(G10,2)="R2",OR(LEFT(H10,3)="T02",LEFT(I10,2)="P8")),"T02 atau P8 tidak boleh R2; ","")&IF(AND(LEFT(H10,3)="T01",LEFT(I10,2)<>"P6",N10=""),"T01 biasanya P6; jelaskan di V12; ","")&IF(AND(LEFT(I10,2)="P1",LEFT(K10,2)<>"K4",N10=""),"P1 biasanya K4; jelaskan di V12; ",""))) | R10: =IF(INDEX(Korpus!$B:$B,$A10)="","",INDEX(Korpus!$B:$B,$A10)) -> C. Pembahasan | S10: =IF(INDEX(Korpus!$C:$C,$A10)="","",INDEX(Korpus!$C:$C,$A10)) -> 5. Pentingnya Perlindungan Data Pribadi
A11: 11 | B11: =IF(Petunjuk!$C$4="","",Petunjuk!$C$4) -> Afriansyah | C11: =IF(INDEX(Korpus!$A:$A,$A11)="","",INDEX(Korpus!$A:$A,$A11)) -> 2019MHN201 | D11: =TRIM(INDEX(Korpus!$D:$D,$A11)&" "&INDEX(Korpus!$E:$E,$A11)) -> Paragraf 4 Kalimat 4 | E11: =IF(INDEX(Korpus!$F:$F,$A11)="","",INDEX(Korpus!$F:$F,$A11)) -> Hak privasi telah berkembang sehingga dapat digunakan untuk merumuskan hak untuk melindungi data pribadi. | P11: =IF(COUNTA(F11:K11)=6,"Lengkap","Belum lengkap ("&(6-COUNTA(F11:K11))&")") -> Belum lengkap (6) | Q11: =IF(COUNTA(F11:K11)<6,"",IF(IF(AND(LEFT(G11,2)="R0",LEFT(K11,2)<>"K5"),"R0 harus K5; ","")&IF(AND(LEFT(G11,2)="R1",LEFT(K11,2)="K3"),"R1 tidak boleh K3 (fungsional); ","")&IF(AND(LEFT(G11,2)="R2",LEFT(K11,2)="K5"),"R2 tidak boleh K5; ","")&IF(AND(LEFT(G11,2)="R2",OR(LEFT(F11,2)="S6",LEFT(F11,2)="S7",LEFT(F11,2)="S8")),"R2 tidak boleh S6/S7/S8; ","")&IF(AND(LEFT(G11,2)="R2",OR(LEFT(H11,3)="T02",LEFT(I11,2)="P8")),"T02 atau P8 tidak boleh R2; ","")&IF(AND(LEFT(H11,3)="T01",LEFT(I11,2)<>"P6",N11=""),"T01 biasanya P6; jelaskan di V12; ","")&IF(AND(LEFT(I11,2)="P1",LEFT(K11,2)<>"K4",N11=""),"P1 biasanya K4; jelaskan di V12; ","")="","OK",IF(AND(LEFT(G11,2)="R0",LEFT(K11,2)<>"K5"),"R0 harus K5; ","")&IF(AND(LEFT(G11,2)="R1",LEFT(K11,2)="K3"),"R1 tidak boleh K3 (fungsional); ","")&IF(AND(LEFT(G11,2)="R2",LEFT(K11,2)="K5"),"R2 tidak boleh K5; ","")&IF(AND(LEFT(G11,2)="R2",OR(LEFT(F11,2)="S6",LEFT(F11,2)="S7",LEFT(F11,2)="S8")),"R2 tidak boleh S6/S7/S8; ","")&IF(AND(LEFT(G11,2)="R2",OR(LEFT(H11,3)="T02",LEFT(I11,2)="P8")),"T02 atau P8 tidak boleh R2; ","")&IF(AND(LEFT(H11,3)="T01",LEFT(I11,2)<>"P6",N11=""),"T01 biasanya P6; jelaskan di V12; ","")&IF(AND(LEFT(I11,2)="P1",LEFT(K11,2)<>"K4",N11=""),"P1 biasanya K4; jelaskan di V12; ",""))) | R11: =IF(INDEX(Korpus!$B:$B,$A11)="","",INDEX(Korpus!$B:$B,$A11)) -> C. Pembahasan | S11: =IF(INDEX(Korpus!$C:$C,$A11)="","",INDEX(Korpus!$C:$C,$A11)) -> 5. Pentingnya Perlindungan Data Pribadi
A12: 12 | B12: =IF(Petunjuk!$C$4="","",Petunjuk!$C$4) -> Afriansyah | C12: =IF(INDEX(Korpus!$A:$A,$A12)="","",INDEX(Korpus!$A:$A,$A12)) -> 2019MHN201 | D12: =TRIM(INDEX(Korpus!$D:$D,$A12)&" "&INDEX(Korpus!$E:$E,$A12)) -> Paragraf 5 Kalimat 1 | E12: =IF(INDEX(Korpus!$F:$F,$A12)="","",INDEX(Korpus!$F:$F,$A12)) -> Perlindungan data pribadi telah diatur di dalam UUD NKRI Tahun 1945. | P12: =IF(COUNTA(F12:K12)=6,"Lengkap","Belum lengkap ("&(6-COUNTA(F12:K12))&")") -> Belum lengkap (6) | Q12: =IF(COUNTA(F12:K12)<6,"",IF(IF(AND(LEFT(G12,2)="R0",LEFT(K12,2)<>"K5"),"R0 harus K5; ","")&IF(AND(LEFT(G12,2)="R1",LEFT(K12,2)="K3"),"R1 tidak boleh K3 (fungsional); ","")&IF(AND(LEFT(G12,2)="R2",LEFT(K12,2)="K5"),"R2 tidak boleh K5; ","")&IF(AND(LEFT(G12,2)="R2",OR(LEFT(F12,2)="S6",LEFT(F12,2)="S7",LEFT(F12,2)="S8")),"R2 tidak boleh S6/S7/S8; ","")&IF(AND(LEFT(G12,2)="R2",OR(LEFT(H12,3)="T02",LEFT(I12,2)="P8")),"T02 atau P8 tidak boleh R2; ","")&IF(AND(LEFT(H12,3)="T01",LEFT(I12,2)<>"P6",N12=""),"T01 biasanya P6; jelaskan di V12; ","")&IF(AND(LEFT(I12,2)="P1",LEFT(K12,2)<>"K4",N12=""),"P1 biasanya K4; jelaskan di V12; ","")="","OK",IF(AND(LEFT(G12,2)="R0",LEFT(K12,2)<>"K5"),"R0 harus K5; ","")&IF(AND(LEFT(G12,2)="R1",LEFT(K12,2)="K3"),"R1 tidak boleh K3 (fungsional); ","")&IF(AND(LEFT(G12,2)="R2",LEFT(K12,2)="K5"),"R2 tidak boleh K5; ","")&IF(AND(LEFT(G12,2)="R2",OR(LEFT(F12,2)="S6",LEFT(F12,2)="S7",LEFT(F12,2)="S8")),"R2 tidak boleh S6/S7/S8; ","")&IF(AND(LEFT(G12,2)="R2",OR(LEFT(H12,3)="T02",LEFT(I12,2)="P8")),"T02 atau P8 tidak boleh R2; ","")&IF(AND(LEFT(H12,3)="T01",LEFT(I12,2)<>"P6",N12=""),"T01 biasanya P6; jelaskan di V12; ","")&IF(AND(LEFT(I12,2)="P1",LEFT(K12,2)<>"K4",N12=""),"P1 biasanya K4; jelaskan di V12; ",""))) | R12: =IF(INDEX(Korpus!$B:$B,$A12)="","",INDEX(Korpus!$B:$B,$A12)) -> C. Pembahasan | S12: =IF(INDEX(Korpus!$C:$C,$A12)="","",INDEX(Korpus!$C:$C,$A12)) -> 5. Pentingnya Perlindungan Data Pribadi
A13: 13 | B13: =IF(Petunjuk!$C$4="","",Petunjuk!$C$4) -> Afriansyah | C13: =IF(INDEX(Korpus!$A:$A,$A13)="","",INDEX(Korpus!$A:$A,$A13)) -> 2019MHN201 | D13: =TRIM(INDEX(Korpus!$D:$D,$A13)&" "&INDEX(Korpus!$E:$E,$A13)) -> Paragraf 5 Kalimat 2 | E13: =IF(INDEX(Korpus!$F:$F,$A13)="","",INDEX(Korpus!$F:$F,$A13)) -> Dalam Pasal 28 G ayat (1) disebutkan bahwa “Setiap orang berhak atas perlindungan diri pribadi, data juga berhubungan dengan konsep hak keluarga, kehormatan, martabat, dan harta benda yang di bawah kekuasaannya, serta berhak atas rasa aman dan perlindungan dari ancaman ketakutan untuk berbuat atau tidak berbuat sesuatu yang merupakan hak asasi.” | F13: S5 - Setiap Orang atau pihak umum | H13: T01 - Definisi, Istilah, dan Ruang Lingkup | I13: P3 - Hak | J13: F7 - Tata kelola dan hak subjek | O13: Ya | P13: =IF(COUNTA(F13:K13)=6,"Lengkap","Belum lengkap ("&(6-COUNTA(F13:K13))&")") -> Belum lengkap (2) | Q13: =IF(COUNTA(F13:K13)<6,"",IF(IF(AND(LEFT(G13,2)="R0",LEFT(K13,2)<>"K5"),"R0 harus K5; ","")&IF(AND(LEFT(G13,2)="R1",LEFT(K13,2)="K3"),"R1 tidak boleh K3 (fungsional); ","")&IF(AND(LEFT(G13,2)="R2",LEFT(K13,2)="K5"),"R2 tidak boleh K5; ","")&IF(AND(LEFT(G13,2)="R2",OR(LEFT(F13,2)="S6",LEFT(F13,2)="S7",LEFT(F13,2)="S8")),"R2 tidak boleh S6/S7/S8; ","")&IF(AND(LEFT(G13,2)="R2",OR(LEFT(H13,3)="T02",LEFT(I13,2)="P8")),"T02 atau P8 tidak boleh R2; ","")&IF(AND(LEFT(H13,3)="T01",LEFT(I13,2)<>"P6",N13=""),"T01 biasanya P6; jelaskan di V12; ","")&IF(AND(LEFT(I13,2)="P1",LEFT(K13,2)<>"K4",N13=""),"P1 biasanya K4; jelaskan di V12; ","")="","OK",IF(AND(LEFT(G13,2)="R0",LEFT(K13,2)<>"K5"),"R0 harus K5; ","")&IF(AND(LEFT(G13,2)="R1",LEFT(K13,2)="K3"),"R1 tidak boleh K3 (fungsional); ","")&IF(AND(LEFT(G13,2)="R2",LEFT(K13,2)="K5"),"R2 tidak boleh K5; ","")&IF(AND(LEFT(G13,2)="R2",OR(LEFT(F13,2)="S6",LEFT(F13,2)="S7",LEFT(F13,2)="S8")),"R2 tidak boleh S6/S7/S8; ","")&IF(AND(LEFT(G13,2)="R2",OR(LEFT(H13,3)="T02",LEFT(I13,2)="P8")),"T02 atau P8 tidak boleh R2; ","")&IF(AND(LEFT(H13,3)="T01",LEFT(I13,2)<>"P6",N13=""),"T01 biasanya P6; jelaskan di V12; ","")&IF(AND(LEFT(I13,2)="P1",LEFT(K13,2)<>"K4",N13=""),"P1 biasanya K4; jelaskan di V12; ",""))) | R13: =IF(INDEX(Korpus!$B:$B,$A13)="","",INDEX(Korpus!$B:$B,$A13)) -> C. Pembahasan | S13: =IF(INDEX(Korpus!$C:$C,$A13)="","",INDEX(Korpus!$C:$C,$A13)) -> 5. Pentingnya Perlindungan Data Pribadi
A14: 14 | B14: =IF(Petunjuk!$C$4="","",Petunjuk!$C$4) -> Afriansyah | C14: =IF(INDEX(Korpus!$A:$A,$A14)="","",INDEX(Korpus!$A:$A,$A14)) -> 2019MHN201 | D14: =TRIM(INDEX(Korpus!$D:$D,$A14)&" "&INDEX(Korpus!$E:$E,$A14)) -> Paragraf 6 Kalimat 1 | E14: =IF(INDEX(Korpus!$F:$F,$A14)="","",INDEX(Korpus!$F:$F,$A14)) -> Selain itu beberapa peraturan nasional secara umum telah mengatur untuk memberikan perlindungan data pribadi antara lain: | P14: =IF(COUNTA(F14:K14)=6,"Lengkap","Belum lengkap ("&(6-COUNTA(F14:K14))&")") -> Belum lengkap (6) | Q14: =IF(COUNTA(F14:K14)<6,"",IF(IF(AND(LEFT(G14,2)="R0",LEFT(K14,2)<>"K5"),"R0 harus K5; ","")&IF(AND(LEFT(G14,2)="R1",LEFT(K14,2)="K3"),"R1 tidak boleh K3 (fungsional); ","")&IF(AND(LEFT(G14,2)="R2",LEFT(K14,2)="K5"),"R2 tidak boleh K5; ","")&IF(AND(LEFT(G14,2)="R2",OR(LEFT(F14,2)="S6",LEFT(F14,2)="S7",LEFT(F14,2)="S8")),"R2 tidak boleh S6/S7/S8; ","")&IF(AND(LEFT(G14,2)="R2",OR(LEFT(H14,3)="T02",LEFT(I14,2)="P8")),"T02 atau P8 tidak boleh R2; ","")&IF(AND(LEFT(H14,3)="T01",LEFT(I14,2)<>"P6",N14=""),"T01 biasanya P6; jelaskan di V12; ","")&IF(AND(LEFT(I14,2)="P1",LEFT(K14,2)<>"K4",N14=""),"P1 biasanya K4; jelaskan di V12; ","")="","OK",IF(AND(LEFT(G14,2)="R0",LEFT(K14,2)<>"K5"),"R0 harus K5; ","")&IF(AND(LEFT(G14,2)="R1",LEFT(K14,2)="K3"),"R1 tidak boleh K3 (fungsional); ","")&IF(AND(LEFT(G14,2)="R2",LEFT(K14,2)="K5"),"R2 tidak boleh K5; ","")&IF(AND(LEFT(G14,2)="R2",OR(LEFT(F14,2)="S6",LEFT(F14,2)="S7",LEFT(F14,2)="S8")),"R2 tidak boleh S6/S7/S8; ","")&IF(AND(LEFT(G14,2)="R2",OR(LEFT(H14,3)="T02",LEFT(I14,2)="P8")),"T02 atau P8 tidak boleh R2; ","")&IF(AND(LEFT(H14,3)="T01",LEFT(I14,2)<>"P6",N14=""),"T01 biasanya P6; jelaskan di V12; ","")&IF(AND(LEFT(I14,2)="P1",LEFT(K14,2)<>"K4",N14=""),"P1 biasanya K4; jelaskan di V12; ",""))) | R14: =IF(INDEX(Korpus!$B:$B,$A14)="","",INDEX(Korpus!$B:$B,$A14)) -> C. Pembahasan | S14: =IF(INDEX(Korpus!$C:$C,$A14)="","",INDEX(Korpus!$C:$C,$A14)) -> 5. Pentingnya Perlindungan Data Pribadi
A15: 15 | B15: =IF(Petunjuk!$C$4="","",Petunjuk!$C$4) -> Afriansyah | C15: =IF(INDEX(Korpus!$A:$A,$A15)="","",INDEX(Korpus!$A:$A,$A15)) -> 2019MHN201 | D15: =TRIM(INDEX(Korpus!$D:$D,$A15)&" "&INDEX(Korpus!$E:$E,$A15)) -> Paragraf 6 Kalimat 2 | E15: =IF(INDEX(Korpus!$F:$F,$A15)="","",INDEX(Korpus!$F:$F,$A15)) -> 1) Undang-Undang Nomor 19 Tahun 2016 Tentang Perubahan Atas Undang-Undang Nomor 11 Tahun 2008 Tentang Informasi dan Transaksi Elektronik | P15: =IF(COUNTA(F15:K15)=6,"Lengkap","Belum lengkap ("&(6-COUNTA(F15:K15))&")") -> Belum lengkap (6) | Q15: =IF(COUNTA(F15:K15)<6,"",IF(IF(AND(LEFT(G15,2)="R0",LEFT(K15,2)<>"K5"),"R0 harus K5; ","")&IF(AND(LEFT(G15,2)="R1",LEFT(K15,2)="K3"),"R1 tidak boleh K3 (fungsional); ","")&IF(AND(LEFT(G15,2)="R2",LEFT(K15,2)="K5"),"R2 tidak boleh K5; ","")&IF(AND(LEFT(G15,2)="R2",OR(LEFT(F15,2)="S6",LEFT(F15,2)="S7",LEFT(F15,2)="S8")),"R2 tidak boleh S6/S7/S8; ","")&IF(AND(LEFT(G15,2)="R2",OR(LEFT(H15,3)="T02",LEFT(I15,2)="P8")),"T02 atau P8 tidak boleh R2; ","")&IF(AND(LEFT(H15,3)="T01",LEFT(I15,2)<>"P6",N15=""),"T01 biasanya P6; jelaskan di V12; ","")&IF(AND(LEFT(I15,2)="P1",LEFT(K15,2)<>"K4",N15=""),"P1 biasanya K4; jelaskan di V12; ","")="","OK",IF(AND(LEFT(G15,2)="R0",LEFT(K15,2)<>"K5"),"R0 harus K5; ","")&IF(AND(LEFT(G15,2)="R1",LEFT(K15,2)="K3"),"R1 tidak boleh K3 (fungsional); ","")&IF(AND(LEFT(G15,2)="R2",LEFT(K15,2)="K5"),"R2 tidak boleh K5; ","")&IF(AND(LEFT(G15,2)="R2",OR(LEFT(F15,2)="S6",LEFT(F15,2)="S7",LEFT(F15,2)="S8")),"R2 tidak boleh S6/S7/S8; ","")&IF(AND(LEFT(G15,2)="R2",OR(LEFT(H15,3)="T02",LEFT(I15,2)="P8")),"T02 atau P8 tidak boleh R2; ","")&IF(AND(LEFT(H15,3)="T01",LEFT(I15,2)<>"P6",N15=""),"T01 biasanya P6; jelaskan di V12; ","")&IF(AND(LEFT(I15,2)="P1",LEFT(K15,2)<>"K4",N15=""),"P1 biasanya K4; jelaskan di V12; ",""))) | R15: =IF(INDEX(Korpus!$B:$B,$A15)="","",INDEX(Korpus!$B:$B,$A15)) -> C. Pembahasan | S15: =IF(INDEX(Korpus!$C:$C,$A15)="","",INDEX(Korpus!$C:$C,$A15)) -> 5. Pentingnya Perlindungan Data Pribadi
A16: 16 | B16: =IF(Petunjuk!$C$4="","",Petunjuk!$C$4) -> Afriansyah | C16: =IF(INDEX(Korpus!$A:$A,$A16)="","",INDEX(Korpus!$A:$A,$A16)) -> 2019MHN201 | D16: =TRIM(INDEX(Korpus!$D:$D,$A16)&" "&INDEX(Korpus!$E:$E,$A16)) -> Paragraf 6 Kalimat 3 | E16: =IF(INDEX(Korpus!$F:$F,$A16)="","",INDEX(Korpus!$F:$F,$A16)) -> 2) Undang-Undang Nomor 11 Tahun 2008 Tentang Informasi dan Transaksi Elektronik | P16: =IF(COUNTA(F16:K16)=6,"Lengkap","Belum lengkap ("&(6-COUNTA(F16:K16))&")") -> Belum lengkap (6) | Q16: =IF(COUNTA(F16:K16)<6,"",IF(IF(AND(LEFT(G16,2)="R0",LEFT(K16,2)<>"K5"),"R0 harus K5; ","")&IF(AND(LEFT(G16,2)="R1",LEFT(K16,2)="K3"),"R1 tidak boleh K3 (fungsional); ","")&IF(AND(LEFT(G16,2)="R2",LEFT(K16,2)="K5"),"R2 tidak boleh K5; ","")&IF(AND(LEFT(G16,2)="R2",OR(LEFT(F16,2)="S6",LEFT(F16,2)="S7",LEFT(F16,2)="S8")),"R2 tidak boleh S6/S7/S8; ","")&IF(AND(LEFT(G16,2)="R2",OR(LEFT(H16,3)="T02",LEFT(I16,2)="P8")),"T02 atau P8 tidak boleh R2; ","")&IF(AND(LEFT(H16,3)="T01",LEFT(I16,2)<>"P6",N16=""),"T01 biasanya P6; jelaskan di V12; ","")&IF(AND(LEFT(I16,2)="P1",LEFT(K16,2)<>"K4",N16=""),"P1 biasanya K4; jelaskan di V12; ","")="","OK",IF(AND(LEFT(G16,2)="R0",LEFT(K16,2)<>"K5"),"R0 harus K5; ","")&IF(AND(LEFT(G16,2)="R1",LEFT(K16,2)="K3"),"R1 tidak boleh K3 (fungsional); ","")&IF(AND(LEFT(G16,2)="R2",LEFT(K16,2)="K5"),"R2 tidak boleh K5; ","")&IF(AND(LEFT(G16,2)="R2",OR(LEFT(F16,2)="S6",LEFT(F16,2)="S7",LEFT(F16,2)="S8")),"R2 tidak boleh S6/S7/S8; ","")&IF(AND(LEFT(G16,2)="R2",OR(LEFT(H16,3)="T02",LEFT(I16,2)="P8")),"T02 atau P8 tidak boleh R2; ","")&IF(AND(LEFT(H16,3)="T01",LEFT(I16,2)<>"P6",N16=""),"T01 biasanya P6; jelaskan di V12; ","")&IF(AND(LEFT(I16,2)="P1",LEFT(K16,2)<>"K4",N16=""),"P1 biasanya K4; jelaskan di V12; ",""))) | R16: =IF(INDEX(Korpus!$B:$B,$A16)="","",INDEX(Korpus!$B:$B,$A16)) -> C. Pembahasan | S16: =IF(INDEX(Korpus!$C:$C,$A16)="","",INDEX(Korpus!$C:$C,$A16)) -> 5. Pentingnya Perlindungan Data Pribadi
A17: 17 | B17: =IF(Petunjuk!$C$4="","",Petunjuk!$C$4) -> Afriansyah | C17: =IF(INDEX(Korpus!$A:$A,$A17)="","",INDEX(Korpus!$A:$A,$A17)) -> 2019MHN201 | D17: =TRIM(INDEX(Korpus!$D:$D,$A17)&" "&INDEX(Korpus!$E:$E,$A17)) -> Paragraf 6 Kalimat 13 | E17: =IF(INDEX(Korpus!$F:$F,$A17)="","",INDEX(Korpus!$F:$F,$A17)) -> 12) Peraturan Menteri Komunikasi dan Informasi Nomor 20 Tahun 2016 Tentang Perlindungan Data Pribadi Dalam Sistem Elektronik | P17: =IF(COUNTA(F17:K17)=6,"Lengkap","Belum lengkap ("&(6-COUNTA(F17:K17))&")") -> Belum lengkap (6) | Q17: =IF(COUNTA(F17:K17)<6,"",IF(IF(AND(LEFT(G17,2)="R0",LEFT(K17,2)<>"K5"),"R0 harus K5; ","")&IF(AND(LEFT(G17,2)="R1",LEFT(K17,2)="K3"),"R1 tidak boleh K3 (fungsional); ","")&IF(AND(LEFT(G17,2)="R2",LEFT(K17,2)="K5"),"R2 tidak boleh K5; ","")&IF(AND(LEFT(G17,2)="R2",OR(LEFT(F17,2)="S6",LEFT(F17,2)="S7",LEFT(F17,2)="S8")),"R2 tidak boleh S6/S7/S8; ","")&IF(AND(LEFT(G17,2)="R2",OR(LEFT(H17,3)="T02",LEFT(I17,2)="P8")),"T02 atau P8 tidak boleh R2; ","")&IF(AND(LEFT(H17,3)="T01",LEFT(I17,2)<>"P6",N17=""),"T01 biasanya P6; jelaskan di V12; ","")&IF(AND(LEFT(I17,2)="P1",LEFT(K17,2)<>"K4",N17=""),"P1 biasanya K4; jelaskan di V12; ","")="","OK",IF(AND(LEFT(G17,2)="R0",LEFT(K17,2)<>"K5"),"R0 harus K5; ","")&IF(AND(LEFT(G17,2)="R1",LEFT(K17,2)="K3"),"R1 tidak boleh K3 (fungsional); ","")&IF(AND(LEFT(G17,2)="R2",LEFT(K17,2)="K5"),"R2 tidak boleh K5; ","")&IF(AND(LEFT(G17,2)="R2",OR(LEFT(F17,2)="S6",LEFT(F17,2)="S7",LEFT(F17,2)="S8")),"R2 tidak boleh S6/S7/S8; ","")&IF(AND(LEFT(G17,2)="R2",OR(LEFT(H17,3)="T02",LEFT(I17,2)="P8")),"T02 atau P8 tidak boleh R2; ","")&IF(AND(LEFT(H17,3)="T01",LEFT(I17,2)<>"P6",N17=""),"T01 biasanya P6; jelaskan di V12; ","")&IF(AND(LEFT(I17,2)="P1",LEFT(K17,2)<>"K4",N17=""),"P1 biasanya K4; jelaskan di V12; ",""))) | R17: =IF(INDEX(Korpus!$B:$B,$A17)="","",INDEX(Korpus!$B:$B,$A17)) -> C. Pembahasan | S17: =IF(INDEX(Korpus!$C:$C,$A17)="","",INDEX(Korpus!$C:$C,$A17)) -> 5. Pentingnya Perlindungan Data Pribadi
A18: 18 | B18: =IF(Petunjuk!$C$4="","",Petunjuk!$C$4) -> Afriansyah | C18: =IF(INDEX(Korpus!$A:$A,$A18)="","",INDEX(Korpus!$A:$A,$A18)) -> 2019MHN201 | D18: =TRIM(INDEX(Korpus!$D:$D,$A18)&" "&INDEX(Korpus!$E:$E,$A18)) -> Paragraf 6 Kalimat 14 | E18: =IF(INDEX(Korpus!$F:$F,$A18)="","",INDEX(Korpus!$F:$F,$A18)) -> 13) Peraturan Pemerintah Nomor 82 Tahun 2012 Tentang Penyelenggaraan Sistem dan Transaksi Elektronik | P18: =IF(COUNTA(F18:K18)=6,"Lengkap","Belum lengkap ("&(6-COUNTA(F18:K18))&")") -> Belum lengkap (6) | Q18: =IF(COUNTA(F18:K18)<6,"",IF(IF(AND(LEFT(G18,2)="R0",LEFT(K18,2)<>"K5"),"R0 harus K5; ","")&IF(AND(LEFT(G18,2)="R1",LEFT(K18,2)="K3"),"R1 tidak boleh K3 (fungsional); ","")&IF(AND(LEFT(G18,2)="R2",LEFT(K18,2)="K5"),"R2 tidak boleh K5; ","")&IF(AND(LEFT(G18,2)="R2",OR(LEFT(F18,2)="S6",LEFT(F18,2)="S7",LEFT(F18,2)="S8")),"R2 tidak boleh S6/S7/S8; ","")&IF(AND(LEFT(G18,2)="R2",OR(LEFT(H18,3)="T02",LEFT(I18,2)="P8")),"T02 atau P8 tidak boleh R2; ","")&IF(AND(LEFT(H18,3)="T01",LEFT(I18,2)<>"P6",N18=""),"T01 biasanya P6; jelaskan di V12; ","")&IF(AND(LEFT(I18,2)="P1",LEFT(K18,2)<>"K4",N18=""),"P1 biasanya K4; jelaskan di V12; ","")="","OK",IF(AND(LEFT(G18,2)="R0",LEFT(K18,2)<>"K5"),"R0 harus K5; ","")&IF(AND(LEFT(G18,2)="R1",LEFT(K18,2)="K3"),"R1 tidak boleh K3 (fungsional); ","")&IF(AND(LEFT(G18,2)="R2",LEFT(K18,2)="K5"),"R2 tidak boleh K5; ","")&IF(AND(LEFT(G18,2)="R2",OR(LEFT(F18,2)="S6",LEFT(F18,2)="S7",LEFT(F18,2)="S8")),"R2 tidak boleh S6/S7/S8; ","")&IF(AND(LEFT(G18,2)="R2",OR(LEFT(H18,3)="T02",LEFT(I18,2)="P8")),"T02 atau P8 tidak boleh R2; ","")&IF(AND(LEFT(H18,3)="T01",LEFT(I18,2)<>"P6",N18=""),"T01 biasanya P6; jelaskan di V12; ","")&IF(AND(LEFT(I18,2)="P1",LEFT(K18,2)<>"K4",N18=""),"P1 biasanya K4; jelaskan di V12; ",""))) | R18: =IF(INDEX(Korpus!$B:$B,$A18)="","",INDEX(Korpus!$B:$B,$A18)) -> C. Pembahasan | S18: =IF(INDEX(Korpus!$C:$C,$A18)="","",INDEX(Korpus!$C:$C,$A18)) -> 5. Pentingnya Perlindungan Data Pribadi
A19: 19 | B19: =IF(Petunjuk!$C$4="","",Petunjuk!$C$4) -> Afriansyah | C19: =IF(INDEX(Korpus!$A:$A,$A19)="","",INDEX(Korpus!$A:$A,$A19)) -> 2019MHN201 | D19: =TRIM(INDEX(Korpus!$D:$D,$A19)&" "&INDEX(Korpus!$E:$E,$A19)) -> Paragraf 6 Kalimat 16 | E19: =IF(INDEX(Korpus!$F:$F,$A19)="","",INDEX(Korpus!$F:$F,$A19)) -> 15) Peraturan Menteri Komunikasi dan Informasi Nomor 4 Tahun 2016 Tentang Sistem Manajemen Pengaman Informasi | P19: =IF(COUNTA(F19:K19)=6,"Lengkap","Belum lengkap ("&(6-COUNTA(F19:K19))&")") -> Belum lengkap (6) | Q19: =IF(COUNTA(F19:K19)<6,"",IF(IF(AND(LEFT(G19,2)="R0",LEFT(K19,2)<>"K5"),"R0 harus K5; ","")&IF(AND(LEFT(G19,2)="R1",LEFT(K19,2)="K3"),"R1 tidak boleh K3 (fungsional); ","")&IF(AND(LEFT(G19,2)="R2",LEFT(K19,2)="K5"),"R2 tidak boleh K5; ","")&IF(AND(LEFT(G19,2)="R2",OR(LEFT(F19,2)="S6",LEFT(F19,2)="S7",LEFT(F19,2)="S8")),"R2 tidak boleh S6/S7/S8; ","")&IF(AND(LEFT(G19,2)="R2",OR(LEFT(H19,3)="T02",LEFT(I19,2)="P8")),"T02 atau P8 tidak boleh R2; ","")&IF(AND(LEFT(H19,3)="T01",LEFT(I19,2)<>"P6",N19=""),"T01 biasanya P6; jelaskan di V12; ","")&IF(AND(LEFT(I19,2)="P1",LEFT(K19,2)<>"K4",N19=""),"P1 biasanya K4; jelaskan di V12; ","")="","OK",IF(AND(LEFT(G19,2)="R0",LEFT(K19,2)<>"K5"),"R0 harus K5; ","")&IF(AND(LEFT(G19,2)="R1",LEFT(K19,2)="K3"),"R1 tidak boleh K3 (fungsional); ","")&IF(AND(LEFT(G19,2)="R2",LEFT(K19,2)="K5"),"R2 tidak boleh K5; ","")&IF(AND(LEFT(G19,2)="R2",OR(LEFT(F19,2)="S6",LEFT(F19,2)="S7",LEFT(F19,2)="S8")),"R2 tidak boleh S6/S7/S8; ","")&IF(AND(LEFT(G19,2)="R2",OR(LEFT(H19,3)="T02",LEFT(I19,2)="P8")),"T02 atau P8 tidak boleh R2; ","")&IF(AND(LEFT(H19,3)="T01",LEFT(I19,2)<>"P6",N19=""),"T01 biasanya P6; jelaskan di V12; ","")&IF(AND(LEFT(I19,2)="P1",LEFT(K19,2)<>"K4",N19=""),"P1 biasanya K4; jelaskan di V12; ",""))) | R19: =IF(INDEX(Korpus!$B:$B,$A19)="","",INDEX(Korpus!$B:$B,$A19)) -> C. Pembahasan | S19: =IF(INDEX(Korpus!$C:$C,$A19)="","",INDEX(Korpus!$C:$C,$A19)) -> 5. Pentingnya Perlindungan Data Pribadi
A20: 20 | B20: =IF(Petunjuk!$C$4="","",Petunjuk!$C$4) -> Afriansyah | C20: =IF(INDEX(Korpus!$A:$A,$A20)="","",INDEX(Korpus!$A:$A,$A20)) -> 2019MHN201 | D20: =TRIM(INDEX(Korpus!$D:$D,$A20)&" "&INDEX(Korpus!$E:$E,$A20)) -> Paragraf 7 Kalimat 2 | E20: =IF(INDEX(Korpus!$F:$F,$A20)="","",INDEX(Korpus!$F:$F,$A20)) -> Dalam Pasal 26 huruf a disebutkan bahwa menjaga kerahasiaan, keutuhan, dan ketersediaan data pribadi, data transaksi, dan data keuangan yang dikelolanya sejak data diperoleh hingga data tersebut dimusnahkan. | P20: =IF(COUNTA(F20:K20)=6,"Lengkap","Belum lengkap ("&(6-COUNTA(F20:K20))&")") -> Belum lengkap (6) | Q20: =IF(COUNTA(F20:K20)<6,"",IF(IF(AND(LEFT(G20,2)="R0",LEFT(K20,2)<>"K5"),"R0 harus K5; ","")&IF(AND(LEFT(G20,2)="R1",LEFT(K20,2)="K3"),"R1 tidak boleh K3 (fungsional); ","")&IF(AND(LEFT(G20,2)="R2",LEFT(K20,2)="K5"),"R2 tidak boleh K5; ","")&IF(AND(LEFT(G20,2)="R2",OR(LEFT(F20,2)="S6",LEFT(F20,2)="S7",LEFT(F20,2)="S8")),"R2 tidak boleh S6/S7/S8; ","")&IF(AND(LEFT(G20,2)="R2",OR(LEFT(H20,3)="T02",LEFT(I20,2)="P8")),"T02 atau P8 tidak boleh R2; ","")&IF(AND(LEFT(H20,3)="T01",LEFT(I20,2)<>"P6",N20=""),"T01 biasanya P6; jelaskan di V12; ","")&IF(AND(LEFT(I20,2)="P1",LEFT(K20,2)<>"K4",N20=""),"P1 biasanya K4; jelaskan di V12; ","")="","OK",IF(AND(LEFT(G20,2)="R0",LEFT(K20,2)<>"K5"),"R0 harus K5; ","")&IF(AND(LEFT(G20,2)="R1",LEFT(K20,2)="K3"),"R1 tidak boleh K3 (fungsional); ","")&IF(AND(LEFT(G20,2)="R2",LEFT(K20,2)="K5"),"R2 tidak boleh K5; ","")&IF(AND(LEFT(G20,2)="R2",OR(LEFT(F20,2)="S6",LEFT(F20,2)="S7",LEFT(F20,2)="S8")),"R2 tidak boleh S6/S7/S8; ","")&IF(AND(LEFT(G20,2)="R2",OR(LEFT(H20,3)="T02",LEFT(I20,2)="P8")),"T02 atau P8 tidak boleh R2; ","")&IF(AND(LEFT(H20,3)="T01",LEFT(I20,2)<>"P6",N20=""),"T01 biasanya P6; jelaskan di V12; ","")&IF(AND(LEFT(I20,2)="P1",LEFT(K20,2)<>"K4",N20=""),"P1 biasanya K4; jelaskan di V12; ",""))) | R20: =IF(INDEX(Korpus!$B:$B,$A20)="","",INDEX(Korpus!$B:$B,$A20)) -> C. Pembahasan | S20: =IF(INDEX(Korpus!$C:$C,$A20)="","",INDEX(Korpus!$C:$C,$A20)) -> 5. Pentingnya Perlindungan Data Pribadi
A21: 21 | B21: =IF(Petunjuk!$C$4="","",Petunjuk!$C$4) -> Afriansyah | C21: =IF(INDEX(Korpus!$A:$A,$A21)="","",INDEX(Korpus!$A:$A,$A21)) -> 2019MHN201 | D21: =TRIM(INDEX(Korpus!$D:$D,$A21)&" "&INDEX(Korpus!$E:$E,$A21)) -> Paragraf 7 Kalimat 3 | E21: =IF(INDEX(Korpus!$F:$F,$A21)="","",INDEX(Korpus!$F:$F,$A21)) -> Selain itu Peraturan OJK Nomor 13 Tahun 2018 Tentang Inovasi Keuangan Digital di Sektor Keuangan, telah memasukkan poin terkait perlindungan dan kerahasiaan data. | F21: S7 - Otoritas Penetap atau Pengawas Kebijakan | I21: P8 - Deskriptif, argumentatif, dan rujukan | J21: F7 - Tata kelola dan hak subjek | O21: Ya | P21: =IF(COUNTA(F21:K21)=6,"Lengkap","Belum lengkap ("&(6-COUNTA(F21:K21))&")") -> Belum lengkap (3) | Q21: =IF(COUNTA(F21:K21)<6,"",IF(IF(AND(LEFT(G21,2)="R0",LEFT(K21,2)<>"K5"),"R0 harus K5; ","")&IF(AND(LEFT(G21,2)="R1",LEFT(K21,2)="K3"),"R1 tidak boleh K3 (fungsional); ","")&IF(AND(LEFT(G21,2)="R2",LEFT(K21,2)="K5"),"R2 tidak boleh K5; ","")&IF(AND(LEFT(G21,2)="R2",OR(LEFT(F21,2)="S6",LEFT(F21,2)="S7",LEFT(F21,2)="S8")),"R2 tidak boleh S6/S7/S8; ","")&IF(AND(LEFT(G21,2)="R2",OR(LEFT(H21,3)="T02",LEFT(I21,2)="P8")),"T02 atau P8 tidak boleh R2; ","")&IF(AND(LEFT(H21,3)="T01",LEFT(I21,2)<>"P6",N21=""),"T01 biasanya P6; jelaskan di V12; ","")&IF(AND(LEFT(I21,2)="P1",LEFT(K21,2)<>"K4",N21=""),"P1 biasanya K4; jelaskan di V12; ","")="","OK",IF(AND(LEFT(G21,2)="R0",LEFT(K21,2)<>"K5"),"R0 harus K5; ","")&IF(AND(LEFT(G21,2)="R1",LEFT(K21,2)="K3"),"R1 tidak boleh K3 (fungsional); ","")&IF(AND(LEFT(G21,2)="R2",LEFT(K21,2)="K5"),"R2 tidak boleh K5; ","")&IF(AND(LEFT(G21,2)="R2",OR(LEFT(F21,2)="S6",LEFT(F21,2)="S7",LEFT(F21,2)="S8")),"R2 tidak boleh S6/S7/S8; ","")&IF(AND(LEFT(G21,2)="R2",OR(LEFT(H21,3)="T02",LEFT(I21,2)="P8")),"T02 atau P8 tidak boleh R2; ","")&IF(AND(LEFT(H21,3)="T01",LEFT(I21,2)<>"P6",N21=""),"T01 biasanya P6; jelaskan di V12; ","")&IF(AND(LEFT(I21,2)="P1",LEFT(K21,2)<>"K4",N21=""),"P1 biasanya K4; jelaskan di V12; ",""))) | R21: =IF(INDEX(Korpus!$B:$B,$A21)="","",INDEX(Korpus!$B:$B,$A21)) -> C. Pembahasan | S21: =IF(INDEX(Korpus!$C:$C,$A21)="","",INDEX(Korpus!$C:$C,$A21)) -> 5. Pentingnya Perlindungan Data Pribadi
A22: 22 | B22: =IF(Petunjuk!$C$4="","",Petunjuk!$C$4) -> Afriansyah | C22: =IF(INDEX(Korpus!$A:$A,$A22)="","",INDEX(Korpus!$A:$A,$A22)) -> 2019MHN201 | D22: =TRIM(INDEX(Korpus!$D:$D,$A22)&" "&INDEX(Korpus!$E:$E,$A22)) -> Paragraf 7 Kalimat 4 | E22: =IF(INDEX(Korpus!$F:$F,$A22)="","",INDEX(Korpus!$F:$F,$A22)) -> Pasal 30 ayat (1) menyebutkan bahwa Penyelenggara wajib menjaga kerahasiaan data pribadi, data transaksi, dan data keuangan yang dikelolanya sejak diperoleh hingga data tersebut dimusnahkan. | P22: =IF(COUNTA(F22:K22)=6,"Lengkap","Belum lengkap ("&(6-COUNTA(F22:K22))&")") -> Belum lengkap (6) | Q22: =IF(COUNTA(F22:K22)<6,"",IF(IF(AND(LEFT(G22,2)="R0",LEFT(K22,2)<>"K5"),"R0 harus K5; ","")&IF(AND(LEFT(G22,2)="R1",LEFT(K22,2)="K3"),"R1 tidak boleh K3 (fungsional); ","")&IF(AND(LEFT(G22,2)="R2",LEFT(K22,2)="K5"),"R2 tidak boleh K5; ","")&IF(AND(LEFT(G22,2)="R2",OR(LEFT(F22,2)="S6",LEFT(F22,2)="S7",LEFT(F22,2)="S8")),"R2 tidak boleh S6/S7/S8; ","")&IF(AND(LEFT(G22,2)="R2",OR(LEFT(H22,3)="T02",LEFT(I22,2)="P8")),"T02 atau P8 tidak boleh R2; ","")&IF(AND(LEFT(H22,3)="T01",LEFT(I22,2)<>"P6",N22=""),"T01 biasanya P6; jelaskan di V12; ","")&IF(AND(LEFT(I22,2)="P1",LEFT(K22,2)<>"K4",N22=""),"P1 biasanya K4; jelaskan di V12; ","")="","OK",IF(AND(LEFT(G22,2)="R0",LEFT(K22,2)<>"K5"),"R0 harus K5; ","")&IF(AND(LEFT(G22,2)="R1",LEFT(K22,2)="K3"),"R1 tidak boleh K3 (fungsional); ","")&IF(AND(LEFT(G22,2)="R2",LEFT(K22,2)="K5"),"R2 tidak boleh K5; ","")&IF(AND(LEFT(G22,2)="R2",OR(LEFT(F22,2)="S6",LEFT(F22,2)="S7",LEFT(F22,2)="S8")),"R2 tidak boleh S6/S7/S8; ","")&IF(AND(LEFT(G22,2)="R2",OR(LEFT(H22,3)="T02",LEFT(I22,2)="P8")),"T02 atau P8 tidak boleh R2; ","")&IF(AND(LEFT(H22,3)="T01",LEFT(I22,2)<>"P6",N22=""),"T01 biasanya P6; jelaskan di V12; ","")&IF(AND(LEFT(I22,2)="P1",LEFT(K22,2)<>"K4",N22=""),"P1 biasanya K4; jelaskan di V12; ",""))) | R22: =IF(INDEX(Korpus!$B:$B,$A22)="","",INDEX(Korpus!$B:$B,$A22)) -> C. Pembahasan | S22: =IF(INDEX(Korpus!$C:$C,$A22)="","",INDEX(Korpus!$C:$C,$A22)) -> 5. Pentingnya Perlindungan Data Pribadi
A23: 23 | B23: =IF(Petunjuk!$C$4="","",Petunjuk!$C$4) -> Afriansyah | C23: =IF(INDEX(Korpus!$A:$A,$A23)="","",INDEX(Korpus!$A:$A,$A23)) -> 2019MHN201 | D23: =TRIM(INDEX(Korpus!$D:$D,$A23)&" "&INDEX(Korpus!$E:$E,$A23)) -> Paragraf 8 Kalimat 1 | E23: =IF(INDEX(Korpus!$F:$F,$A23)="","",INDEX(Korpus!$F:$F,$A23)) -> Banyaknya peraturan yang mengatur tentang perlindungan data pribadi menunjukkan pentingnya data pribadi untuk dilindungi. | P23: =IF(COUNTA(F23:K23)=6,"Lengkap","Belum lengkap ("&(6-COUNTA(F23:K23))&")") -> Belum lengkap (6) | Q23: =IF(COUNTA(F23:K23)<6,"",IF(IF(AND(LEFT(G23,2)="R0",LEFT(K23,2)<>"K5"),"R0 harus K5; ","")&IF(AND(LEFT(G23,2)="R1",LEFT(K23,2)="K3"),"R1 tidak boleh K3 (fungsional); ","")&IF(AND(LEFT(G23,2)="R2",LEFT(K23,2)="K5"),"R2 tidak boleh K5; ","")&IF(AND(LEFT(G23,2)="R2",OR(LEFT(F23,2)="S6",LEFT(F23,2)="S7",LEFT(F23,2)="S8")),"R2 tidak boleh S6/S7/S8; ","")&IF(AND(LEFT(G23,2)="R2",OR(LEFT(H23,3)="T02",LEFT(I23,2)="P8")),"T02 atau P8 tidak boleh R2; ","")&IF(AND(LEFT(H23,3)="T01",LEFT(I23,2)<>"P6",N23=""),"T01 biasanya P6; jelaskan di V12; ","")&IF(AND(LEFT(I23,2)="P1",LEFT(K23,2)<>"K4",N23=""),"P1 biasanya K4; jelaskan di V12; ","")="","OK",IF(AND(LEFT(G23,2)="R0",LEFT(K23,2)<>"K5"),"R0 harus K5; ","")&IF(AND(LEFT(G23,2)="R1",LEFT(K23,2)="K3"),"R1 tidak boleh K3 (fungsional); ","")&IF(AND(LEFT(G23,2)="R2",LEFT(K23,2)="K5"),"R2 tidak boleh K5; ","")&IF(AND(LEFT(G23,2)="R2",OR(LEFT(F23,2)="S6",LEFT(F23,2)="S7",LEFT(F23,2)="S8")),"R2 tidak boleh S6/S7/S8; ","")&IF(AND(LEFT(G23,2)="R2",OR(LEFT(H23,3)="T02",LEFT(I23,2)="P8")),"T02 atau P8 tidak boleh R2; ","")&IF(AND(LEFT(H23,3)="T01",LEFT(I23,2)<>"P6",N23=""),"T01 biasanya P6; jelaskan di V12; ","")&IF(AND(LEFT(I23,2)="P1",LEFT(K23,2)<>"K4",N23=""),"P1 biasanya K4; jelaskan di V12; ",""))) | R23: =IF(INDEX(Korpus!$B:$B,$A23)="","",INDEX(Korpus!$B:$B,$A23)) -> C. Pembahasan | S23: =IF(INDEX(Korpus!$C:$C,$A23)="","",INDEX(Korpus!$C:$C,$A23)) -> 5. Pentingnya Perlindungan Data Pribadi
A24: 24 | B24: =IF(Petunjuk!$C$4="","",Petunjuk!$C$4) -> Afriansyah | C24: =IF(INDEX(Korpus!$A:$A,$A24)="","",INDEX(Korpus!$A:$A,$A24)) -> 2019MHN201 | D24: =TRIM(INDEX(Korpus!$D:$D,$A24)&" "&INDEX(Korpus!$E:$E,$A24)) -> Paragraf 8 Kalimat 3 | E24: =IF(INDEX(Korpus!$F:$F,$A24)="","",INDEX(Korpus!$F:$F,$A24)) -> Oleh karena itu perlu disusun suatu undang-undang yang secara khusus dapat memberikan perlindungan data pribadi. | P24: =IF(COUNTA(F24:K24)=6,"Lengkap","Belum lengkap ("&(6-COUNTA(F24:K24))&")") -> Belum lengkap (6) | Q24: =IF(COUNTA(F24:K24)<6,"",IF(IF(AND(LEFT(G24,2)="R0",LEFT(K24,2)<>"K5"),"R0 harus K5; ","")&IF(AND(LEFT(G24,2)="R1",LEFT(K24,2)="K3"),"R1 tidak boleh K3 (fungsional); ","")&IF(AND(LEFT(G24,2)="R2",LEFT(K24,2)="K5"),"R2 tidak boleh K5; ","")&IF(AND(LEFT(G24,2)="R2",OR(LEFT(F24,2)="S6",LEFT(F24,2)="S7",LEFT(F24,2)="S8")),"R2 tidak boleh S6/S7/S8; ","")&IF(AND(LEFT(G24,2)="R2",OR(LEFT(H24,3)="T02",LEFT(I24,2)="P8")),"T02 atau P8 tidak boleh R2; ","")&IF(AND(LEFT(H24,3)="T01",LEFT(I24,2)<>"P6",N24=""),"T01 biasanya P6; jelaskan di V12; ","")&IF(AND(LEFT(I24,2)="P1",LEFT(K24,2)<>"K4",N24=""),"P1 biasanya K4; jelaskan di V12; ","")="","OK",IF(AND(LEFT(G24,2)="R0",LEFT(K24,2)<>"K5"),"R0 harus K5; ","")&IF(AND(LEFT(G24,2)="R1",LEFT(K24,2)="K3"),"R1 tidak boleh K3 (fungsional); ","")&IF(AND(LEFT(G24,2)="R2",LEFT(K24,2)="K5"),"R2 tidak boleh K5; ","")&IF(AND(LEFT(G24,2)="R2",OR(LEFT(F24,2)="S6",LEFT(F24,2)="S7",LEFT(F24,2)="S8")),"R2 tidak boleh S6/S7/S8; ","")&IF(AND(LEFT(G24,2)="R2",OR(LEFT(H24,3)="T02",LEFT(I24,2)="P8")),"T02 atau P8 tidak boleh R2; ","")&IF(AND(LEFT(H24,3)="T01",LEFT(I24,2)<>"P6",N24=""),"T01 biasanya P6; jelaskan di V12; ","")&IF(AND(LEFT(I24,2)="P1",LEFT(K24,2)<>"K4",N24=""),"P1 biasanya K4; jelaskan di V12; ",""))) | R24: =IF(INDEX(Korpus!$B:$B,$A24)="","",INDEX(Korpus!$B:$B,$A24)) -> C. Pembahasan | S24: =IF(INDEX(Korpus!$C:$C,$A24)="","",INDEX(Korpus!$C:$C,$A24)) -> 5. Pentingnya Perlindungan Data Pribadi
A25: 25 | B25: =IF(Petunjuk!$C$4="","",Petunjuk!$C$4) -> Afriansyah | C25: =IF(INDEX(Korpus!$A:$A,$A25)="","",INDEX(Korpus!$A:$A,$A25)) -> 2019MHN201 | D25: =TRIM(INDEX(Korpus!$D:$D,$A25)&" "&INDEX(Korpus!$E:$E,$A25)) -> Paragraf 1 Kalimat 3 | E25: =IF(INDEX(Korpus!$F:$F,$A25)="","",INDEX(Korpus!$F:$F,$A25)) -> Selain itu juga sudah ada Peraturan Menteri Nomor 20 Tahun 2016 tentang Perlindungan Data Pribadi namun belum cukup memberikan perlindungan kepada konsumen. | F25: S7 - Otoritas Penetap atau Pengawas Kebijakan | J25: F7 - Tata kelola dan hak subjek | K25: K4 - Batasan atau aturan bisnis hukum. Apakah teks membatasi apa yang boleh dilakukan sistem, atau apa dan siapa yang tercakup? | O25: Ya | P25: =IF(COUNTA(F25:K25)=6,"Lengkap","Belum lengkap ("&(6-COUNTA(F25:K25))&")") -> Belum lengkap (3) | Q25: =IF(COUNTA(F25:K25)<6,"",IF(IF(AND(LEFT(G25,2)="R0",LEFT(K25,2)<>"K5"),"R0 harus K5; ","")&IF(AND(LEFT(G25,2)="R1",LEFT(K25,2)="K3"),"R1 tidak boleh K3 (fungsional); ","")&IF(AND(LEFT(G25,2)="R2",LEFT(K25,2)="K5"),"R2 tidak boleh K5; ","")&IF(AND(LEFT(G25,2)="R2",OR(LEFT(F25,2)="S6",LEFT(F25,2)="S7",LEFT(F25,2)="S8")),"R2 tidak boleh S6/S7/S8; ","")&IF(AND(LEFT(G25,2)="R2",OR(LEFT(H25,3)="T02",LEFT(I25,2)="P8")),"T02 atau P8 tidak boleh R2; ","")&IF(AND(LEFT(H25,3)="T01",LEFT(I25,2)<>"P6",N25=""),"T01 biasanya P6; jelaskan di V12; ","")&IF(AND(LEFT(I25,2)="P1",LEFT(K25,2)<>"K4",N25=""),"P1 biasanya K4; jelaskan di V12; ","")="","OK",IF(AND(LEFT(G25,2)="R0",LEFT(K25,2)<>"K5"),"R0 harus K5; ","")&IF(AND(LEFT(G25,2)="R1",LEFT(K25,2)="K3"),"R1 tidak boleh K3 (fungsional); ","")&IF(AND(LEFT(G25,2)="R2",LEFT(K25,2)="K5"),"R2 tidak boleh K5; ","")&IF(AND(LEFT(G25,2)="R2",OR(LEFT(F25,2)="S6",LEFT(F25,2)="S7",LEFT(F25,2)="S8")),"R2 tidak boleh S6/S7/S8; ","")&IF(AND(LEFT(G25,2)="R2",OR(LEFT(H25,3)="T02",LEFT(I25,2)="P8")),"T02 atau P8 tidak boleh R2; ","")&IF(AND(LEFT(H25,3)="T01",LEFT(I25,2)<>"P6",N25=""),"T01 biasanya P6; jelaskan di V12; ","")&IF(AND(LEFT(I25,2)="P1",LEFT(K25,2)<>"K4",N25=""),"P1 biasanya K4; jelaskan di V12; ",""))) | R25: =IF(INDEX(Korpus!$B:$B,$A25)="","",INDEX(Korpus!$B:$B,$A25)) -> D. Penutup | S25: =IF(INDEX(Korpus!$C:$C,$A25)="","",INDEX(Korpus!$C:$C,$A25))
A26: 26 | B26: =IF(Petunjuk!$C$4="","",Petunjuk!$C$4) -> Afriansyah | C26: =IF(INDEX(Korpus!$A:$A,$A26)="","",INDEX(Korpus!$A:$A,$A26)) -> 2019MHN201 | D26: =TRIM(INDEX(Korpus!$D:$D,$A26)&" "&INDEX(Korpus!$E:$E,$A26)) -> Paragraf 1 Kalimat 4 | E26: =IF(INDEX(Korpus!$F:$F,$A26)="","",INDEX(Korpus!$F:$F,$A26)) -> Oleh karenanya Pemerintah perlu segera memberikan perlindungan data pribadi nasabah agar tidak disalahgunakan. | P26: =IF(COUNTA(F26:K26)=6,"Lengkap","Belum lengkap ("&(6-COUNTA(F26:K26))&")") -> Belum lengkap (6) | Q26: =IF(COUNTA(F26:K26)<6,"",IF(IF(AND(LEFT(G26,2)="R0",LEFT(K26,2)<>"K5"),"R0 harus K5; ","")&IF(AND(LEFT(G26,2)="R1",LEFT(K26,2)="K3"),"R1 tidak boleh K3 (fungsional); ","")&IF(AND(LEFT(G26,2)="R2",LEFT(K26,2)="K5"),"R2 tidak boleh K5; ","")&IF(AND(LEFT(G26,2)="R2",OR(LEFT(F26,2)="S6",LEFT(F26,2)="S7",LEFT(F26,2)="S8")),"R2 tidak boleh S6/S7/S8; ","")&IF(AND(LEFT(G26,2)="R2",OR(LEFT(H26,3)="T02",LEFT(I26,2)="P8")),"T02 atau P8 tidak boleh R2; ","")&IF(AND(LEFT(H26,3)="T01",LEFT(I26,2)<>"P6",N26=""),"T01 biasanya P6; jelaskan di V12; ","")&IF(AND(LEFT(I26,2)="P1",LEFT(K26,2)<>"K4",N26=""),"P1 biasanya K4; jelaskan di V12; ","")="","OK",IF(AND(LEFT(G26,2)="R0",LEFT(K26,2)<>"K5"),"R0 harus K5; ","")&IF(AND(LEFT(G26,2)="R1",LEFT(K26,2)="K3"),"R1 tidak boleh K3 (fungsional); ","")&IF(AND(LEFT(G26,2)="R2",LEFT(K26,2)="K5"),"R2 tidak boleh K5; ","")&IF(AND(LEFT(G26,2)="R2",OR(LEFT(F26,2)="S6",LEFT(F26,2)="S7",LEFT(F26,2)="S8")),"R2 tidak boleh S6/S7/S8; ","")&IF(AND(LEFT(G26,2)="R2",OR(LEFT(H26,3)="T02",LEFT(I26,2)="P8")),"T02 atau P8 tidak boleh R2; ","")&IF(AND(LEFT(H26,3)="T01",LEFT(I26,2)<>"P6",N26=""),"T01 biasanya P6; jelaskan di V12; ","")&IF(AND(LEFT(I26,2)="P1",LEFT(K26,2)<>"K4",N26=""),"P1 biasanya K4; jelaskan di V12; ",""))) | R26: =IF(INDEX(Korpus!$B:$B,$A26)="","",INDEX(Korpus!$B:$B,$A26)) -> D. Penutup | S26: =IF(INDEX(Korpus!$C:$C,$A26)="","",INDEX(Korpus!$C:$C,$A26))
A27: 27 | B27: =IF(Petunjuk!$C$4="","",Petunjuk!$C$4) -> Afriansyah | C27: =IF(INDEX(Korpus!$A:$A,$A27)="","",INDEX(Korpus!$A:$A,$A27)) -> UU 23 Thn 2002 (Perlindungan Anak) | D27: =TRIM(INDEX(Korpus!$D:$D,$A27)&" "&INDEX(Korpus!$E:$E,$A27)) -> Pasal 27 | E27: =IF(INDEX(Korpus!$F:$F,$A27)="","",INDEX(Korpus!$F:$F,$A27)) -> (1) Identitas diri setiap anak harus diberikan sejak kelahirannya.(2) Identitas sebagaimana dimaksud dalam ayat (1) dituangkan dalam akta kelahiran.(3) Pembuatan akta kelahiran didasarkan pada surat keterangan dari orang yang menyaksikan dan/atau membantu proses kelahiran. Dalam hal anak yang proses kelahirannya tidak diketahui, dan orang tuanya tidak diketahui keberadaannya, pembuatan akta kelahiran untuk anak tersebut didasarkan pada keterangan orang yang menemukannya. | P27: =IF(COUNTA(F27:K27)=6,"Lengkap","Belum lengkap ("&(6-COUNTA(F27:K27))&")") -> Belum lengkap (6) | Q27: =IF(COUNTA(F27:K27)<6,"",IF(IF(AND(LEFT(G27,2)="R0",LEFT(K27,2)<>"K5"),"R0 harus K5; ","")&IF(AND(LEFT(G27,2)="R1",LEFT(K27,2)="K3"),"R1 tidak boleh K3 (fungsional); ","")&IF(AND(LEFT(G27,2)="R2",LEFT(K27,2)="K5"),"R2 tidak boleh K5; ","")&IF(AND(LEFT(G27,2)="R2",OR(LEFT(F27,2)="S6",LEFT(F27,2)="S7",LEFT(F27,2)="S8")),"R2 tidak boleh S6/S7/S8; ","")&IF(AND(LEFT(G27,2)="R2",OR(LEFT(H27,3)="T02",LEFT(I27,2)="P8")),"T02 atau P8 tidak boleh R2; ","")&IF(AND(LEFT(H27,3)="T01",LEFT(I27,2)<>"P6",N27=""),"T01 biasanya P6; jelaskan di V12; ","")&IF(AND(LEFT(I27,2)="P1",LEFT(K27,2)<>"K4",N27=""),"P1 biasanya K4; jelaskan di V12; ","")="","OK",IF(AND(LEFT(G27,2)="R0",LEFT(K27,2)<>"K5"),"R0 harus K5; ","")&IF(AND(LEFT(G27,2)="R1",LEFT(K27,2)="K3"),"R1 tidak boleh K3 (fungsional); ","")&IF(AND(LEFT(G27,2)="R2",LEFT(K27,2)="K5"),"R2 tidak boleh K5; ","")&IF(AND(LEFT(G27,2)="R2",OR(LEFT(F27,2)="S6",LEFT(F27,2)="S7",LEFT(F27,2)="S8")),"R2 tidak boleh S6/S7/S8; ","")&IF(AND(LEFT(G27,2)="R2",OR(LEFT(H27,3)="T02",LEFT(I27,2)="P8")),"T02 atau P8 tidak boleh R2; ","")&IF(AND(LEFT(H27,3)="T01",LEFT(I27,2)<>"P6",N27=""),"T01 biasanya P6; jelaskan di V12; ","")&IF(AND(LEFT(I27,2)="P1",LEFT(K27,2)<>"K4",N27=""),"P1 biasanya K4; jelaskan di V12; ",""))) | R27: =IF(INDEX(Korpus!$B:$B,$A27)="","",INDEX(Korpus!$B:$B,$A27)) -> BAB V KEDUDUKAN ANAK | S27: =IF(INDEX(Korpus!$C:$C,$A27)="","",INDEX(Korpus!$C:$C,$A27)) -> Bagian Kesatu Identitas Anak
A28: 28 | B28: =IF(Petunjuk!$C$4="","",Petunjuk!$C$4) -> Afriansyah | C28: =IF(INDEX(Korpus!$A:$A,$A28)="","",INDEX(Korpus!$A:$A,$A28)) -> UU 27 Thn 2022 (PDP) | D28: =TRIM(INDEX(Korpus!$D:$D,$A28)&" "&INDEX(Korpus!$E:$E,$A28)) -> Pasal 1 | E28: =IF(INDEX(Korpus!$F:$F,$A28)="","",INDEX(Korpus!$F:$F,$A28)) -> Dalam Undang-Undang ini yang dimaksud dengan: 1. Data Pribadi adalah data tentang orang perseorangan yang teridentifikasi atau dapat diidentifikasi secara tersendiri atau dikombinasi dengan informasi lainnya baik secara langsung maupun tidak langsung melalui sistem elektronik atau nonelektronik. 2. Pelindungan Data Pribadi adalah keseluruhan upaya untuk melindungi Data Pribadi dalam rangkaian pemrosesan Data Pribadi guna menjamin hak konstitusional subjek Data Pribadi. 3. Informasi adalah keterangan, pernyataan, gagasan, dan tanda-tanda yang mengandung nilai, makna, dan pesan, baik data, fakta, maupun penjelasannya yang dapat dilihat, didengar, dan dibaca yang disajikan dalam berbagai kemasan dan format sesuai dengan perkembangan teknologi informasi dan komunikasi secara elektronik ataupun nonelektronik. 4. Pengendali Data Pribadi adalah setiap orang, badan publik, dan organisasi internasional yang bertindak sendiri-sendiri atau bersama-sama dalam menentukan tujuan dan melakukan kendali pemrosesan Data Pribadi. 5. Prosesor Data Pribadi adalah setiap orang, badan publik, dan organisasi internasional yang bertindak sendiri-sendiri atau bersama-sama dalam melakukan pemrosesan Data Pribadi atas nama Pengendali Data Pribadi. 6. Subjek Data Pribadi adalah orang perseorangan yang pada dirinya melekat Data Pribadi. 7. Setiap Orang adalah orang perseorangan atau korporasi. 8. Korporasi adalah kumpulan orang dan/ atau kekayaan yang terorganisasi baik yang berbadan hukum maupun tidak berbadan hukum. 9. Badan Publik adalah lembaga eksekutif, legislatif, yudikatif, dan badan lain yang fungsi dan tugas pokoknya berkaitan dengan penyelenggaraan negara, yang sebagian atau seluruh dananya bersumber dari Anggaran Pendapatan dan Belanja Negara dan/ atau Anggaran Pendapatan dan Belanja Daerah, atau organisasi nonpemerintah sepanjang sebagian atau seluruh dananya bersumber dari Anggaran Pendapatan dan Belanja Negara dan/ atau Anggaran. Pendapatan dan Belanja Daerah, sumbangan masyarakat, dan/atau luar negeri. 10. Organisasi Internasional adalah organisasi yang diakui sebagai subjek hukum internasional dan mempunyai kapasitas untuk membuat perjanjian internasional. | P28: =IF(COUNTA(F28:K28)=6,"Lengkap","Belum lengkap ("&(6-COUNTA(F28:K28))&")") -> Belum lengkap (6) | Q28: =IF(COUNTA(F28:K28)<6,"",IF(IF(AND(LEFT(G28,2)="R0",LEFT(K28,2)<>"K5"),"R0 harus K5; ","")&IF(AND(LEFT(G28,2)="R1",LEFT(K28,2)="K3"),"R1 tidak boleh K3 (fungsional); ","")&IF(AND(LEFT(G28,2)="R2",LEFT(K28,2)="K5"),"R2 tidak boleh K5; ","")&IF(AND(LEFT(G28,2)="R2",OR(LEFT(F28,2)="S6",LEFT(F28,2)="S7",LEFT(F28,2)="S8")),"R2 tidak boleh S6/S7/S8; ","")&IF(AND(LEFT(G28,2)="R2",OR(LEFT(H28,3)="T02",LEFT(I28,2)="P8")),"T02 atau P8 tidak boleh R2; ","")&IF(AND(LEFT(H28,3)="T01",LEFT(I28,2)<>"P6",N28=""),"T01 biasanya P6; jelaskan di V12; ","")&IF(AND(LEFT(I28,2)="P1",LEFT(K28,2)<>"K4",N28=""),"P1 biasanya K4; jelaskan di V12; ","")="","OK",IF(AND(LEFT(G28,2)="R0",LEFT(K28,2)<>"K5"),"R0 harus K5; ","")&IF(AND(LEFT(G28,2)="R1",LEFT(K28,2)="K3"),"R1 tidak boleh K3 (fungsional); ","")&IF(AND(LEFT(G28,2)="R2",LEFT(K28,2)="K5"),"R2 tidak boleh K5; ","")&IF(AND(LEFT(G28,2)="R2",OR(LEFT(F28,2)="S6",LEFT(F28,2)="S7",LEFT(F28,2)="S8")),"R2 tidak boleh S6/S7/S8; ","")&IF(AND(LEFT(G28,2)="R2",OR(LEFT(H28,3)="T02",LEFT(I28,2)="P8")),"T02 atau P8 tidak boleh R2; ","")&IF(AND(LEFT(H28,3)="T01",LEFT(I28,2)<>"P6",N28=""),"T01 biasanya P6; jelaskan di V12; ","")&IF(AND(LEFT(I28,2)="P1",LEFT(K28,2)<>"K4",N28=""),"P1 biasanya K4; jelaskan di V12; ",""))) | R28: =IF(INDEX(Korpus!$B:$B,$A28)="","",INDEX(Korpus!$B:$B,$A28)) -> BAB I KETENTUAN UMUM | S28: =IF(INDEX(Korpus!$C:$C,$A28)="","",INDEX(Korpus!$C:$C,$A28))
