Workbook

Sheet Petunjuk
A1: Template Krippendorff's Alpha (α) – Petunjuk Penggunaan
A3: A. SPESIFIKASI TEMPLATE
A4: • | B4: Jumlah coder: 2 sampai 4 (dipilih di sel Input!H4).
A5: • | B5: Jenis data: Nominal dan Ordinal (dipilih di sel Input!H5).
A6: • | B6: Banyak data (unit) per coder: 1 sampai 100 baris (Input!A5:E104). Maksimal 20 kategori. Mendukung data hilang (sel kosong).
A7: • | B7: Kategori boleh berupa angka (1, 2, 3 …) atau teks (Positif, Netral …).
A9: B. LANGKAH PENGGUNAAN
A10: 1 | B10: Buka sheet Input. Template sudah berisi Contoh 1 (nominal). Untuk data Anda: blok B5:E104 lalu tekan Delete; kosongkan H10:H29 dan H6.
A11: 2 | B11: Pilih Jumlah coder (H4) dan Jenis data (H5) dari dropdown. Kolom coder di luar jumlah yang dipilih otomatis berwarna abu-abu dan diabaikan.
A12: 3 | B12: Isi Daftar Kategori di H10:H29 mulai dari atas. Nominal: urutan bebas. Ordinal: WAJIB urut dari rendah ke tinggi (mis. 1,2,3,4,5 atau Rendah, Sedang, Tinggi).
A13: 4 | B13: Isi data pada B5:E104: satu baris = satu unit yang dikode, satu kolom = satu coder. Pilih dari dropdown atau ketik persis sama dengan kategori. Kosongkan sel jika coder tidak mengkode unit itu.
A14: 5 | B14: Lihat hasil di panel HASIL (Input!H32:H38) – Alpha, interpretasi, jumlah unit, dan status data. Rincian matriks ada di sheet Hasil_Alpha.
A15: 6 | B15: Periksa Status data. Sel merah di Input = entri yang tidak ada di daftar kategori (mis. salah ketik atau spasi berlebih) dan tidak ikut dihitung.
A16: 7 | B16: Untuk mencoba contoh ordinal: salin data dari Contoh_Data ke Input, set H4=3, H5=Ordinal, H10:H14 = 1–5, hapus kategori lain (H15:H29). Hasil harus = nilai acuan.
A18: C. ISI SETIAP SHEET
B19: Input | C19: Pengaturan, daftar kategori, data coder, dan ringkasan hasil (satu-satunya sheet yang perlu diisi).
B20: Hitung_Unit | C20: Konversi tiap nilai menjadi indeks kategori, jumlah nilai per unit (m), bobot 1/(m−1), dan hitungan per kategori.
B21: Hasil_Alpha | C21: Ringkasan (Do, De, Alpha, interpretasi), matriks koinsidensi, matriks harapan, dan matriks selisih kuadrat.
B22: Contoh_Data | C22: Dua contoh data (nominal & ordinal) beserta nilai acuan Alpha untuk verifikasi.
A24: D. RUMUS YANG DIPAKAI
B25: Alpha | C25: α = 1 − Do / De, dengan Do = (1/n)·Σ o_ck·δ²_ck dan De = (1/n)·Σ e_ck·δ²_ck.
B26: Matriks koinsidensi | C26: o_ck = Σ_unit [ n_uc·n_uk − (c=k)·n_uc ] / (m_u − 1). Hanya unit dengan m_u ≥ 2 nilai yang dihitung.
B27: Matriks harapan | C27: e_ck = n_c·n_k / (n − 1) untuk c≠k; e_cc = n_c·(n_c − 1) / (n − 1). n_c = total baris c pada matriks koinsidensi.
B28: δ² Nominal | C28: 0 bila c = k; 1 bila c ≠ k.
B29: δ² Ordinal | C29: (n_c/2 + n_(c+1) + … + n_(k−1) + n_k/2)², yaitu (Σ n_g dari c sampai k) − (n_c + n_k)/2, dikuadratkan.
A31: E. FORMULA EXCEL KUNCI
B32: Hitung_Unit!B5 (indeks) | C32: IF(Input!B5="","",IF(B$3>Input!$H$4,"",IFERROR(MATCH(Input!B5,Input!$H$10:$H$29,0),"ERR")))
B33: Hitung_Unit!H5 (bobot) | C33: IF(F5>=2, 1/(F5−1), 0)
B34: Hitung_Unit!I5 (n_uk) | C34: COUNTIF($B5:$E5, I$3)
B35: Hasil_Alpha!C21 (o_ck) | C35: SUMPRODUCT(Hitung_Unit!$I$5:$I$104, Hitung_Unit!$I$5:$I$104−1, Hitung_Unit!$H$5:$H$104) [−1 hanya untuk c = k]
B36: Hasil_Alpha!F9 (Do) | C36: SUMPRODUCT(matriks_koinsidensi, matriks_selisih) / n
B37: Hasil_Alpha!F10 (De) | C37: SUMPRODUCT(matriks_harapan, matriks_selisih) / n
B38: Hasil_Alpha!F11 (Alpha) | C38: IF(n<=1,"N/A",IF(De=0,"N/A",1 − Do/De))
A40: F. INTERPRETASI & CATATAN
B41: α ≥ 0,800 | C41: Reliabel – data dapat diandalkan.
B42: 0,667 ≤ α < 0,800 | C42: Tentatif – hanya untuk kesimpulan awal.
B43: α < 0,667 | C43: Tidak reliabel. Ambang ini mengikuti saran Krippendorff (2004) dan dapat disesuaikan dengan bidang/tujuan penelitian Anda.
B44: Hasil N/A | C44: Terjadi bila tidak ada unit dengan ≥2 nilai, atau seluruh nilai jatuh pada satu kategori saja (variasi nol, De = 0), sehingga Alpha tidak terdefinisi.
B45: Data hilang | C45: Sel kosong diperbolehkan; unit dengan hanya 1 nilai tidak dihitung. Jumlah coder per unit boleh berbeda-beda.
B46: Sampel kecil | C46: Dengan unit sangat sedikit (mis. 1–5), Alpha sangat tidak stabil; interpretasikan dengan hati-hati.
...

Sheet Input
A1: Template Krippendorff's Alpha (α) – Reliabilitas Antar-Coder
A2: Sel kuning/biru = isi sendiri | Sel hitam = otomatis (jangan diubah) | Data mulai baris 5, satu baris = satu unit | Kosongkan sel bila coder tidak mengkode unit tsb.
A3: Jumlah data → | B3: =IF(1<=$H$4,COUNTA(B5:B104),"-") -> 12 | C3: =IF(2<=$H$4,COUNTA(C5:C104),"-") -> 12 | D3: =IF(3<=$H$4,COUNTA(D5:D104),"-") -> - | E3: =IF(4<=$H$4,COUNTA(E5:E104),"-") -> - | G3: PENGATURAN
A4: No. Unit | B4: Fenny | C4: Afriansyah | D4: Claude | E4: Gemini | G4: Jumlah coder (2–4) | H4: 2
A5: 1 | B5: K2 | C5: K1 | D5: K5 | E5: K5 | G5: Jenis data (Nominal / Ordinal) | H5: Nominal
A6: 2 | B6: K2 | C6: K1 | D6: K5 | E6: K5 | G6: Nama variabel (opsional) | H6: RELEVANSI
A7: 3 | B7: K5 | C7: K4 | D7: K5 | E7: K5
A8: 4 | B8: K4 | C8: K3 | D8: K3 | E8: K3 | G8: DAFTAR KATEGORI (maks. 20)
A9: 5 | B9: K3 | C9: K4 | D9: K4 | E9: K4 | G9: Urutan | H9: Kategori / kode (ordinal: rendah → tinggi)
A10: 6 | B10: K5 | C10: K4 | D10: K4 | E10: K4 | G10: 1 | H10: K1
A11: 7 | B11: K2 | C11: K4 | D11: K3 | E11: K3 | G11: 2 | H11: K2
A12: 8 | B12: K2 | C12: K4 | D12: K2 | E12: K2 | G12: 3 | H12: K3
A13: 9 | B13: K4 | C13: K3 | D13: K2 | E13: K2 | G13: 4 | H13: K4
A14: 10 | B14: K4 | C14: K3 | D14: K3 | E14: K3 | G14: 5 | H14: K5
A15: 11 | B15: K5 | C15: K4 | D15: K4 | E15: K4 | G15: 6
A16: 12 | B16: K2 | C16: K4 | D16: K1 | E16: K1 | G16: 7
A17: 13 | G17: 8
A18: 14 | G18: 9
A19: 15 | G19: 10
A20: 16 | G20: 11
A21: 17 | G21: 12
A22: 18 | G22: 13
A23: 19 | G23: 14
A24: 20 | G24: 15
A25: 21 | G25: 16
A26: 22 | G26: 17
A27: 23 | G27: 18
A28: 24 | G28: 19
A29: 25 | G29: 20
A30: 26
A31: 27 | G31: HASIL
A32: 28 | G32: Krippendorff's Alpha (α) | H32: =Hasil_Alpha!F11 -> -0.42857143
A33: 29 | G33: Interpretasi | H33: =Hasil_Alpha!F12 -> Tidak reliabel (α < 0,667)
A34: 30 | G34: Jumlah unit terisi (N) | H34: =Hasil_Alpha!F6 -> 12
A35: 31 | G35: Unit dipasangkan (≥2 nilai) | H35: =Hasil_Alpha!F7 -> 12
A36: 32 | G36: Total nilai dipasangkan (n) | H36: =Hasil_Alpha!F8 -> 20
A37: 33 | G37: Kesepakatan teramati | H37: =Hasil_Alpha!F13 -> 0
A38: 34 | G38: Status data | H38: =Hasil_Alpha!F15 -> Catatan: ada data pada kolom coder yang tidak dipakai (abu-abu)
A39: 35
A40: 36
...

Sheet Hitung_Unit
A1: Perhitungan per Unit (otomatis – jangan diubah)
A2: Kolom B–E: indeks kategori tiap coder · F: jumlah nilai (m) · G: entri tidak valid · H: bobot 1/(m−1) · I–AB: jumlah nilai per kategori (n_uk)
A3: Indeks → | B3: 1 | C3: 2 | D3: 3 | E3: 4 | I3: 1 | J3: 2 | K3: 3 | L3: 4 | M3: 5 | N3: 6 | O3: 7 | P3: 8 | Q3: 9 | R3: 10 | S3: 11 | T3: 12 | U3: 13 | V3: 14 | W3: 15 | X3: 16 | Y3: 17 | Z3: 18 | AA3: 19 | AB3: 20
A4: Unit | B4: =Input!B4 -> Fenny | C4: =Input!C4 -> Afriansyah | D4: =Input!D4 -> Claude | E4: =Input!E4 -> Gemini | F4: m | G4: ERR | H4: Bobot | I4: =IF(Input!$H$10="","",Input!$H$10) -> K1 | J4: =IF(Input!$H$11="","",Input!$H$11) -> K2 | K4: =IF(Input!$H$12="","",Input!$H$12) -> K3 | L4: =IF(Input!$H$13="","",Input!$H$13) -> K4 | M4: =IF(Input!$H$14="","",Input!$H$14) -> K5 | N4: =IF(Input!$H$15="","",Input!$H$15) | O4: =IF(Input!$H$16="","",Input!$H$16) | P4: =IF(Input!$H$17="","",Input!$H$17) | Q4: =IF(Input!$H$18="","",Input!$H$18) | R4: =IF(Input!$H$19="","",Input!$H$19) | S4: =IF(Input!$H$20="","",Input!$H$20) | T4: =IF(Input!$H$21="","",Input!$H$21) | U4: =IF(Input!$H$22="","",Input!$H$22) | V4: =IF(Input!$H$23="","",Input!$H$23) | W4: =IF(Input!$H$24="","",Input!$H$24) | X4: =IF(Input!$H$25="","",Input!$H$25) | Y4: =IF(Input!$H$26="","",Input!$H$26) | Z4: =IF(Input!$H$27="","",Input!$H$27) | AA4: =IF(Input!$H$28="","",Input!$H$28) | AB4: =IF(Input!$H$29="","",Input!$H$29)
A5: =Input!A5 -> 1 | B5: =IF(Input!B5="","",IF(B$3>Input!$H$4,"",IFERROR(MATCH(Input!B5,Input!$H$10:$H$29,0),"ERR"))) -> 2 | C5: =IF(Input!C5="","",IF(C$3>Input!$H$4,"",IFERROR(MATCH(Input!C5,Input!$H$10:$H$29,0),"ERR"))) -> 1 | D5: =IF(Input!D5="","",IF(D$3>Input!$H$4,"",IFERROR(MATCH(Input!D5,Input!$H$10:$H$29,0),"ERR"))) | E5: =IF(Input!E5="","",IF(E$3>Input!$H$4,"",IFERROR(MATCH(Input!E5,Input!$H$10:$H$29,0),"ERR"))) | F5: =COUNT(B5:E5) -> 2 | G5: =COUNTIF(B5:E5,"ERR") -> 0 | H5: =IF(F5>=2,1/(F5-1),0) -> 1 | I5: =COUNTIF($B5:$E5,I$3) -> 0 | J5: =COUNTIF($B5:$E5,J$3) -> 1 | K5: =COUNTIF($B5:$E5,K$3) -> 0 | L5: =COUNTIF($B5:$E5,L$3) -> 0 | M5: =COUNTIF($B5:$E5,M$3) -> 0 | N5: =COUNTIF($B5:$E5,N$3) -> 0 | O5: =COUNTIF($B5:$E5,O$3) -> 0 | P5: =COUNTIF($B5:$E5,P$3) -> 0 | ... AB5: =COUNTIF($B5:$E5,AB$3) -> 0
A6: =Input!A6 -> 2 | B6: =IF(Input!B6="","",IF(B$3>Input!$H$4,"",IFERROR(MATCH(Input!B6,Input!$H$10:$H$29,0),"ERR"))) -> 2 | C6: =IF(Input!C6="","",IF(C$3>Input!$H$4,"",IFERROR(MATCH(Input!C6,Input!$H$10:$H$29,0),"ERR"))) -> 1 | D6: =IF(Input!D6="","",IF(D$3>Input!$H$4,"",IFERROR(MATCH(Input!D6,Input!$H$10:$H$29,0),"ERR"))) | E6: =IF(Input!E6="","",IF(E$3>Input!$H$4,"",IFERROR(MATCH(Input!E6,Input!$H$10:$H$29,0),"ERR"))) | F6: =COUNT(B6:E6) -> 2 | G6: =COUNTIF(B6:E6,"ERR") -> 0 | H6: =IF(F6>=2,1/(F6-1),0) -> 1 | I6: =COUNTIF($B6:$E6,I$3) -> 0 | J6: =COUNTIF($B6:$E6,J$3) -> 1 | K6: =COUNTIF($B6:$E6,K$3) -> 0 | L6: =COUNTIF($B6:$E6,L$3) -> 0 | M6: =COUNTIF($B6:$E6,M$3) -> 0 | N6: =COUNTIF($B6:$E6,N$3) -> 0 | O6: =COUNTIF($B6:$E6,O$3) -> 0 | P6: =COUNTIF($B6:$E6,P$3) -> 0 | ... AB6: =COUNTIF($B6:$E6,AB$3) -> 0
A7: =Input!A7 -> 3 | B7: =IF(Input!B7="","",IF(B$3>Input!$H$4,"",IFERROR(MATCH(Input!B7,Input!$H$10:$H$29,0),"ERR"))) -> 5 | C7: =IF(Input!C7="","",IF(C$3>Input!$H$4,"",IFERROR(MATCH(Input!C7,Input!$H$10:$H$29,0),"ERR"))) -> 4 | D7: =IF(Input!D7="","",IF(D$3>Input!$H$4,"",IFERROR(MATCH(Input!D7,Input!$H$10:$H$29,0),"ERR"))) | E7: =IF(Input!E7="","",IF(E$3>Input!$H$4,"",IFERROR(MATCH(Input!E7,Input!$H$10:$H$29,0),"ERR"))) | F7: =COUNT(B7:E7) -> 2 | G7: =COUNTIF(B7:E7,"ERR") -> 0 | H7: =IF(F7>=2,1/(F7-1),0) -> 1 | I7: =COUNTIF($B7:$E7,I$3) -> 0 | J7: =COUNTIF($B7:$E7,J$3) -> 0 | K7: =COUNTIF($B7:$E7,K$3) -> 0 | L7: =COUNTIF($B7:$E7,L$3) -> 1 | M7: =COUNTIF($B7:$E7,M$3) -> 1 | N7: =COUNTIF($B7:$E7,N$3) -> 0 | O7: =COUNTIF($B7:$E7,O$3) -> 0 | P7: =COUNTIF($B7:$E7,P$3) -> 0 | ... AB7: =COUNTIF($B7:$E7,AB$3) -> 0
A8: =Input!A8 -> 4 | B8: =IF(Input!B8="","",IF(B$3>Input!$H$4,"",IFERROR(MATCH(Input!B8,Input!$H$10:$H$29,0),"ERR"))) -> 4 | C8: =IF(Input!C8="","",IF(C$3>Input!$H$4,"",IFERROR(MATCH(Input!C8,Input!$H$10:$H$29,0),"ERR"))) -> 3 | D8: =IF(Input!D8="","",IF(D$3>Input!$H$4,"",IFERROR(MATCH(Input!D8,Input!$H$10:$H$29,0),"ERR"))) | E8: =IF(Input!E8="","",IF(E$3>Input!$H$4,"",IFERROR(MATCH(Input!E8,Input!$H$10:$H$29,0),"ERR"))) | F8: =COUNT(B8:E8) -> 2 | G8: =COUNTIF(B8:E8,"ERR") -> 0 | H8: =IF(F8>=2,1/(F8-1),0) -> 1 | I8: =COUNTIF($B8:$E8,I$3) -> 0 | J8: =COUNTIF($B8:$E8,J$3) -> 0 | K8: =COUNTIF($B8:$E8,K$3) -> 1 | L8: =COUNTIF($B8:$E8,L$3) -> 1 | M8: =COUNTIF($B8:$E8,M$3) -> 0 | N8: =COUNTIF($B8:$E8,N$3) -> 0 | O8: =COUNTIF($B8:$E8,O$3) -> 0 | P8: =COUNTIF($B8:$E8,P$3) -> 0 | ... AB8: =COUNTIF($B8:$E8,AB$3) -> 0
A9: =Input!A9 -> 5 | B9: =IF(Input!B9="","",IF(B$3>Input!$H$4,"",IFERROR(MATCH(Input!B9,Input!$H$10:$H$29,0),"ERR"))) -> 3 | C9: =IF(Input!C9="","",IF(C$3>Input!$H$4,"",IFERROR(MATCH(Input!C9,Input!$H$10:$H$29,0),"ERR"))) -> 4 | D9: =IF(Input!D9="","",IF(D$3>Input!$H$4,"",IFERROR(MATCH(Input!D9,Input!$H$10:$H$29,0),"ERR"))) | E9: =IF(Input!E9="","",IF(E$3>Input!$H$4,"",IFERROR(MATCH(Input!E9,Input!$H$10:$H$29,0),"ERR"))) | F9: =COUNT(B9:E9) -> 2 | G9: =COUNTIF(B9:E9,"ERR") -> 0 | H9: =IF(F9>=2,1/(F9-1),0) -> 1 | I9: =COUNTIF($B9:$E9,I$3) -> 0 | J9: =COUNTIF($B9:$E9,J$3) -> 0 | K9: =COUNTIF($B9:$E9,K$3) -> 1 | L9: =COUNTIF($B9:$E9,L$3) -> 1 | M9: =COUNTIF($B9:$E9,M$3) -> 0 | N9: =COUNTIF($B9:$E9,N$3) -> 0 | O9: =COUNTIF($B9:$E9,O$3) -> 0 | P9: =COUNTIF($B9:$E9,P$3) -> 0 | ... AB9: =COUNTIF($B9:$E9,AB$3) -> 0
A10: =Input!A10 -> 6 | B10: =IF(Input!B10="","",IF(B$3>Input!$H$4,"",IFERROR(MATCH(Input!B10,Input!$H$10:$H$29,0),"ERR"))) -> 5 | C10: =IF(Input!C10="","",IF(C$3>Input!$H$4,"",IFERROR(MATCH(Input!C10,Input!$H$10:$H$29,0),"ERR"))) -> 4 | D10: =IF(Input!D10="","",IF(D$3>Input!$H$4,"",IFERROR(MATCH(Input!D10,Input!$H$10:$H$29,0),"ERR"))) | E10: =IF(Input!E10="","",IF(E$3>Input!$H$4,"",IFERROR(MATCH(Input!E10,Input!$H$10:$H$29,0),"ERR"))) | F10: =COUNT(B10:E10) -> 2 | G10: =COUNTIF(B10:E10,"ERR") -> 0 | H10: =IF(F10>=2,1/(F10-1),0) -> 1 | I10: =COUNTIF($B10:$E10,I$3) -> 0 | J10: =COUNTIF($B10:$E10,J$3) -> 0 | K10: =COUNTIF($B10:$E10,K$3) -> 0 | L10: =COUNTIF($B10:$E10,L$3) -> 1 | M10: =COUNTIF($B10:$E10,M$3) -> 1 | N10: =COUNTIF($B10:$E10,N$3) -> 0 | O10: =COUNTIF($B10:$E10,O$3) -> 0 | P10: =COUNTIF($B10:$E10,P$3) -> 0 | ... AB10: =COUNTIF($B10:$E10,AB$3) -> 0
A11: =Input!A11 -> 7 | B11: =IF(Input!B11="","",IF(B$3>Input!$H$4,"",IFERROR(MATCH(Input!B11,Input!$H$10:$H$29,0),"ERR"))) -> 2 | C11: =IF(Input!C11="","",IF(C$3>Input!$H$4,"",IFERROR(MATCH(Input!C11,Input!$H$10:$H$29,0),"ERR"))) -> 4 | D11: =IF(Input!D11="","",IF(D$3>Input!$H$4,"",IFERROR(MATCH(Input!D11,Input!$H$10:$H$29,0),"ERR"))) | E11: =IF(Input!E11="","",IF(E$3>Input!$H$4,"",IFERROR(MATCH(Input!E11,Input!$H$10:$H$29,0),"ERR"))) | F11: =COUNT(B11:E11) -> 2 | G11: =COUNTIF(B11:E11,"ERR") -> 0 | H11: =IF(F11>=2,1/(F11-1),0) -> 1 | I11: =COUNTIF($B11:$E11,I$3) -> 0 | J11: =COUNTIF($B11:$E11,J$3) -> 1 | K11: =COUNTIF($B11:$E11,K$3) -> 0 | L11: =COUNTIF($B11:$E11,L$3) -> 1 | M11: =COUNTIF($B11:$E11,M$3) -> 0 | N11: =COUNTIF($B11:$E11,N$3) -> 0 | O11: =COUNTIF($B11:$E11,O$3) -> 0 | P11: =COUNTIF($B11:$E11,P$3) -> 0 | ... AB11: =COUNTIF($B11:$E11,AB$3) -> 0
A12: =Input!A12 -> 8 | B12: =IF(Input!B12="","",IF(B$3>Input!$H$4,"",IFERROR(MATCH(Input!B12,Input!$H$10:$H$29,0),"ERR"))) -> 2 | C12: =IF(Input!C12="","",IF(C$3>Input!$H$4,"",IFERROR(MATCH(Input!C12,Input!$H$10:$H$29,0),"ERR"))) -> 4 | D12: =IF(Input!D12="","",IF(D$3>Input!$H$4,"",IFERROR(MATCH(Input!D12,Input!$H$10:$H$29,0),"ERR"))) | E12: =IF(Input!E12="","",IF(E$3>Input!$H$4,"",IFERROR(MATCH(Input!E12,Input!$H$10:$H$29,0),"ERR"))) | F12: =COUNT(B12:E12) -> 2 | G12: =COUNTIF(B12:E12,"ERR") -> 0 | H12: =IF(F12>=2,1/(F12-1),0) -> 1 | I12: =COUNTIF($B12:$E12,I$3) -> 0 | J12: =COUNTIF($B12:$E12,J$3) -> 1 | K12: =COUNTIF($B12:$E12,K$3) -> 0 | L12: =COUNTIF($B12:$E12,L$3) -> 1 | M12: =COUNTIF($B12:$E12,M$3) -> 0 | N12: =COUNTIF($B12:$E12,N$3) -> 0 | O12: =COUNTIF($B12:$E12,O$3) -> 0 | P12: =COUNTIF($B12:$E12,P$3) -> 0 | ... AB12: =COUNTIF($B12:$E12,AB$3) -> 0
A13: =Input!A13 -> 9 | B13: =IF(Input!B13="","",IF(B$3>Input!$H$4,"",IFERROR(MATCH(Input!B13,Input!$H$10:$H$29,0),"ERR"))) -> 4 | C13: =IF(Input!C13="","",IF(C$3>Input!$H$4,"",IFERROR(MATCH(Input!C13,Input!$H$10:$H$29,0),"ERR"))) -> 3 | D13: =IF(Input!D13="","",IF(D$3>Input!$H$4,"",IFERROR(MATCH(Input!D13,Input!$H$10:$H$29,0),"ERR"))) | E13: =IF(Input!E13="","",IF(E$3>Input!$H$4,"",IFERROR(MATCH(Input!E13,Input!$H$10:$H$29,0),"ERR"))) | F13: =COUNT(B13:E13) -> 2 | G13: =COUNTIF(B13:E13,"ERR") -> 0 | H13: =IF(F13>=2,1/(F13-1),0) -> 1 | I13: =COUNTIF($B13:$E13,I$3) -> 0 | J13: =COUNTIF($B13:$E13,J$3) -> 0 | K13: =COUNTIF($B13:$E13,K$3) -> 1 | L13: =COUNTIF($B13:$E13,L$3) -> 1 | M13: =COUNTIF($B13:$E13,M$3) -> 0 | N13: =COUNTIF($B13:$E13,N$3) -> 0 | O13: =COUNTIF($B13:$E13,O$3) -> 0 | P13: =COUNTIF($B13:$E13,P$3) -> 0 | ... AB13: =COUNTIF($B13:$E13,AB$3) -> 0
A14: =Input!A14 -> 10 | B14: =IF(Input!B14="","",IF(B$3>Input!$H$4,"",IFERROR(MATCH(Input!B14,Input!$H$10:$H$29,0),"ERR"))) -> 4 | C14: =IF(Input!C14="","",IF(C$3>Input!$H$4,"",IFERROR(MATCH(Input!C14,Input!$H$10:$H$29,0),"ERR"))) -> 3 | D14: =IF(Input!D14="","",IF(D$3>Input!$H$4,"",IFERROR(MATCH(Input!D14,Input!$H$10:$H$29,0),"ERR"))) | E14: =IF(Input!E14="","",IF(E$3>Input!$H$4,"",IFERROR(MATCH(Input!E14,Input!$H$10:$H$29,0),"ERR"))) | F14: =COUNT(B14:E14) -> 2 | G14: =COUNTIF(B14:E14,"ERR") -> 0 | H14: =IF(F14>=2,1/(F14-1),0) -> 1 | I14: =COUNTIF($B14:$E14,I$3) -> 0 | J14: =COUNTIF($B14:$E14,J$3) -> 0 | K14: =COUNTIF($B14:$E14,K$3) -> 1 | L14: =COUNTIF($B14:$E14,L$3) -> 1 | M14: =COUNTIF($B14:$E14,M$3) -> 0 | N14: =COUNTIF($B14:$E14,N$3) -> 0 | O14: =COUNTIF($B14:$E14,O$3) -> 0 | P14: =COUNTIF($B14:$E14,P$3) -> 0 | ... AB14: =COUNTIF($B14:$E14,AB$3) -> 0
A15: =Input!A15 -> 11 | B15: =IF(Input!B15="","",IF(B$3>Input!$H$4,"",IFERROR(MATCH(Input!B15,Input!$H$10:$H$29,0),"ERR"))) -> 5 | C15: =IF(Input!C15="","",IF(C$3>Input!$H$4,"",IFERROR(MATCH(Input!C15,Input!$H$10:$H$29,0),"ERR"))) -> 4 | D15: =IF(Input!D15="","",IF(D$3>Input!$H$4,"",IFERROR(MATCH(Input!D15,Input!$H$10:$H$29,0),"ERR"))) | E15: =IF(Input!E15="","",IF(E$3>Input!$H$4,"",IFERROR(MATCH(Input!E15,Input!$H$10:$H$29,0),"ERR"))) | F15: =COUNT(B15:E15) -> 2 | G15: =COUNTIF(B15:E15,"ERR") -> 0 | H15: =IF(F15>=2,1/(F15-1),0) -> 1 | I15: =COUNTIF($B15:$E15,I$3) -> 0 | J15: =COUNTIF($B15:$E15,J$3) -> 0 | K15: =COUNTIF($B15:$E15,K$3) -> 0 | L15: =COUNTIF($B15:$E15,L$3) -> 1 | M15: =COUNTIF($B15:$E15,M$3) -> 1 | N15: =COUNTIF($B15:$E15,N$3) -> 0 | O15: =COUNTIF($B15:$E15,O$3) -> 0 | P15: =COUNTIF($B15:$E15,P$3) -> 0 | ... AB15: =COUNTIF($B15:$E15,AB$3) -> 0
A16: =Input!A16 -> 12 | B16: =IF(Input!B16="","",IF(B$3>Input!$H$4,"",IFERROR(MATCH(Input!B16,Input!$H$10:$H$29,0),"ERR"))) -> 2 | C16: =IF(Input!C16="","",IF(C$3>Input!$H$4,"",IFERROR(MATCH(Input!C16,Input!$H$10:$H$29,0),"ERR"))) -> 4 | D16: =IF(Input!D16="","",IF(D$3>Input!$H$4,"",IFERROR(MATCH(Input!D16,Input!$H$10:$H$29,0),"ERR"))) | E16: =IF(Input!E16="","",IF(E$3>Input!$H$4,"",IFERROR(MATCH(Input!E16,Input!$H$10:$H$29,0),"ERR"))) | F16: =COUNT(B16:E16) -> 2 | G16: =COUNTIF(B16:E16,"ERR") -> 0 | H16: =IF(F16>=2,1/(F16-1),0) -> 1 | I16: =COUNTIF($B16:$E16,I$3) -> 0 | J16: =COUNTIF($B16:$E16,J$3) -> 1 | K16: =COUNTIF($B16:$E16,K$3) -> 0 | L16: =COUNTIF($B16:$E16,L$3) -> 1 | M16: =COUNTIF($B16:$E16,M$3) -> 0 | N16: =COUNTIF($B16:$E16,N$3) -> 0 | O16: =COUNTIF($B16:$E16,O$3) -> 0 | P16: =COUNTIF($B16:$E16,P$3) -> 0 | ... AB16: =COUNTIF($B16:$E16,AB$3) -> 0
... A104: =Input!A104 -> 100 | B104: =IF(Input!B104="","",IF(B$3>Input!$H$4,"",IFERROR(MATCH(Input!B104,Input!$H$10:$H$29,0),"ERR"))) | C104: =IF(Input!C104="","",IF(C$3>Input!$H$4,"",IFERROR(MATCH(Input!C104,Input!$H$10:$H$29,0),"ERR"))) | D104: =IF(Input!D104="","",IF(D$3>Input!$H$4,"",IFERROR(MATCH(Input!D104,Input!$H$10:$H$29,0),"ERR"))) | E104: =IF(Input!E104="","",IF(E$3>Input!$H$4,"",IFERROR(MATCH(Input!E104,Input!$H$10:$H$29,0),"ERR"))) | F104: =COUNT(B104:E104) -> 0 | G104: =COUNTIF(B104:E104,"ERR") -> 0 | H104: =IF(F104>=2,1/(F104-1),0) -> 0 | I104: =COUNTIF($B104:$E104,I$3) -> 0 | J104: =COUNTIF($B104:$E104,J$3) -> 0 | K104: =COUNTIF($B104:$E104,K$3) -> 0 | L104: =COUNTIF($B104:$E104,L$3) -> 0 | M104: =COUNTIF($B104:$E104,M$3) -> 0 | N104: =COUNTIF($B104:$E104,N$3) -> 0 | O104: =COUNTIF($B104:$E104,O$3) -> 0 | P104: =COUNTIF($B104:$E104,P$3) -> 0 | ... AB104: =COUNTIF($B104:$E104,AB$3) -> 0

Sheet Hasil_Alpha
A1: Hasil Perhitungan Krippendorff's Alpha
A2: Seluruh sel pada sheet ini otomatis (rumus). Alpha = 1 − Do/De.
A3: RINGKASAN
A4: Jenis data | F4: =Input!H5 -> Nominal
A5: Jumlah coder | F5: =Input!H4 -> 2
A6: Jumlah unit terisi (N) | F6: =COUNTIF(Hitung_Unit!F5:F104,">=1") -> 12
A7: Unit dapat dipasangkan (≥2 nilai) | F7: =COUNTIF(Hitung_Unit!F5:F104,">=2") -> 12
A8: Total nilai dipasangkan (n) | F8: =$W$41 -> 20
A9: Do – disagreement teramati | F9: =IF($W$41>1,SUMPRODUCT($C$21:$V$40,$C$72:$V$91)/$W$41,"") -> 1
A10: De – disagreement diharapkan | F10: =IF($W$41>1,SUMPRODUCT($C$47:$V$66,$C$72:$V$91)/$W$41,"") -> 0.7
A11: KRIPPENDORFF'S ALPHA (α) | F11: =IF(F8<=1,"N/A",IF(F10=0,"N/A",1-F9/F10)) -> -0.42857143
A12: Interpretasi | F12: =IF(F11="N/A","Tidak dapat dihitung (data kurang / semua nilai sama)",IF(F11>=0.8,"Reliabel (α ≥ 0,800)",IF(F11>=0.667,"Tentatif (0,667 ≤ α < 0,800)","Tidak reliabel (α < 0,667)"))) -> Tidak reliabel (α < 0,667)
A13: Kesepakatan teramati (persen) | F13: =IF($W$41>1,(C21+D22+E23+F24+G25+H26+I27+J28+K29+L30+M31+N32+O33+P34+Q35+R36+S37+T38+U39+V40)/$W$41,"") -> 0
A14: Entri di luar daftar kategori | F14: =SUM(Hitung_Unit!G5:G104) -> 0
A15: Status data | F15: =IF(OR(Input!H4<2,Input!H4>4),"PERIKSA: jumlah coder harus 2–4",IF(AND(Input!H5<>"Nominal",Input!H5<>"Ordinal"),"PERIKSA: jenis data harus Nominal/Ordinal",IF(COUNTA(Input!H10:H29)<2,"PERIKSA: isi minimal 2 kategori di Input",IF(F14>0,"PERIKSA: "&F14&" entri tidak ada di daftar kategori (sel merah di Input)",IF(F6=0,"Belum ada data",IF(COUNTA(Input!B5:E104)>SUM(Input!B3:E3),"Catatan: ada data pada kolom coder yang tidak dipakai (abu-abu)",IF(F7<F6,"Catatan: "&(F6-F7)&" unit hanya punya 1 nilai, tidak ikut dihitung","OK – data valid"))))))) -> Catatan: ada data pada kolom coder yang tidak dipakai (abu-abu)
A18: 1. Matriks Koinsidensi (o_ck) – jumlah pasangan nilai antar-coder dalam unit yang sama
A19: c \ k | B19: Kategori | C19: 1 | D19: 2 | E19: 3 | F19: 4 | G19: 5 | H19: 6 | I19: 7 | J19: 8 | K19: 9 | L19: 10 | M19: 11 | N19: 12 | O19: 13 | P19: 14 | Q19: 15 | R19: 16 | S19: 17 | T19: 18 | U19: 19 | V19: 20 | W19: n_c
C20: =IF(Input!$H$10="","",Input!$H$10) -> K1 | D20: =IF(Input!$H$11="","",Input!$H$11) -> K2 | E20: =IF(Input!$H$12="","",Input!$H$12) -> K3 | F20: =IF(Input!$H$13="","",Input!$H$13) -> K4 | G20: =IF(Input!$H$14="","",Input!$H$14) -> K5 | H20: =IF(Input!$H$15="","",Input!$H$15) | I20: =IF(Input!$H$16="","",Input!$H$16) | J20: =IF(Input!$H$17="","",Input!$H$17) | K20: =IF(Input!$H$18="","",Input!$H$18) | L20: =IF(Input!$H$19="","",Input!$H$19) | M20: =IF(Input!$H$20="","",Input!$H$20) | N20: =IF(Input!$H$21="","",Input!$H$21) | O20: =IF(Input!$H$22="","",Input!$H$22) | P20: =IF(Input!$H$23="","",Input!$H$23) | Q20: =IF(Input!$H$24="","",Input!$H$24) | R20: =IF(Input!$H$25="","",Input!$H$25) | S20: =IF(Input!$H$26="","",Input!$H$26) | T20: =IF(Input!$H$27="","",Input!$H$27) | U20: =IF(Input!$H$28="","",Input!$H$28) | V20: =IF(Input!$H$29="","",Input!$H$29)
A21: 1 | B21: =IF(Input!$H$10="","",Input!$H$10) -> K1 | C21: =SUMPRODUCT(Hitung_Unit!$I$5:$I$104,Hitung_Unit!$I$5:$I$104-1,Hitung_Unit!$H$5:$H$104) -> 0 | D21: =SUMPRODUCT(Hitung_Unit!$I$5:$I$104,Hitung_Unit!$J$5:$J$104,Hitung_Unit!$H$5:$H$104) -> 0 | E21: =SUMPRODUCT(Hitung_Unit!$I$5:$I$104,Hitung_Unit!$K$5:$K$104,Hitung_Unit!$H$5:$H$104) -> 0 | F21: =SUMPRODUCT(Hitung_Unit!$I$5:$I$104,Hitung_Unit!$L$5:$L$104,Hitung_Unit!$H$5:$H$104) -> 0 | G21: =SUMPRODUCT(Hitung_Unit!$I$5:$I$104,Hitung_Unit!$M$5:$M$104,Hitung_Unit!$H$5:$H$104) -> 0 | H21: =SUMPRODUCT(Hitung_Unit!$I$5:$I$104,Hitung_Unit!$N$5:$N$104,Hitung_Unit!$H$5:$H$104) -> 0 | I21: =SUMPRODUCT(Hitung_Unit!$I$5:$I$104,Hitung_Unit!$O$5:$O$104,Hitung_Unit!$H$5:$H$104) -> 0 | J21: =SUMPRODUCT(Hitung_Unit!$I$5:$I$104,Hitung_Unit!$P$5:$P$104,Hitung_Unit!$H$5:$H$104) -> 0 | K21: =SUMPRODUCT(Hitung_Unit!$I$5:$I$104,Hitung_Unit!$Q$5:$Q$104,Hitung_Unit!$H$5:$H$104) -> 0 | L21: =SUMPRODUCT(Hitung_Unit!$I$5:$I$104,Hitung_Unit!$R$5:$R$104,Hitung_Unit!$H$5:$H$104) -> 0 | M21: =SUMPRODUCT(Hitung_Unit!$I$5:$I$104,Hitung_Unit!$S$5:$S$104,Hitung_Unit!$H$5:$H$104) -> 0 | N21: =SUMPRODUCT(Hitung_Unit!$I$5:$I$104,Hitung_Unit!$T$5:$T$104,Hitung_Unit!$H$5:$H$104) -> 0 | O21: =SUMPRODUCT(Hitung_Unit!$I$5:$I$104,Hitung_Unit!$U$5:$U$104,Hitung_Unit!$H$5:$H$104) -> 0 | P21: =SUMPRODUCT(Hitung_Unit!$I$5:$I$104,Hitung_Unit!$V$5:$V$104,Hitung_Unit!$H$5:$H$104) -> 0 | Q21: =SUMPRODUCT(Hitung_Unit!$I$5:$I$104,Hitung_Unit!$W$5:$W$104,Hitung_Unit!$H$5:$H$104) -> 0 | R21: =SUMPRODUCT(Hitung_Unit!$I$5:$I$104,Hitung_Unit!$X$5:$X$104,Hitung_Unit!$H$5:$H$104) -> 0 | S21: =SUMPRODUCT(Hitung_Unit!$I$5:$I$104,Hitung_Unit!$Y$5:$Y$104,Hitung_Unit!$H$5:$H$104) -> 0 | T21: =SUMPRODUCT(Hitung_Unit!$I$5:$I$104,Hitung_Unit!$Z$5:$Z$104,Hitung_Unit!$H$5:$H$104) -> 0 | U21: =SUMPRODUCT(Hitung_Unit!$I$5:$I$104,Hitung_Unit!$AA$5:$AA$104,Hitung_Unit!$H$5:$H$104) -> 0 | V21: =SUMPRODUCT(Hitung_Unit!$I$5:$I$104,Hitung_Unit!$AB$5:$AB$104,Hitung_Unit!$H$5:$H$104) -> 0 | W21: =SUM(C21:V21) -> 0
A22: 2 | B22: =IF(Input!$H$11="","",Input!$H$11) -> K2 | C22: =SUMPRODUCT(Hitung_Unit!$J$5:$J$104,Hitung_Unit!$I$5:$I$104,Hitung_Unit!$H$5:$H$104) -> 0 | D22: =SUMPRODUCT(Hitung_Unit!$J$5:$J$104,Hitung_Unit!$J$5:$J$104-1,Hitung_Unit!$H$5:$H$104) -> 0 | E22: =SUMPRODUCT(Hitung_Unit!$J$5:$J$104,Hitung_Unit!$K$5:$K$104,Hitung_Unit!$H$5:$H$104) -> 0 | F22: =SUMPRODUCT(Hitung_Unit!$J$5:$J$104,Hitung_Unit!$L$5:$L$104,Hitung_Unit!$H$5:$H$104) -> 3 | G22: =SUMPRODUCT(Hitung_Unit!$J$5:$J$104,Hitung_Unit!$M$5:$M$104,Hitung_Unit!$H$5:$H$104) -> 0 | H22: =SUMPRODUCT(Hitung_Unit!$J$5:$J$104,Hitung_Unit!$N$5:$N$104,Hitung_Unit!$H$5:$H$104) -> 0 | I22: =SUMPRODUCT(Hitung_Unit!$J$5:$J$104,Hitung_Unit!$O$5:$O$104,Hitung_Unit!$H$5:$H$104) -> 0 | J22: =SUMPRODUCT(Hitung_Unit!$J$5:$J$104,Hitung_Unit!$P$5:$P$104,Hitung_Unit!$H$5:$H$104) -> 0 | K22: =SUMPRODUCT(Hitung_Unit!$J$5:$J$104,Hitung_Unit!$Q$5:$Q$104,Hitung_Unit!$H$5:$H$104) -> 0 | L22: =SUMPRODUCT(Hitung_Unit!$J$5:$J$104,Hitung_Unit!$R$5:$R$104,Hitung_Unit!$H$5:$H$104) -> 0 | M22: =SUMPRODUCT(Hitung_Unit!$J$5:$J$104,Hitung_Unit!$S$5:$S$104,Hitung_Unit!$H$5:$H$104) -> 0 | N22: =SUMPRODUCT(Hitung_Unit!$J$5:$J$104,Hitung_Unit!$T$5:$T$104,Hitung_Unit!$H$5:$H$104) -> 0 | O22: =SUMPRODUCT(Hitung_Unit!$J$5:$J$104,Hitung_Unit!$U$5:$U$104,Hitung_Unit!$H$5:$H$104) -> 0 | P22: =SUMPRODUCT(Hitung_Unit!$J$5:$J$104,Hitung_Unit!$V$5:$V$104,Hitung_Unit!$H$5:$H$104) -> 0 | Q22: =SUMPRODUCT(Hitung_Unit!$J$5:$J$104,Hitung_Unit!$W$5:$W$104,Hitung_Unit!$H$5:$H$104) -> 0 | R22: =SUMPRODUCT(Hitung_Unit!$J$5:$J$104,Hitung_Unit!$X$5:$X$104,Hitung_Unit!$H$5:$H$104) -> 0 | S22: =SUMPRODUCT(Hitung_Unit!$J$5:$J$104,Hitung_Unit!$Y$5:$Y$104,Hitung_Unit!$H$5:$H$104) -> 0 | T22: =SUMPRODUCT(Hitung_Unit!$J$5:$J$104,Hitung_Unit!$Z$5:$Z$104,Hitung_Unit!$H$5:$H$104) -> 0 | U22: =SUMPRODUCT(Hitung_Unit!$J$5:$J$104,Hitung_Unit!$AA$5:$AA$104,Hitung_Unit!$H$5:$H$104) -> 0 | V22: =SUMPRODUCT(Hitung_Unit!$J$5:$J$104,Hitung_Unit!$AB$5:$AB$104,Hitung_Unit!$H$5:$H$104) -> 0 | W22: =SUM(C22:V22) -> 3
A23: 3 | B23: =IF(Input!$H$12="","",Input!$H$12) -> K3 | C23: =SUMPRODUCT(Hitung_Unit!$K$5:$K$104,Hitung_Unit!$I$5:$I$104,Hitung_Unit!$H$5:$H$104) -> 0 | D23: =SUMPRODUCT(Hitung_Unit!$K$5:$K$104,Hitung_Unit!$J$5:$J$104,Hitung_Unit!$H$5:$H$104) -> 0 | E23: =SUMPRODUCT(Hitung_Unit!$K$5:$K$104,Hitung_Unit!$K$5:$K$104-1,Hitung_Unit!$H$5:$H$104) -> 0 | F23: =SUMPRODUCT(Hitung_Unit!$K$5:$K$104,Hitung_Unit!$L$5:$L$104,Hitung_Unit!$H$5:$H$104) -> 4 | G23: =SUMPRODUCT(Hitung_Unit!$K$5:$K$104,Hitung_Unit!$M$5:$M$104,Hitung_Unit!$H$5:$H$104) -> 0 | H23: =SUMPRODUCT(Hitung_Unit!$K$5:$K$104,Hitung_Unit!$N$5:$N$104,Hitung_Unit!$H$5:$H$104) -> 0 | I23: =SUMPRODUCT(Hitung_Unit!$K$5:$K$104,Hitung_Unit!$O$5:$O$104,Hitung_Unit!$H$5:$H$104) -> 0 | J23: =SUMPRODUCT(Hitung_Unit!$K$5:$K$104,Hitung_Unit!$P$5:$P$104,Hitung_Unit!$H$5:$H$104) -> 0 | K23: =SUMPRODUCT(Hitung_Unit!$K$5:$K$104,Hitung_Unit!$Q$5:$Q$104,Hitung_Unit!$H$5:$H$104) -> 0 | L23: =SUMPRODUCT(Hitung_Unit!$K$5:$K$104,Hitung_Unit!$R$5:$R$104,Hitung_Unit!$H$5:$H$104) -> 0 | M23: =SUMPRODUCT(Hitung_Unit!$K$5:$K$104,Hitung_Unit!$S$5:$S$104,Hitung_Unit!$H$5:$H$104) -> 0 | N23: =SUMPRODUCT(Hitung_Unit!$K$5:$K$104,Hitung_Unit!$T$5:$T$104,Hitung_Unit!$H$5:$H$104) -> 0 | O23: =SUMPRODUCT(Hitung_Unit!$K$5:$K$104,Hitung_Unit!$U$5:$U$104,Hitung_Unit!$H$5:$H$104) -> 0 | P23: =SUMPRODUCT(Hitung_Unit!$K$5:$K$104,Hitung_Unit!$V$5:$V$104,Hitung_Unit!$H$5:$H$104) -> 0 | Q23: =SUMPRODUCT(Hitung_Unit!$K$5:$K$104,Hitung_Unit!$W$5:$W$104,Hitung_Unit!$H$5:$H$104) -> 0 | R23: =SUMPRODUCT(Hitung_Unit!$K$5:$K$104,Hitung_Unit!$X$5:$X$104,Hitung_Unit!$H$5:$H$104) -> 0 | S23: =SUMPRODUCT(Hitung_Unit!$K$5:$K$104,Hitung_Unit!$Y$5:$Y$104,Hitung_Unit!$H$5:$H$104) -> 0 | T23: =SUMPRODUCT(Hitung_Unit!$K$5:$K$104,Hitung_Unit!$Z$5:$Z$104,Hitung_Unit!$H$5:$H$104) -> 0 | U23: =SUMPRODUCT(Hitung_Unit!$K$5:$K$104,Hitung_Unit!$AA$5:$AA$104,Hitung_Unit!$H$5:$H$104) -> 0 | V23: =SUMPRODUCT(Hitung_Unit!$K$5:$K$104,Hitung_Unit!$AB$5:$AB$104,Hitung_Unit!$H$5:$H$104) -> 0 | W23: =SUM(C23:V23) -> 4
A24: 4 | B24: =IF(Input!$H$13="","",Input!$H$13) -> K4 | C24: =SUMPRODUCT(Hitung_Unit!$L$5:$L$104,Hitung_Unit!$I$5:$I$104,Hitung_Unit!$H$5:$H$104) -> 0 | D24: =SUMPRODUCT(Hitung_Unit!$L$5:$L$104,Hitung_Unit!$J$5:$J$104,Hitung_Unit!$H$5:$H$104) -> 3 | E24: =SUMPRODUCT(Hitung_Unit!$L$5:$L$104,Hitung_Unit!$K$5:$K$104,Hitung_Unit!$H$5:$H$104) -> 4 | F24: =SUMPRODUCT(Hitung_Unit!$L$5:$L$104,Hitung_Unit!$L$5:$L$104-1,Hitung_Unit!$H$5:$H$104) -> 0 | G24: =SUMPRODUCT(Hitung_Unit!$L$5:$L$104,Hitung_Unit!$M$5:$M$104,Hitung_Unit!$H$5:$H$104) -> 3 | H24: =SUMPRODUCT(Hitung_Unit!$L$5:$L$104,Hitung_Unit!$N$5:$N$104,Hitung_Unit!$H$5:$H$104) -> 0 | I24: =SUMPRODUCT(Hitung_Unit!$L$5:$L$104,Hitung_Unit!$O$5:$O$104,Hitung_Unit!$H$5:$H$104) -> 0 | J24: =SUMPRODUCT(Hitung_Unit!$L$5:$L$104,Hitung_Unit!$P$5:$P$104,Hitung_Unit!$H$5:$H$104) -> 0 | K24: =SUMPRODUCT(Hitung_Unit!$L$5:$L$104,Hitung_Unit!$Q$5:$Q$104,Hitung_Unit!$H$5:$H$104) -> 0 | L24: =SUMPRODUCT(Hitung_Unit!$L$5:$L$104,Hitung_Unit!$R$5:$R$104,Hitung_Unit!$H$5:$H$104) -> 0 | M24: =SUMPRODUCT(Hitung_Unit!$L$5:$L$104,Hitung_Unit!$S$5:$S$104,Hitung_Unit!$H$5:$H$104) -> 0 | N24: =SUMPRODUCT(Hitung_Unit!$L$5:$L$104,Hitung_Unit!$T$5:$T$104,Hitung_Unit!$H$5:$H$104) -> 0 | O24: =SUMPRODUCT(Hitung_Unit!$L$5:$L$104,Hitung_Unit!$U$5:$U$104,Hitung_Unit!$H$5:$H$104) -> 0 | P24: =SUMPRODUCT(Hitung_Unit!$L$5:$L$104,Hitung_Unit!$V$5:$V$104,Hitung_Unit!$H$5:$H$104) -> 0 | Q24: =SUMPRODUCT(Hitung_Unit!$L$5:$L$104,Hitung_Unit!$W$5:$W$104,Hitung_Unit!$H$5:$H$104) -> 0 | R24: =SUMPRODUCT(Hitung_Unit!$L$5:$L$104,Hitung_Unit!$X$5:$X$104,Hitung_Unit!$H$5:$H$104) -> 0 | S24: =SUMPRODUCT(Hitung_Unit!$L$5:$L$104,Hitung_Unit!$Y$5:$Y$104,Hitung_Unit!$H$5:$H$104) -> 0 | T24: =SUMPRODUCT(Hitung_Unit!$L$5:$L$104,Hitung_Unit!$Z$5:$Z$104,Hitung_Unit!$H$5:$H$104) -> 0 | U24: =SUMPRODUCT(Hitung_Unit!$L$5:$L$104,Hitung_Unit!$AA$5:$AA$104,Hitung_Unit!$H$5:$H$104) -> 0 | V24: =SUMPRODUCT(Hitung_Unit!$L$5:$L$104,Hitung_Unit!$AB$5:$AB$104,Hitung_Unit!$H$5:$H$104) -> 0 | W24: =SUM(C24:V24) -> 10
A25: 5 | B25: =IF(Input!$H$14="","",Input!$H$14) -> K5 | C25: =SUMPRODUCT(Hitung_Unit!$M$5:$M$104,Hitung_Unit!$I$5:$I$104,Hitung_Unit!$H$5:$H$104) -> 0 | D25: =SUMPRODUCT(Hitung_Unit!$M$5:$M$104,Hitung_Unit!$J$5:$J$104,Hitung_Unit!$H$5:$H$104) -> 0 | E25: =SUMPRODUCT(Hitung_Unit!$M$5:$M$104,Hitung_Unit!$K$5:$K$104,Hitung_Unit!$H$5:$H$104) -> 0 | F25: =SUMPRODUCT(Hitung_Unit!$M$5:$M$104,Hitung_Unit!$L$5:$L$104,Hitung_Unit!$H$5:$H$104) -> 3 | G25: =SUMPRODUCT(Hitung_Unit!$M$5:$M$104,Hitung_Unit!$M$5:$M$104-1,Hitung_Unit!$H$5:$H$104) -> 0 | H25: =SUMPRODUCT(Hitung_Unit!$M$5:$M$104,Hitung_Unit!$N$5:$N$104,Hitung_Unit!$H$5:$H$104) -> 0 | I25: =SUMPRODUCT(Hitung_Unit!$M$5:$M$104,Hitung_Unit!$O$5:$O$104,Hitung_Unit!$H$5:$H$104) -> 0 | J25: =SUMPRODUCT(Hitung_Unit!$M$5:$M$104,Hitung_Unit!$P$5:$P$104,Hitung_Unit!$H$5:$H$104) -> 0 | K25: =SUMPRODUCT(Hitung_Unit!$M$5:$M$104,Hitung_Unit!$Q$5:$Q$104,Hitung_Unit!$H$5:$H$104) -> 0 | L25: =SUMPRODUCT(Hitung_Unit!$M$5:$M$104,Hitung_Unit!$R$5:$R$104,Hitung_Unit!$H$5:$H$104) -> 0 | M25: =SUMPRODUCT(Hitung_Unit!$M$5:$M$104,Hitung_Unit!$S$5:$S$104,Hitung_Unit!$H$5:$H$104) -> 0 | N25: =SUMPRODUCT(Hitung_Unit!$M$5:$M$104,Hitung_Unit!$T$5:$T$104,Hitung_Unit!$H$5:$H$104) -> 0 | O25: =SUMPRODUCT(Hitung_Unit!$M$5:$M$104,Hitung_Unit!$U$5:$U$104,Hitung_Unit!$H$5:$H$104) -> 0 | P25: =SUMPRODUCT(Hitung_Unit!$M$5:$M$104,Hitung_Unit!$V$5:$V$104,Hitung_Unit!$H$5:$H$104) -> 0 | Q25: =SUMPRODUCT(Hitung_Unit!$M$5:$M$104,Hitung_Unit!$W$5:$W$104,Hitung_Unit!$H$5:$H$104) -> 0 | R25: =SUMPRODUCT(Hitung_Unit!$M$5:$M$104,Hitung_Unit!$X$5:$X$104,Hitung_Unit!$H$5:$H$104) -> 0 | S25: =SUMPRODUCT(Hitung_Unit!$M$5:$M$104,Hitung_Unit!$Y$5:$Y$104,Hitung_Unit!$H$5:$H$104) -> 0 | T25: =SUMPRODUCT(Hitung_Unit!$M$5:$M$104,Hitung_Unit!$Z$5:$Z$104,Hitung_Unit!$H$5:$H$104) -> 0 | U25: =SUMPRODUCT(Hitung_Unit!$M$5:$M$104,Hitung_Unit!$AA$5:$AA$104,Hitung_Unit!$H$5:$H$104) -> 0 | V25: =SUMPRODUCT(Hitung_Unit!$M$5:$M$104,Hitung_Unit!$AB$5:$AB$104,Hitung_Unit!$H$5:$H$104) -> 0 | W25: =SUM(C25:V25) -> 3
A26: 6 | B26: =IF(Input!$H$15="","",Input!$H$15) | C26: =SUMPRODUCT(Hitung_Unit!$N$5:$N$104,Hitung_Unit!$I$5:$I$104,Hitung_Unit!$H$5:$H$104) -> 0 | D26: =SUMPRODUCT(Hitung_Unit!$N$5:$N$104,Hitung_Unit!$J$5:$J$104,Hitung_Unit!$H$5:$H$104) -> 0 | E26: =SUMPRODUCT(Hitung_Unit!$N$5:$N$104,Hitung_Unit!$K$5:$K$104,Hitung_Unit!$H$5:$H$104) -> 0 | F26: =SUMPRODUCT(Hitung_Unit!$N$5:$N$104,Hitung_Unit!$L$5:$L$104,Hitung_Unit!$H$5:$H$104) -> 0 | G26: =SUMPRODUCT(Hitung_Unit!$N$5:$N$104,Hitung_Unit!$M$5:$M$104,Hitung_Unit!$H$5:$H$104) -> 0 | H26: =SUMPRODUCT(Hitung_Unit!$N$5:$N$104,Hitung_Unit!$N$5:$N$104-1,Hitung_Unit!$H$5:$H$104) -> 0 | I26: =SUMPRODUCT(Hitung_Unit!$N$5:$N$104,Hitung_Unit!$O$5:$O$104,Hitung_Unit!$H$5:$H$104) -> 0 | J26: =SUMPRODUCT(Hitung_Unit!$N$5:$N$104,Hitung_Unit!$P$5:$P$104,Hitung_Unit!$H$5:$H$104) -> 0 | K26: =SUMPRODUCT(Hitung_Unit!$N$5:$N$104,Hitung_Unit!$Q$5:$Q$104,Hitung_Unit!$H$5:$H$104) -> 0 | L26: =SUMPRODUCT(Hitung_Unit!$N$5:$N$104,Hitung_Unit!$R$5:$R$104,Hitung_Unit!$H$5:$H$104) -> 0 | M26: =SUMPRODUCT(Hitung_Unit!$N$5:$N$104,Hitung_Unit!$S$5:$S$104,Hitung_Unit!$H$5:$H$104) -> 0 | N26: =SUMPRODUCT(Hitung_Unit!$N$5:$N$104,Hitung_Unit!$T$5:$T$104,Hitung_Unit!$H$5:$H$104) -> 0 | O26: =SUMPRODUCT(Hitung_Unit!$N$5:$N$104,Hitung_Unit!$U$5:$U$104,Hitung_Unit!$H$5:$H$104) -> 0 | P26: =SUMPRODUCT(Hitung_Unit!$N$5:$N$104,Hitung_Unit!$V$5:$V$104,Hitung_Unit!$H$5:$H$104) -> 0 | Q26: =SUMPRODUCT(Hitung_Unit!$N$5:$N$104,Hitung_Unit!$W$5:$W$104,Hitung_Unit!$H$5:$H$104) -> 0 | R26: =SUMPRODUCT(Hitung_Unit!$N$5:$N$104,Hitung_Unit!$X$5:$X$104,Hitung_Unit!$H$5:$H$104) -> 0 | S26: =SUMPRODUCT(Hitung_Unit!$N$5:$N$104,Hitung_Unit!$Y$5:$Y$104,Hitung_Unit!$H$5:$H$104) -> 0 | T26: =SUMPRODUCT(Hitung_Unit!$N$5:$N$104,Hitung_Unit!$Z$5:$Z$104,Hitung_Unit!$H$5:$H$104) -> 0 | U26: =SUMPRODUCT(Hitung_Unit!$N$5:$N$104,Hitung_Unit!$AA$5:$AA$104,Hitung_Unit!$H$5:$H$104) -> 0 | V26: =SUMPRODUCT(Hitung_Unit!$N$5:$N$104,Hitung_Unit!$AB$5:$AB$104,Hitung_Unit!$H$5:$H$104) -> 0 | W26: =SUM(C26:V26) -> 0
A27: 7 | B27: =IF(Input!$H$16="","",Input!$H$16) | C27: =SUMPRODUCT(Hitung_Unit!$O$5:$O$104,Hitung_Unit!$I$5:$I$104,Hitung_Unit!$H$5:$H$104) -> 0 | D27: =SUMPRODUCT(Hitung_Unit!$O$5:$O$104,Hitung_Unit!$J$5:$J$104,Hitung_Unit!$H$5:$H$104) -> 0 | E27: =SUMPRODUCT(Hitung_Unit!$O$5:$O$104,Hitung_Unit!$K$5:$K$104,Hitung_Unit!$H$5:$H$104) -> 0 | F27: =SUMPRODUCT(Hitung_Unit!$O$5:$O$104,Hitung_Unit!$L$5:$L$104,Hitung_Unit!$H$5:$H$104) -> 0 | G27: =SUMPRODUCT(Hitung_Unit!$O$5:$O$104,Hitung_Unit!$M$5:$M$104,Hitung_Unit!$H$5:$H$104) -> 0 | H27: =SUMPRODUCT(Hitung_Unit!$O$5:$O$104,Hitung_Unit!$N$5:$N$104,Hitung_Unit!$H$5:$H$104) -> 0 | I27: =SUMPRODUCT(Hitung_Unit!$O$5:$O$104,Hitung_Unit!$O$5:$O$104-1,Hitung_Unit!$H$5:$H$104) -> 0 | J27: =SUMPRODUCT(Hitung_Unit!$O$5:$O$104,Hitung_Unit!$P$5:$P$104,Hitung_Unit!$H$5:$H$104) -> 0 | K27: =SUMPRODUCT(Hitung_Unit!$O$5:$O$104,Hitung_Unit!$Q$5:$Q$104,Hitung_Unit!$H$5:$H$104) -> 0 | L27: =SUMPRODUCT(Hitung_Unit!$O$5:$O$104,Hitung_Unit!$R$5:$R$104,Hitung_Unit!$H$5:$H$104) -> 0 | M27: =SUMPRODUCT(Hitung_Unit!$O$5:$O$104,Hitung_Unit!$S$5:$S$104,Hitung_Unit!$H$5:$H$104) -> 0 | N27: =SUMPRODUCT(Hitung_Unit!$O$5:$O$104,Hitung_Unit!$T$5:$T$104,Hitung_Unit!$H$5:$H$104) -> 0 | O27: =SUMPRODUCT(Hitung_Unit!$O$5:$O$104,Hitung_Unit!$U$5:$U$104,Hitung_Unit!$H$5:$H$104) -> 0 | P27: =SUMPRODUCT(Hitung_Unit!$O$5:$O$104,Hitung_Unit!$V$5:$V$104,Hitung_Unit!$H$5:$H$104) -> 0 | Q27: =SUMPRODUCT(Hitung_Unit!$O$5:$O$104,Hitung_Unit!$W$5:$W$104,Hitung_Unit!$H$5:$H$104) -> 0 | R27: =SUMPRODUCT(Hitung_Unit!$O$5:$O$104,Hitung_Unit!$X$5:$X$104,Hitung_Unit!$H$5:$H$104) -> 0 | S27: =SUMPRODUCT(Hitung_Unit!$O$5:$O$104,Hitung_Unit!$Y$5:$Y$104,Hitung_Unit!$H$5:$H$104) -> 0 | T27: =SUMPRODUCT(Hitung_Unit!$O$5:$O$104,Hitung_Unit!$Z$5:$Z$104,Hitung_Unit!$H$5:$H$104) -> 0 | U27: =SUMPRODUCT(Hitung_Unit!$O$5:$O$104,Hitung_Unit!$AA$5:$AA$104,Hitung_Unit!$H$5:$H$104) -> 0 | V27: =SUMPRODUCT(Hitung_Unit!$O$5:$O$104,Hitung_Unit!$AB$5:$AB$104,Hitung_Unit!$H$5:$H$104) -> 0 | W27: =SUM(C27:V27) -> 0
A28: 8 | B28: =IF(Input!$H$17="","",Input!$H$17) | C28: =SUMPRODUCT(Hitung_Unit!$P$5:$P$104,Hitung_Unit!$I$5:$I$104,Hitung_Unit!$H$5:$H$104) -> 0 | D28: =SUMPRODUCT(Hitung_Unit!$P$5:$P$104,Hitung_Unit!$J$5:$J$104,Hitung_Unit!$H$5:$H$104) -> 0 | E28: =SUMPRODUCT(Hitung_Unit!$P$5:$P$104,Hitung_Unit!$K$5:$K$104,Hitung_Unit!$H$5:$H$104) -> 0 | F28: =SUMPRODUCT(Hitung_Unit!$P$5:$P$104,Hitung_Unit!$L$5:$L$104,Hitung_Unit!$H$5:$H$104) -> 0 | G28: =SUMPRODUCT(Hitung_Unit!$P$5:$P$104,Hitung_Unit!$M$5:$M$104,Hitung_Unit!$H$5:$H$104) -> 0 | H28: =SUMPRODUCT(Hitung_Unit!$P$5:$P$104,Hitung_Unit!$N$5:$N$104,Hitung_Unit!$H$5:$H$104) -> 0 | I28: =SUMPRODUCT(Hitung_Unit!$P$5:$P$104,Hitung_Unit!$O$5:$O$104,Hitung_Unit!$H$5:$H$104) -> 0 | J28: =SUMPRODUCT(Hitung_Unit!$P$5:$P$104,Hitung_Unit!$P$5:$P$104-1,Hitung_Unit!$H$5:$H$104) -> 0 | K28: =SUMPRODUCT(Hitung_Unit!$P$5:$P$104,Hitung_Unit!$Q$5:$Q$104,Hitung_Unit!$H$5:$H$104) -> 0 | L28: =SUMPRODUCT(Hitung_Unit!$P$5:$P$104,Hitung_Unit!$R$5:$R$104,Hitung_Unit!$H$5:$H$104) -> 0 | M28: =SUMPRODUCT(Hitung_Unit!$P$5:$P$104,Hitung_Unit!$S$5:$S$104,Hitung_Unit!$H$5:$H$104) -> 0 | N28: =SUMPRODUCT(Hitung_Unit!$P$5:$P$104,Hitung_Unit!$T$5:$T$104,Hitung_Unit!$H$5:$H$104) -> 0 | O28: =SUMPRODUCT(Hitung_Unit!$P$5:$P$104,Hitung_Unit!$U$5:$U$104,Hitung_Unit!$H$5:$H$104) -> 0 | P28: =SUMPRODUCT(Hitung_Unit!$P$5:$P$104,Hitung_Unit!$V$5:$V$104,Hitung_Unit!$H$5:$H$104) -> 0 | Q28: =SUMPRODUCT(Hitung_Unit!$P$5:$P$104,Hitung_Unit!$W$5:$W$104,Hitung_Unit!$H$5:$H$104) -> 0 | R28: =SUMPRODUCT(Hitung_Unit!$P$5:$P$104,Hitung_Unit!$X$5:$X$104,Hitung_Unit!$H$5:$H$104) -> 0 | S28: =SUMPRODUCT(Hitung_Unit!$P$5:$P$104,Hitung_Unit!$Y$5:$Y$104,Hitung_Unit!$H$5:$H$104) -> 0 | T28: =SUMPRODUCT(Hitung_Unit!$P$5:$P$104,Hitung_Unit!$Z$5:$Z$104,Hitung_Unit!$H$5:$H$104) -> 0 | U28: =SUMPRODUCT(Hitung_Unit!$P$5:$P$104,Hitung_Unit!$AA$5:$AA$104,Hitung_Unit!$H$5:$H$104) -> 0 | V28: =SUMPRODUCT(Hitung_Unit!$P$5:$P$104,Hitung_Unit!$AB$5:$AB$104,Hitung_Unit!$H$5:$H$104) -> 0 | W28: =SUM(C28:V28) -> 0
A29: 9 | B29: =IF(Input!$H$18="","",Input!$H$18) | C29: =SUMPRODUCT(Hitung_Unit!$Q$5:$Q$104,Hitung_Unit!$I$5:$I$104,Hitung_Unit!$H$5:$H$104) -> 0 | D29: =SUMPRODUCT(Hitung_Unit!$Q$5:$Q$104,Hitung_Unit!$J$5:$J$104,Hitung_Unit!$H$5:$H$104) -> 0 | E29: =SUMPRODUCT(Hitung_Unit!$Q$5:$Q$104,Hitung_Unit!$K$5:$K$104,Hitung_Unit!$H$5:$H$104) -> 0 | F29: =SUMPRODUCT(Hitung_Unit!$Q$5:$Q$104,Hitung_Unit!$L$5:$L$104,Hitung_Unit!$H$5:$H$104) -> 0 | G29: =SUMPRODUCT(Hitung_Unit!$Q$5:$Q$104,Hitung_Unit!$M$5:$M$104,Hitung_Unit!$H$5:$H$104) -> 0 | H29: =SUMPRODUCT(Hitung_Unit!$Q$5:$Q$104,Hitung_Unit!$N$5:$N$104,Hitung_Unit!$H$5:$H$104) -> 0 | I29: =SUMPRODUCT(Hitung_Unit!$Q$5:$Q$104,Hitung_Unit!$O$5:$O$104,Hitung_Unit!$H$5:$H$104) -> 0 | J29: =SUMPRODUCT(Hitung_Unit!$Q$5:$Q$104,Hitung_Unit!$P$5:$P$104,Hitung_Unit!$H$5:$H$104) -> 0 | K29: =SUMPRODUCT(Hitung_Unit!$Q$5:$Q$104,Hitung_Unit!$Q$5:$Q$104-1,Hitung_Unit!$H$5:$H$104) -> 0 | L29: =SUMPRODUCT(Hitung_Unit!$Q$5:$Q$104,Hitung_Unit!$R$5:$R$104,Hitung_Unit!$H$5:$H$104) -> 0 | M29: =SUMPRODUCT(Hitung_Unit!$Q$5:$Q$104,Hitung_Unit!$S$5:$S$104,Hitung_Unit!$H$5:$H$104) -> 0 | N29: =SUMPRODUCT(Hitung_Unit!$Q$5:$Q$104,Hitung_Unit!$T$5:$T$104,Hitung_Unit!$H$5:$H$104) -> 0 | O29: =SUMPRODUCT(Hitung_Unit!$Q$5:$Q$104,Hitung_Unit!$U$5:$U$104,Hitung_Unit!$H$5:$H$104) -> 0 | P29: =SUMPRODUCT(Hitung_Unit!$Q$5:$Q$104,Hitung_Unit!$V$5:$V$104,Hitung_Unit!$H$5:$H$104) -> 0 | Q29: =SUMPRODUCT(Hitung_Unit!$Q$5:$Q$104,Hitung_Unit!$W$5:$W$104,Hitung_Unit!$H$5:$H$104) -> 0 | R29: =SUMPRODUCT(Hitung_Unit!$Q$5:$Q$104,Hitung_Unit!$X$5:$X$104,Hitung_Unit!$H$5:$H$104) -> 0 | S29: =SUMPRODUCT(Hitung_Unit!$Q$5:$Q$104,Hitung_Unit!$Y$5:$Y$104,Hitung_Unit!$H$5:$H$104) -> 0 | T29: =SUMPRODUCT(Hitung_Unit!$Q$5:$Q$104,Hitung_Unit!$Z$5:$Z$104,Hitung_Unit!$H$5:$H$104) -> 0 | U29: =SUMPRODUCT(Hitung_Unit!$Q$5:$Q$104,Hitung_Unit!$AA$5:$AA$104,Hitung_Unit!$H$5:$H$104) -> 0 | V29: =SUMPRODUCT(Hitung_Unit!$Q$5:$Q$104,Hitung_Unit!$AB$5:$AB$104,Hitung_Unit!$H$5:$H$104) -> 0 | W29: =SUM(C29:V29) -> 0
A30: 10 | B30: =IF(Input!$H$19="","",Input!$H$19) | C30: =SUMPRODUCT(Hitung_Unit!$R$5:$R$104,Hitung_Unit!$I$5:$I$104,Hitung_Unit!$H$5:$H$104) -> 0 | D30: =SUMPRODUCT(Hitung_Unit!$R$5:$R$104,Hitung_Unit!$J$5:$J$104,Hitung_Unit!$H$5:$H$104) -> 0 | E30: =SUMPRODUCT(Hitung_Unit!$R$5:$R$104,Hitung_Unit!$K$5:$K$104,Hitung_Unit!$H$5:$H$104) -> 0 | F30: =SUMPRODUCT(Hitung_Unit!$R$5:$R$104,Hitung_Unit!$L$5:$L$104,Hitung_Unit!$H$5:$H$104) -> 0 | G30: =SUMPRODUCT(Hitung_Unit!$R$5:$R$104,Hitung_Unit!$M$5:$M$104,Hitung_Unit!$H$5:$H$104) -> 0 | H30: =SUMPRODUCT(Hitung_Unit!$R$5:$R$104,Hitung_Unit!$N$5:$N$104,Hitung_Unit!$H$5:$H$104) -> 0 | I30: =SUMPRODUCT(Hitung_Unit!$R$5:$R$104,Hitung_Unit!$O$5:$O$104,Hitung_Unit!$H$5:$H$104) -> 0 | J30: =SUMPRODUCT(Hitung_Unit!$R$5:$R$104,Hitung_Unit!$P$5:$P$104,Hitung_Unit!$H$5:$H$104) -> 0 | K30: =SUMPRODUCT(Hitung_Unit!$R$5:$R$104,Hitung_Unit!$Q$5:$Q$104,Hitung_Unit!$H$5:$H$104) -> 0 | L30: =SUMPRODUCT(Hitung_Unit!$R$5:$R$104,Hitung_Unit!$R$5:$R$104-1,Hitung_Unit!$H$5:$H$104) -> 0 | M30: =SUMPRODUCT(Hitung_Unit!$R$5:$R$104,Hitung_Unit!$S$5:$S$104,Hitung_Unit!$H$5:$H$104) -> 0 | N30: =SUMPRODUCT(Hitung_Unit!$R$5:$R$104,Hitung_Unit!$T$5:$T$104,Hitung_Unit!$H$5:$H$104) -> 0 | O30: =SUMPRODUCT(Hitung_Unit!$R$5:$R$104,Hitung_Unit!$U$5:$U$104,Hitung_Unit!$H$5:$H$104) -> 0 | P30: =SUMPRODUCT(Hitung_Unit!$R$5:$R$104,Hitung_Unit!$V$5:$V$104,Hitung_Unit!$H$5:$H$104) -> 0 | Q30: =SUMPRODUCT(Hitung_Unit!$R$5:$R$104,Hitung_Unit!$W$5:$W$104,Hitung_Unit!$H$5:$H$104) -> 0 | R30: =SUMPRODUCT(Hitung_Unit!$R$5:$R$104,Hitung_Unit!$X$5:$X$104,Hitung_Unit!$H$5:$H$104) -> 0 | S30: =SUMPRODUCT(Hitung_Unit!$R$5:$R$104,Hitung_Unit!$Y$5:$Y$104,Hitung_Unit!$H$5:$H$104) -> 0 | T30: =SUMPRODUCT(Hitung_Unit!$R$5:$R$104,Hitung_Unit!$Z$5:$Z$104,Hitung_Unit!$H$5:$H$104) -> 0 | U30: =SUMPRODUCT(Hitung_Unit!$R$5:$R$104,Hitung_Unit!$AA$5:$AA$104,Hitung_Unit!$H$5:$H$104) -> 0 | V30: =SUMPRODUCT(Hitung_Unit!$R$5:$R$104,Hitung_Unit!$AB$5:$AB$104,Hitung_Unit!$H$5:$H$104) -> 0 | W30: =SUM(C30:V30) -> 0
A31: 11 | B31: =IF(Input!$H$20="","",Input!$H$20) | C31: =SUMPRODUCT(Hitung_Unit!$S$5:$S$104,Hitung_Unit!$I$5:$I$104,Hitung_Unit!$H$5:$H$104) -> 0 | D31: =SUMPRODUCT(Hitung_Unit!$S$5:$S$104,Hitung_Unit!$J$5:$J$104,Hitung_Unit!$H$5:$H$104) -> 0 | E31: =SUMPRODUCT(Hitung_Unit!$S$5:$S$104,Hitung_Unit!$K$5:$K$104,Hitung_Unit!$H$5:$H$104) -> 0 | F31: =SUMPRODUCT(Hitung_Unit!$S$5:$S$104,Hitung_Unit!$L$5:$L$104,Hitung_Unit!$H$5:$H$104) -> 0 | G31: =SUMPRODUCT(Hitung_Unit!$S$5:$S$104,Hitung_Unit!$M$5:$M$104,Hitung_Unit!$H$5:$H$104) -> 0 | H31: =SUMPRODUCT(Hitung_Unit!$S$5:$S$104,Hitung_Unit!$N$5:$N$104,Hitung_Unit!$H$5:$H$104) -> 0 | I31: =SUMPRODUCT(Hitung_Unit!$S$5:$S$104,Hitung_Unit!$O$5:$O$104,Hitung_Unit!$H$5:$H$104) -> 0 | J31: =SUMPRODUCT(Hitung_Unit!$S$5:$S$104,Hitung_Unit!$P$5:$P$104,Hitung_Unit!$H$5:$H$104) -> 0 | K31: =SUMPRODUCT(Hitung_Unit!$S$5:$S$104,Hitung_Unit!$Q$5:$Q$104,Hitung_Unit!$H$5:$H$104) -> 0 | L31: =SUMPRODUCT(Hitung_Unit!$S$5:$S$104,Hitung_Unit!$R$5:$R$104,Hitung_Unit!$H$5:$H$104) -> 0 | M31: =SUMPRODUCT(Hitung_Unit!$S$5:$S$104,Hitung_Unit!$S$5:$S$104-1,Hitung_Unit!$H$5:$H$104) -> 0 | N31: =SUMPRODUCT(Hitung_Unit!$S$5:$S$104,Hitung_Unit!$T$5:$T$104,Hitung_Unit!$H$5:$H$104) -> 0 | O31: =SUMPRODUCT(Hitung_Unit!$S$5:$S$104,Hitung_Unit!$U$5:$U$104,Hitung_Unit!$H$5:$H$104) -> 0 | P31: =SUMPRODUCT(Hitung_Unit!$S$5:$S$104,Hitung_Unit!$V$5:$V$104,Hitung_Unit!$H$5:$H$104) -> 0 | Q31: =SUMPRODUCT(Hitung_Unit!$S$5:$S$104,Hitung_Unit!$W$5:$W$104,Hitung_Unit!$H$5:$H$104) -> 0 | R31: =SUMPRODUCT(Hitung_Unit!$S$5:$S$104,Hitung_Unit!$X$5:$X$104,Hitung_Unit!$H$5:$H$104) -> 0 | S31: =SUMPRODUCT(Hitung_Unit!$S$5:$S$104,Hitung_Unit!$Y$5:$Y$104,Hitung_Unit!$H$5:$H$104) -> 0 | T31: =SUMPRODUCT(Hitung_Unit!$S$5:$S$104,Hitung_Unit!$Z$5:$Z$104,Hitung_Unit!$H$5:$H$104) -> 0 | U31: =SUMPRODUCT(Hitung_Unit!$S$5:$S$104,Hitung_Unit!$AA$5:$AA$104,Hitung_Unit!$H$5:$H$104) -> 0 | V31: =SUMPRODUCT(Hitung_Unit!$S$5:$S$104,Hitung_Unit!$AB$5:$AB$104,Hitung_Unit!$H$5:$H$104) -> 0 | W31: =SUM(C31:V31) -> 0
A32: 12 | B32: =IF(Input!$H$21="","",Input!$H$21) | C32: =SUMPRODUCT(Hitung_Unit!$T$5:$T$104,Hitung_Unit!$I$5:$I$104,Hitung_Unit!$H$5:$H$104) -> 0 | D32: =SUMPRODUCT(Hitung_Unit!$T$5:$T$104,Hitung_Unit!$J$5:$J$104,Hitung_Unit!$H$5:$H$104) -> 0 | E32: =SUMPRODUCT(Hitung_Unit!$T$5:$T$104,Hitung_Unit!$K$5:$K$104,Hitung_Unit!$H$5:$H$104) -> 0 | F32: =SUMPRODUCT(Hitung_Unit!$T$5:$T$104,Hitung_Unit!$L$5:$L$104,Hitung_Unit!$H$5:$H$104) -> 0 | G32: =SUMPRODUCT(Hitung_Unit!$T$5:$T$104,Hitung_Unit!$M$5:$M$104,Hitung_Unit!$H$5:$H$104) -> 0 | H32: =SUMPRODUCT(Hitung_Unit!$T$5:$T$104,Hitung_Unit!$N$5:$N$104,Hitung_Unit!$H$5:$H$104) -> 0 | I32: =SUMPRODUCT(Hitung_Unit!$T$5:$T$104,Hitung_Unit!$O$5:$O$104,Hitung_Unit!$H$5:$H$104) -> 0 | J32: =SUMPRODUCT(Hitung_Unit!$T$5:$T$104,Hitung_Unit!$P$5:$P$104,Hitung_Unit!$H$5:$H$104) -> 0 | K32: =SUMPRODUCT(Hitung_Unit!$T$5:$T$104,Hitung_Unit!$Q$5:$Q$104,Hitung_Unit!$H$5:$H$104) -> 0 | L32: =SUMPRODUCT(Hitung_Unit!$T$5:$T$104,Hitung_Unit!$R$5:$R$104,Hitung_Unit!$H$5:$H$104) -> 0 | M32: =SUMPRODUCT(Hitung_Unit!$T$5:$T$104,Hitung_Unit!$S$5:$S$104,Hitung_Unit!$H$5:$H$104) -> 0 | N32: =SUMPRODUCT(Hitung_Unit!$T$5:$T$104,Hitung_Unit!$T$5:$T$104-1,Hitung_Unit!$H$5:$H$104) -> 0 | O32: =SUMPRODUCT(Hitung_Unit!$T$5:$T$104,Hitung_Unit!$U$5:$U$104,Hitung_Unit!$H$5:$H$104) -> 0 | P32: =SUMPRODUCT(Hitung_Unit!$T$5:$T$104,Hitung_Unit!$V$5:$V$104,Hitung_Unit!$H$5:$H$104) -> 0 | Q32: =SUMPRODUCT(Hitung_Unit!$T$5:$T$104,Hitung_Unit!$W$5:$W$104,Hitung_Unit!$H$5:$H$104) -> 0 | R32: =SUMPRODUCT(Hitung_Unit!$T$5:$T$104,Hitung_Unit!$X$5:$X$104,Hitung_Unit!$H$5:$H$104) -> 0 | S32: =SUMPRODUCT(Hitung_Unit!$T$5:$T$104,Hitung_Unit!$Y$5:$Y$104,Hitung_Unit!$H$5:$H$104) -> 0 | T32: =SUMPRODUCT(Hitung_Unit!$T$5:$T$104,Hitung_Unit!$Z$5:$Z$104,Hitung_Unit!$H$5:$H$104) -> 0 | U32: =SUMPRODUCT(Hitung_Unit!$T$5:$T$104,Hitung_Unit!$AA$5:$AA$104,Hitung_Unit!$H$5:$H$104) -> 0 | V32: =SUMPRODUCT(Hitung_Unit!$T$5:$T$104,Hitung_Unit!$AB$5:$AB$104,Hitung_Unit!$H$5:$H$104) -> 0 | W32: =SUM(C32:V32) -> 0
A33: 13 | B33: =IF(Input!$H$22="","",Input!$H$22) | C33: =SUMPRODUCT(Hitung_Unit!$U$5:$U$104,Hitung_Unit!$I$5:$I$104,Hitung_Unit!$H$5:$H$104) -> 0 | D33: =SUMPRODUCT(Hitung_Unit!$U$5:$U$104,Hitung_Unit!$J$5:$J$104,Hitung_Unit!$H$5:$H$104) -> 0 | E33: =SUMPRODUCT(Hitung_Unit!$U$5:$U$104,Hitung_Unit!$K$5:$K$104,Hitung_Unit!$H$5:$H$104) -> 0 | F33: =SUMPRODUCT(Hitung_Unit!$U$5:$U$104,Hitung_Unit!$L$5:$L$104,Hitung_Unit!$H$5:$H$104) -> 0 | G33: =SUMPRODUCT(Hitung_Unit!$U$5:$U$104,Hitung_Unit!$M$5:$M$104,Hitung_Unit!$H$5:$H$104) -> 0 | H33: =SUMPRODUCT(Hitung_Unit!$U$5:$U$104,Hitung_Unit!$N$5:$N$104,Hitung_Unit!$H$5:$H$104) -> 0 | I33: =SUMPRODUCT(Hitung_Unit!$U$5:$U$104,Hitung_Unit!$O$5:$O$104,Hitung_Unit!$H$5:$H$104) -> 0 | J33: =SUMPRODUCT(Hitung_Unit!$U$5:$U$104,Hitung_Unit!$P$5:$P$104,Hitung_Unit!$H$5:$H$104) -> 0 | K33: =SUMPRODUCT(Hitung_Unit!$U$5:$U$104,Hitung_Unit!$Q$5:$Q$104,Hitung_Unit!$H$5:$H$104) -> 0 | L33: =SUMPRODUCT(Hitung_Unit!$U$5:$U$104,Hitung_Unit!$R$5:$R$104,Hitung_Unit!$H$5:$H$104) -> 0 | M33: =SUMPRODUCT(Hitung_Unit!$U$5:$U$104,Hitung_Unit!$S$5:$S$104,Hitung_Unit!$H$5:$H$104) -> 0 | N33: =SUMPRODUCT(Hitung_Unit!$U$5:$U$104,Hitung_Unit!$T$5:$T$104,Hitung_Unit!$H$5:$H$104) -> 0 | O33: =SUMPRODUCT(Hitung_Unit!$U$5:$U$104,Hitung_Unit!$U$5:$U$104-1,Hitung_Unit!$H$5:$H$104) -> 0 | P33: =SUMPRODUCT(Hitung_Unit!$U$5:$U$104,Hitung_Unit!$V$5:$V$104,Hitung_Unit!$H$5:$H$104) -> 0 | Q33: =SUMPRODUCT(Hitung_Unit!$U$5:$U$104,Hitung_Unit!$W$5:$W$104,Hitung_Unit!$H$5:$H$104) -> 0 | R33: =SUMPRODUCT(Hitung_Unit!$U$5:$U$104,Hitung_Unit!$X$5:$X$104,Hitung_Unit!$H$5:$H$104) -> 0 | S33: =SUMPRODUCT(Hitung_Unit!$U$5:$U$104,Hitung_Unit!$Y$5:$Y$104,Hitung_Unit!$H$5:$H$104) -> 0 | T33: =SUMPRODUCT(Hitung_Unit!$U$5:$U$104,Hitung_Unit!$Z$5:$Z$104,Hitung_Unit!$H$5:$H$104) -> 0 | U33: =SUMPRODUCT(Hitung_Unit!$U$5:$U$104,Hitung_Unit!$AA$5:$AA$104,Hitung_Unit!$H$5:$H$104) -> 0 | V33: =SUMPRODUCT(Hitung_Unit!$U$5:$U$104,Hitung_Unit!$AB$5:$AB$104,Hitung_Unit!$H$5:$H$104) -> 0 | W33: =SUM(C33:V33) -> 0
A34: 14 | B34: =IF(Input!$H$23="","",Input!$H$23) | C34: =SUMPRODUCT(Hitung_Unit!$V$5:$V$104,Hitung_Unit!$I$5:$I$104,Hitung_Unit!$H$5:$H$104) -> 0 | D34: =SUMPRODUCT(Hitung_Unit!$V$5:$V$104,Hitung_Unit!$J$5:$J$104,Hitung_Unit!$H$5:$H$104) -> 0 | E34: =SUMPRODUCT(Hitung_Unit!$V$5:$V$104,Hitung_Unit!$K$5:$K$104,Hitung_Unit!$H$5:$H$104) -> 0 | F34: =SUMPRODUCT(Hitung_Unit!$V$5:$V$104,Hitung_Unit!$L$5:$L$104,Hitung_Unit!$H$5:$H$104) -> 0 | G34: =SUMPRODUCT(Hitung_Unit!$V$5:$V$104,Hitung_Unit!$M$5:$M$104,Hitung_Unit!$H$5:$H$104) -> 0 | H34: =SUMPRODUCT(Hitung_Unit!$V$5:$V$104,Hitung_Unit!$N$5:$N$104,Hitung_Unit!$H$5:$H$104) -> 0 | I34: =SUMPRODUCT(Hitung_Unit!$V$5:$V$104,Hitung_Unit!$O$5:$O$104,Hitung_Unit!$H$5:$H$104) -> 0 | J34: =SUMPRODUCT(Hitung_Unit!$V$5:$V$104,Hitung_Unit!$P$5:$P$104,Hitung_Unit!$H$5:$H$104) -> 0 | K34: =SUMPRODUCT(Hitung_Unit!$V$5:$V$104,Hitung_Unit!$Q$5:$Q$104,Hitung_Unit!$H$5:$H$104) -> 0 | L34: =SUMPRODUCT(Hitung_Unit!$V$5:$V$104,Hitung_Unit!$R$5:$R$104,Hitung_Unit!$H$5:$H$104) -> 0 | M34: =SUMPRODUCT(Hitung_Unit!$V$5:$V$104,Hitung_Unit!$S$5:$S$104,Hitung_Unit!$H$5:$H$104) -> 0 | N34: =SUMPRODUCT(Hitung_Unit!$V$5:$V$104,Hitung_Unit!$T$5:$T$104,Hitung_Unit!$H$5:$H$104) -> 0 | O34: =SUMPRODUCT(Hitung_Unit!$V$5:$V$104,Hitung_Unit!$U$5:$U$104,Hitung_Unit!$H$5:$H$104) -> 0 | P34: =SUMPRODUCT(Hitung_Unit!$V$5:$V$104,Hitung_Unit!$V$5:$V$104-1,Hitung_Unit!$H$5:$H$104) -> 0 | Q34: =SUMPRODUCT(Hitung_Unit!$V$5:$V$104,Hitung_Unit!$W$5:$W$104,Hitung_Unit!$H$5:$H$104) -> 0 | R34: =SUMPRODUCT(Hitung_Unit!$V$5:$V$104,Hitung_Unit!$X$5:$X$104,Hitung_Unit!$H$5:$H$104) -> 0 | S34: =SUMPRODUCT(Hitung_Unit!$V$5:$V$104,Hitung_Unit!$Y$5:$Y$104,Hitung_Unit!$H$5:$H$104) -> 0 | T34: =SUMPRODUCT(Hitung_Unit!$V$5:$V$104,Hitung_Unit!$Z$5:$Z$104,Hitung_Unit!$H$5:$H$104) -> 0 | U34: =SUMPRODUCT(Hitung_Unit!$V$5:$V$104,Hitung_Unit!$AA$5:$AA$104,Hitung_Unit!$H$5:$H$104) -> 0 | V34: =SUMPRODUCT(Hitung_Unit!$V$5:$V$104,Hitung_Unit!$AB$5:$AB$104,Hitung_Unit!$H$5:$H$104) -> 0 | W34: =SUM(C34:V34) -> 0
A35: 15 | B35: =IF(Input!$H$24="","",Input!$H$24) | C35: =SUMPRODUCT(Hitung_Unit!$W$5:$W$104,Hitung_Unit!$I$5:$I$104,Hitung_Unit!$H$5:$H$104) -> 0 | D35: =SUMPRODUCT(Hitung_Unit!$W$5:$W$104,Hitung_Unit!$J$5:$J$104,Hitung_Unit!$H$5:$H$104) -> 0 | E35: =SUMPRODUCT(Hitung_Unit!$W$5:$W$104,Hitung_Unit!$K$5:$K$104,Hitung_Unit!$H$5:$H$104) -> 0 | F35: =SUMPRODUCT(Hitung_Unit!$W$5:$W$104,Hitung_Unit!$L$5:$L$104,Hitung_Unit!$H$5:$H$104) -> 0 | G35: =SUMPRODUCT(Hitung_Unit!$W$5:$W$104,Hitung_Unit!$M$5:$M$104,Hitung_Unit!$H$5:$H$104) -> 0 | H35: =SUMPRODUCT(Hitung_Unit!$W$5:$W$104,Hitung_Unit!$N$5:$N$104,Hitung_Unit!$H$5:$H$104) -> 0 | I35: =SUMPRODUCT(Hitung_Unit!$W$5:$W$104,Hitung_Unit!$O$5:$O$104,Hitung_Unit!$H$5:$H$104) -> 0 | J35: =SUMPRODUCT(Hitung_Unit!$W$5:$W$104,Hitung_Unit!$P$5:$P$104,Hitung_Unit!$H$5:$H$104) -> 0 | K35: =SUMPRODUCT(Hitung_Unit!$W$5:$W$104,Hitung_Unit!$Q$5:$Q$104,Hitung_Unit!$H$5:$H$104) -> 0 | L35: =SUMPRODUCT(Hitung_Unit!$W$5:$W$104,Hitung_Unit!$R$5:$R$104,Hitung_Unit!$H$5:$H$104) -> 0 | M35: =SUMPRODUCT(Hitung_Unit!$W$5:$W$104,Hitung_Unit!$S$5:$S$104,Hitung_Unit!$H$5:$H$104) -> 0 | N35: =SUMPRODUCT(Hitung_Unit!$W$5:$W$104,Hitung_Unit!$T$5:$T$104,Hitung_Unit!$H$5:$H$104) -> 0 | O35: =SUMPRODUCT(Hitung_Unit!$W$5:$W$104,Hitung_Unit!$U$5:$U$104,Hitung_Unit!$H$5:$H$104) -> 0 | P35: =SUMPRODUCT(Hitung_Unit!$W$5:$W$104,Hitung_Unit!$V$5:$V$104,Hitung_Unit!$H$5:$H$104) -> 0 | Q35: =SUMPRODUCT(Hitung_Unit!$W$5:$W$104,Hitung_Unit!$W$5:$W$104-1,Hitung_Unit!$H$5:$H$104) -> 0 | R35: =SUMPRODUCT(Hitung_Unit!$W$5:$W$104,Hitung_Unit!$X$5:$X$104,Hitung_Unit!$H$5:$H$104) -> 0 | S35: =SUMPRODUCT(Hitung_Unit!$W$5:$W$104,Hitung_Unit!$Y$5:$Y$104,Hitung_Unit!$H$5:$H$104) -> 0 | T35: =SUMPRODUCT(Hitung_Unit!$W$5:$W$104,Hitung_Unit!$Z$5:$Z$104,Hitung_Unit!$H$5:$H$104) -> 0 | U35: =SUMPRODUCT(Hitung_Unit!$W$5:$W$104,Hitung_Unit!$AA$5:$AA$104,Hitung_Unit!$H$5:$H$104) -> 0 | V35: =SUMPRODUCT(Hitung_Unit!$W$5:$W$104,Hitung_Unit!$AB$5:$AB$104,Hitung_Unit!$H$5:$H$104) -> 0 | W35: =SUM(C35:V35) -> 0
A36: 16 | B36: =IF(Input!$H$25="","",Input!$H$25) | C36: =SUMPRODUCT(Hitung_Unit!$X$5:$X$104,Hitung_Unit!$I$5:$I$104,Hitung_Unit!$H$5:$H$104) -> 0 | D36: =SUMPRODUCT(Hitung_Unit!$X$5:$X$104,Hitung_Unit!$J$5:$J$104,Hitung_Unit!$H$5:$H$104) -> 0 | E36: =SUMPRODUCT(Hitung_Unit!$X$5:$X$104,Hitung_Unit!$K$5:$K$104,Hitung_Unit!$H$5:$H$104) -> 0 | F36: =SUMPRODUCT(Hitung_Unit!$X$5:$X$104,Hitung_Unit!$L$5:$L$104,Hitung_Unit!$H$5:$H$104) -> 0 | G36: =SUMPRODUCT(Hitung_Unit!$X$5:$X$104,Hitung_Unit!$M$5:$M$104,Hitung_Unit!$H$5:$H$104) -> 0 | H36: =SUMPRODUCT(Hitung_Unit!$X$5:$X$104,Hitung_Unit!$N$5:$N$104,Hitung_Unit!$H$5:$H$104) -> 0 | I36: =SUMPRODUCT(Hitung_Unit!$X$5:$X$104,Hitung_Unit!$O$5:$O$104,Hitung_Unit!$H$5:$H$104) -> 0 | J36: =SUMPRODUCT(Hitung_Unit!$X$5:$X$104,Hitung_Unit!$P$5:$P$104,Hitung_Unit!$H$5:$H$104) -> 0 | K36: =SUMPRODUCT(Hitung_Unit!$X$5:$X$104,Hitung_Unit!$Q$5:$Q$104,Hitung_Unit!$H$5:$H$104) -> 0 | L36: =SUMPRODUCT(Hitung_Unit!$X$5:$X$104,Hitung_Unit!$R$5:$R$104,Hitung_Unit!$H$5:$H$104) -> 0 | M36: =SUMPRODUCT(Hitung_Unit!$X$5:$X$104,Hitung_Unit!$S$5:$S$104,Hitung_Unit!$H$5:$H$104) -> 0 | N36: =SUMPRODUCT(Hitung_Unit!$X$5:$X$104,Hitung_Unit!$T$5:$T$104,Hitung_Unit!$H$5:$H$104) -> 0 | O36: =SUMPRODUCT(Hitung_Unit!$X$5:$X$104,Hitung_Unit!$U$5:$U$104,Hitung_Unit!$H$5:$H$104) -> 0 | P36: =SUMPRODUCT(Hitung_Unit!$X$5:$X$104,Hitung_Unit!$V$5:$V$104,Hitung_Unit!$H$5:$H$104) -> 0 | Q36: =SUMPRODUCT(Hitung_Unit!$X$5:$X$104,Hitung_Unit!$W$5:$W$104,Hitung_Unit!$H$5:$H$104) -> 0 | R36: =SUMPRODUCT(Hitung_Unit!$X$5:$X$104,Hitung_Unit!$X$5:$X$104-1,Hitung_Unit!$H$5:$H$104) -> 0 | S36: =SUMPRODUCT(Hitung_Unit!$X$5:$X$104,Hitung_Unit!$Y$5:$Y$104,Hitung_Unit!$H$5:$H$104) -> 0 | T36: =SUMPRODUCT(Hitung_Unit!$X$5:$X$104,Hitung_Unit!$Z$5:$Z$104,Hitung_Unit!$H$5:$H$104) -> 0 | U36: =SUMPRODUCT(Hitung_Unit!$X$5:$X$104,Hitung_Unit!$AA$5:$AA$104,Hitung_Unit!$H$5:$H$104) -> 0 | V36: =SUMPRODUCT(Hitung_Unit!$X$5:$X$104,Hitung_Unit!$AB$5:$AB$104,Hitung_Unit!$H$5:$H$104) -> 0 | W36: =SUM(C36:V36) -> 0
A37: 17 | B37: =IF(Input!$H$26="","",Input!$H$26) | C37: =SUMPRODUCT(Hitung_Unit!$Y$5:$Y$104,Hitung_Unit!$I$5:$I$104,Hitung_Unit!$H$5:$H$104) -> 0 | D37: =SUMPRODUCT(Hitung_Unit!$Y$5:$Y$104,Hitung_Unit!$J$5:$J$104,Hitung_Unit!$H$5:$H$104) -> 0 | E37: =SUMPRODUCT(Hitung_Unit!$Y$5:$Y$104,Hitung_Unit!$K$5:$K$104,Hitung_Unit!$H$5:$H$104) -> 0 | F37: =SUMPRODUCT(Hitung_Unit!$Y$5:$Y$104,Hitung_Unit!$L$5:$L$104,Hitung_Unit!$H$5:$H$104) -> 0 | G37: =SUMPRODUCT(Hitung_Unit!$Y$5:$Y$104,Hitung_Unit!$M$5:$M$104,Hitung_Unit!$H$5:$H$104) -> 0 | H37: =SUMPRODUCT(Hitung_Unit!$Y$5:$Y$104,Hitung_Unit!$N$5:$N$104,Hitung_Unit!$H$5:$H$104) -> 0 | I37: =SUMPRODUCT(Hitung_Unit!$Y$5:$Y$104,Hitung_Unit!$O$5:$O$104,Hitung_Unit!$H$5:$H$104) -> 0 | J37: =SUMPRODUCT(Hitung_Unit!$Y$5:$Y$104,Hitung_Unit!$P$5:$P$104,Hitung_Unit!$H$5:$H$104) -> 0 | K37: =SUMPRODUCT(Hitung_Unit!$Y$5:$Y$104,Hitung_Unit!$Q$5:$Q$104,Hitung_Unit!$H$5:$H$104) -> 0 | L37: =SUMPRODUCT(Hitung_Unit!$Y$5:$Y$104,Hitung_Unit!$R$5:$R$104,Hitung_Unit!$H$5:$H$104) -> 0 | M37: =SUMPRODUCT(Hitung_Unit!$Y$5:$Y$104,Hitung_Unit!$S$5:$S$104,Hitung_Unit!$H$5:$H$104) -> 0 | N37: =SUMPRODUCT(Hitung_Unit!$Y$5:$Y$104,Hitung_Unit!$T$5:$T$104,Hitung_Unit!$H$5:$H$104) -> 0 | O37: =SUMPRODUCT(Hitung_Unit!$Y$5:$Y$104,Hitung_Unit!$U$5:$U$104,Hitung_Unit!$H$5:$H$104) -> 0 | P37: =SUMPRODUCT(Hitung_Unit!$Y$5:$Y$104,Hitung_Unit!$V$5:$V$104,Hitung_Unit!$H$5:$H$104) -> 0 | Q37: =SUMPRODUCT(Hitung_Unit!$Y$5:$Y$104,Hitung_Unit!$W$5:$W$104,Hitung_Unit!$H$5:$H$104) -> 0 | R37: =SUMPRODUCT(Hitung_Unit!$Y$5:$Y$104,Hitung_Unit!$X$5:$X$104,Hitung_Unit!$H$5:$H$104) -> 0 | S37: =SUMPRODUCT(Hitung_Unit!$Y$5:$Y$104,Hitung_Unit!$Y$5:$Y$104-1,Hitung_Unit!$H$5:$H$104) -> 0 | T37: =SUMPRODUCT(Hitung_Unit!$Y$5:$Y$104,Hitung_Unit!$Z$5:$Z$104,Hitung_Unit!$H$5:$H$104) -> 0 | U37: =SUMPRODUCT(Hitung_Unit!$Y$5:$Y$104,Hitung_Unit!$AA$5:$AA$104,Hitung_Unit!$H$5:$H$104) -> 0 | V37: =SUMPRODUCT(Hitung_Unit!$Y$5:$Y$104,Hitung_Unit!$AB$5:$AB$104,Hitung_Unit!$H$5:$H$104) -> 0 | W37: =SUM(C37:V37) -> 0
A38: 18 | B38: =IF(Input!$H$27="","",Input!$H$27) | C38: =SUMPRODUCT(Hitung_Unit!$Z$5:$Z$104,Hitung_Unit!$I$5:$I$104,Hitung_Unit!$H$5:$H$104) -> 0 | D38: =SUMPRODUCT(Hitung_Unit!$Z$5:$Z$104,Hitung_Unit!$J$5:$J$104,Hitung_Unit!$H$5:$H$104) -> 0 | E38: =SUMPRODUCT(Hitung_Unit!$Z$5:$Z$104,Hitung_Unit!$K$5:$K$104,Hitung_Unit!$H$5:$H$104) -> 0 | F38: =SUMPRODUCT(Hitung_Unit!$Z$5:$Z$104,Hitung_Unit!$L$5:$L$104,Hitung_Unit!$H$5:$H$104) -> 0 | G38: =SUMPRODUCT(Hitung_Unit!$Z$5:$Z$104,Hitung_Unit!$M$5:$M$104,Hitung_Unit!$H$5:$H$104) -> 0 | H38: =SUMPRODUCT(Hitung_Unit!$Z$5:$Z$104,Hitung_Unit!$N$5:$N$104,Hitung_Unit!$H$5:$H$104) -> 0 | I38: =SUMPRODUCT(Hitung_Unit!$Z$5:$Z$104,Hitung_Unit!$O$5:$O$104,Hitung_Unit!$H$5:$H$104) -> 0 | J38: =SUMPRODUCT(Hitung_Unit!$Z$5:$Z$104,Hitung_Unit!$P$5:$P$104,Hitung_Unit!$H$5:$H$104) -> 0 | K38: =SUMPRODUCT(Hitung_Unit!$Z$5:$Z$104,Hitung_Unit!$Q$5:$Q$104,Hitung_Unit!$H$5:$H$104) -> 0 | L38: =SUMPRODUCT(Hitung_Unit!$Z$5:$Z$104,Hitung_Unit!$R$5:$R$104,Hitung_Unit!$H$5:$H$104) -> 0 | M38: =SUMPRODUCT(Hitung_Unit!$Z$5:$Z$104,Hitung_Unit!$S$5:$S$104,Hitung_Unit!$H$5:$H$104) -> 0 | N38: =SUMPRODUCT(Hitung_Unit!$Z$5:$Z$104,Hitung_Unit!$T$5:$T$104,Hitung_Unit!$H$5:$H$104) -> 0 | O38: =SUMPRODUCT(Hitung_Unit!$Z$5:$Z$104,Hitung_Unit!$U$5:$U$104,Hitung_Unit!$H$5:$H$104) -> 0 | P38: =SUMPRODUCT(Hitung_Unit!$Z$5:$Z$104,Hitung_Unit!$V$5:$V$104,Hitung_Unit!$H$5:$H$104) -> 0 | Q38: =SUMPRODUCT(Hitung_Unit!$Z$5:$Z$104,Hitung_Unit!$W$5:$W$104,Hitung_Unit!$H$5:$H$104) -> 0 | R38: =SUMPRODUCT(Hitung_Unit!$Z$5:$Z$104,Hitung_Unit!$X$5:$X$104,Hitung_Unit!$H$5:$H$104) -> 0 | S38: =SUMPRODUCT(Hitung_Unit!$Z$5:$Z$104,Hitung_Unit!$Y$5:$Y$104,Hitung_Unit!$H$5:$H$104) -> 0 | T38: =SUMPRODUCT(Hitung_Unit!$Z$5:$Z$104,Hitung_Unit!$Z$5:$Z$104-1,Hitung_Unit!$H$5:$H$104) -> 0 | U38: =SUMPRODUCT(Hitung_Unit!$Z$5:$Z$104,Hitung_Unit!$AA$5:$AA$104,Hitung_Unit!$H$5:$H$104) -> 0 | V38: =SUMPRODUCT(Hitung_Unit!$Z$5:$Z$104,Hitung_Unit!$AB$5:$AB$104,Hitung_Unit!$H$5:$H$104) -> 0 | W38: =SUM(C38:V38) -> 0
